<mujoco model="humanoid">
  <compiler angle="degree" inertiafromgeom="true" coordinate="global"/>
  <include file="./common/materials.xml"/>
  <visual>
    <headlight ambient=".4 .4 .4" diffuse=".8 .8 .8" specular="0.1 0.1 0.1"/>
    <map znear=".01"/>
    <quality shadowsize="2048"/>
  </visual>
  <default>
    <joint damping="0.0" armature="0.01" stiffness="0.0" limited="true"/>
    <geom conaffinity="7" condim="1" contype="7" margin="0.001" material="self" rgba="0.8 0.6 .4 1"/>
  </default>
  <statistic extent="3" center="0 0 1"/>
  <option timestep="0.00222222222"/>
  <asset>
    <texture type="skybox" file="./common/sky1.png" gridsize="3 4" gridlayout=".U..LFRB.D.." width="8192" height="8192"/>
    <texture builtin="flat" height="1278" mark="cross" markrgb="1 1 1" name="texgeom" random="0.01" rgb1=".8 .6 .4" rgb2=".8 .6 .4" type="cube" width="127"/>
  </asset>
  <worldbody>
    <light cutoff="100" diffuse="1 1 1" dir="-0 0 -1.3" directional="true" exponent="1" pos="0 0 1.3" specular=".1 .1 .1"/>
    <geom condim="3" friction="1. .1 .1" material="grid" name="floor" pos="0 0 0" rgba=".8 .9 .8 1" size="100 100 .2" type="plane"/>
    <body name="Hips" pos="0.0000 0.0000 1.0000" user="0.0000 0.0003 1.0000">
      <joint armature="0" damping="0" limited="false" name="Hips" pos="0.0000 0.0000 1.0000" stiffness="0" type="free"/>
      <geom pos="0.0000 0.0000 0.9780" size="0.0950" type="sphere"/>
      <body name="RightUpLeg" pos="-0.1272 0.0000 1.0000" user="-0.1272 -0.4343 1.0000">
        <joint axis="0.0000 0.0000 1.0000" name="RightUpLeg_z" pos="-0.1272 0.0000 1.0000" range="-1800.0 1800.0" type="hinge"/>
        <joint axis="1.0000 0.0000 0.0000" name="RightUpLeg_x" pos="-0.1272 0.0000 1.0000" range="-1800.0 1800.0" type="hinge"/>
        <joint axis="0.0000 1.0000 0.0000" name="RightUpLeg_y" pos="-0.1272 0.0000 1.0000" range="-1800.0 1800.0" type="hinge"/>
        <geom contype="1" conaffinity="1" fromto="-0.1272 -0.0200 1.0000 -0.1272 -0.4143 1.0000" size="0.0490" type="capsule"/>
        <body name="RightLeg" pos="-0.1272 -0.4343 1.0000" user="-0.1272 -0.8831 1.0000">
          <joint axis="1.0000 0.0000 0.0000" name="RightLeg_x" pos="-0.1272 -0.4343 1.0000" range="-1800.0 1800.0" type="hinge"/>
          <geom contype="1" conaffinity="1" fromto="-0.1272 -0.4543 1.0000 -0.1272 -0.8631 1.0000" size="0.0400" type="capsule"/>
          <body name="RightFoot" pos="-0.1272 -0.8831 1.0000" user="-0.1272 -0.8831 1.1515">
            <geom contype="1" conaffinity="1" pos="-0.1272 -0.8831 1.0477" size="0.0620 0.0300 0.1000" quat="0.9952 -0.0871 0.0038 -0.0435" type="box"/>
            <joint axis="0.0000 0.0000 1.0000" name="RightFoot_z" pos="-0.1272 -0.8831 1.0000" range="-1800.0 1800.0" type="hinge"/>
            <joint axis="1.0000 0.0000 0.0000" name="RightFoot_x" pos="-0.1272 -0.8831 1.0000" range="-1800.0 1800.0" type="hinge"/>
            <joint axis="0.0000 1.0000 0.0000" name="RightFoot_y" pos="-0.1272 -0.8831 1.0000" range="-1800.0 1800.0" type="hinge"/>
          </body>
        </body>
      </body>
      <body name="LeftUpLeg" pos="0.1272 0.0000 1.0000" user="0.1272 -0.4343 1.0000">
            <joint axis="0.0000 0.0000 1.0000" name="LeftUpLeg_z" pos="0.1272 0.0000 1.0000" range="-1800.0 1800.0" type="hinge"/>
            <joint axis="1.0000 0.0000 0.0000" name="LeftUpLeg_x" pos="0.1272 0.0000 1.0000" range="-1800.0 1800.0" type="hinge"/>
            <joint axis="0.0000 1.0000 0.0000" name="LeftUpLeg_y" pos="0.1272 0.0000 1.0000" range="-1800.0 1800.0" type="hinge"/>
            <geom contype="2" conaffinity="2" fromto="0.1272 -0.0200 1.0000 0.1272 -0.4143 1.0000" size="0.0490" type="capsule"/>
            <body name="LeftLeg" pos="0.1272 -0.4343 1.0000" user="0.1272 -0.8831 1.0000">
            <joint axis="1.0000 0.0000 0.0000" name="LeftLeg_x" pos="0.1272 -0.4343 1.0000" range="-1800.0 1800.0" type="hinge"/>
            <geom contype="2" conaffinity="2" fromto="0.1272 -0.4543 1.0000 0.1272 -0.8631 1.0000" size="0.0400" type="capsule"/>
            <body name="LeftFoot" pos="0.1272 -0.8831 1.0000" user="0.1272 -0.8831 1.1515">
                <geom contype="2" conaffinity="2" pos="0.1272 -0.8831 1.0477" size="0.0620 0.0300 0.1000" quat="0.9952 -0.0871 -0.0038 0.0435" type="box"/>
                <joint axis="0.0000 0.0000 1.0000" name="LeftFoot_z" pos="0.1272 -0.8831 1.0000" range="-1800.0 1800.0" type="hinge"/>
                <joint axis="1.0000 0.0000 0.0000" name="LeftFoot_x" pos="0.1272 -0.8831 1.0000" range="-1800.0 1800.0" type="hinge"/>
                <joint axis="0.0000 1.0000 0.0000" name="LeftFoot_y" pos="0.1272 -0.8831 1.0000" range="-1800.0 1800.0" type="hinge"/>
            </body>
        </body>
      </body>
      <body name="Spine" pos="0.0000 0.0010 1.0000" user="0.0000 0.2469 1.0000">
        <geom fromto="-0.0700 0.1240 1.0000 0.0700 0.1240 1.0000" size="0.0450" type="capsule"/>
        <geom fromto="-0.0700 0.2160 1.0000 0.0700 0.2160 1.0000" size="0.0450" type="capsule"/>
        <joint axis="0.0000 0.0000 1.0000" name="Spine_z" pos="0.0000 0.0010 1.0000" range="-1800.0 1800.0" type="hinge"/>
        <joint axis="1.0000 0.0000 0.0000" name="Spine_x" pos="0.0000 0.0010 1.0000" range="-1800.0 1800.0" type="hinge"/>
        <joint axis="0.0000 1.0000 0.0000" name="Spine_y" pos="0.0000 0.0010 1.0000" range="-1800.0 1800.0" type="hinge"/>
        <body name="Spine1" pos="0.0000 0.2469 1.0000" user="0.0000 0.4954 1.0000">
          <geom fromto="-0.0700 0.3091 1.0000 0.0700 0.3091 1.0000" size="0.0450" type="capsule"/>
          <geom fromto="-0.0700 0.4011 1.0000 0.0700 0.4011 1.0000" size="0.0450" type="capsule"/>
          <joint axis="0.0000 0.0000 1.0000" name="Spine1_z" pos="0.0000 0.2469 1.0000" range="-1800.0 1800.0" type="hinge"/>
          <joint axis="1.0000 0.0000 0.0000" name="Spine1_x" pos="0.0000 0.2469 1.0000" range="-1800.0 1800.0" type="hinge"/>
          <joint axis="0.0000 1.0000 0.0000" name="Spine1_y" pos="0.0000 0.2469 1.0000" range="-1800.0 1800.0" type="hinge"/>
          <body name="Neck" pos="0.0000 0.4954 1.0000" user="0.0000 0.5881 1.0000">
            <joint axis="0.0000 0.0000 1.0000" name="Neck_z" pos="0.0000 0.4954 1.0000" range="-1800.0 1800.0" type="hinge"/>
            <joint axis="1.0000 0.0000 0.0000" name="Neck_x" pos="0.0000 0.4954 1.0000" range="-1800.0 1800.0" type="hinge"/>
            <joint axis="0.0000 1.0000 0.0000" name="Neck_y" pos="0.0000 0.4954 1.0000" range="-1800.0 1800.0" type="hinge"/>
            <geom fromto="0.0000 0.4754 1.0000 0.0000 0.5281 1.0000" size="0.0300" type="capsule"/>
            <body name="Head" pos="0.0000 0.5881 1.0000" user="0.0000 0.7031 1.0000">
              <geom pos="0.0000 0.6401 0.9660" size="0.0750" type="sphere"/>
              <joint axis="0.0000 0.0000 1.0000" name="Head_z" pos="0.0000 0.5881 1.0000" range="-1800.0 1800.0" type="hinge"/>
              <joint axis="1.0000 0.0000 0.0000" name="Head_x" pos="0.0000 0.5881 1.0000" range="-1800.0 1800.0" type="hinge"/>
              <joint axis="0.0000 1.0000 0.0000" name="Head_y" pos="0.0000 0.5881 1.0000" range="-1800.0 1800.0" type="hinge"/>
            </body>
          </body>
          <body name="LeftShoulder" pos="0.0000 0.4954 1.0000" user="0.0000 0.6203 1.0000">
            <joint axis="0.0000 0.0000 1.0000" name="LeftShoulder_z" pos="0.0000 0.4954 1.0000" range="-1800.0 1800.0" type="hinge"/>
            <joint axis="1.0000 0.0000 0.0000" name="LeftShoulder_x" pos="0.0000 0.4954 1.0000" range="-1800.0 1800.0" type="hinge"/>
            <joint axis="0.0000 1.0000 0.0000" name="LeftShoulder_y" pos="0.0000 0.4954 1.0000" range="-1800.0 1800.0" type="hinge"/>
            <geom fromto="0.0000 0.5154 1.0000 0.0000 0.6003 1.0000" size="0.0400" type="capsule"/>
            <body name="LeftArm" pos="0.0000 0.6203 1.0000" user="0.0000 0.8800 1.0000">
              <joint axis="0.0000 0.0000 1.0000" name="LeftArm_z" pos="0.0000 0.6203 1.0000" range="-1800.0 1800.0" type="hinge"/>
              <joint axis="1.0000 0.0000 0.0000" name="LeftArm_x" pos="0.0000 0.6203 1.0000" range="-1800.0 1800.0" type="hinge"/>
              <joint axis="0.0000 1.0000 0.0000" name="LeftArm_y" pos="0.0000 0.6203 1.0000" range="-1800.0 1800.0" type="hinge"/>
              <geom fromto="0.0000 0.6403 1.0000 0.0000 0.8600 1.0000" size="0.0340" type="capsule"/>
              <body name="LeftForeArm" pos="0.0000 0.8800 1.0000" user="0.0000 1.1256 1.0000">
                <joint axis="1.0000 0.0000 0.0000" name="LeftForeArm_x" pos="0.0000 0.8800 1.0000" range="-1800.0 1800.0" type="hinge"/>
                <geom fromto="0.0000 0.9000 1.0000 0.0000 1.1056 1.0000" size="0.0300" type="capsule"/>
                <body name="LeftHand" pos="0.0000 1.1256 1.0000" user="0.0000 1.1256 1.0000">
                  <geom pos="0.0000 1.1256 1.0000" size="0.0400" type="sphere"/>
                  <joint axis="0.0000 0.0000 1.0000" name="LeftHand_z" pos="0.0000 1.1256 1.0000" range="-1800.0 1800.0" type="hinge"/>
                  <joint axis="1.0000 0.0000 0.0000" name="LeftHand_x" pos="0.0000 1.1256 1.0000" range="-1800.0 1800.0" type="hinge"/>
                  <joint axis="0.0000 1.0000 0.0000" name="LeftHand_y" pos="0.0000 1.1256 1.0000" range="-1800.0 1800.0" type="hinge"/>
                </body>
              </body>
            </body>
          </body>
          <body name="RightShoulder" pos="-0.0000 0.4954 1.0000" user="0.0000 0.6203 1.0000">
            <joint axis="0.0000 0.0000 1.0000" name="RightShoulder_z" pos="0.0000 0.4954 1.0000" range="-1800.0 1800.0" type="hinge"/>
            <joint axis="1.0000 0.0000 0.0000" name="RightShoulder_x" pos="0.0000 0.4954 1.0000" range="-1800.0 1800.0" type="hinge"/>
            <joint axis="0.0000 1.0000 0.0000" name="RightShoulder_y" pos="0.0000 0.4954 1.0000" range="-1800.0 1800.0" type="hinge"/>
            <geom fromto="-0.0000 0.5154 1.0000 -0.0000 0.6003 1.0000" size="0.0400" type="capsule"/>
            <body name="RightArm" pos="-0.0000 0.6203 1.0000" user="0.0000 0.8800 1.0000">
              <joint axis="0.0000 0.0000 1.0000" name="RightArm_z" pos="0.0000 0.6203 1.0000" range="-1800.0 1800.0" type="hinge"/>
              <joint axis="1.0000 0.0000 0.0000" name="RightArm_x" pos="0.0000 0.6203 1.0000" range="-1800.0 1800.0" type="hinge"/>
              <joint axis="0.0000 1.0000 0.0000" name="RightArm_y" pos="0.0000 0.6203 1.0000" range="-1800.0 1800.0" type="hinge"/>
              <geom fromto="-0.0000 0.6403 1.0000 -0.0000 0.8600 1.0000" size="0.0340" type="capsule"/>
              <body name="RightForeArm" pos="-0.0000 0.8800 1.0000" user="0.0000 1.1256 1.0000">
                <joint axis="1.0000 0.0000 0.0000" name="RightForeArm_x" pos="0.0000 0.8800 1.0000" range="-1800.0 1800.0" type="hinge"/>
                <geom fromto="-0.0000 0.9000 1.0000 -0.0000 1.1056 1.0000" size="0.0300" type="capsule"/>
                <body name="RightHand" pos="-0.0000 1.1256 1.0000" user="0.0000 1.1256 1.0000">
                  <geom pos="-0.0000 1.1256 1.0000" size="0.0400" type="sphere"/>
                  <joint axis="0.0000 0.0000 1.0000" name="RightHand_z" pos="0.0000 1.1256 1.0000" range="-1800.0 1800.0" type="hinge"/>
                  <joint axis="1.0000 0.0000 0.0000" name="RightHand_x" pos="0.0000 1.1256 1.0000" range="-1800.0 1800.0" type="hinge"/>
                  <joint axis="0.0000 1.0000 0.0000" name="RightHand_y" pos="0.0000 1.1256 1.0000" range="-1800.0 1800.0" type="hinge"/>
                </body>
              </body>
            </body>
          </body>
        </body>
      </body>
    </body>
  </worldbody>
  <actuator>
    <motor gear="1" joint="RightUpLeg_z" name="RightUpLeg_z"/>
    <motor gear="1" joint="RightUpLeg_x" name="RightUpLeg_x"/>
    <motor gear="1" joint="RightUpLeg_y" name="RightUpLeg_y"/>
    <motor gear="1" joint="RightLeg_x" name="RightLeg_x"/>
    <motor gear="1" joint="RightFoot_z" name="RightFoot_z"/>
    <motor gear="1" joint="RightFoot_x" name="RightFoot_x"/>
    <motor gear="1" joint="RightFoot_y" name="RightFoot_y"/>
    <motor gear="1" joint="LeftUpLeg_z" name="LeftUpLeg_z"/>
    <motor gear="1" joint="LeftUpLeg_x" name="LeftUpLeg_x"/>
    <motor gear="1" joint="LeftUpLeg_y" name="LeftUpLeg_y"/>
    <motor gear="1" joint="LeftLeg_x" name="LeftLeg_x"/>
    <motor gear="1" joint="LeftFoot_z" name="LeftFoot_z"/>
    <motor gear="1" joint="LeftFoot_x" name="LeftFoot_x"/>
    <motor gear="1" joint="LeftFoot_y" name="LeftFoot_y"/>
    <motor gear="1" joint="Spine_z" name="Spine_z"/>
    <motor gear="1" joint="Spine_x" name="Spine_x"/>
    <motor gear="1" joint="Spine_y" name="Spine_y"/>
    <motor gear="1" joint="Spine1_z" name="Spine1_z"/>
    <motor gear="1" joint="Spine1_x" name="Spine1_x"/>
    <motor gear="1" joint="Spine1_y" name="Spine1_y"/>
    <motor gear="1" joint="Neck_z" name="Neck_z"/>
    <motor gear="1" joint="Neck_x" name="Neck_x"/>
    <motor gear="1" joint="Neck_y" name="Neck_y"/>
    <motor gear="1" joint="Head_z" name="Head_z"/>
    <motor gear="1" joint="Head_x" name="Head_x"/>
    <motor gear="1" joint="Head_y" name="Head_y"/>
    <motor gear="1" joint="LeftShoulder_z" name="LeftShoulder_z"/>
    <motor gear="1" joint="LeftShoulder_x" name="LeftShoulder_x"/>
    <motor gear="1" joint="LeftShoulder_y" name="LeftShoulder_y"/>
    <motor gear="1" joint="LeftArm_z" name="LeftArm_z"/>
    <motor gear="1" joint="LeftArm_x" name="LeftArm_x"/>
    <motor gear="1" joint="LeftArm_y" name="LeftArm_y"/>
    <motor gear="1" joint="LeftForeArm_x" name="LeftForeArm_x"/>
    <motor gear="1" joint="LeftHand_z" name="LeftHand_z"/>
    <motor gear="1" joint="LeftHand_x" name="LeftHand_x"/>
    <motor gear="1" joint="LeftHand_y" name="LeftHand_y"/>
    <motor gear="1" joint="RightShoulder_z" name="RightShoulder_z"/>
    <motor gear="1" joint="RightShoulder_x" name="RightShoulder_x"/>
    <motor gear="1" joint="RightShoulder_y" name="RightShoulder_y"/>
    <motor gear="1" joint="RightArm_z" name="RightArm_z"/>
    <motor gear="1" joint="RightArm_x" name="RightArm_x"/>
    <motor gear="1" joint="RightArm_y" name="RightArm_y"/>
    <motor gear="1" joint="RightForeArm_x" name="RightForeArm_x"/>
    <motor gear="1" joint="RightHand_z" name="RightHand_z"/>
    <motor gear="1" joint="RightHand_x" name="RightHand_x"/>
    <motor gear="1" joint="RightHand_y" name="RightHand_y"/>
  </actuator>
</mujoco>
