<mujoco model="humanoid">
  <compiler angle="degree" inertiafromgeom="true" coordinate="global"/>
  <include file="./common/materials.xml"/>
  <size njmax="8000" nconmax="4000"/>
  <visual>
    <headlight ambient=".4 .4 .4" diffuse=".8 .8 .8" specular="0.1 0.1 0.1"/>
    <map znear=".01"/>
    <quality shadowsize="2048"/>
  </visual>
  <default>
    <joint damping="0.0" armature="0.01" stiffness="0.0" limited="true"/>
    <geom conaffinity="7" condim="1" contype="7" margin="0.001" material="self" rgba="0.8 0.6 .4 1"/>
  </default>
  <statistic extent="3" center="0 0 1"/>
  <option timestep="0.00222222222"/>
  <asset>
    <texture type="skybox" file="./common/sky1.png" gridsize="3 4" gridlayout=".U..LFRB.D.." width="8192" height="8192"/>
    <texture builtin="flat" height="1278" mark="cross" markrgb="1 1 1" name="texgeom" random="0.01" rgb1=".8 .6 .4" rgb2=".8 .6 .4" type="cube" width="127"/>
  </asset>
  <worldbody>
    <light cutoff="100" diffuse="1 1 1" dir="-0 0 -1.3" directional="true" exponent="1" pos="0 0 1.3" specular=".1 .1 .1"/>
    <geom condim="3" friction="1. .1 .1" material="grid" name="floor" pos="0 0 0" rgba=".8 .9 .8 1" size="100 100 .2" type="plane"/>
    <body name="Hips" pos="0.0000 0.0000 1.0000" user="-0.0001 -0.0251 0.9883">
      <joint name="Hips" pos="0.0000 0.0000 1.0000" limited="false" type="free" armature="0" damping="0" stiffness="0"/>
      <geom size="0.0300" type="sphere" pos="0.0000 0.0000 1.0000"/>
      <body name="LeftUpLeg" pos="0.0714 -0.0896 0.9920" user="0.1020 -0.4538 0.9853">
        <joint name="LeftUpLeg_z" type="hinge" pos="0.0714 -0.0896 0.9920" axis="0.0000 0.0000 1.0000" range="-180.0000 180.0000"/>
        <joint name="LeftUpLeg_x" type="hinge" pos="0.0714 -0.0896 0.9920" axis="1.0000 0.0000 0.0000" range="-180.0000 180.0000"/>
        <joint name="LeftUpLeg_y" type="hinge" pos="0.0714 -0.0896 0.9920" axis="0.0000 1.0000 0.0000" range="-180.0000 180.0000"/>
        <geom size="0.0300" type="capsule" fromto="0.0730 -0.1095 0.9916 0.1004 -0.4339 0.9856"/>
        <body name="LeftLeg" pos="0.1020 -0.4538 0.9853" user="0.0905 -0.8371 0.9418">
          <joint name="LeftLeg_z" type="hinge" pos="0.1020 -0.4538 0.9853" axis="0.0000 0.0000 1.0000" range="-180.0000 180.0000"/>
          <joint name="LeftLeg_x" type="hinge" pos="0.1020 -0.4538 0.9853" axis="1.0000 0.0000 0.0000" range="-180.0000 180.0000"/>
          <joint name="LeftLeg_y" type="hinge" pos="0.1020 -0.4538 0.9853" axis="0.0000 1.0000 0.0000" range="-180.0000 180.0000"/>
          <geom size="0.0300" type="capsule" fromto="0.1014 -0.4737 0.9830 0.0911 -0.8173 0.9440"/>
          <body name="LeftFoot" pos="0.0905 -0.8371 0.9418" user="0.1138 -0.8918 1.0561">
            <joint name="LeftFoot_z" type="hinge" pos="0.0905 -0.8371 0.9418" axis="0.0000 0.0000 1.0000" range="-180.0000 180.0000"/>
            <joint name="LeftFoot_x" type="hinge" pos="0.0905 -0.8371 0.9418" axis="1.0000 0.0000 0.0000" range="-180.0000 180.0000"/>
            <joint name="LeftFoot_y" type="hinge" pos="0.0905 -0.8371 0.9418" axis="0.0000 1.0000 0.0000" range="-180.0000 180.0000"/>
            <geom size="0.0300" type="capsule" fromto="0.0941 -0.8456 0.9595 0.1102 -0.8833 1.0384"/>
            <body name="LeftToe" pos="0.1138 -0.8918 1.0561" user="0.1138 -0.8918 1.0561">
              <joint name="LeftToe_z" type="hinge" pos="0.1138 -0.8918 1.0561" axis="0.0000 0.0000 1.0000" range="-180.0000 180.0000"/>
              <joint name="LeftToe_x" type="hinge" pos="0.1138 -0.8918 1.0561" axis="1.0000 0.0000 0.0000" range="-180.0000 180.0000"/>
              <joint name="LeftToe_y" type="hinge" pos="0.1138 -0.8918 1.0561" axis="0.0000 1.0000 0.0000" range="-180.0000 180.0000"/>
              <geom size="0.0300" type="capsule" fromto="0.1138 -0.8918 1.0601 0.1138 -0.8918 1.0521"/>
            </body>
          </body>
        </body>
      </body>
      <body name="RightUpLeg" pos="-0.0690 -0.0890 0.9952" user="-0.1052 -0.4596 0.9860">
        <joint name="RightUpLeg_z" type="hinge" pos="-0.0690 -0.0890 0.9952" axis="0.0000 0.0000 1.0000" range="-180.0000 180.0000"/>
        <joint name="RightUpLeg_x" type="hinge" pos="-0.0690 -0.0890 0.9952" axis="1.0000 0.0000 0.0000" range="-180.0000 180.0000"/>
        <joint name="RightUpLeg_y" type="hinge" pos="-0.0690 -0.0890 0.9952" axis="0.0000 1.0000 0.0000" range="-180.0000 180.0000"/>
        <geom size="0.0300" type="capsule" fromto="-0.0710 -0.1089 0.9947 -0.1032 -0.4397 0.9865"/>
        <body name="RightLeg" pos="-0.1052 -0.4596 0.9860" user="-0.0911 -0.8432 0.9441">
          <joint name="RightLeg_z" type="hinge" pos="-0.1052 -0.4596 0.9860" axis="0.0000 0.0000 1.0000" range="-180.0000 180.0000"/>
          <joint name="RightLeg_x" type="hinge" pos="-0.1052 -0.4596 0.9860" axis="1.0000 0.0000 0.0000" range="-180.0000 180.0000"/>
          <joint name="RightLeg_y" type="hinge" pos="-0.1052 -0.4596 0.9860" axis="0.0000 1.0000 0.0000" range="-180.0000 180.0000"/>
          <geom size="0.0300" type="capsule" fromto="-0.1044 -0.4795 0.9838 -0.0919 -0.8234 0.9463"/>
          <body name="RightFoot" pos="-0.0911 -0.8432 0.9441" user="-0.1132 -0.8897 1.0620">
            <joint name="RightFoot_z" type="hinge" pos="-0.0911 -0.8432 0.9441" axis="0.0000 0.0000 1.0000" range="-180.0000 180.0000"/>
            <joint name="RightFoot_x" type="hinge" pos="-0.0911 -0.8432 0.9441" axis="1.0000 0.0000 0.0000" range="-180.0000 180.0000"/>
            <joint name="RightFoot_y" type="hinge" pos="-0.0911 -0.8432 0.9441" axis="0.0000 1.0000 0.0000" range="-180.0000 180.0000"/>
            <geom size="0.0300" type="capsule" fromto="-0.0946 -0.8505 0.9625 -0.1098 -0.8824 1.0437"/>
            <body name="RightToe" pos="-0.1132 -0.8897 1.0620" user="-0.1132 -0.8897 1.0620">
              <joint name="RightToe_z" type="hinge" pos="-0.1132 -0.8897 1.0620" axis="0.0000 0.0000 1.0000" range="-180.0000 180.0000"/>
              <joint name="RightToe_x" type="hinge" pos="-0.1132 -0.8897 1.0620" axis="1.0000 0.0000 0.0000" range="-180.0000 180.0000"/>
              <joint name="RightToe_y" type="hinge" pos="-0.1132 -0.8897 1.0620" axis="0.0000 1.0000 0.0000" range="-180.0000 180.0000"/>
              <geom size="0.0300" type="capsule" fromto="-0.1132 -0.8897 1.0660 -0.1132 -0.8897 1.0580"/>
            </body>
          </body>
        </body>
      </body>
      <body name="Spine" pos="-0.0025 0.1033 0.9778" user="0.0011 0.2309 0.9761">
        <joint name="Spine_z" type="hinge" pos="-0.0025 0.1033 0.9778" axis="0.0000 0.0000 1.0000" range="-180.0000 180.0000"/>
        <joint name="Spine_x" type="hinge" pos="-0.0025 0.1033 0.9778" axis="1.0000 0.0000 0.0000" range="-180.0000 180.0000"/>
        <joint name="Spine_y" type="hinge" pos="-0.0025 0.1033 0.9778" axis="0.0000 1.0000 0.0000" range="-180.0000 180.0000"/>
        <geom size="0.0300" type="capsule" fromto="-0.0019 0.1232 0.9775 0.0005 0.2109 0.9764"/>
        <body name="Spine1" pos="0.0011 0.2309 0.9761" user="0.0031 0.2800 1.0040">
          <joint name="Spine1_z" type="hinge" pos="0.0011 0.2309 0.9761" axis="0.0000 0.0000 1.0000" range="-180.0000 180.0000"/>
          <joint name="Spine1_x" type="hinge" pos="0.0011 0.2309 0.9761" axis="1.0000 0.0000 0.0000" range="-180.0000 180.0000"/>
          <joint name="Spine1_y" type="hinge" pos="0.0011 0.2309 0.9761" axis="0.0000 1.0000 0.0000" range="-180.0000 180.0000"/>
          <geom size="0.0300" type="capsule" fromto="0.0018 0.2483 0.9860 0.0024 0.2626 0.9941"/>
          <body name="Spine2" pos="0.0031 0.2800 1.0040" user="0.0019 0.4272 0.9612">
            <joint name="Spine2_z" type="hinge" pos="0.0031 0.2800 1.0040" axis="0.0000 0.0000 1.0000" range="-180.0000 180.0000"/>
            <joint name="Spine2_x" type="hinge" pos="0.0031 0.2800 1.0040" axis="1.0000 0.0000 0.0000" range="-180.0000 180.0000"/>
            <joint name="Spine2_y" type="hinge" pos="0.0031 0.2800 1.0040" axis="0.0000 1.0000 0.0000" range="-180.0000 180.0000"/>
            <geom size="0.0300" type="capsule" fromto="0.0029 0.2992 0.9984 0.0020 0.4080 0.9667"/>
            <body name="Neck" pos="0.0011 0.4882 0.9542" user="0.0047 0.5506 1.0044">
              <joint name="Neck_z" type="hinge" pos="0.0011 0.4882 0.9542" axis="0.0000 0.0000 1.0000" range="-180.0000 180.0000"/>
              <joint name="Neck_x" type="hinge" pos="0.0011 0.4882 0.9542" axis="1.0000 0.0000 0.0000" range="-180.0000 180.0000"/>
              <joint name="Neck_y" type="hinge" pos="0.0011 0.4882 0.9542" axis="0.0000 1.0000 0.0000" range="-180.0000 180.0000"/>
              <geom size="0.0300" type="capsule" fromto="0.0020 0.5038 0.9667 0.0038 0.5350 0.9919"/>
              <body name="Mouth" pos="0.0047 0.5506 1.0044" user="0.0047 0.5506 1.0044">
                <joint name="Mouth_z" type="hinge" pos="0.0047 0.5506 1.0044" axis="0.0000 0.0000 1.0000" range="-180.0000 180.0000"/>
                <joint name="Mouth_x" type="hinge" pos="0.0047 0.5506 1.0044" axis="1.0000 0.0000 0.0000" range="-180.0000 180.0000"/>
                <joint name="Mouth_y" type="hinge" pos="0.0047 0.5506 1.0044" axis="0.0000 1.0000 0.0000" range="-180.0000 180.0000"/>
                <geom size="0.0300" type="capsule" fromto="0.0047 0.5506 1.0084 0.0047 0.5506 1.0004"/>
              </body>
            </body>
            <body name="LeftChest" pos="0.0784 0.3978 0.9671" user="0.1637 0.4295 0.9598">
              <joint name="LeftChest_z" type="hinge" pos="0.0784 0.3978 0.9671" axis="0.0000 0.0000 1.0000" range="-180.0000 180.0000"/>
              <joint name="LeftChest_x" type="hinge" pos="0.0784 0.3978 0.9671" axis="1.0000 0.0000 0.0000" range="-180.0000 180.0000"/>
              <joint name="LeftChest_y" type="hinge" pos="0.0784 0.3978 0.9671" axis="0.0000 1.0000 0.0000" range="-180.0000 180.0000"/>
              <geom size="0.0300" type="capsule" fromto="0.0971 0.4047 0.9655 0.1450 0.4226 0.9614"/>
              <body name="LeftShoulder" pos="0.1637 0.4295 0.9598" user="0.4150 0.4175 0.9323">
                <joint name="LeftShoulder_z" type="hinge" pos="0.1637 0.4295 0.9598" axis="0.0000 0.0000 1.0000" range="-180.0000 180.0000"/>
                <joint name="LeftShoulder_x" type="hinge" pos="0.1637 0.4295 0.9598" axis="1.0000 0.0000 0.0000" range="-180.0000 180.0000"/>
                <joint name="LeftShoulder_y" type="hinge" pos="0.1637 0.4295 0.9598" axis="0.0000 1.0000 0.0000" range="-180.0000 180.0000"/>
                <geom size="0.0300" type="capsule" fromto="0.1836 0.4286 0.9576 0.3951 0.4185 0.9345"/>
                <body name="LeftArm" pos="0.4150 0.4175 0.9323" user="0.6530 0.4265 0.9323">
                  <joint name="LeftArm_z" type="hinge" pos="0.4150 0.4175 0.9323" axis="0.0000 0.0000 1.0000" range="-180.0000 180.0000"/>
                  <joint name="LeftArm_x" type="hinge" pos="0.4150 0.4175 0.9323" axis="1.0000 0.0000 0.0000" range="-180.0000 180.0000"/>
                  <joint name="LeftArm_y" type="hinge" pos="0.4150 0.4175 0.9323" axis="0.0000 1.0000 0.0000" range="-180.0000 180.0000"/>
                  <geom size="0.0300" type="capsule" fromto="0.4349 0.4183 0.9323 0.6330 0.4258 0.9323"/>
                  <body name="LeftWrist" pos="0.6530 0.4265 0.9323" user="0.7326 0.4169 0.9191">
                    <joint name="LeftWrist_z" type="hinge" pos="0.6530 0.4265 0.9323" axis="0.0000 0.0000 1.0000" range="-180.0000 180.0000"/>
                    <joint name="LeftWrist_x" type="hinge" pos="0.6530 0.4265 0.9323" axis="1.0000 0.0000 0.0000" range="-180.0000 180.0000"/>
                    <joint name="LeftWrist_y" type="hinge" pos="0.6530 0.4265 0.9323" axis="0.0000 1.0000 0.0000" range="-180.0000 180.0000"/>
                    <geom size="0.0300" type="capsule" fromto="0.6726 0.4242 0.9291 0.7131 0.4192 0.9224"/>
                    <body name="LeftHand" pos="0.7326 0.4169 0.9191" user="0.7326 0.4169 0.9191">
                      <joint name="LeftHand_z" type="hinge" pos="0.7326 0.4169 0.9191" axis="0.0000 0.0000 1.0000" range="-180.0000 180.0000"/>
                      <joint name="LeftHand_x" type="hinge" pos="0.7326 0.4169 0.9191" axis="1.0000 0.0000 0.0000" range="-180.0000 180.0000"/>
                      <joint name="LeftHand_y" type="hinge" pos="0.7326 0.4169 0.9191" axis="0.0000 1.0000 0.0000" range="-180.0000 180.0000"/>
                      <geom size="0.0300" type="capsule" fromto="0.7326 0.4169 0.9231 0.7326 0.4169 0.9151"/>
                    </body>
                  </body>
                </body>
              </body>
            </body>
            <body name="RightChest" pos="-0.0739 0.3956 0.9622" user="-0.1631 0.4284 0.9524">
              <joint name="RightChest_z" type="hinge" pos="-0.0739 0.3956 0.9622" axis="0.0000 0.0000 1.0000" range="-180.0000 180.0000"/>
              <joint name="RightChest_x" type="hinge" pos="-0.0739 0.3956 0.9622" axis="1.0000 0.0000 0.0000" range="-180.0000 180.0000"/>
              <joint name="RightChest_y" type="hinge" pos="-0.0739 0.3956 0.9622" axis="0.0000 1.0000 0.0000" range="-180.0000 180.0000"/>
              <geom size="0.0300" type="capsule" fromto="-0.0926 0.4025 0.9601 -0.1445 0.4215 0.9544"/>
              <body name="RightShoulder" pos="-0.1631 0.4284 0.9524" user="-0.4091 0.4152 0.9322">
                <joint name="RightShoulder_z" type="hinge" pos="-0.1631 0.4284 0.9524" axis="0.0000 0.0000 1.0000" range="-180.0000 180.0000"/>
                <joint name="RightShoulder_x" type="hinge" pos="-0.1631 0.4284 0.9524" axis="1.0000 0.0000 0.0000" range="-180.0000 180.0000"/>
                <joint name="RightShoulder_y" type="hinge" pos="-0.1631 0.4284 0.9524" axis="0.0000 1.0000 0.0000" range="-180.0000 180.0000"/>
                <geom size="0.0300" type="capsule" fromto="-0.1830 0.4273 0.9507 -0.3892 0.4163 0.9338"/>
                <body name="RightArm" pos="-0.4091 0.4152 0.9322" user="-0.6543 0.4238 0.9287">
                  <joint name="RightArm_z" type="hinge" pos="-0.4091 0.4152 0.9322" axis="0.0000 0.0000 1.0000" range="-180.0000 180.0000"/>
                  <joint name="RightArm_x" type="hinge" pos="-0.4091 0.4152 0.9322" axis="1.0000 0.0000 0.0000" range="-180.0000 180.0000"/>
                  <joint name="RightArm_y" type="hinge" pos="-0.4091 0.4152 0.9322" axis="0.0000 1.0000 0.0000" range="-180.0000 180.0000"/>
                  <geom size="0.0300" type="capsule" fromto="-0.4291 0.4159 0.9319 -0.6343 0.4231 0.9290"/>
                  <body name="RightWrist" pos="-0.6543 0.4238 0.9287" user="-0.7347 0.4166 0.9182">
                    <joint name="RightWrist_z" type="hinge" pos="-0.6543 0.4238 0.9287" axis="0.0000 0.0000 1.0000" range="-180.0000 180.0000"/>
                    <joint name="RightWrist_x" type="hinge" pos="-0.6543 0.4238 0.9287" axis="1.0000 0.0000 0.0000" range="-180.0000 180.0000"/>
                    <joint name="RightWrist_y" type="hinge" pos="-0.6543 0.4238 0.9287" axis="0.0000 1.0000 0.0000" range="-180.0000 180.0000"/>
                    <geom size="0.0300" type="capsule" fromto="-0.6741 0.4221 0.9261 -0.7149 0.4184 0.9208"/>
                    <body name="RightHand" pos="-0.7347 0.4166 0.9182" user="-0.7347 0.4166 0.9182">
                      <joint name="RightHand_z" type="hinge" pos="-0.7347 0.4166 0.9182" axis="0.0000 0.0000 1.0000" range="-180.0000 180.0000"/>
                      <joint name="RightHand_x" type="hinge" pos="-0.7347 0.4166 0.9182" axis="1.0000 0.0000 0.0000" range="-180.0000 180.0000"/>
                      <joint name="RightHand_y" type="hinge" pos="-0.7347 0.4166 0.9182" axis="0.0000 1.0000 0.0000" range="-180.0000 180.0000"/>
                      <geom size="0.0300" type="capsule" fromto="-0.7347 0.4166 0.9222 -0.7347 0.4166 0.9142"/>
                    </body>
                  </body>
                </body>
              </body>
            </body>
          </body>
        </body>
      </body>
    </body>
  </worldbody>
  <actuator>
    <motor name="LeftUpLeg_z" joint="LeftUpLeg_z" gear="1"/>
    <motor name="LeftUpLeg_x" joint="LeftUpLeg_x" gear="1"/>
    <motor name="LeftUpLeg_y" joint="LeftUpLeg_y" gear="1"/>
    <motor name="LeftLeg_z" joint="LeftLeg_z" gear="1"/>
    <motor name="LeftLeg_x" joint="LeftLeg_x" gear="1"/>
    <motor name="LeftLeg_y" joint="LeftLeg_y" gear="1"/>
    <motor name="LeftFoot_z" joint="LeftFoot_z" gear="1"/>
    <motor name="LeftFoot_x" joint="LeftFoot_x" gear="1"/>
    <motor name="LeftFoot_y" joint="LeftFoot_y" gear="1"/>
    <motor name="LeftToe_z" joint="LeftToe_z" gear="1"/>
    <motor name="LeftToe_x" joint="LeftToe_x" gear="1"/>
    <motor name="LeftToe_y" joint="LeftToe_y" gear="1"/>
    <motor name="RightUpLeg_z" joint="RightUpLeg_z" gear="1"/>
    <motor name="RightUpLeg_x" joint="RightUpLeg_x" gear="1"/>
    <motor name="RightUpLeg_y" joint="RightUpLeg_y" gear="1"/>
    <motor name="RightLeg_z" joint="RightLeg_z" gear="1"/>
    <motor name="RightLeg_x" joint="RightLeg_x" gear="1"/>
    <motor name="RightLeg_y" joint="RightLeg_y" gear="1"/>
    <motor name="RightFoot_z" joint="RightFoot_z" gear="1"/>
    <motor name="RightFoot_x" joint="RightFoot_x" gear="1"/>
    <motor name="RightFoot_y" joint="RightFoot_y" gear="1"/>
    <motor name="RightToe_z" joint="RightToe_z" gear="1"/>
    <motor name="RightToe_x" joint="RightToe_x" gear="1"/>
    <motor name="RightToe_y" joint="RightToe_y" gear="1"/>
    <motor name="Spine_z" joint="Spine_z" gear="1"/>
    <motor name="Spine_x" joint="Spine_x" gear="1"/>
    <motor name="Spine_y" joint="Spine_y" gear="1"/>
    <motor name="Spine1_z" joint="Spine1_z" gear="1"/>
    <motor name="Spine1_x" joint="Spine1_x" gear="1"/>
    <motor name="Spine1_y" joint="Spine1_y" gear="1"/>
    <motor name="Spine2_z" joint="Spine2_z" gear="1"/>
    <motor name="Spine2_x" joint="Spine2_x" gear="1"/>
    <motor name="Spine2_y" joint="Spine2_y" gear="1"/>
    <motor name="Neck_z" joint="Neck_z" gear="1"/>
    <motor name="Neck_x" joint="Neck_x" gear="1"/>
    <motor name="Neck_y" joint="Neck_y" gear="1"/>
    <motor name="Mouth_z" joint="Mouth_z" gear="1"/>
    <motor name="Mouth_x" joint="Mouth_x" gear="1"/>
    <motor name="Mouth_y" joint="Mouth_y" gear="1"/>
    <motor name="LeftChest_z" joint="LeftChest_z" gear="1"/>
    <motor name="LeftChest_x" joint="LeftChest_x" gear="1"/>
    <motor name="LeftChest_y" joint="LeftChest_y" gear="1"/>
    <motor name="LeftShoulder_z" joint="LeftShoulder_z" gear="1"/>
    <motor name="LeftShoulder_x" joint="LeftShoulder_x" gear="1"/>
    <motor name="LeftShoulder_y" joint="LeftShoulder_y" gear="1"/>
    <motor name="LeftArm_z" joint="LeftArm_z" gear="1"/>
    <motor name="LeftArm_x" joint="LeftArm_x" gear="1"/>
    <motor name="LeftArm_y" joint="LeftArm_y" gear="1"/>
    <motor name="LeftWrist_z" joint="LeftWrist_z" gear="1"/>
    <motor name="LeftWrist_x" joint="LeftWrist_x" gear="1"/>
    <motor name="LeftWrist_y" joint="LeftWrist_y" gear="1"/>
    <motor name="LeftHand_z" joint="LeftHand_z" gear="1"/>
    <motor name="LeftHand_x" joint="LeftHand_x" gear="1"/>
    <motor name="LeftHand_y" joint="LeftHand_y" gear="1"/>
    <motor name="RightChest_z" joint="RightChest_z" gear="1"/>
    <motor name="RightChest_x" joint="RightChest_x" gear="1"/>
    <motor name="RightChest_y" joint="RightChest_y" gear="1"/>
    <motor name="RightShoulder_z" joint="RightShoulder_z" gear="1"/>
    <motor name="RightShoulder_x" joint="RightShoulder_x" gear="1"/>
    <motor name="RightShoulder_y" joint="RightShoulder_y" gear="1"/>
    <motor name="RightArm_z" joint="RightArm_z" gear="1"/>
    <motor name="RightArm_x" joint="RightArm_x" gear="1"/>
    <motor name="RightArm_y" joint="RightArm_y" gear="1"/>
    <motor name="RightWrist_z" joint="RightWrist_z" gear="1"/>
    <motor name="RightWrist_x" joint="RightWrist_x" gear="1"/>
    <motor name="RightWrist_y" joint="RightWrist_y" gear="1"/>
    <motor name="RightHand_z" joint="RightHand_z" gear="1"/>
    <motor name="RightHand_x" joint="RightHand_x" gear="1"/>
    <motor name="RightHand_y" joint="RightHand_y" gear="1"/>
  </actuator>
</mujoco>
