<mujoco model="humanoid">
  <compiler angle="degree" inertiafromgeom="true" coordinate="global"/>
  <include file="./common/materials.xml"/>
  <visual>
    <headlight ambient=".4 .4 .4" diffuse=".8 .8 .8" specular="0.1 0.1 0.1"/>
    <map znear=".01"/>
    <quality shadowsize="2048"/>
  </visual>
  <default>
    <joint damping="0.0" armature="0.01" stiffness="0.0" limited="true"/>
    <geom conaffinity="7" condim="1" contype="7" margin="0.001" material="self" rgba="0.8 0.6 .4 1"/>
  </default>
  <statistic extent="3" center="0 0 1"/>
  <option timestep="0.00222222222">
    <flag contact="disable"/>
  </option>
  <size njmax="1000"/>
  <asset>
    <texture type="skybox" file="./common/sky1.png" gridsize="3 4" gridlayout=".U..LFRB.D.." width="8192" height="8192"/>
    <texture builtin="flat" height="1278" mark="cross" markrgb="1 1 1" name="texgeom" random="0.01" rgb1=".8 .6 .4" rgb2=".8 .6 .4" type="cube" width="127"/>
    <mesh file="./geom/Hips.stl"/>
    <mesh file="./geom/LeftUpLeg.stl"/>
    <mesh file="./geom/RightUpLeg.stl"/>
    <mesh file="./geom/Spine.stl"/>
    <mesh file="./geom/LeftLeg.stl"/>
    <mesh file="./geom/RightLeg.stl"/>
    <mesh file="./geom/Spine1.stl"/>
    <mesh file="./geom/LeftFoot.stl"/>
    <mesh file="./geom/RightFoot.stl"/>
    <mesh file="./geom/Spine2.stl"/>
    <mesh file="./geom/LeftToe.stl"/>
    <mesh file="./geom/RightToe.stl"/>
    <mesh file="./geom/Neck.stl"/>
    <mesh file="./geom/LeftChest.stl"/>
    <mesh file="./geom/RightChest.stl"/>
    <mesh file="./geom/Mouth.stl"/>
    <mesh file="./geom/LeftShoulder.stl"/>
    <mesh file="./geom/RightShoulder.stl"/>
    <mesh file="./geom/LeftArm.stl"/>
    <mesh file="./geom/RightArm.stl"/>
    <mesh file="./geom/LeftWrist.stl"/>
    <mesh file="./geom/RightWrist.stl"/>
    <mesh file="./geom/LeftHand.stl"/>
    <mesh file="./geom/RightHand.stl"/>
  </asset>
  <worldbody>
    <light cutoff="100" diffuse="1 1 1" dir="-0 0 -1.3" directional="true" exponent="1" pos="0 0 1.3" specular=".1 .1 .1"/>
    <geom condim="3" friction="1. .1 .1" material="grid" name="floor" pos="0 0 0" rgba=".8 .9 .8 1" size="100 100 .2" type="plane"/>
    <body name="Hips" pos="-0.0018 -0.2233 0.0282" quat="1.0000 0.0000 0.0000 0.0000">
      <joint name="Hips" pos="-0.0018 -0.2233 0.0282" limited="false" type="free" armature="0" damping="0" stiffness="0"/>
      <geom type="mesh" mesh="Hips" contype="1" conaffinity="1"/>
      <body name="LeftUpLeg" pos="0.0677 -0.3147 0.0214" quat="1.0000 0.0000 0.0000 0.0000">
        <joint name="LeftUpLeg_z" type="hinge" pos="0.0677 -0.3147 0.0214" axis="0.0000 0.0000 1.0000" range="-180.0000 180.0000"/>
        <joint name="LeftUpLeg_y" type="hinge" pos="0.0677 -0.3147 0.0214" axis="0.0000 1.0000 0.0000" range="-180.0000 180.0000"/>
        <joint name="LeftUpLeg_x" type="hinge" pos="0.0677 -0.3147 0.0214" axis="1.0000 0.0000 0.0000" range="-180.0000 180.0000"/>
        <geom type="mesh" mesh="LeftUpLeg" contype="1" conaffinity="1"/>
        <body name="LeftLeg" pos="0.1020 -0.6899 0.0169" quat="1.0000 0.0000 0.0000 0.0000">
          <joint name="LeftLeg_z" type="hinge" pos="0.1020 -0.6899 0.0169" axis="0.0000 0.0000 1.0000" range="-180.0000 180.0000"/>
          <joint name="LeftLeg_y" type="hinge" pos="0.1020 -0.6899 0.0169" axis="0.0000 1.0000 0.0000" range="-180.0000 180.0000"/>
          <joint name="LeftLeg_x" type="hinge" pos="0.1020 -0.6899 0.0169" axis="1.0000 0.0000 0.0000" range="-180.0000 180.0000"/>
          <geom type="mesh" mesh="LeftLeg" contype="1" conaffinity="1"/>
          <body name="LeftFoot" pos="0.0884 -1.0879 -0.0268" quat="1.0000 0.0000 0.0000 0.0000">
            <joint name="LeftFoot_z" type="hinge" pos="0.0884 -1.0879 -0.0268" axis="0.0000 0.0000 1.0000" range="-180.0000 180.0000"/>
            <joint name="LeftFoot_y" type="hinge" pos="0.0884 -1.0879 -0.0268" axis="0.0000 1.0000 0.0000" range="-180.0000 180.0000"/>
            <joint name="LeftFoot_x" type="hinge" pos="0.0884 -1.0879 -0.0268" axis="1.0000 0.0000 0.0000" range="-180.0000 180.0000"/>
            <geom type="mesh" mesh="LeftFoot" contype="1" conaffinity="1"/>
            <body name="LeftToe" pos="0.1148 -1.1437 0.0925" quat="1.0000 0.0000 0.0000 0.0000">
              <joint name="LeftToe_z" type="hinge" pos="0.1148 -1.1437 0.0925" axis="0.0000 0.0000 1.0000" range="-180.0000 180.0000"/>
              <joint name="LeftToe_y" type="hinge" pos="0.1148 -1.1437 0.0925" axis="0.0000 1.0000 0.0000" range="-180.0000 180.0000"/>
              <joint name="LeftToe_x" type="hinge" pos="0.1148 -1.1437 0.0925" axis="1.0000 0.0000 0.0000" range="-180.0000 180.0000"/>
              <geom type="mesh" mesh="LeftToe" contype="1" conaffinity="1"/>
            </body>
          </body>
        </body>
      </body>
      <body name="RightUpLeg" pos="-0.0695 -0.3139 0.0239" quat="1.0000 0.0000 0.0000 0.0000">
        <joint name="RightUpLeg_z" type="hinge" pos="-0.0695 -0.3139 0.0239" axis="0.0000 0.0000 1.0000" range="-180.0000 180.0000"/>
        <joint name="RightUpLeg_y" type="hinge" pos="-0.0695 -0.3139 0.0239" axis="0.0000 1.0000 0.0000" range="-180.0000 180.0000"/>
        <joint name="RightUpLeg_x" type="hinge" pos="-0.0695 -0.3139 0.0239" axis="1.0000 0.0000 0.0000" range="-180.0000 180.0000"/>
        <geom type="mesh" mesh="RightUpLeg" contype="1" conaffinity="1"/>
        <body name="RightLeg" pos="-0.1078 -0.6964 0.0150" quat="1.0000 0.0000 0.0000 0.0000">
          <joint name="RightLeg_z" type="hinge" pos="-0.1078 -0.6964 0.0150" axis="0.0000 0.0000 1.0000" range="-180.0000 180.0000"/>
          <joint name="RightLeg_y" type="hinge" pos="-0.1078 -0.6964 0.0150" axis="0.0000 1.0000 0.0000" range="-180.0000 180.0000"/>
          <joint name="RightLeg_x" type="hinge" pos="-0.1078 -0.6964 0.0150" axis="1.0000 0.0000 0.0000" range="-180.0000 180.0000"/>
          <geom type="mesh" mesh="RightLeg" contype="1" conaffinity="1"/>
          <body name="RightFoot" pos="-0.0920 -1.0948 -0.0273" quat="1.0000 0.0000 0.0000 0.0000">
            <joint name="RightFoot_z" type="hinge" pos="-0.0920 -1.0948 -0.0273" axis="0.0000 0.0000 1.0000" range="-180.0000 180.0000"/>
            <joint name="RightFoot_y" type="hinge" pos="-0.0920 -1.0948 -0.0273" axis="0.0000 1.0000 0.0000" range="-180.0000 180.0000"/>
            <joint name="RightFoot_x" type="hinge" pos="-0.0920 -1.0948 -0.0273" axis="1.0000 0.0000 0.0000" range="-180.0000 180.0000"/>
            <geom type="mesh" mesh="RightFoot" contype="1" conaffinity="1"/>
            <body name="RightToe" pos="-0.1174 -1.1430 0.0961" quat="1.0000 0.0000 0.0000 0.0000">
              <joint name="RightToe_z" type="hinge" pos="-0.1174 -1.1430 0.0961" axis="0.0000 0.0000 1.0000" range="-180.0000 180.0000"/>
              <joint name="RightToe_y" type="hinge" pos="-0.1174 -1.1430 0.0961" axis="0.0000 1.0000 0.0000" range="-180.0000 180.0000"/>
              <joint name="RightToe_x" type="hinge" pos="-0.1174 -1.1430 0.0961" axis="1.0000 0.0000 0.0000" range="-180.0000 180.0000"/>
              <geom type="mesh" mesh="RightToe" contype="1" conaffinity="1"/>
            </body>
          </body>
        </body>
      </body>
      <body name="Spine" pos="-0.0043 -0.1144 0.0015" quat="1.0000 0.0000 0.0000 0.0000">
        <joint name="Spine_z" type="hinge" pos="-0.0043 -0.1144 0.0015" axis="0.0000 0.0000 1.0000" range="-180.0000 180.0000"/>
        <joint name="Spine_y" type="hinge" pos="-0.0043 -0.1144 0.0015" axis="0.0000 1.0000 0.0000" range="-180.0000 180.0000"/>
        <joint name="Spine_x" type="hinge" pos="-0.0043 -0.1144 0.0015" axis="1.0000 0.0000 0.0000" range="-180.0000 180.0000"/>
        <geom type="mesh" mesh="Spine" contype="1" conaffinity="1"/>
        <body name="Spine1" pos="0.0012 0.0208 0.0026" quat="1.0000 0.0000 0.0000 0.0000">
          <joint name="Spine1_z" type="hinge" pos="0.0012 0.0208 0.0026" axis="0.0000 0.0000 1.0000" range="-180.0000 180.0000"/>
          <joint name="Spine1_y" type="hinge" pos="0.0012 0.0208 0.0026" axis="0.0000 1.0000 0.0000" range="-180.0000 180.0000"/>
          <joint name="Spine1_x" type="hinge" pos="0.0012 0.0208 0.0026" axis="1.0000 0.0000 0.0000" range="-180.0000 180.0000"/>
          <geom type="mesh" mesh="Spine1" contype="1" conaffinity="1"/>
          <body name="Spine2" pos="0.0026 0.0737 0.0280" quat="1.0000 0.0000 0.0000 0.0000">
            <joint name="Spine2_z" type="hinge" pos="0.0026 0.0737 0.0280" axis="0.0000 0.0000 1.0000" range="-180.0000 180.0000"/>
            <joint name="Spine2_y" type="hinge" pos="0.0026 0.0737 0.0280" axis="0.0000 1.0000 0.0000" range="-180.0000 180.0000"/>
            <joint name="Spine2_x" type="hinge" pos="0.0026 0.0737 0.0280" axis="1.0000 0.0000 0.0000" range="-180.0000 180.0000"/>
            <geom type="mesh" mesh="Spine2" contype="1" conaffinity="1"/>
            <body name="Neck" pos="-0.0002 0.2876 -0.0148" quat="1.0000 0.0000 0.0000 0.0000">
              <joint name="Neck_z" type="hinge" pos="-0.0002 0.2876 -0.0148" axis="0.0000 0.0000 1.0000" range="-180.0000 180.0000"/>
              <joint name="Neck_y" type="hinge" pos="-0.0002 0.2876 -0.0148" axis="0.0000 1.0000 0.0000" range="-180.0000 180.0000"/>
              <joint name="Neck_x" type="hinge" pos="-0.0002 0.2876 -0.0148" axis="1.0000 0.0000 0.0000" range="-180.0000 180.0000"/>
              <geom type="mesh" mesh="Neck" contype="1" conaffinity="1"/>
              <body name="Mouth" pos="0.0050 0.3526 0.0365" quat="1.0000 0.0000 0.0000 0.0000">
                <joint name="Mouth_z" type="hinge" pos="0.0050 0.3526 0.0365" axis="0.0000 0.0000 1.0000" range="-180.0000 180.0000"/>
                <joint name="Mouth_y" type="hinge" pos="0.0050 0.3526 0.0365" axis="0.0000 1.0000 0.0000" range="-180.0000 180.0000"/>
                <joint name="Mouth_x" type="hinge" pos="0.0050 0.3526 0.0365" axis="1.0000 0.0000 0.0000" range="-180.0000 180.0000"/>
                <geom type="mesh" mesh="Mouth" contype="1" conaffinity="1"/>
              </body>
            </body>
            <body name="LeftChest" pos="0.0815 0.1955 -0.0060" quat="1.0000 0.0000 0.0000 0.0000">
              <joint name="LeftChest_z" type="hinge" pos="0.0815 0.1955 -0.0060" axis="0.0000 0.0000 1.0000" range="-180.0000 180.0000"/>
              <joint name="LeftChest_y" type="hinge" pos="0.0815 0.1955 -0.0060" axis="0.0000 1.0000 0.0000" range="-180.0000 180.0000"/>
              <joint name="LeftChest_x" type="hinge" pos="0.0815 0.1955 -0.0060" axis="1.0000 0.0000 0.0000" range="-180.0000 180.0000"/>
              <geom type="mesh" mesh="LeftChest" contype="1" conaffinity="1"/>
              <body name="LeftShoulder" pos="0.1724 0.2260 -0.0149" quat="1.0000 0.0000 0.0000 0.0000">
                <joint name="LeftShoulder_z" type="hinge" pos="0.1724 0.2260 -0.0149" axis="0.0000 0.0000 1.0000" range="-180.0000 180.0000"/>
                <joint name="LeftShoulder_y" type="hinge" pos="0.1724 0.2260 -0.0149" axis="0.0000 1.0000 0.0000" range="-180.0000 180.0000"/>
                <joint name="LeftShoulder_x" type="hinge" pos="0.1724 0.2260 -0.0149" axis="1.0000 0.0000 0.0000" range="-180.0000 180.0000"/>
                <geom type="mesh" mesh="LeftShoulder" contype="1" conaffinity="1"/>
                <body name="LeftArm" pos="0.4320 0.2132 -0.0424" quat="1.0000 0.0000 0.0000 0.0000">
                  <joint name="LeftArm_z" type="hinge" pos="0.4320 0.2132 -0.0424" axis="0.0000 0.0000 1.0000" range="-720.0000 720.0000"/>
                  <joint name="LeftArm_y" type="hinge" pos="0.4320 0.2132 -0.0424" axis="0.0000 1.0000 0.0000" range="-720.0000 720.0000"/>
                  <joint name="LeftArm_x" type="hinge" pos="0.4320 0.2132 -0.0424" axis="1.0000 0.0000 0.0000" range="-720.0000 720.0000"/>
                  <geom type="mesh" mesh="LeftArm" contype="1" conaffinity="1"/>
                  <body name="LeftWrist" pos="0.6813 0.2222 -0.0435" quat="1.0000 0.0000 0.0000 0.0000">
                    <joint name="LeftWrist_z" type="hinge" pos="0.6813 0.2222 -0.0435" axis="0.0000 0.0000 1.0000" range="-180.0000 180.0000"/>
                    <joint name="LeftWrist_y" type="hinge" pos="0.6813 0.2222 -0.0435" axis="0.0000 1.0000 0.0000" range="-180.0000 180.0000"/>
                    <joint name="LeftWrist_x" type="hinge" pos="0.6813 0.2222 -0.0435" axis="1.0000 0.0000 0.0000" range="-180.0000 180.0000"/>
                    <geom type="mesh" mesh="LeftWrist" contype="1" conaffinity="1"/>
                    <body name="LeftHand" pos="0.7653 0.2140 -0.0585" quat="1.0000 0.0000 0.0000 0.0000">
                      <joint name="LeftHand_z" type="hinge" pos="0.7653 0.2140 -0.0585" axis="0.0000 0.0000 1.0000" range="-180.0000 180.0000"/>
                      <joint name="LeftHand_y" type="hinge" pos="0.7653 0.2140 -0.0585" axis="0.0000 1.0000 0.0000" range="-180.0000 180.0000"/>
                      <joint name="LeftHand_x" type="hinge" pos="0.7653 0.2140 -0.0585" axis="1.0000 0.0000 0.0000" range="-180.0000 180.0000"/>
                      <geom type="mesh" mesh="LeftHand" contype="1" conaffinity="1"/>
                    </body>
                  </body>
                </body>
              </body>
            </body>
            <body name="RightChest" pos="-0.0791 0.1926 -0.0106" quat="1.0000 0.0000 0.0000 0.0000">
              <joint name="RightChest_z" type="hinge" pos="-0.0791 0.1926 -0.0106" axis="0.0000 0.0000 1.0000" range="-180.0000 180.0000"/>
              <joint name="RightChest_y" type="hinge" pos="-0.0791 0.1926 -0.0106" axis="0.0000 1.0000 0.0000" range="-180.0000 180.0000"/>
              <joint name="RightChest_x" type="hinge" pos="-0.0791 0.1926 -0.0106" axis="1.0000 0.0000 0.0000" range="-180.0000 180.0000"/>
              <geom type="mesh" mesh="RightChest" contype="1" conaffinity="1"/>
              <body name="RightShoulder" pos="-0.1752 0.2251 -0.0197" quat="1.0000 0.0000 0.0000 0.0000">
                <joint name="RightShoulder_z" type="hinge" pos="-0.1752 0.2251 -0.0197" axis="0.0000 0.0000 1.0000" range="-180.0000 180.0000"/>
                <joint name="RightShoulder_y" type="hinge" pos="-0.1752 0.2251 -0.0197" axis="0.0000 1.0000 0.0000" range="-180.0000 180.0000"/>
                <joint name="RightShoulder_x" type="hinge" pos="-0.1752 0.2251 -0.0197" axis="1.0000 0.0000 0.0000" range="-180.0000 180.0000"/>
                <geom type="mesh" mesh="RightShoulder" contype="1" conaffinity="1"/>
                <body name="RightArm" pos="-0.4289 0.2118 -0.0411" quat="1.0000 0.0000 0.0000 0.0000">
                  <joint name="RightArm_z" type="hinge" pos="-0.4289 0.2118 -0.0411" axis="0.0000 0.0000 1.0000" range="-720.0000 720.0000"/>
                  <joint name="RightArm_y" type="hinge" pos="-0.4289 0.2118 -0.0411" axis="0.0000 1.0000 0.0000" range="-720.0000 720.0000"/>
                  <joint name="RightArm_x" type="hinge" pos="-0.4289 0.2118 -0.0411" axis="1.0000 0.0000 0.0000" range="-720.0000 720.0000"/>
                  <geom type="mesh" mesh="RightArm" contype="1" conaffinity="1"/>
                  <body name="RightWrist" pos="-0.6842 0.2196 -0.0467" quat="1.0000 0.0000 0.0000 0.0000">
                    <joint name="RightWrist_z" type="hinge" pos="-0.6842 0.2196 -0.0467" axis="0.0000 0.0000 1.0000" range="-180.0000 180.0000"/>
                    <joint name="RightWrist_y" type="hinge" pos="-0.6842 0.2196 -0.0467" axis="0.0000 1.0000 0.0000" range="-180.0000 180.0000"/>
                    <joint name="RightWrist_x" type="hinge" pos="-0.6842 0.2196 -0.0467" axis="1.0000 0.0000 0.0000" range="-180.0000 180.0000"/>
                    <geom type="mesh" mesh="RightWrist" contype="1" conaffinity="1"/>
                    <body name="RightHand" pos="-0.7688 0.2134 -0.0570" quat="1.0000 0.0000 0.0000 0.0000">
                      <joint name="RightHand_z" type="hinge" pos="-0.7688 0.2134 -0.0570" axis="0.0000 0.0000 1.0000" range="-180.0000 180.0000"/>
                      <joint name="RightHand_y" type="hinge" pos="-0.7688 0.2134 -0.0570" axis="0.0000 1.0000 0.0000" range="-180.0000 180.0000"/>
                      <joint name="RightHand_x" type="hinge" pos="-0.7688 0.2134 -0.0570" axis="1.0000 0.0000 0.0000" range="-180.0000 180.0000"/>
                      <geom type="mesh" mesh="RightHand" contype="1" conaffinity="1"/>
                    </body>
                  </body>
                </body>
              </body>
            </body>
          </body>
        </body>
      </body>
    </body>
    <body name="1_Hips" pos="-0.0018 -0.2233 0.0282" quat="1.0000 0.0000 0.0000 0.0000">
      <joint name="1_Hips" pos="-0.0018 -0.2233 0.0282" limited="false" type="free" armature="0" damping="0" stiffness="0"/>
      <geom type="mesh" mesh="Hips" contype="1" conaffinity="1"/>
      <body name="1_LeftUpLeg" pos="0.0677 -0.3147 0.0214" quat="1.0000 0.0000 0.0000 0.0000">
        <joint name="1_LeftUpLeg_z" type="hinge" pos="0.0677 -0.3147 0.0214" axis="0.0000 0.0000 1.0000" range="-180.0000 180.0000"/>
        <joint name="1_LeftUpLeg_y" type="hinge" pos="0.0677 -0.3147 0.0214" axis="0.0000 1.0000 0.0000" range="-180.0000 180.0000"/>
        <joint name="1_LeftUpLeg_x" type="hinge" pos="0.0677 -0.3147 0.0214" axis="1.0000 0.0000 0.0000" range="-180.0000 180.0000"/>
        <geom type="mesh" mesh="LeftUpLeg" contype="1" conaffinity="1"/>
        <body name="1_LeftLeg" pos="0.1020 -0.6899 0.0169" quat="1.0000 0.0000 0.0000 0.0000">
          <joint name="1_LeftLeg_z" type="hinge" pos="0.1020 -0.6899 0.0169" axis="0.0000 0.0000 1.0000" range="-180.0000 180.0000"/>
          <joint name="1_LeftLeg_y" type="hinge" pos="0.1020 -0.6899 0.0169" axis="0.0000 1.0000 0.0000" range="-180.0000 180.0000"/>
          <joint name="1_LeftLeg_x" type="hinge" pos="0.1020 -0.6899 0.0169" axis="1.0000 0.0000 0.0000" range="-180.0000 180.0000"/>
          <geom type="mesh" mesh="LeftLeg" contype="1" conaffinity="1"/>
          <body name="1_LeftFoot" pos="0.0884 -1.0879 -0.0268" quat="1.0000 0.0000 0.0000 0.0000">
            <joint name="1_LeftFoot_z" type="hinge" pos="0.0884 -1.0879 -0.0268" axis="0.0000 0.0000 1.0000" range="-180.0000 180.0000"/>
            <joint name="1_LeftFoot_y" type="hinge" pos="0.0884 -1.0879 -0.0268" axis="0.0000 1.0000 0.0000" range="-180.0000 180.0000"/>
            <joint name="1_LeftFoot_x" type="hinge" pos="0.0884 -1.0879 -0.0268" axis="1.0000 0.0000 0.0000" range="-180.0000 180.0000"/>
            <geom type="mesh" mesh="LeftFoot" contype="1" conaffinity="1"/>
            <body name="1_LeftToe" pos="0.1148 -1.1437 0.0925" quat="1.0000 0.0000 0.0000 0.0000">
              <joint name="1_LeftToe_z" type="hinge" pos="0.1148 -1.1437 0.0925" axis="0.0000 0.0000 1.0000" range="-180.0000 180.0000"/>
              <joint name="1_LeftToe_y" type="hinge" pos="0.1148 -1.1437 0.0925" axis="0.0000 1.0000 0.0000" range="-180.0000 180.0000"/>
              <joint name="1_LeftToe_x" type="hinge" pos="0.1148 -1.1437 0.0925" axis="1.0000 0.0000 0.0000" range="-180.0000 180.0000"/>
              <geom type="mesh" mesh="LeftToe" contype="1" conaffinity="1"/>
            </body>
          </body>
        </body>
      </body>
      <body name="1_RightUpLeg" pos="-0.0695 -0.3139 0.0239" quat="1.0000 0.0000 0.0000 0.0000">
        <joint name="1_RightUpLeg_z" type="hinge" pos="-0.0695 -0.3139 0.0239" axis="0.0000 0.0000 1.0000" range="-180.0000 180.0000"/>
        <joint name="1_RightUpLeg_y" type="hinge" pos="-0.0695 -0.3139 0.0239" axis="0.0000 1.0000 0.0000" range="-180.0000 180.0000"/>
        <joint name="1_RightUpLeg_x" type="hinge" pos="-0.0695 -0.3139 0.0239" axis="1.0000 0.0000 0.0000" range="-180.0000 180.0000"/>
        <geom type="mesh" mesh="RightUpLeg" contype="1" conaffinity="1"/>
        <body name="1_RightLeg" pos="-0.1078 -0.6964 0.0150" quat="1.0000 0.0000 0.0000 0.0000">
          <joint name="1_RightLeg_z" type="hinge" pos="-0.1078 -0.6964 0.0150" axis="0.0000 0.0000 1.0000" range="-180.0000 180.0000"/>
          <joint name="1_RightLeg_y" type="hinge" pos="-0.1078 -0.6964 0.0150" axis="0.0000 1.0000 0.0000" range="-180.0000 180.0000"/>
          <joint name="1_RightLeg_x" type="hinge" pos="-0.1078 -0.6964 0.0150" axis="1.0000 0.0000 0.0000" range="-180.0000 180.0000"/>
          <geom type="mesh" mesh="RightLeg" contype="1" conaffinity="1"/>
          <body name="1_RightFoot" pos="-0.0920 -1.0948 -0.0273" quat="1.0000 0.0000 0.0000 0.0000">
            <joint name="1_RightFoot_z" type="hinge" pos="-0.0920 -1.0948 -0.0273" axis="0.0000 0.0000 1.0000" range="-180.0000 180.0000"/>
            <joint name="1_RightFoot_y" type="hinge" pos="-0.0920 -1.0948 -0.0273" axis="0.0000 1.0000 0.0000" range="-180.0000 180.0000"/>
            <joint name="1_RightFoot_x" type="hinge" pos="-0.0920 -1.0948 -0.0273" axis="1.0000 0.0000 0.0000" range="-180.0000 180.0000"/>
            <geom type="mesh" mesh="RightFoot" contype="1" conaffinity="1"/>
            <body name="1_RightToe" pos="-0.1174 -1.1430 0.0961" quat="1.0000 0.0000 0.0000 0.0000">
              <joint name="1_RightToe_z" type="hinge" pos="-0.1174 -1.1430 0.0961" axis="0.0000 0.0000 1.0000" range="-180.0000 180.0000"/>
              <joint name="1_RightToe_y" type="hinge" pos="-0.1174 -1.1430 0.0961" axis="0.0000 1.0000 0.0000" range="-180.0000 180.0000"/>
              <joint name="1_RightToe_x" type="hinge" pos="-0.1174 -1.1430 0.0961" axis="1.0000 0.0000 0.0000" range="-180.0000 180.0000"/>
              <geom type="mesh" mesh="RightToe" contype="1" conaffinity="1"/>
            </body>
          </body>
        </body>
      </body>
      <body name="1_Spine" pos="-0.0043 -0.1144 0.0015" quat="1.0000 0.0000 0.0000 0.0000">
        <joint name="1_Spine_z" type="hinge" pos="-0.0043 -0.1144 0.0015" axis="0.0000 0.0000 1.0000" range="-180.0000 180.0000"/>
        <joint name="1_Spine_y" type="hinge" pos="-0.0043 -0.1144 0.0015" axis="0.0000 1.0000 0.0000" range="-180.0000 180.0000"/>
        <joint name="1_Spine_x" type="hinge" pos="-0.0043 -0.1144 0.0015" axis="1.0000 0.0000 0.0000" range="-180.0000 180.0000"/>
        <geom type="mesh" mesh="Spine" contype="1" conaffinity="1"/>
        <body name="1_Spine1" pos="0.0012 0.0208 0.0026" quat="1.0000 0.0000 0.0000 0.0000">
          <joint name="1_Spine1_z" type="hinge" pos="0.0012 0.0208 0.0026" axis="0.0000 0.0000 1.0000" range="-180.0000 180.0000"/>
          <joint name="1_Spine1_y" type="hinge" pos="0.0012 0.0208 0.0026" axis="0.0000 1.0000 0.0000" range="-180.0000 180.0000"/>
          <joint name="1_Spine1_x" type="hinge" pos="0.0012 0.0208 0.0026" axis="1.0000 0.0000 0.0000" range="-180.0000 180.0000"/>
          <geom type="mesh" mesh="Spine1" contype="1" conaffinity="1"/>
          <body name="1_Spine2" pos="0.0026 0.0737 0.0280" quat="1.0000 0.0000 0.0000 0.0000">
            <joint name="1_Spine2_z" type="hinge" pos="0.0026 0.0737 0.0280" axis="0.0000 0.0000 1.0000" range="-180.0000 180.0000"/>
            <joint name="1_Spine2_y" type="hinge" pos="0.0026 0.0737 0.0280" axis="0.0000 1.0000 0.0000" range="-180.0000 180.0000"/>
            <joint name="1_Spine2_x" type="hinge" pos="0.0026 0.0737 0.0280" axis="1.0000 0.0000 0.0000" range="-180.0000 180.0000"/>
            <geom type="mesh" mesh="Spine2" contype="1" conaffinity="1"/>
            <body name="1_Neck" pos="-0.0002 0.2876 -0.0148" quat="1.0000 0.0000 0.0000 0.0000">
              <joint name="1_Neck_z" type="hinge" pos="-0.0002 0.2876 -0.0148" axis="0.0000 0.0000 1.0000" range="-180.0000 180.0000"/>
              <joint name="1_Neck_y" type="hinge" pos="-0.0002 0.2876 -0.0148" axis="0.0000 1.0000 0.0000" range="-180.0000 180.0000"/>
              <joint name="1_Neck_x" type="hinge" pos="-0.0002 0.2876 -0.0148" axis="1.0000 0.0000 0.0000" range="-180.0000 180.0000"/>
              <geom type="mesh" mesh="Neck" contype="1" conaffinity="1"/>
              <body name="1_Mouth" pos="0.0050 0.3526 0.0365" quat="1.0000 0.0000 0.0000 0.0000">
                <joint name="1_Mouth_z" type="hinge" pos="0.0050 0.3526 0.0365" axis="0.0000 0.0000 1.0000" range="-180.0000 180.0000"/>
                <joint name="1_Mouth_y" type="hinge" pos="0.0050 0.3526 0.0365" axis="0.0000 1.0000 0.0000" range="-180.0000 180.0000"/>
                <joint name="1_Mouth_x" type="hinge" pos="0.0050 0.3526 0.0365" axis="1.0000 0.0000 0.0000" range="-180.0000 180.0000"/>
                <geom type="mesh" mesh="Mouth" contype="1" conaffinity="1"/>
              </body>
            </body>
            <body name="1_LeftChest" pos="0.0815 0.1955 -0.0060" quat="1.0000 0.0000 0.0000 0.0000">
              <joint name="1_LeftChest_z" type="hinge" pos="0.0815 0.1955 -0.0060" axis="0.0000 0.0000 1.0000" range="-180.0000 180.0000"/>
              <joint name="1_LeftChest_y" type="hinge" pos="0.0815 0.1955 -0.0060" axis="0.0000 1.0000 0.0000" range="-180.0000 180.0000"/>
              <joint name="1_LeftChest_x" type="hinge" pos="0.0815 0.1955 -0.0060" axis="1.0000 0.0000 0.0000" range="-180.0000 180.0000"/>
              <geom type="mesh" mesh="LeftChest" contype="1" conaffinity="1"/>
              <body name="1_LeftShoulder" pos="0.1724 0.2260 -0.0149" quat="1.0000 0.0000 0.0000 0.0000">
                <joint name="1_LeftShoulder_z" type="hinge" pos="0.1724 0.2260 -0.0149" axis="0.0000 0.0000 1.0000" range="-180.0000 180.0000"/>
                <joint name="1_LeftShoulder_y" type="hinge" pos="0.1724 0.2260 -0.0149" axis="0.0000 1.0000 0.0000" range="-180.0000 180.0000"/>
                <joint name="1_LeftShoulder_x" type="hinge" pos="0.1724 0.2260 -0.0149" axis="1.0000 0.0000 0.0000" range="-180.0000 180.0000"/>
                <geom type="mesh" mesh="LeftShoulder" contype="1" conaffinity="1"/>
                <body name="1_LeftArm" pos="0.4320 0.2132 -0.0424" quat="1.0000 0.0000 0.0000 0.0000">
                  <joint name="1_LeftArm_z" type="hinge" pos="0.4320 0.2132 -0.0424" axis="0.0000 0.0000 1.0000" range="-720.0000 720.0000"/>
                  <joint name="1_LeftArm_y" type="hinge" pos="0.4320 0.2132 -0.0424" axis="0.0000 1.0000 0.0000" range="-720.0000 720.0000"/>
                  <joint name="1_LeftArm_x" type="hinge" pos="0.4320 0.2132 -0.0424" axis="1.0000 0.0000 0.0000" range="-720.0000 720.0000"/>
                  <geom type="mesh" mesh="LeftArm" contype="1" conaffinity="1"/>
                  <body name="1_LeftWrist" pos="0.6813 0.2222 -0.0435" quat="1.0000 0.0000 0.0000 0.0000">
                    <joint name="1_LeftWrist_z" type="hinge" pos="0.6813 0.2222 -0.0435" axis="0.0000 0.0000 1.0000" range="-180.0000 180.0000"/>
                    <joint name="1_LeftWrist_y" type="hinge" pos="0.6813 0.2222 -0.0435" axis="0.0000 1.0000 0.0000" range="-180.0000 180.0000"/>
                    <joint name="1_LeftWrist_x" type="hinge" pos="0.6813 0.2222 -0.0435" axis="1.0000 0.0000 0.0000" range="-180.0000 180.0000"/>
                    <geom type="mesh" mesh="LeftWrist" contype="1" conaffinity="1"/>
                    <body name="1_LeftHand" pos="0.7653 0.2140 -0.0585" quat="1.0000 0.0000 0.0000 0.0000">
                      <joint name="1_LeftHand_z" type="hinge" pos="0.7653 0.2140 -0.0585" axis="0.0000 0.0000 1.0000" range="-180.0000 180.0000"/>
                      <joint name="1_LeftHand_y" type="hinge" pos="0.7653 0.2140 -0.0585" axis="0.0000 1.0000 0.0000" range="-180.0000 180.0000"/>
                      <joint name="1_LeftHand_x" type="hinge" pos="0.7653 0.2140 -0.0585" axis="1.0000 0.0000 0.0000" range="-180.0000 180.0000"/>
                      <geom type="mesh" mesh="LeftHand" contype="1" conaffinity="1"/>
                    </body>
                  </body>
                </body>
              </body>
            </body>
            <body name="1_RightChest" pos="-0.0791 0.1926 -0.0106" quat="1.0000 0.0000 0.0000 0.0000">
              <joint name="1_RightChest_z" type="hinge" pos="-0.0791 0.1926 -0.0106" axis="0.0000 0.0000 1.0000" range="-180.0000 180.0000"/>
              <joint name="1_RightChest_y" type="hinge" pos="-0.0791 0.1926 -0.0106" axis="0.0000 1.0000 0.0000" range="-180.0000 180.0000"/>
              <joint name="1_RightChest_x" type="hinge" pos="-0.0791 0.1926 -0.0106" axis="1.0000 0.0000 0.0000" range="-180.0000 180.0000"/>
              <geom type="mesh" mesh="RightChest" contype="1" conaffinity="1"/>
              <body name="1_RightShoulder" pos="-0.1752 0.2251 -0.0197" quat="1.0000 0.0000 0.0000 0.0000">
                <joint name="1_RightShoulder_z" type="hinge" pos="-0.1752 0.2251 -0.0197" axis="0.0000 0.0000 1.0000" range="-180.0000 180.0000"/>
                <joint name="1_RightShoulder_y" type="hinge" pos="-0.1752 0.2251 -0.0197" axis="0.0000 1.0000 0.0000" range="-180.0000 180.0000"/>
                <joint name="1_RightShoulder_x" type="hinge" pos="-0.1752 0.2251 -0.0197" axis="1.0000 0.0000 0.0000" range="-180.0000 180.0000"/>
                <geom type="mesh" mesh="RightShoulder" contype="1" conaffinity="1"/>
                <body name="1_RightArm" pos="-0.4289 0.2118 -0.0411" quat="1.0000 0.0000 0.0000 0.0000">
                  <joint name="1_RightArm_z" type="hinge" pos="-0.4289 0.2118 -0.0411" axis="0.0000 0.0000 1.0000" range="-720.0000 720.0000"/>
                  <joint name="1_RightArm_y" type="hinge" pos="-0.4289 0.2118 -0.0411" axis="0.0000 1.0000 0.0000" range="-720.0000 720.0000"/>
                  <joint name="1_RightArm_x" type="hinge" pos="-0.4289 0.2118 -0.0411" axis="1.0000 0.0000 0.0000" range="-720.0000 720.0000"/>
                  <geom type="mesh" mesh="RightArm" contype="1" conaffinity="1"/>
                  <body name="1_RightWrist" pos="-0.6842 0.2196 -0.0467" quat="1.0000 0.0000 0.0000 0.0000">
                    <joint name="1_RightWrist_z" type="hinge" pos="-0.6842 0.2196 -0.0467" axis="0.0000 0.0000 1.0000" range="-180.0000 180.0000"/>
                    <joint name="1_RightWrist_y" type="hinge" pos="-0.6842 0.2196 -0.0467" axis="0.0000 1.0000 0.0000" range="-180.0000 180.0000"/>
                    <joint name="1_RightWrist_x" type="hinge" pos="-0.6842 0.2196 -0.0467" axis="1.0000 0.0000 0.0000" range="-180.0000 180.0000"/>
                    <geom type="mesh" mesh="RightWrist" contype="1" conaffinity="1"/>
                    <body name="1_RightHand" pos="-0.7688 0.2134 -0.0570" quat="1.0000 0.0000 0.0000 0.0000">
                      <joint name="1_RightHand_z" type="hinge" pos="-0.7688 0.2134 -0.0570" axis="0.0000 0.0000 1.0000" range="-180.0000 180.0000"/>
                      <joint name="1_RightHand_y" type="hinge" pos="-0.7688 0.2134 -0.0570" axis="0.0000 1.0000 0.0000" range="-180.0000 180.0000"/>
                      <joint name="1_RightHand_x" type="hinge" pos="-0.7688 0.2134 -0.0570" axis="1.0000 0.0000 0.0000" range="-180.0000 180.0000"/>
                      <geom type="mesh" mesh="RightHand" contype="1" conaffinity="1"/>
                    </body>
                  </body>
                </body>
              </body>
            </body>
          </body>
        </body>
      </body>
    </body>
    <body name="2_Hips" pos="-0.0018 -0.2233 0.0282" quat="1.0000 0.0000 0.0000 0.0000">
      <joint name="2_Hips" pos="-0.0018 -0.2233 0.0282" limited="false" type="free" armature="0" damping="0" stiffness="0"/>
      <geom type="mesh" mesh="Hips" contype="1" conaffinity="1"/>
      <body name="2_LeftUpLeg" pos="0.0677 -0.3147 0.0214" quat="1.0000 0.0000 0.0000 0.0000">
        <joint name="2_LeftUpLeg_z" type="hinge" pos="0.0677 -0.3147 0.0214" axis="0.0000 0.0000 1.0000" range="-180.0000 180.0000"/>
        <joint name="2_LeftUpLeg_y" type="hinge" pos="0.0677 -0.3147 0.0214" axis="0.0000 1.0000 0.0000" range="-180.0000 180.0000"/>
        <joint name="2_LeftUpLeg_x" type="hinge" pos="0.0677 -0.3147 0.0214" axis="1.0000 0.0000 0.0000" range="-180.0000 180.0000"/>
        <geom type="mesh" mesh="LeftUpLeg" contype="1" conaffinity="1"/>
        <body name="2_LeftLeg" pos="0.1020 -0.6899 0.0169" quat="1.0000 0.0000 0.0000 0.0000">
          <joint name="2_LeftLeg_z" type="hinge" pos="0.1020 -0.6899 0.0169" axis="0.0000 0.0000 1.0000" range="-180.0000 180.0000"/>
          <joint name="2_LeftLeg_y" type="hinge" pos="0.1020 -0.6899 0.0169" axis="0.0000 1.0000 0.0000" range="-180.0000 180.0000"/>
          <joint name="2_LeftLeg_x" type="hinge" pos="0.1020 -0.6899 0.0169" axis="1.0000 0.0000 0.0000" range="-180.0000 180.0000"/>
          <geom type="mesh" mesh="LeftLeg" contype="1" conaffinity="1"/>
          <body name="2_LeftFoot" pos="0.0884 -1.0879 -0.0268" quat="1.0000 0.0000 0.0000 0.0000">
            <joint name="2_LeftFoot_z" type="hinge" pos="0.0884 -1.0879 -0.0268" axis="0.0000 0.0000 1.0000" range="-180.0000 180.0000"/>
            <joint name="2_LeftFoot_y" type="hinge" pos="0.0884 -1.0879 -0.0268" axis="0.0000 1.0000 0.0000" range="-180.0000 180.0000"/>
            <joint name="2_LeftFoot_x" type="hinge" pos="0.0884 -1.0879 -0.0268" axis="1.0000 0.0000 0.0000" range="-180.0000 180.0000"/>
            <geom type="mesh" mesh="LeftFoot" contype="1" conaffinity="1"/>
            <body name="2_LeftToe" pos="0.1148 -1.1437 0.0925" quat="1.0000 0.0000 0.0000 0.0000">
              <joint name="2_LeftToe_z" type="hinge" pos="0.1148 -1.1437 0.0925" axis="0.0000 0.0000 1.0000" range="-180.0000 180.0000"/>
              <joint name="2_LeftToe_y" type="hinge" pos="0.1148 -1.1437 0.0925" axis="0.0000 1.0000 0.0000" range="-180.0000 180.0000"/>
              <joint name="2_LeftToe_x" type="hinge" pos="0.1148 -1.1437 0.0925" axis="1.0000 0.0000 0.0000" range="-180.0000 180.0000"/>
              <geom type="mesh" mesh="LeftToe" contype="1" conaffinity="1"/>
            </body>
          </body>
        </body>
      </body>
      <body name="2_RightUpLeg" pos="-0.0695 -0.3139 0.0239" quat="1.0000 0.0000 0.0000 0.0000">
        <joint name="2_RightUpLeg_z" type="hinge" pos="-0.0695 -0.3139 0.0239" axis="0.0000 0.0000 1.0000" range="-180.0000 180.0000"/>
        <joint name="2_RightUpLeg_y" type="hinge" pos="-0.0695 -0.3139 0.0239" axis="0.0000 1.0000 0.0000" range="-180.0000 180.0000"/>
        <joint name="2_RightUpLeg_x" type="hinge" pos="-0.0695 -0.3139 0.0239" axis="1.0000 0.0000 0.0000" range="-180.0000 180.0000"/>
        <geom type="mesh" mesh="RightUpLeg" contype="1" conaffinity="1"/>
        <body name="2_RightLeg" pos="-0.1078 -0.6964 0.0150" quat="1.0000 0.0000 0.0000 0.0000">
          <joint name="2_RightLeg_z" type="hinge" pos="-0.1078 -0.6964 0.0150" axis="0.0000 0.0000 1.0000" range="-180.0000 180.0000"/>
          <joint name="2_RightLeg_y" type="hinge" pos="-0.1078 -0.6964 0.0150" axis="0.0000 1.0000 0.0000" range="-180.0000 180.0000"/>
          <joint name="2_RightLeg_x" type="hinge" pos="-0.1078 -0.6964 0.0150" axis="1.0000 0.0000 0.0000" range="-180.0000 180.0000"/>
          <geom type="mesh" mesh="RightLeg" contype="1" conaffinity="1"/>
          <body name="2_RightFoot" pos="-0.0920 -1.0948 -0.0273" quat="1.0000 0.0000 0.0000 0.0000">
            <joint name="2_RightFoot_z" type="hinge" pos="-0.0920 -1.0948 -0.0273" axis="0.0000 0.0000 1.0000" range="-180.0000 180.0000"/>
            <joint name="2_RightFoot_y" type="hinge" pos="-0.0920 -1.0948 -0.0273" axis="0.0000 1.0000 0.0000" range="-180.0000 180.0000"/>
            <joint name="2_RightFoot_x" type="hinge" pos="-0.0920 -1.0948 -0.0273" axis="1.0000 0.0000 0.0000" range="-180.0000 180.0000"/>
            <geom type="mesh" mesh="RightFoot" contype="1" conaffinity="1"/>
            <body name="2_RightToe" pos="-0.1174 -1.1430 0.0961" quat="1.0000 0.0000 0.0000 0.0000">
              <joint name="2_RightToe_z" type="hinge" pos="-0.1174 -1.1430 0.0961" axis="0.0000 0.0000 1.0000" range="-180.0000 180.0000"/>
              <joint name="2_RightToe_y" type="hinge" pos="-0.1174 -1.1430 0.0961" axis="0.0000 1.0000 0.0000" range="-180.0000 180.0000"/>
              <joint name="2_RightToe_x" type="hinge" pos="-0.1174 -1.1430 0.0961" axis="1.0000 0.0000 0.0000" range="-180.0000 180.0000"/>
              <geom type="mesh" mesh="RightToe" contype="1" conaffinity="1"/>
            </body>
          </body>
        </body>
      </body>
      <body name="2_Spine" pos="-0.0043 -0.1144 0.0015" quat="1.0000 0.0000 0.0000 0.0000">
        <joint name="2_Spine_z" type="hinge" pos="-0.0043 -0.1144 0.0015" axis="0.0000 0.0000 1.0000" range="-180.0000 180.0000"/>
        <joint name="2_Spine_y" type="hinge" pos="-0.0043 -0.1144 0.0015" axis="0.0000 1.0000 0.0000" range="-180.0000 180.0000"/>
        <joint name="2_Spine_x" type="hinge" pos="-0.0043 -0.1144 0.0015" axis="1.0000 0.0000 0.0000" range="-180.0000 180.0000"/>
        <geom type="mesh" mesh="Spine" contype="1" conaffinity="1"/>
        <body name="2_Spine1" pos="0.0012 0.0208 0.0026" quat="1.0000 0.0000 0.0000 0.0000">
          <joint name="2_Spine1_z" type="hinge" pos="0.0012 0.0208 0.0026" axis="0.0000 0.0000 1.0000" range="-180.0000 180.0000"/>
          <joint name="2_Spine1_y" type="hinge" pos="0.0012 0.0208 0.0026" axis="0.0000 1.0000 0.0000" range="-180.0000 180.0000"/>
          <joint name="2_Spine1_x" type="hinge" pos="0.0012 0.0208 0.0026" axis="1.0000 0.0000 0.0000" range="-180.0000 180.0000"/>
          <geom type="mesh" mesh="Spine1" contype="1" conaffinity="1"/>
          <body name="2_Spine2" pos="0.0026 0.0737 0.0280" quat="1.0000 0.0000 0.0000 0.0000">
            <joint name="2_Spine2_z" type="hinge" pos="0.0026 0.0737 0.0280" axis="0.0000 0.0000 1.0000" range="-180.0000 180.0000"/>
            <joint name="2_Spine2_y" type="hinge" pos="0.0026 0.0737 0.0280" axis="0.0000 1.0000 0.0000" range="-180.0000 180.0000"/>
            <joint name="2_Spine2_x" type="hinge" pos="0.0026 0.0737 0.0280" axis="1.0000 0.0000 0.0000" range="-180.0000 180.0000"/>
            <geom type="mesh" mesh="Spine2" contype="1" conaffinity="1"/>
            <body name="2_Neck" pos="-0.0002 0.2876 -0.0148" quat="1.0000 0.0000 0.0000 0.0000">
              <joint name="2_Neck_z" type="hinge" pos="-0.0002 0.2876 -0.0148" axis="0.0000 0.0000 1.0000" range="-180.0000 180.0000"/>
              <joint name="2_Neck_y" type="hinge" pos="-0.0002 0.2876 -0.0148" axis="0.0000 1.0000 0.0000" range="-180.0000 180.0000"/>
              <joint name="2_Neck_x" type="hinge" pos="-0.0002 0.2876 -0.0148" axis="1.0000 0.0000 0.0000" range="-180.0000 180.0000"/>
              <geom type="mesh" mesh="Neck" contype="1" conaffinity="1"/>
              <body name="2_Mouth" pos="0.0050 0.3526 0.0365" quat="1.0000 0.0000 0.0000 0.0000">
                <joint name="2_Mouth_z" type="hinge" pos="0.0050 0.3526 0.0365" axis="0.0000 0.0000 1.0000" range="-180.0000 180.0000"/>
                <joint name="2_Mouth_y" type="hinge" pos="0.0050 0.3526 0.0365" axis="0.0000 1.0000 0.0000" range="-180.0000 180.0000"/>
                <joint name="2_Mouth_x" type="hinge" pos="0.0050 0.3526 0.0365" axis="1.0000 0.0000 0.0000" range="-180.0000 180.0000"/>
                <geom type="mesh" mesh="Mouth" contype="1" conaffinity="1"/>
              </body>
            </body>
            <body name="2_LeftChest" pos="0.0815 0.1955 -0.0060" quat="1.0000 0.0000 0.0000 0.0000">
              <joint name="2_LeftChest_z" type="hinge" pos="0.0815 0.1955 -0.0060" axis="0.0000 0.0000 1.0000" range="-180.0000 180.0000"/>
              <joint name="2_LeftChest_y" type="hinge" pos="0.0815 0.1955 -0.0060" axis="0.0000 1.0000 0.0000" range="-180.0000 180.0000"/>
              <joint name="2_LeftChest_x" type="hinge" pos="0.0815 0.1955 -0.0060" axis="1.0000 0.0000 0.0000" range="-180.0000 180.0000"/>
              <geom type="mesh" mesh="LeftChest" contype="1" conaffinity="1"/>
              <body name="2_LeftShoulder" pos="0.1724 0.2260 -0.0149" quat="1.0000 0.0000 0.0000 0.0000">
                <joint name="2_LeftShoulder_z" type="hinge" pos="0.1724 0.2260 -0.0149" axis="0.0000 0.0000 1.0000" range="-180.0000 180.0000"/>
                <joint name="2_LeftShoulder_y" type="hinge" pos="0.1724 0.2260 -0.0149" axis="0.0000 1.0000 0.0000" range="-180.0000 180.0000"/>
                <joint name="2_LeftShoulder_x" type="hinge" pos="0.1724 0.2260 -0.0149" axis="1.0000 0.0000 0.0000" range="-180.0000 180.0000"/>
                <geom type="mesh" mesh="LeftShoulder" contype="1" conaffinity="1"/>
                <body name="2_LeftArm" pos="0.4320 0.2132 -0.0424" quat="1.0000 0.0000 0.0000 0.0000">
                  <joint name="2_LeftArm_z" type="hinge" pos="0.4320 0.2132 -0.0424" axis="0.0000 0.0000 1.0000" range="-720.0000 720.0000"/>
                  <joint name="2_LeftArm_y" type="hinge" pos="0.4320 0.2132 -0.0424" axis="0.0000 1.0000 0.0000" range="-720.0000 720.0000"/>
                  <joint name="2_LeftArm_x" type="hinge" pos="0.4320 0.2132 -0.0424" axis="1.0000 0.0000 0.0000" range="-720.0000 720.0000"/>
                  <geom type="mesh" mesh="LeftArm" contype="1" conaffinity="1"/>
                  <body name="2_LeftWrist" pos="0.6813 0.2222 -0.0435" quat="1.0000 0.0000 0.0000 0.0000">
                    <joint name="2_LeftWrist_z" type="hinge" pos="0.6813 0.2222 -0.0435" axis="0.0000 0.0000 1.0000" range="-180.0000 180.0000"/>
                    <joint name="2_LeftWrist_y" type="hinge" pos="0.6813 0.2222 -0.0435" axis="0.0000 1.0000 0.0000" range="-180.0000 180.0000"/>
                    <joint name="2_LeftWrist_x" type="hinge" pos="0.6813 0.2222 -0.0435" axis="1.0000 0.0000 0.0000" range="-180.0000 180.0000"/>
                    <geom type="mesh" mesh="LeftWrist" contype="1" conaffinity="1"/>
                    <body name="2_LeftHand" pos="0.7653 0.2140 -0.0585" quat="1.0000 0.0000 0.0000 0.0000">
                      <joint name="2_LeftHand_z" type="hinge" pos="0.7653 0.2140 -0.0585" axis="0.0000 0.0000 1.0000" range="-180.0000 180.0000"/>
                      <joint name="2_LeftHand_y" type="hinge" pos="0.7653 0.2140 -0.0585" axis="0.0000 1.0000 0.0000" range="-180.0000 180.0000"/>
                      <joint name="2_LeftHand_x" type="hinge" pos="0.7653 0.2140 -0.0585" axis="1.0000 0.0000 0.0000" range="-180.0000 180.0000"/>
                      <geom type="mesh" mesh="LeftHand" contype="1" conaffinity="1"/>
                    </body>
                  </body>
                </body>
              </body>
            </body>
            <body name="2_RightChest" pos="-0.0791 0.1926 -0.0106" quat="1.0000 0.0000 0.0000 0.0000">
              <joint name="2_RightChest_z" type="hinge" pos="-0.0791 0.1926 -0.0106" axis="0.0000 0.0000 1.0000" range="-180.0000 180.0000"/>
              <joint name="2_RightChest_y" type="hinge" pos="-0.0791 0.1926 -0.0106" axis="0.0000 1.0000 0.0000" range="-180.0000 180.0000"/>
              <joint name="2_RightChest_x" type="hinge" pos="-0.0791 0.1926 -0.0106" axis="1.0000 0.0000 0.0000" range="-180.0000 180.0000"/>
              <geom type="mesh" mesh="RightChest" contype="1" conaffinity="1"/>
              <body name="2_RightShoulder" pos="-0.1752 0.2251 -0.0197" quat="1.0000 0.0000 0.0000 0.0000">
                <joint name="2_RightShoulder_z" type="hinge" pos="-0.1752 0.2251 -0.0197" axis="0.0000 0.0000 1.0000" range="-180.0000 180.0000"/>
                <joint name="2_RightShoulder_y" type="hinge" pos="-0.1752 0.2251 -0.0197" axis="0.0000 1.0000 0.0000" range="-180.0000 180.0000"/>
                <joint name="2_RightShoulder_x" type="hinge" pos="-0.1752 0.2251 -0.0197" axis="1.0000 0.0000 0.0000" range="-180.0000 180.0000"/>
                <geom type="mesh" mesh="RightShoulder" contype="1" conaffinity="1"/>
                <body name="2_RightArm" pos="-0.4289 0.2118 -0.0411" quat="1.0000 0.0000 0.0000 0.0000">
                  <joint name="2_RightArm_z" type="hinge" pos="-0.4289 0.2118 -0.0411" axis="0.0000 0.0000 1.0000" range="-720.0000 720.0000"/>
                  <joint name="2_RightArm_y" type="hinge" pos="-0.4289 0.2118 -0.0411" axis="0.0000 1.0000 0.0000" range="-720.0000 720.0000"/>
                  <joint name="2_RightArm_x" type="hinge" pos="-0.4289 0.2118 -0.0411" axis="1.0000 0.0000 0.0000" range="-720.0000 720.0000"/>
                  <geom type="mesh" mesh="RightArm" contype="1" conaffinity="1"/>
                  <body name="2_RightWrist" pos="-0.6842 0.2196 -0.0467" quat="1.0000 0.0000 0.0000 0.0000">
                    <joint name="2_RightWrist_z" type="hinge" pos="-0.6842 0.2196 -0.0467" axis="0.0000 0.0000 1.0000" range="-180.0000 180.0000"/>
                    <joint name="2_RightWrist_y" type="hinge" pos="-0.6842 0.2196 -0.0467" axis="0.0000 1.0000 0.0000" range="-180.0000 180.0000"/>
                    <joint name="2_RightWrist_x" type="hinge" pos="-0.6842 0.2196 -0.0467" axis="1.0000 0.0000 0.0000" range="-180.0000 180.0000"/>
                    <geom type="mesh" mesh="RightWrist" contype="1" conaffinity="1"/>
                    <body name="2_RightHand" pos="-0.7688 0.2134 -0.0570" quat="1.0000 0.0000 0.0000 0.0000">
                      <joint name="2_RightHand_z" type="hinge" pos="-0.7688 0.2134 -0.0570" axis="0.0000 0.0000 1.0000" range="-180.0000 180.0000"/>
                      <joint name="2_RightHand_y" type="hinge" pos="-0.7688 0.2134 -0.0570" axis="0.0000 1.0000 0.0000" range="-180.0000 180.0000"/>
                      <joint name="2_RightHand_x" type="hinge" pos="-0.7688 0.2134 -0.0570" axis="1.0000 0.0000 0.0000" range="-180.0000 180.0000"/>
                      <geom type="mesh" mesh="RightHand" contype="1" conaffinity="1"/>
                    </body>
                  </body>
                </body>
              </body>
            </body>
          </body>
        </body>
      </body>
    </body>
    <body name="3_Hips" pos="-0.0018 -0.2233 0.0282" quat="1.0000 0.0000 0.0000 0.0000">
      <joint name="3_Hips" pos="-0.0018 -0.2233 0.0282" limited="false" type="free" armature="0" damping="0" stiffness="0"/>
      <geom type="mesh" mesh="Hips" contype="1" conaffinity="1"/>
      <body name="3_LeftUpLeg" pos="0.0677 -0.3147 0.0214" quat="1.0000 0.0000 0.0000 0.0000">
        <joint name="3_LeftUpLeg_z" type="hinge" pos="0.0677 -0.3147 0.0214" axis="0.0000 0.0000 1.0000" range="-180.0000 180.0000"/>
        <joint name="3_LeftUpLeg_y" type="hinge" pos="0.0677 -0.3147 0.0214" axis="0.0000 1.0000 0.0000" range="-180.0000 180.0000"/>
        <joint name="3_LeftUpLeg_x" type="hinge" pos="0.0677 -0.3147 0.0214" axis="1.0000 0.0000 0.0000" range="-180.0000 180.0000"/>
        <geom type="mesh" mesh="LeftUpLeg" contype="1" conaffinity="1"/>
        <body name="3_LeftLeg" pos="0.1020 -0.6899 0.0169" quat="1.0000 0.0000 0.0000 0.0000">
          <joint name="3_LeftLeg_z" type="hinge" pos="0.1020 -0.6899 0.0169" axis="0.0000 0.0000 1.0000" range="-180.0000 180.0000"/>
          <joint name="3_LeftLeg_y" type="hinge" pos="0.1020 -0.6899 0.0169" axis="0.0000 1.0000 0.0000" range="-180.0000 180.0000"/>
          <joint name="3_LeftLeg_x" type="hinge" pos="0.1020 -0.6899 0.0169" axis="1.0000 0.0000 0.0000" range="-180.0000 180.0000"/>
          <geom type="mesh" mesh="LeftLeg" contype="1" conaffinity="1"/>
          <body name="3_LeftFoot" pos="0.0884 -1.0879 -0.0268" quat="1.0000 0.0000 0.0000 0.0000">
            <joint name="3_LeftFoot_z" type="hinge" pos="0.0884 -1.0879 -0.0268" axis="0.0000 0.0000 1.0000" range="-180.0000 180.0000"/>
            <joint name="3_LeftFoot_y" type="hinge" pos="0.0884 -1.0879 -0.0268" axis="0.0000 1.0000 0.0000" range="-180.0000 180.0000"/>
            <joint name="3_LeftFoot_x" type="hinge" pos="0.0884 -1.0879 -0.0268" axis="1.0000 0.0000 0.0000" range="-180.0000 180.0000"/>
            <geom type="mesh" mesh="LeftFoot" contype="1" conaffinity="1"/>
            <body name="3_LeftToe" pos="0.1148 -1.1437 0.0925" quat="1.0000 0.0000 0.0000 0.0000">
              <joint name="3_LeftToe_z" type="hinge" pos="0.1148 -1.1437 0.0925" axis="0.0000 0.0000 1.0000" range="-180.0000 180.0000"/>
              <joint name="3_LeftToe_y" type="hinge" pos="0.1148 -1.1437 0.0925" axis="0.0000 1.0000 0.0000" range="-180.0000 180.0000"/>
              <joint name="3_LeftToe_x" type="hinge" pos="0.1148 -1.1437 0.0925" axis="1.0000 0.0000 0.0000" range="-180.0000 180.0000"/>
              <geom type="mesh" mesh="LeftToe" contype="1" conaffinity="1"/>
            </body>
          </body>
        </body>
      </body>
      <body name="3_RightUpLeg" pos="-0.0695 -0.3139 0.0239" quat="1.0000 0.0000 0.0000 0.0000">
        <joint name="3_RightUpLeg_z" type="hinge" pos="-0.0695 -0.3139 0.0239" axis="0.0000 0.0000 1.0000" range="-180.0000 180.0000"/>
        <joint name="3_RightUpLeg_y" type="hinge" pos="-0.0695 -0.3139 0.0239" axis="0.0000 1.0000 0.0000" range="-180.0000 180.0000"/>
        <joint name="3_RightUpLeg_x" type="hinge" pos="-0.0695 -0.3139 0.0239" axis="1.0000 0.0000 0.0000" range="-180.0000 180.0000"/>
        <geom type="mesh" mesh="RightUpLeg" contype="1" conaffinity="1"/>
        <body name="3_RightLeg" pos="-0.1078 -0.6964 0.0150" quat="1.0000 0.0000 0.0000 0.0000">
          <joint name="3_RightLeg_z" type="hinge" pos="-0.1078 -0.6964 0.0150" axis="0.0000 0.0000 1.0000" range="-180.0000 180.0000"/>
          <joint name="3_RightLeg_y" type="hinge" pos="-0.1078 -0.6964 0.0150" axis="0.0000 1.0000 0.0000" range="-180.0000 180.0000"/>
          <joint name="3_RightLeg_x" type="hinge" pos="-0.1078 -0.6964 0.0150" axis="1.0000 0.0000 0.0000" range="-180.0000 180.0000"/>
          <geom type="mesh" mesh="RightLeg" contype="1" conaffinity="1"/>
          <body name="3_RightFoot" pos="-0.0920 -1.0948 -0.0273" quat="1.0000 0.0000 0.0000 0.0000">
            <joint name="3_RightFoot_z" type="hinge" pos="-0.0920 -1.0948 -0.0273" axis="0.0000 0.0000 1.0000" range="-180.0000 180.0000"/>
            <joint name="3_RightFoot_y" type="hinge" pos="-0.0920 -1.0948 -0.0273" axis="0.0000 1.0000 0.0000" range="-180.0000 180.0000"/>
            <joint name="3_RightFoot_x" type="hinge" pos="-0.0920 -1.0948 -0.0273" axis="1.0000 0.0000 0.0000" range="-180.0000 180.0000"/>
            <geom type="mesh" mesh="RightFoot" contype="1" conaffinity="1"/>
            <body name="3_RightToe" pos="-0.1174 -1.1430 0.0961" quat="1.0000 0.0000 0.0000 0.0000">
              <joint name="3_RightToe_z" type="hinge" pos="-0.1174 -1.1430 0.0961" axis="0.0000 0.0000 1.0000" range="-180.0000 180.0000"/>
              <joint name="3_RightToe_y" type="hinge" pos="-0.1174 -1.1430 0.0961" axis="0.0000 1.0000 0.0000" range="-180.0000 180.0000"/>
              <joint name="3_RightToe_x" type="hinge" pos="-0.1174 -1.1430 0.0961" axis="1.0000 0.0000 0.0000" range="-180.0000 180.0000"/>
              <geom type="mesh" mesh="RightToe" contype="1" conaffinity="1"/>
            </body>
          </body>
        </body>
      </body>
      <body name="3_Spine" pos="-0.0043 -0.1144 0.0015" quat="1.0000 0.0000 0.0000 0.0000">
        <joint name="3_Spine_z" type="hinge" pos="-0.0043 -0.1144 0.0015" axis="0.0000 0.0000 1.0000" range="-180.0000 180.0000"/>
        <joint name="3_Spine_y" type="hinge" pos="-0.0043 -0.1144 0.0015" axis="0.0000 1.0000 0.0000" range="-180.0000 180.0000"/>
        <joint name="3_Spine_x" type="hinge" pos="-0.0043 -0.1144 0.0015" axis="1.0000 0.0000 0.0000" range="-180.0000 180.0000"/>
        <geom type="mesh" mesh="Spine" contype="1" conaffinity="1"/>
        <body name="3_Spine1" pos="0.0012 0.0208 0.0026" quat="1.0000 0.0000 0.0000 0.0000">
          <joint name="3_Spine1_z" type="hinge" pos="0.0012 0.0208 0.0026" axis="0.0000 0.0000 1.0000" range="-180.0000 180.0000"/>
          <joint name="3_Spine1_y" type="hinge" pos="0.0012 0.0208 0.0026" axis="0.0000 1.0000 0.0000" range="-180.0000 180.0000"/>
          <joint name="3_Spine1_x" type="hinge" pos="0.0012 0.0208 0.0026" axis="1.0000 0.0000 0.0000" range="-180.0000 180.0000"/>
          <geom type="mesh" mesh="Spine1" contype="1" conaffinity="1"/>
          <body name="3_Spine2" pos="0.0026 0.0737 0.0280" quat="1.0000 0.0000 0.0000 0.0000">
            <joint name="3_Spine2_z" type="hinge" pos="0.0026 0.0737 0.0280" axis="0.0000 0.0000 1.0000" range="-180.0000 180.0000"/>
            <joint name="3_Spine2_y" type="hinge" pos="0.0026 0.0737 0.0280" axis="0.0000 1.0000 0.0000" range="-180.0000 180.0000"/>
            <joint name="3_Spine2_x" type="hinge" pos="0.0026 0.0737 0.0280" axis="1.0000 0.0000 0.0000" range="-180.0000 180.0000"/>
            <geom type="mesh" mesh="Spine2" contype="1" conaffinity="1"/>
            <body name="3_Neck" pos="-0.0002 0.2876 -0.0148" quat="1.0000 0.0000 0.0000 0.0000">
              <joint name="3_Neck_z" type="hinge" pos="-0.0002 0.2876 -0.0148" axis="0.0000 0.0000 1.0000" range="-180.0000 180.0000"/>
              <joint name="3_Neck_y" type="hinge" pos="-0.0002 0.2876 -0.0148" axis="0.0000 1.0000 0.0000" range="-180.0000 180.0000"/>
              <joint name="3_Neck_x" type="hinge" pos="-0.0002 0.2876 -0.0148" axis="1.0000 0.0000 0.0000" range="-180.0000 180.0000"/>
              <geom type="mesh" mesh="Neck" contype="1" conaffinity="1"/>
              <body name="3_Mouth" pos="0.0050 0.3526 0.0365" quat="1.0000 0.0000 0.0000 0.0000">
                <joint name="3_Mouth_z" type="hinge" pos="0.0050 0.3526 0.0365" axis="0.0000 0.0000 1.0000" range="-180.0000 180.0000"/>
                <joint name="3_Mouth_y" type="hinge" pos="0.0050 0.3526 0.0365" axis="0.0000 1.0000 0.0000" range="-180.0000 180.0000"/>
                <joint name="3_Mouth_x" type="hinge" pos="0.0050 0.3526 0.0365" axis="1.0000 0.0000 0.0000" range="-180.0000 180.0000"/>
                <geom type="mesh" mesh="Mouth" contype="1" conaffinity="1"/>
              </body>
            </body>
            <body name="3_LeftChest" pos="0.0815 0.1955 -0.0060" quat="1.0000 0.0000 0.0000 0.0000">
              <joint name="3_LeftChest_z" type="hinge" pos="0.0815 0.1955 -0.0060" axis="0.0000 0.0000 1.0000" range="-180.0000 180.0000"/>
              <joint name="3_LeftChest_y" type="hinge" pos="0.0815 0.1955 -0.0060" axis="0.0000 1.0000 0.0000" range="-180.0000 180.0000"/>
              <joint name="3_LeftChest_x" type="hinge" pos="0.0815 0.1955 -0.0060" axis="1.0000 0.0000 0.0000" range="-180.0000 180.0000"/>
              <geom type="mesh" mesh="LeftChest" contype="1" conaffinity="1"/>
              <body name="3_LeftShoulder" pos="0.1724 0.2260 -0.0149" quat="1.0000 0.0000 0.0000 0.0000">
                <joint name="3_LeftShoulder_z" type="hinge" pos="0.1724 0.2260 -0.0149" axis="0.0000 0.0000 1.0000" range="-180.0000 180.0000"/>
                <joint name="3_LeftShoulder_y" type="hinge" pos="0.1724 0.2260 -0.0149" axis="0.0000 1.0000 0.0000" range="-180.0000 180.0000"/>
                <joint name="3_LeftShoulder_x" type="hinge" pos="0.1724 0.2260 -0.0149" axis="1.0000 0.0000 0.0000" range="-180.0000 180.0000"/>
                <geom type="mesh" mesh="LeftShoulder" contype="1" conaffinity="1"/>
                <body name="3_LeftArm" pos="0.4320 0.2132 -0.0424" quat="1.0000 0.0000 0.0000 0.0000">
                  <joint name="3_LeftArm_z" type="hinge" pos="0.4320 0.2132 -0.0424" axis="0.0000 0.0000 1.0000" range="-720.0000 720.0000"/>
                  <joint name="3_LeftArm_y" type="hinge" pos="0.4320 0.2132 -0.0424" axis="0.0000 1.0000 0.0000" range="-720.0000 720.0000"/>
                  <joint name="3_LeftArm_x" type="hinge" pos="0.4320 0.2132 -0.0424" axis="1.0000 0.0000 0.0000" range="-720.0000 720.0000"/>
                  <geom type="mesh" mesh="LeftArm" contype="1" conaffinity="1"/>
                  <body name="3_LeftWrist" pos="0.6813 0.2222 -0.0435" quat="1.0000 0.0000 0.0000 0.0000">
                    <joint name="3_LeftWrist_z" type="hinge" pos="0.6813 0.2222 -0.0435" axis="0.0000 0.0000 1.0000" range="-180.0000 180.0000"/>
                    <joint name="3_LeftWrist_y" type="hinge" pos="0.6813 0.2222 -0.0435" axis="0.0000 1.0000 0.0000" range="-180.0000 180.0000"/>
                    <joint name="3_LeftWrist_x" type="hinge" pos="0.6813 0.2222 -0.0435" axis="1.0000 0.0000 0.0000" range="-180.0000 180.0000"/>
                    <geom type="mesh" mesh="LeftWrist" contype="1" conaffinity="1"/>
                    <body name="3_LeftHand" pos="0.7653 0.2140 -0.0585" quat="1.0000 0.0000 0.0000 0.0000">
                      <joint name="3_LeftHand_z" type="hinge" pos="0.7653 0.2140 -0.0585" axis="0.0000 0.0000 1.0000" range="-180.0000 180.0000"/>
                      <joint name="3_LeftHand_y" type="hinge" pos="0.7653 0.2140 -0.0585" axis="0.0000 1.0000 0.0000" range="-180.0000 180.0000"/>
                      <joint name="3_LeftHand_x" type="hinge" pos="0.7653 0.2140 -0.0585" axis="1.0000 0.0000 0.0000" range="-180.0000 180.0000"/>
                      <geom type="mesh" mesh="LeftHand" contype="1" conaffinity="1"/>
                    </body>
                  </body>
                </body>
              </body>
            </body>
            <body name="3_RightChest" pos="-0.0791 0.1926 -0.0106" quat="1.0000 0.0000 0.0000 0.0000">
              <joint name="3_RightChest_z" type="hinge" pos="-0.0791 0.1926 -0.0106" axis="0.0000 0.0000 1.0000" range="-180.0000 180.0000"/>
              <joint name="3_RightChest_y" type="hinge" pos="-0.0791 0.1926 -0.0106" axis="0.0000 1.0000 0.0000" range="-180.0000 180.0000"/>
              <joint name="3_RightChest_x" type="hinge" pos="-0.0791 0.1926 -0.0106" axis="1.0000 0.0000 0.0000" range="-180.0000 180.0000"/>
              <geom type="mesh" mesh="RightChest" contype="1" conaffinity="1"/>
              <body name="3_RightShoulder" pos="-0.1752 0.2251 -0.0197" quat="1.0000 0.0000 0.0000 0.0000">
                <joint name="3_RightShoulder_z" type="hinge" pos="-0.1752 0.2251 -0.0197" axis="0.0000 0.0000 1.0000" range="-180.0000 180.0000"/>
                <joint name="3_RightShoulder_y" type="hinge" pos="-0.1752 0.2251 -0.0197" axis="0.0000 1.0000 0.0000" range="-180.0000 180.0000"/>
                <joint name="3_RightShoulder_x" type="hinge" pos="-0.1752 0.2251 -0.0197" axis="1.0000 0.0000 0.0000" range="-180.0000 180.0000"/>
                <geom type="mesh" mesh="RightShoulder" contype="1" conaffinity="1"/>
                <body name="3_RightArm" pos="-0.4289 0.2118 -0.0411" quat="1.0000 0.0000 0.0000 0.0000">
                  <joint name="3_RightArm_z" type="hinge" pos="-0.4289 0.2118 -0.0411" axis="0.0000 0.0000 1.0000" range="-720.0000 720.0000"/>
                  <joint name="3_RightArm_y" type="hinge" pos="-0.4289 0.2118 -0.0411" axis="0.0000 1.0000 0.0000" range="-720.0000 720.0000"/>
                  <joint name="3_RightArm_x" type="hinge" pos="-0.4289 0.2118 -0.0411" axis="1.0000 0.0000 0.0000" range="-720.0000 720.0000"/>
                  <geom type="mesh" mesh="RightArm" contype="1" conaffinity="1"/>
                  <body name="3_RightWrist" pos="-0.6842 0.2196 -0.0467" quat="1.0000 0.0000 0.0000 0.0000">
                    <joint name="3_RightWrist_z" type="hinge" pos="-0.6842 0.2196 -0.0467" axis="0.0000 0.0000 1.0000" range="-180.0000 180.0000"/>
                    <joint name="3_RightWrist_y" type="hinge" pos="-0.6842 0.2196 -0.0467" axis="0.0000 1.0000 0.0000" range="-180.0000 180.0000"/>
                    <joint name="3_RightWrist_x" type="hinge" pos="-0.6842 0.2196 -0.0467" axis="1.0000 0.0000 0.0000" range="-180.0000 180.0000"/>
                    <geom type="mesh" mesh="RightWrist" contype="1" conaffinity="1"/>
                    <body name="3_RightHand" pos="-0.7688 0.2134 -0.0570" quat="1.0000 0.0000 0.0000 0.0000">
                      <joint name="3_RightHand_z" type="hinge" pos="-0.7688 0.2134 -0.0570" axis="0.0000 0.0000 1.0000" range="-180.0000 180.0000"/>
                      <joint name="3_RightHand_y" type="hinge" pos="-0.7688 0.2134 -0.0570" axis="0.0000 1.0000 0.0000" range="-180.0000 180.0000"/>
                      <joint name="3_RightHand_x" type="hinge" pos="-0.7688 0.2134 -0.0570" axis="1.0000 0.0000 0.0000" range="-180.0000 180.0000"/>
                      <geom type="mesh" mesh="RightHand" contype="1" conaffinity="1"/>
                    </body>
                  </body>
                </body>
              </body>
            </body>
          </body>
        </body>
      </body>
    </body>
    <body name="4_Hips" pos="-0.0018 -0.2233 0.0282" quat="1.0000 0.0000 0.0000 0.0000">
      <joint name="4_Hips" pos="-0.0018 -0.2233 0.0282" limited="false" type="free" armature="0" damping="0" stiffness="0"/>
      <geom type="mesh" mesh="Hips" contype="1" conaffinity="1"/>
      <body name="4_LeftUpLeg" pos="0.0677 -0.3147 0.0214" quat="1.0000 0.0000 0.0000 0.0000">
        <joint name="4_LeftUpLeg_z" type="hinge" pos="0.0677 -0.3147 0.0214" axis="0.0000 0.0000 1.0000" range="-180.0000 180.0000"/>
        <joint name="4_LeftUpLeg_y" type="hinge" pos="0.0677 -0.3147 0.0214" axis="0.0000 1.0000 0.0000" range="-180.0000 180.0000"/>
        <joint name="4_LeftUpLeg_x" type="hinge" pos="0.0677 -0.3147 0.0214" axis="1.0000 0.0000 0.0000" range="-180.0000 180.0000"/>
        <geom type="mesh" mesh="LeftUpLeg" contype="1" conaffinity="1"/>
        <body name="4_LeftLeg" pos="0.1020 -0.6899 0.0169" quat="1.0000 0.0000 0.0000 0.0000">
          <joint name="4_LeftLeg_z" type="hinge" pos="0.1020 -0.6899 0.0169" axis="0.0000 0.0000 1.0000" range="-180.0000 180.0000"/>
          <joint name="4_LeftLeg_y" type="hinge" pos="0.1020 -0.6899 0.0169" axis="0.0000 1.0000 0.0000" range="-180.0000 180.0000"/>
          <joint name="4_LeftLeg_x" type="hinge" pos="0.1020 -0.6899 0.0169" axis="1.0000 0.0000 0.0000" range="-180.0000 180.0000"/>
          <geom type="mesh" mesh="LeftLeg" contype="1" conaffinity="1"/>
          <body name="4_LeftFoot" pos="0.0884 -1.0879 -0.0268" quat="1.0000 0.0000 0.0000 0.0000">
            <joint name="4_LeftFoot_z" type="hinge" pos="0.0884 -1.0879 -0.0268" axis="0.0000 0.0000 1.0000" range="-180.0000 180.0000"/>
            <joint name="4_LeftFoot_y" type="hinge" pos="0.0884 -1.0879 -0.0268" axis="0.0000 1.0000 0.0000" range="-180.0000 180.0000"/>
            <joint name="4_LeftFoot_x" type="hinge" pos="0.0884 -1.0879 -0.0268" axis="1.0000 0.0000 0.0000" range="-180.0000 180.0000"/>
            <geom type="mesh" mesh="LeftFoot" contype="1" conaffinity="1"/>
            <body name="4_LeftToe" pos="0.1148 -1.1437 0.0925" quat="1.0000 0.0000 0.0000 0.0000">
              <joint name="4_LeftToe_z" type="hinge" pos="0.1148 -1.1437 0.0925" axis="0.0000 0.0000 1.0000" range="-180.0000 180.0000"/>
              <joint name="4_LeftToe_y" type="hinge" pos="0.1148 -1.1437 0.0925" axis="0.0000 1.0000 0.0000" range="-180.0000 180.0000"/>
              <joint name="4_LeftToe_x" type="hinge" pos="0.1148 -1.1437 0.0925" axis="1.0000 0.0000 0.0000" range="-180.0000 180.0000"/>
              <geom type="mesh" mesh="LeftToe" contype="1" conaffinity="1"/>
            </body>
          </body>
        </body>
      </body>
      <body name="4_RightUpLeg" pos="-0.0695 -0.3139 0.0239" quat="1.0000 0.0000 0.0000 0.0000">
        <joint name="4_RightUpLeg_z" type="hinge" pos="-0.0695 -0.3139 0.0239" axis="0.0000 0.0000 1.0000" range="-180.0000 180.0000"/>
        <joint name="4_RightUpLeg_y" type="hinge" pos="-0.0695 -0.3139 0.0239" axis="0.0000 1.0000 0.0000" range="-180.0000 180.0000"/>
        <joint name="4_RightUpLeg_x" type="hinge" pos="-0.0695 -0.3139 0.0239" axis="1.0000 0.0000 0.0000" range="-180.0000 180.0000"/>
        <geom type="mesh" mesh="RightUpLeg" contype="1" conaffinity="1"/>
        <body name="4_RightLeg" pos="-0.1078 -0.6964 0.0150" quat="1.0000 0.0000 0.0000 0.0000">
          <joint name="4_RightLeg_z" type="hinge" pos="-0.1078 -0.6964 0.0150" axis="0.0000 0.0000 1.0000" range="-180.0000 180.0000"/>
          <joint name="4_RightLeg_y" type="hinge" pos="-0.1078 -0.6964 0.0150" axis="0.0000 1.0000 0.0000" range="-180.0000 180.0000"/>
          <joint name="4_RightLeg_x" type="hinge" pos="-0.1078 -0.6964 0.0150" axis="1.0000 0.0000 0.0000" range="-180.0000 180.0000"/>
          <geom type="mesh" mesh="RightLeg" contype="1" conaffinity="1"/>
          <body name="4_RightFoot" pos="-0.0920 -1.0948 -0.0273" quat="1.0000 0.0000 0.0000 0.0000">
            <joint name="4_RightFoot_z" type="hinge" pos="-0.0920 -1.0948 -0.0273" axis="0.0000 0.0000 1.0000" range="-180.0000 180.0000"/>
            <joint name="4_RightFoot_y" type="hinge" pos="-0.0920 -1.0948 -0.0273" axis="0.0000 1.0000 0.0000" range="-180.0000 180.0000"/>
            <joint name="4_RightFoot_x" type="hinge" pos="-0.0920 -1.0948 -0.0273" axis="1.0000 0.0000 0.0000" range="-180.0000 180.0000"/>
            <geom type="mesh" mesh="RightFoot" contype="1" conaffinity="1"/>
            <body name="4_RightToe" pos="-0.1174 -1.1430 0.0961" quat="1.0000 0.0000 0.0000 0.0000">
              <joint name="4_RightToe_z" type="hinge" pos="-0.1174 -1.1430 0.0961" axis="0.0000 0.0000 1.0000" range="-180.0000 180.0000"/>
              <joint name="4_RightToe_y" type="hinge" pos="-0.1174 -1.1430 0.0961" axis="0.0000 1.0000 0.0000" range="-180.0000 180.0000"/>
              <joint name="4_RightToe_x" type="hinge" pos="-0.1174 -1.1430 0.0961" axis="1.0000 0.0000 0.0000" range="-180.0000 180.0000"/>
              <geom type="mesh" mesh="RightToe" contype="1" conaffinity="1"/>
            </body>
          </body>
        </body>
      </body>
      <body name="4_Spine" pos="-0.0043 -0.1144 0.0015" quat="1.0000 0.0000 0.0000 0.0000">
        <joint name="4_Spine_z" type="hinge" pos="-0.0043 -0.1144 0.0015" axis="0.0000 0.0000 1.0000" range="-180.0000 180.0000"/>
        <joint name="4_Spine_y" type="hinge" pos="-0.0043 -0.1144 0.0015" axis="0.0000 1.0000 0.0000" range="-180.0000 180.0000"/>
        <joint name="4_Spine_x" type="hinge" pos="-0.0043 -0.1144 0.0015" axis="1.0000 0.0000 0.0000" range="-180.0000 180.0000"/>
        <geom type="mesh" mesh="Spine" contype="1" conaffinity="1"/>
        <body name="4_Spine1" pos="0.0012 0.0208 0.0026" quat="1.0000 0.0000 0.0000 0.0000">
          <joint name="4_Spine1_z" type="hinge" pos="0.0012 0.0208 0.0026" axis="0.0000 0.0000 1.0000" range="-180.0000 180.0000"/>
          <joint name="4_Spine1_y" type="hinge" pos="0.0012 0.0208 0.0026" axis="0.0000 1.0000 0.0000" range="-180.0000 180.0000"/>
          <joint name="4_Spine1_x" type="hinge" pos="0.0012 0.0208 0.0026" axis="1.0000 0.0000 0.0000" range="-180.0000 180.0000"/>
          <geom type="mesh" mesh="Spine1" contype="1" conaffinity="1"/>
          <body name="4_Spine2" pos="0.0026 0.0737 0.0280" quat="1.0000 0.0000 0.0000 0.0000">
            <joint name="4_Spine2_z" type="hinge" pos="0.0026 0.0737 0.0280" axis="0.0000 0.0000 1.0000" range="-180.0000 180.0000"/>
            <joint name="4_Spine2_y" type="hinge" pos="0.0026 0.0737 0.0280" axis="0.0000 1.0000 0.0000" range="-180.0000 180.0000"/>
            <joint name="4_Spine2_x" type="hinge" pos="0.0026 0.0737 0.0280" axis="1.0000 0.0000 0.0000" range="-180.0000 180.0000"/>
            <geom type="mesh" mesh="Spine2" contype="1" conaffinity="1"/>
            <body name="4_Neck" pos="-0.0002 0.2876 -0.0148" quat="1.0000 0.0000 0.0000 0.0000">
              <joint name="4_Neck_z" type="hinge" pos="-0.0002 0.2876 -0.0148" axis="0.0000 0.0000 1.0000" range="-180.0000 180.0000"/>
              <joint name="4_Neck_y" type="hinge" pos="-0.0002 0.2876 -0.0148" axis="0.0000 1.0000 0.0000" range="-180.0000 180.0000"/>
              <joint name="4_Neck_x" type="hinge" pos="-0.0002 0.2876 -0.0148" axis="1.0000 0.0000 0.0000" range="-180.0000 180.0000"/>
              <geom type="mesh" mesh="Neck" contype="1" conaffinity="1"/>
              <body name="4_Mouth" pos="0.0050 0.3526 0.0365" quat="1.0000 0.0000 0.0000 0.0000">
                <joint name="4_Mouth_z" type="hinge" pos="0.0050 0.3526 0.0365" axis="0.0000 0.0000 1.0000" range="-180.0000 180.0000"/>
                <joint name="4_Mouth_y" type="hinge" pos="0.0050 0.3526 0.0365" axis="0.0000 1.0000 0.0000" range="-180.0000 180.0000"/>
                <joint name="4_Mouth_x" type="hinge" pos="0.0050 0.3526 0.0365" axis="1.0000 0.0000 0.0000" range="-180.0000 180.0000"/>
                <geom type="mesh" mesh="Mouth" contype="1" conaffinity="1"/>
              </body>
            </body>
            <body name="4_LeftChest" pos="0.0815 0.1955 -0.0060" quat="1.0000 0.0000 0.0000 0.0000">
              <joint name="4_LeftChest_z" type="hinge" pos="0.0815 0.1955 -0.0060" axis="0.0000 0.0000 1.0000" range="-180.0000 180.0000"/>
              <joint name="4_LeftChest_y" type="hinge" pos="0.0815 0.1955 -0.0060" axis="0.0000 1.0000 0.0000" range="-180.0000 180.0000"/>
              <joint name="4_LeftChest_x" type="hinge" pos="0.0815 0.1955 -0.0060" axis="1.0000 0.0000 0.0000" range="-180.0000 180.0000"/>
              <geom type="mesh" mesh="LeftChest" contype="1" conaffinity="1"/>
              <body name="4_LeftShoulder" pos="0.1724 0.2260 -0.0149" quat="1.0000 0.0000 0.0000 0.0000">
                <joint name="4_LeftShoulder_z" type="hinge" pos="0.1724 0.2260 -0.0149" axis="0.0000 0.0000 1.0000" range="-180.0000 180.0000"/>
                <joint name="4_LeftShoulder_y" type="hinge" pos="0.1724 0.2260 -0.0149" axis="0.0000 1.0000 0.0000" range="-180.0000 180.0000"/>
                <joint name="4_LeftShoulder_x" type="hinge" pos="0.1724 0.2260 -0.0149" axis="1.0000 0.0000 0.0000" range="-180.0000 180.0000"/>
                <geom type="mesh" mesh="LeftShoulder" contype="1" conaffinity="1"/>
                <body name="4_LeftArm" pos="0.4320 0.2132 -0.0424" quat="1.0000 0.0000 0.0000 0.0000">
                  <joint name="4_LeftArm_z" type="hinge" pos="0.4320 0.2132 -0.0424" axis="0.0000 0.0000 1.0000" range="-720.0000 720.0000"/>
                  <joint name="4_LeftArm_y" type="hinge" pos="0.4320 0.2132 -0.0424" axis="0.0000 1.0000 0.0000" range="-720.0000 720.0000"/>
                  <joint name="4_LeftArm_x" type="hinge" pos="0.4320 0.2132 -0.0424" axis="1.0000 0.0000 0.0000" range="-720.0000 720.0000"/>
                  <geom type="mesh" mesh="LeftArm" contype="1" conaffinity="1"/>
                  <body name="4_LeftWrist" pos="0.6813 0.2222 -0.0435" quat="1.0000 0.0000 0.0000 0.0000">
                    <joint name="4_LeftWrist_z" type="hinge" pos="0.6813 0.2222 -0.0435" axis="0.0000 0.0000 1.0000" range="-180.0000 180.0000"/>
                    <joint name="4_LeftWrist_y" type="hinge" pos="0.6813 0.2222 -0.0435" axis="0.0000 1.0000 0.0000" range="-180.0000 180.0000"/>
                    <joint name="4_LeftWrist_x" type="hinge" pos="0.6813 0.2222 -0.0435" axis="1.0000 0.0000 0.0000" range="-180.0000 180.0000"/>
                    <geom type="mesh" mesh="LeftWrist" contype="1" conaffinity="1"/>
                    <body name="4_LeftHand" pos="0.7653 0.2140 -0.0585" quat="1.0000 0.0000 0.0000 0.0000">
                      <joint name="4_LeftHand_z" type="hinge" pos="0.7653 0.2140 -0.0585" axis="0.0000 0.0000 1.0000" range="-180.0000 180.0000"/>
                      <joint name="4_LeftHand_y" type="hinge" pos="0.7653 0.2140 -0.0585" axis="0.0000 1.0000 0.0000" range="-180.0000 180.0000"/>
                      <joint name="4_LeftHand_x" type="hinge" pos="0.7653 0.2140 -0.0585" axis="1.0000 0.0000 0.0000" range="-180.0000 180.0000"/>
                      <geom type="mesh" mesh="LeftHand" contype="1" conaffinity="1"/>
                    </body>
                  </body>
                </body>
              </body>
            </body>
            <body name="4_RightChest" pos="-0.0791 0.1926 -0.0106" quat="1.0000 0.0000 0.0000 0.0000">
              <joint name="4_RightChest_z" type="hinge" pos="-0.0791 0.1926 -0.0106" axis="0.0000 0.0000 1.0000" range="-180.0000 180.0000"/>
              <joint name="4_RightChest_y" type="hinge" pos="-0.0791 0.1926 -0.0106" axis="0.0000 1.0000 0.0000" range="-180.0000 180.0000"/>
              <joint name="4_RightChest_x" type="hinge" pos="-0.0791 0.1926 -0.0106" axis="1.0000 0.0000 0.0000" range="-180.0000 180.0000"/>
              <geom type="mesh" mesh="RightChest" contype="1" conaffinity="1"/>
              <body name="4_RightShoulder" pos="-0.1752 0.2251 -0.0197" quat="1.0000 0.0000 0.0000 0.0000">
                <joint name="4_RightShoulder_z" type="hinge" pos="-0.1752 0.2251 -0.0197" axis="0.0000 0.0000 1.0000" range="-180.0000 180.0000"/>
                <joint name="4_RightShoulder_y" type="hinge" pos="-0.1752 0.2251 -0.0197" axis="0.0000 1.0000 0.0000" range="-180.0000 180.0000"/>
                <joint name="4_RightShoulder_x" type="hinge" pos="-0.1752 0.2251 -0.0197" axis="1.0000 0.0000 0.0000" range="-180.0000 180.0000"/>
                <geom type="mesh" mesh="RightShoulder" contype="1" conaffinity="1"/>
                <body name="4_RightArm" pos="-0.4289 0.2118 -0.0411" quat="1.0000 0.0000 0.0000 0.0000">
                  <joint name="4_RightArm_z" type="hinge" pos="-0.4289 0.2118 -0.0411" axis="0.0000 0.0000 1.0000" range="-720.0000 720.0000"/>
                  <joint name="4_RightArm_y" type="hinge" pos="-0.4289 0.2118 -0.0411" axis="0.0000 1.0000 0.0000" range="-720.0000 720.0000"/>
                  <joint name="4_RightArm_x" type="hinge" pos="-0.4289 0.2118 -0.0411" axis="1.0000 0.0000 0.0000" range="-720.0000 720.0000"/>
                  <geom type="mesh" mesh="RightArm" contype="1" conaffinity="1"/>
                  <body name="4_RightWrist" pos="-0.6842 0.2196 -0.0467" quat="1.0000 0.0000 0.0000 0.0000">
                    <joint name="4_RightWrist_z" type="hinge" pos="-0.6842 0.2196 -0.0467" axis="0.0000 0.0000 1.0000" range="-180.0000 180.0000"/>
                    <joint name="4_RightWrist_y" type="hinge" pos="-0.6842 0.2196 -0.0467" axis="0.0000 1.0000 0.0000" range="-180.0000 180.0000"/>
                    <joint name="4_RightWrist_x" type="hinge" pos="-0.6842 0.2196 -0.0467" axis="1.0000 0.0000 0.0000" range="-180.0000 180.0000"/>
                    <geom type="mesh" mesh="RightWrist" contype="1" conaffinity="1"/>
                    <body name="4_RightHand" pos="-0.7688 0.2134 -0.0570" quat="1.0000 0.0000 0.0000 0.0000">
                      <joint name="4_RightHand_z" type="hinge" pos="-0.7688 0.2134 -0.0570" axis="0.0000 0.0000 1.0000" range="-180.0000 180.0000"/>
                      <joint name="4_RightHand_y" type="hinge" pos="-0.7688 0.2134 -0.0570" axis="0.0000 1.0000 0.0000" range="-180.0000 180.0000"/>
                      <joint name="4_RightHand_x" type="hinge" pos="-0.7688 0.2134 -0.0570" axis="1.0000 0.0000 0.0000" range="-180.0000 180.0000"/>
                      <geom type="mesh" mesh="RightHand" contype="1" conaffinity="1"/>
                    </body>
                  </body>
                </body>
              </body>
            </body>
          </body>
        </body>
      </body>
    </body>
    <body name="5_Hips" pos="-0.0018 -0.2233 0.0282" quat="1.0000 0.0000 0.0000 0.0000">
      <joint name="5_Hips" pos="-0.0018 -0.2233 0.0282" limited="false" type="free" armature="0" damping="0" stiffness="0"/>
      <geom type="mesh" mesh="Hips" contype="1" conaffinity="1"/>
      <body name="5_LeftUpLeg" pos="0.0677 -0.3147 0.0214" quat="1.0000 0.0000 0.0000 0.0000">
        <joint name="5_LeftUpLeg_z" type="hinge" pos="0.0677 -0.3147 0.0214" axis="0.0000 0.0000 1.0000" range="-180.0000 180.0000"/>
        <joint name="5_LeftUpLeg_y" type="hinge" pos="0.0677 -0.3147 0.0214" axis="0.0000 1.0000 0.0000" range="-180.0000 180.0000"/>
        <joint name="5_LeftUpLeg_x" type="hinge" pos="0.0677 -0.3147 0.0214" axis="1.0000 0.0000 0.0000" range="-180.0000 180.0000"/>
        <geom type="mesh" mesh="LeftUpLeg" contype="1" conaffinity="1"/>
        <body name="5_LeftLeg" pos="0.1020 -0.6899 0.0169" quat="1.0000 0.0000 0.0000 0.0000">
          <joint name="5_LeftLeg_z" type="hinge" pos="0.1020 -0.6899 0.0169" axis="0.0000 0.0000 1.0000" range="-180.0000 180.0000"/>
          <joint name="5_LeftLeg_y" type="hinge" pos="0.1020 -0.6899 0.0169" axis="0.0000 1.0000 0.0000" range="-180.0000 180.0000"/>
          <joint name="5_LeftLeg_x" type="hinge" pos="0.1020 -0.6899 0.0169" axis="1.0000 0.0000 0.0000" range="-180.0000 180.0000"/>
          <geom type="mesh" mesh="LeftLeg" contype="1" conaffinity="1"/>
          <body name="5_LeftFoot" pos="0.0884 -1.0879 -0.0268" quat="1.0000 0.0000 0.0000 0.0000">
            <joint name="5_LeftFoot_z" type="hinge" pos="0.0884 -1.0879 -0.0268" axis="0.0000 0.0000 1.0000" range="-180.0000 180.0000"/>
            <joint name="5_LeftFoot_y" type="hinge" pos="0.0884 -1.0879 -0.0268" axis="0.0000 1.0000 0.0000" range="-180.0000 180.0000"/>
            <joint name="5_LeftFoot_x" type="hinge" pos="0.0884 -1.0879 -0.0268" axis="1.0000 0.0000 0.0000" range="-180.0000 180.0000"/>
            <geom type="mesh" mesh="LeftFoot" contype="1" conaffinity="1"/>
            <body name="5_LeftToe" pos="0.1148 -1.1437 0.0925" quat="1.0000 0.0000 0.0000 0.0000">
              <joint name="5_LeftToe_z" type="hinge" pos="0.1148 -1.1437 0.0925" axis="0.0000 0.0000 1.0000" range="-180.0000 180.0000"/>
              <joint name="5_LeftToe_y" type="hinge" pos="0.1148 -1.1437 0.0925" axis="0.0000 1.0000 0.0000" range="-180.0000 180.0000"/>
              <joint name="5_LeftToe_x" type="hinge" pos="0.1148 -1.1437 0.0925" axis="1.0000 0.0000 0.0000" range="-180.0000 180.0000"/>
              <geom type="mesh" mesh="LeftToe" contype="1" conaffinity="1"/>
            </body>
          </body>
        </body>
      </body>
      <body name="5_RightUpLeg" pos="-0.0695 -0.3139 0.0239" quat="1.0000 0.0000 0.0000 0.0000">
        <joint name="5_RightUpLeg_z" type="hinge" pos="-0.0695 -0.3139 0.0239" axis="0.0000 0.0000 1.0000" range="-180.0000 180.0000"/>
        <joint name="5_RightUpLeg_y" type="hinge" pos="-0.0695 -0.3139 0.0239" axis="0.0000 1.0000 0.0000" range="-180.0000 180.0000"/>
        <joint name="5_RightUpLeg_x" type="hinge" pos="-0.0695 -0.3139 0.0239" axis="1.0000 0.0000 0.0000" range="-180.0000 180.0000"/>
        <geom type="mesh" mesh="RightUpLeg" contype="1" conaffinity="1"/>
        <body name="5_RightLeg" pos="-0.1078 -0.6964 0.0150" quat="1.0000 0.0000 0.0000 0.0000">
          <joint name="5_RightLeg_z" type="hinge" pos="-0.1078 -0.6964 0.0150" axis="0.0000 0.0000 1.0000" range="-180.0000 180.0000"/>
          <joint name="5_RightLeg_y" type="hinge" pos="-0.1078 -0.6964 0.0150" axis="0.0000 1.0000 0.0000" range="-180.0000 180.0000"/>
          <joint name="5_RightLeg_x" type="hinge" pos="-0.1078 -0.6964 0.0150" axis="1.0000 0.0000 0.0000" range="-180.0000 180.0000"/>
          <geom type="mesh" mesh="RightLeg" contype="1" conaffinity="1"/>
          <body name="5_RightFoot" pos="-0.0920 -1.0948 -0.0273" quat="1.0000 0.0000 0.0000 0.0000">
            <joint name="5_RightFoot_z" type="hinge" pos="-0.0920 -1.0948 -0.0273" axis="0.0000 0.0000 1.0000" range="-180.0000 180.0000"/>
            <joint name="5_RightFoot_y" type="hinge" pos="-0.0920 -1.0948 -0.0273" axis="0.0000 1.0000 0.0000" range="-180.0000 180.0000"/>
            <joint name="5_RightFoot_x" type="hinge" pos="-0.0920 -1.0948 -0.0273" axis="1.0000 0.0000 0.0000" range="-180.0000 180.0000"/>
            <geom type="mesh" mesh="RightFoot" contype="1" conaffinity="1"/>
            <body name="5_RightToe" pos="-0.1174 -1.1430 0.0961" quat="1.0000 0.0000 0.0000 0.0000">
              <joint name="5_RightToe_z" type="hinge" pos="-0.1174 -1.1430 0.0961" axis="0.0000 0.0000 1.0000" range="-180.0000 180.0000"/>
              <joint name="5_RightToe_y" type="hinge" pos="-0.1174 -1.1430 0.0961" axis="0.0000 1.0000 0.0000" range="-180.0000 180.0000"/>
              <joint name="5_RightToe_x" type="hinge" pos="-0.1174 -1.1430 0.0961" axis="1.0000 0.0000 0.0000" range="-180.0000 180.0000"/>
              <geom type="mesh" mesh="RightToe" contype="1" conaffinity="1"/>
            </body>
          </body>
        </body>
      </body>
      <body name="5_Spine" pos="-0.0043 -0.1144 0.0015" quat="1.0000 0.0000 0.0000 0.0000">
        <joint name="5_Spine_z" type="hinge" pos="-0.0043 -0.1144 0.0015" axis="0.0000 0.0000 1.0000" range="-180.0000 180.0000"/>
        <joint name="5_Spine_y" type="hinge" pos="-0.0043 -0.1144 0.0015" axis="0.0000 1.0000 0.0000" range="-180.0000 180.0000"/>
        <joint name="5_Spine_x" type="hinge" pos="-0.0043 -0.1144 0.0015" axis="1.0000 0.0000 0.0000" range="-180.0000 180.0000"/>
        <geom type="mesh" mesh="Spine" contype="1" conaffinity="1"/>
        <body name="5_Spine1" pos="0.0012 0.0208 0.0026" quat="1.0000 0.0000 0.0000 0.0000">
          <joint name="5_Spine1_z" type="hinge" pos="0.0012 0.0208 0.0026" axis="0.0000 0.0000 1.0000" range="-180.0000 180.0000"/>
          <joint name="5_Spine1_y" type="hinge" pos="0.0012 0.0208 0.0026" axis="0.0000 1.0000 0.0000" range="-180.0000 180.0000"/>
          <joint name="5_Spine1_x" type="hinge" pos="0.0012 0.0208 0.0026" axis="1.0000 0.0000 0.0000" range="-180.0000 180.0000"/>
          <geom type="mesh" mesh="Spine1" contype="1" conaffinity="1"/>
          <body name="5_Spine2" pos="0.0026 0.0737 0.0280" quat="1.0000 0.0000 0.0000 0.0000">
            <joint name="5_Spine2_z" type="hinge" pos="0.0026 0.0737 0.0280" axis="0.0000 0.0000 1.0000" range="-180.0000 180.0000"/>
            <joint name="5_Spine2_y" type="hinge" pos="0.0026 0.0737 0.0280" axis="0.0000 1.0000 0.0000" range="-180.0000 180.0000"/>
            <joint name="5_Spine2_x" type="hinge" pos="0.0026 0.0737 0.0280" axis="1.0000 0.0000 0.0000" range="-180.0000 180.0000"/>
            <geom type="mesh" mesh="Spine2" contype="1" conaffinity="1"/>
            <body name="5_Neck" pos="-0.0002 0.2876 -0.0148" quat="1.0000 0.0000 0.0000 0.0000">
              <joint name="5_Neck_z" type="hinge" pos="-0.0002 0.2876 -0.0148" axis="0.0000 0.0000 1.0000" range="-180.0000 180.0000"/>
              <joint name="5_Neck_y" type="hinge" pos="-0.0002 0.2876 -0.0148" axis="0.0000 1.0000 0.0000" range="-180.0000 180.0000"/>
              <joint name="5_Neck_x" type="hinge" pos="-0.0002 0.2876 -0.0148" axis="1.0000 0.0000 0.0000" range="-180.0000 180.0000"/>
              <geom type="mesh" mesh="Neck" contype="1" conaffinity="1"/>
              <body name="5_Mouth" pos="0.0050 0.3526 0.0365" quat="1.0000 0.0000 0.0000 0.0000">
                <joint name="5_Mouth_z" type="hinge" pos="0.0050 0.3526 0.0365" axis="0.0000 0.0000 1.0000" range="-180.0000 180.0000"/>
                <joint name="5_Mouth_y" type="hinge" pos="0.0050 0.3526 0.0365" axis="0.0000 1.0000 0.0000" range="-180.0000 180.0000"/>
                <joint name="5_Mouth_x" type="hinge" pos="0.0050 0.3526 0.0365" axis="1.0000 0.0000 0.0000" range="-180.0000 180.0000"/>
                <geom type="mesh" mesh="Mouth" contype="1" conaffinity="1"/>
              </body>
            </body>
            <body name="5_LeftChest" pos="0.0815 0.1955 -0.0060" quat="1.0000 0.0000 0.0000 0.0000">
              <joint name="5_LeftChest_z" type="hinge" pos="0.0815 0.1955 -0.0060" axis="0.0000 0.0000 1.0000" range="-180.0000 180.0000"/>
              <joint name="5_LeftChest_y" type="hinge" pos="0.0815 0.1955 -0.0060" axis="0.0000 1.0000 0.0000" range="-180.0000 180.0000"/>
              <joint name="5_LeftChest_x" type="hinge" pos="0.0815 0.1955 -0.0060" axis="1.0000 0.0000 0.0000" range="-180.0000 180.0000"/>
              <geom type="mesh" mesh="LeftChest" contype="1" conaffinity="1"/>
              <body name="5_LeftShoulder" pos="0.1724 0.2260 -0.0149" quat="1.0000 0.0000 0.0000 0.0000">
                <joint name="5_LeftShoulder_z" type="hinge" pos="0.1724 0.2260 -0.0149" axis="0.0000 0.0000 1.0000" range="-180.0000 180.0000"/>
                <joint name="5_LeftShoulder_y" type="hinge" pos="0.1724 0.2260 -0.0149" axis="0.0000 1.0000 0.0000" range="-180.0000 180.0000"/>
                <joint name="5_LeftShoulder_x" type="hinge" pos="0.1724 0.2260 -0.0149" axis="1.0000 0.0000 0.0000" range="-180.0000 180.0000"/>
                <geom type="mesh" mesh="LeftShoulder" contype="1" conaffinity="1"/>
                <body name="5_LeftArm" pos="0.4320 0.2132 -0.0424" quat="1.0000 0.0000 0.0000 0.0000">
                  <joint name="5_LeftArm_z" type="hinge" pos="0.4320 0.2132 -0.0424" axis="0.0000 0.0000 1.0000" range="-720.0000 720.0000"/>
                  <joint name="5_LeftArm_y" type="hinge" pos="0.4320 0.2132 -0.0424" axis="0.0000 1.0000 0.0000" range="-720.0000 720.0000"/>
                  <joint name="5_LeftArm_x" type="hinge" pos="0.4320 0.2132 -0.0424" axis="1.0000 0.0000 0.0000" range="-720.0000 720.0000"/>
                  <geom type="mesh" mesh="LeftArm" contype="1" conaffinity="1"/>
                  <body name="5_LeftWrist" pos="0.6813 0.2222 -0.0435" quat="1.0000 0.0000 0.0000 0.0000">
                    <joint name="5_LeftWrist_z" type="hinge" pos="0.6813 0.2222 -0.0435" axis="0.0000 0.0000 1.0000" range="-180.0000 180.0000"/>
                    <joint name="5_LeftWrist_y" type="hinge" pos="0.6813 0.2222 -0.0435" axis="0.0000 1.0000 0.0000" range="-180.0000 180.0000"/>
                    <joint name="5_LeftWrist_x" type="hinge" pos="0.6813 0.2222 -0.0435" axis="1.0000 0.0000 0.0000" range="-180.0000 180.0000"/>
                    <geom type="mesh" mesh="LeftWrist" contype="1" conaffinity="1"/>
                    <body name="5_LeftHand" pos="0.7653 0.2140 -0.0585" quat="1.0000 0.0000 0.0000 0.0000">
                      <joint name="5_LeftHand_z" type="hinge" pos="0.7653 0.2140 -0.0585" axis="0.0000 0.0000 1.0000" range="-180.0000 180.0000"/>
                      <joint name="5_LeftHand_y" type="hinge" pos="0.7653 0.2140 -0.0585" axis="0.0000 1.0000 0.0000" range="-180.0000 180.0000"/>
                      <joint name="5_LeftHand_x" type="hinge" pos="0.7653 0.2140 -0.0585" axis="1.0000 0.0000 0.0000" range="-180.0000 180.0000"/>
                      <geom type="mesh" mesh="LeftHand" contype="1" conaffinity="1"/>
                    </body>
                  </body>
                </body>
              </body>
            </body>
            <body name="5_RightChest" pos="-0.0791 0.1926 -0.0106" quat="1.0000 0.0000 0.0000 0.0000">
              <joint name="5_RightChest_z" type="hinge" pos="-0.0791 0.1926 -0.0106" axis="0.0000 0.0000 1.0000" range="-180.0000 180.0000"/>
              <joint name="5_RightChest_y" type="hinge" pos="-0.0791 0.1926 -0.0106" axis="0.0000 1.0000 0.0000" range="-180.0000 180.0000"/>
              <joint name="5_RightChest_x" type="hinge" pos="-0.0791 0.1926 -0.0106" axis="1.0000 0.0000 0.0000" range="-180.0000 180.0000"/>
              <geom type="mesh" mesh="RightChest" contype="1" conaffinity="1"/>
              <body name="5_RightShoulder" pos="-0.1752 0.2251 -0.0197" quat="1.0000 0.0000 0.0000 0.0000">
                <joint name="5_RightShoulder_z" type="hinge" pos="-0.1752 0.2251 -0.0197" axis="0.0000 0.0000 1.0000" range="-180.0000 180.0000"/>
                <joint name="5_RightShoulder_y" type="hinge" pos="-0.1752 0.2251 -0.0197" axis="0.0000 1.0000 0.0000" range="-180.0000 180.0000"/>
                <joint name="5_RightShoulder_x" type="hinge" pos="-0.1752 0.2251 -0.0197" axis="1.0000 0.0000 0.0000" range="-180.0000 180.0000"/>
                <geom type="mesh" mesh="RightShoulder" contype="1" conaffinity="1"/>
                <body name="5_RightArm" pos="-0.4289 0.2118 -0.0411" quat="1.0000 0.0000 0.0000 0.0000">
                  <joint name="5_RightArm_z" type="hinge" pos="-0.4289 0.2118 -0.0411" axis="0.0000 0.0000 1.0000" range="-720.0000 720.0000"/>
                  <joint name="5_RightArm_y" type="hinge" pos="-0.4289 0.2118 -0.0411" axis="0.0000 1.0000 0.0000" range="-720.0000 720.0000"/>
                  <joint name="5_RightArm_x" type="hinge" pos="-0.4289 0.2118 -0.0411" axis="1.0000 0.0000 0.0000" range="-720.0000 720.0000"/>
                  <geom type="mesh" mesh="RightArm" contype="1" conaffinity="1"/>
                  <body name="5_RightWrist" pos="-0.6842 0.2196 -0.0467" quat="1.0000 0.0000 0.0000 0.0000">
                    <joint name="5_RightWrist_z" type="hinge" pos="-0.6842 0.2196 -0.0467" axis="0.0000 0.0000 1.0000" range="-180.0000 180.0000"/>
                    <joint name="5_RightWrist_y" type="hinge" pos="-0.6842 0.2196 -0.0467" axis="0.0000 1.0000 0.0000" range="-180.0000 180.0000"/>
                    <joint name="5_RightWrist_x" type="hinge" pos="-0.6842 0.2196 -0.0467" axis="1.0000 0.0000 0.0000" range="-180.0000 180.0000"/>
                    <geom type="mesh" mesh="RightWrist" contype="1" conaffinity="1"/>
                    <body name="5_RightHand" pos="-0.7688 0.2134 -0.0570" quat="1.0000 0.0000 0.0000 0.0000">
                      <joint name="5_RightHand_z" type="hinge" pos="-0.7688 0.2134 -0.0570" axis="0.0000 0.0000 1.0000" range="-180.0000 180.0000"/>
                      <joint name="5_RightHand_y" type="hinge" pos="-0.7688 0.2134 -0.0570" axis="0.0000 1.0000 0.0000" range="-180.0000 180.0000"/>
                      <joint name="5_RightHand_x" type="hinge" pos="-0.7688 0.2134 -0.0570" axis="1.0000 0.0000 0.0000" range="-180.0000 180.0000"/>
                      <geom type="mesh" mesh="RightHand" contype="1" conaffinity="1"/>
                    </body>
                  </body>
                </body>
              </body>
            </body>
          </body>
        </body>
      </body>
    </body>
    <body name="6_Hips" pos="-0.0018 -0.2233 0.0282" quat="1.0000 0.0000 0.0000 0.0000">
      <joint name="6_Hips" pos="-0.0018 -0.2233 0.0282" limited="false" type="free" armature="0" damping="0" stiffness="0"/>
      <geom type="mesh" mesh="Hips" contype="1" conaffinity="1"/>
      <body name="6_LeftUpLeg" pos="0.0677 -0.3147 0.0214" quat="1.0000 0.0000 0.0000 0.0000">
        <joint name="6_LeftUpLeg_z" type="hinge" pos="0.0677 -0.3147 0.0214" axis="0.0000 0.0000 1.0000" range="-180.0000 180.0000"/>
        <joint name="6_LeftUpLeg_y" type="hinge" pos="0.0677 -0.3147 0.0214" axis="0.0000 1.0000 0.0000" range="-180.0000 180.0000"/>
        <joint name="6_LeftUpLeg_x" type="hinge" pos="0.0677 -0.3147 0.0214" axis="1.0000 0.0000 0.0000" range="-180.0000 180.0000"/>
        <geom type="mesh" mesh="LeftUpLeg" contype="1" conaffinity="1"/>
        <body name="6_LeftLeg" pos="0.1020 -0.6899 0.0169" quat="1.0000 0.0000 0.0000 0.0000">
          <joint name="6_LeftLeg_z" type="hinge" pos="0.1020 -0.6899 0.0169" axis="0.0000 0.0000 1.0000" range="-180.0000 180.0000"/>
          <joint name="6_LeftLeg_y" type="hinge" pos="0.1020 -0.6899 0.0169" axis="0.0000 1.0000 0.0000" range="-180.0000 180.0000"/>
          <joint name="6_LeftLeg_x" type="hinge" pos="0.1020 -0.6899 0.0169" axis="1.0000 0.0000 0.0000" range="-180.0000 180.0000"/>
          <geom type="mesh" mesh="LeftLeg" contype="1" conaffinity="1"/>
          <body name="6_LeftFoot" pos="0.0884 -1.0879 -0.0268" quat="1.0000 0.0000 0.0000 0.0000">
            <joint name="6_LeftFoot_z" type="hinge" pos="0.0884 -1.0879 -0.0268" axis="0.0000 0.0000 1.0000" range="-180.0000 180.0000"/>
            <joint name="6_LeftFoot_y" type="hinge" pos="0.0884 -1.0879 -0.0268" axis="0.0000 1.0000 0.0000" range="-180.0000 180.0000"/>
            <joint name="6_LeftFoot_x" type="hinge" pos="0.0884 -1.0879 -0.0268" axis="1.0000 0.0000 0.0000" range="-180.0000 180.0000"/>
            <geom type="mesh" mesh="LeftFoot" contype="1" conaffinity="1"/>
            <body name="6_LeftToe" pos="0.1148 -1.1437 0.0925" quat="1.0000 0.0000 0.0000 0.0000">
              <joint name="6_LeftToe_z" type="hinge" pos="0.1148 -1.1437 0.0925" axis="0.0000 0.0000 1.0000" range="-180.0000 180.0000"/>
              <joint name="6_LeftToe_y" type="hinge" pos="0.1148 -1.1437 0.0925" axis="0.0000 1.0000 0.0000" range="-180.0000 180.0000"/>
              <joint name="6_LeftToe_x" type="hinge" pos="0.1148 -1.1437 0.0925" axis="1.0000 0.0000 0.0000" range="-180.0000 180.0000"/>
              <geom type="mesh" mesh="LeftToe" contype="1" conaffinity="1"/>
            </body>
          </body>
        </body>
      </body>
      <body name="6_RightUpLeg" pos="-0.0695 -0.3139 0.0239" quat="1.0000 0.0000 0.0000 0.0000">
        <joint name="6_RightUpLeg_z" type="hinge" pos="-0.0695 -0.3139 0.0239" axis="0.0000 0.0000 1.0000" range="-180.0000 180.0000"/>
        <joint name="6_RightUpLeg_y" type="hinge" pos="-0.0695 -0.3139 0.0239" axis="0.0000 1.0000 0.0000" range="-180.0000 180.0000"/>
        <joint name="6_RightUpLeg_x" type="hinge" pos="-0.0695 -0.3139 0.0239" axis="1.0000 0.0000 0.0000" range="-180.0000 180.0000"/>
        <geom type="mesh" mesh="RightUpLeg" contype="1" conaffinity="1"/>
        <body name="6_RightLeg" pos="-0.1078 -0.6964 0.0150" quat="1.0000 0.0000 0.0000 0.0000">
          <joint name="6_RightLeg_z" type="hinge" pos="-0.1078 -0.6964 0.0150" axis="0.0000 0.0000 1.0000" range="-180.0000 180.0000"/>
          <joint name="6_RightLeg_y" type="hinge" pos="-0.1078 -0.6964 0.0150" axis="0.0000 1.0000 0.0000" range="-180.0000 180.0000"/>
          <joint name="6_RightLeg_x" type="hinge" pos="-0.1078 -0.6964 0.0150" axis="1.0000 0.0000 0.0000" range="-180.0000 180.0000"/>
          <geom type="mesh" mesh="RightLeg" contype="1" conaffinity="1"/>
          <body name="6_RightFoot" pos="-0.0920 -1.0948 -0.0273" quat="1.0000 0.0000 0.0000 0.0000">
            <joint name="6_RightFoot_z" type="hinge" pos="-0.0920 -1.0948 -0.0273" axis="0.0000 0.0000 1.0000" range="-180.0000 180.0000"/>
            <joint name="6_RightFoot_y" type="hinge" pos="-0.0920 -1.0948 -0.0273" axis="0.0000 1.0000 0.0000" range="-180.0000 180.0000"/>
            <joint name="6_RightFoot_x" type="hinge" pos="-0.0920 -1.0948 -0.0273" axis="1.0000 0.0000 0.0000" range="-180.0000 180.0000"/>
            <geom type="mesh" mesh="RightFoot" contype="1" conaffinity="1"/>
            <body name="6_RightToe" pos="-0.1174 -1.1430 0.0961" quat="1.0000 0.0000 0.0000 0.0000">
              <joint name="6_RightToe_z" type="hinge" pos="-0.1174 -1.1430 0.0961" axis="0.0000 0.0000 1.0000" range="-180.0000 180.0000"/>
              <joint name="6_RightToe_y" type="hinge" pos="-0.1174 -1.1430 0.0961" axis="0.0000 1.0000 0.0000" range="-180.0000 180.0000"/>
              <joint name="6_RightToe_x" type="hinge" pos="-0.1174 -1.1430 0.0961" axis="1.0000 0.0000 0.0000" range="-180.0000 180.0000"/>
              <geom type="mesh" mesh="RightToe" contype="1" conaffinity="1"/>
            </body>
          </body>
        </body>
      </body>
      <body name="6_Spine" pos="-0.0043 -0.1144 0.0015" quat="1.0000 0.0000 0.0000 0.0000">
        <joint name="6_Spine_z" type="hinge" pos="-0.0043 -0.1144 0.0015" axis="0.0000 0.0000 1.0000" range="-180.0000 180.0000"/>
        <joint name="6_Spine_y" type="hinge" pos="-0.0043 -0.1144 0.0015" axis="0.0000 1.0000 0.0000" range="-180.0000 180.0000"/>
        <joint name="6_Spine_x" type="hinge" pos="-0.0043 -0.1144 0.0015" axis="1.0000 0.0000 0.0000" range="-180.0000 180.0000"/>
        <geom type="mesh" mesh="Spine" contype="1" conaffinity="1"/>
        <body name="6_Spine1" pos="0.0012 0.0208 0.0026" quat="1.0000 0.0000 0.0000 0.0000">
          <joint name="6_Spine1_z" type="hinge" pos="0.0012 0.0208 0.0026" axis="0.0000 0.0000 1.0000" range="-180.0000 180.0000"/>
          <joint name="6_Spine1_y" type="hinge" pos="0.0012 0.0208 0.0026" axis="0.0000 1.0000 0.0000" range="-180.0000 180.0000"/>
          <joint name="6_Spine1_x" type="hinge" pos="0.0012 0.0208 0.0026" axis="1.0000 0.0000 0.0000" range="-180.0000 180.0000"/>
          <geom type="mesh" mesh="Spine1" contype="1" conaffinity="1"/>
          <body name="6_Spine2" pos="0.0026 0.0737 0.0280" quat="1.0000 0.0000 0.0000 0.0000">
            <joint name="6_Spine2_z" type="hinge" pos="0.0026 0.0737 0.0280" axis="0.0000 0.0000 1.0000" range="-180.0000 180.0000"/>
            <joint name="6_Spine2_y" type="hinge" pos="0.0026 0.0737 0.0280" axis="0.0000 1.0000 0.0000" range="-180.0000 180.0000"/>
            <joint name="6_Spine2_x" type="hinge" pos="0.0026 0.0737 0.0280" axis="1.0000 0.0000 0.0000" range="-180.0000 180.0000"/>
            <geom type="mesh" mesh="Spine2" contype="1" conaffinity="1"/>
            <body name="6_Neck" pos="-0.0002 0.2876 -0.0148" quat="1.0000 0.0000 0.0000 0.0000">
              <joint name="6_Neck_z" type="hinge" pos="-0.0002 0.2876 -0.0148" axis="0.0000 0.0000 1.0000" range="-180.0000 180.0000"/>
              <joint name="6_Neck_y" type="hinge" pos="-0.0002 0.2876 -0.0148" axis="0.0000 1.0000 0.0000" range="-180.0000 180.0000"/>
              <joint name="6_Neck_x" type="hinge" pos="-0.0002 0.2876 -0.0148" axis="1.0000 0.0000 0.0000" range="-180.0000 180.0000"/>
              <geom type="mesh" mesh="Neck" contype="1" conaffinity="1"/>
              <body name="6_Mouth" pos="0.0050 0.3526 0.0365" quat="1.0000 0.0000 0.0000 0.0000">
                <joint name="6_Mouth_z" type="hinge" pos="0.0050 0.3526 0.0365" axis="0.0000 0.0000 1.0000" range="-180.0000 180.0000"/>
                <joint name="6_Mouth_y" type="hinge" pos="0.0050 0.3526 0.0365" axis="0.0000 1.0000 0.0000" range="-180.0000 180.0000"/>
                <joint name="6_Mouth_x" type="hinge" pos="0.0050 0.3526 0.0365" axis="1.0000 0.0000 0.0000" range="-180.0000 180.0000"/>
                <geom type="mesh" mesh="Mouth" contype="1" conaffinity="1"/>
              </body>
            </body>
            <body name="6_LeftChest" pos="0.0815 0.1955 -0.0060" quat="1.0000 0.0000 0.0000 0.0000">
              <joint name="6_LeftChest_z" type="hinge" pos="0.0815 0.1955 -0.0060" axis="0.0000 0.0000 1.0000" range="-180.0000 180.0000"/>
              <joint name="6_LeftChest_y" type="hinge" pos="0.0815 0.1955 -0.0060" axis="0.0000 1.0000 0.0000" range="-180.0000 180.0000"/>
              <joint name="6_LeftChest_x" type="hinge" pos="0.0815 0.1955 -0.0060" axis="1.0000 0.0000 0.0000" range="-180.0000 180.0000"/>
              <geom type="mesh" mesh="LeftChest" contype="1" conaffinity="1"/>
              <body name="6_LeftShoulder" pos="0.1724 0.2260 -0.0149" quat="1.0000 0.0000 0.0000 0.0000">
                <joint name="6_LeftShoulder_z" type="hinge" pos="0.1724 0.2260 -0.0149" axis="0.0000 0.0000 1.0000" range="-180.0000 180.0000"/>
                <joint name="6_LeftShoulder_y" type="hinge" pos="0.1724 0.2260 -0.0149" axis="0.0000 1.0000 0.0000" range="-180.0000 180.0000"/>
                <joint name="6_LeftShoulder_x" type="hinge" pos="0.1724 0.2260 -0.0149" axis="1.0000 0.0000 0.0000" range="-180.0000 180.0000"/>
                <geom type="mesh" mesh="LeftShoulder" contype="1" conaffinity="1"/>
                <body name="6_LeftArm" pos="0.4320 0.2132 -0.0424" quat="1.0000 0.0000 0.0000 0.0000">
                  <joint name="6_LeftArm_z" type="hinge" pos="0.4320 0.2132 -0.0424" axis="0.0000 0.0000 1.0000" range="-720.0000 720.0000"/>
                  <joint name="6_LeftArm_y" type="hinge" pos="0.4320 0.2132 -0.0424" axis="0.0000 1.0000 0.0000" range="-720.0000 720.0000"/>
                  <joint name="6_LeftArm_x" type="hinge" pos="0.4320 0.2132 -0.0424" axis="1.0000 0.0000 0.0000" range="-720.0000 720.0000"/>
                  <geom type="mesh" mesh="LeftArm" contype="1" conaffinity="1"/>
                  <body name="6_LeftWrist" pos="0.6813 0.2222 -0.0435" quat="1.0000 0.0000 0.0000 0.0000">
                    <joint name="6_LeftWrist_z" type="hinge" pos="0.6813 0.2222 -0.0435" axis="0.0000 0.0000 1.0000" range="-180.0000 180.0000"/>
                    <joint name="6_LeftWrist_y" type="hinge" pos="0.6813 0.2222 -0.0435" axis="0.0000 1.0000 0.0000" range="-180.0000 180.0000"/>
                    <joint name="6_LeftWrist_x" type="hinge" pos="0.6813 0.2222 -0.0435" axis="1.0000 0.0000 0.0000" range="-180.0000 180.0000"/>
                    <geom type="mesh" mesh="LeftWrist" contype="1" conaffinity="1"/>
                    <body name="6_LeftHand" pos="0.7653 0.2140 -0.0585" quat="1.0000 0.0000 0.0000 0.0000">
                      <joint name="6_LeftHand_z" type="hinge" pos="0.7653 0.2140 -0.0585" axis="0.0000 0.0000 1.0000" range="-180.0000 180.0000"/>
                      <joint name="6_LeftHand_y" type="hinge" pos="0.7653 0.2140 -0.0585" axis="0.0000 1.0000 0.0000" range="-180.0000 180.0000"/>
                      <joint name="6_LeftHand_x" type="hinge" pos="0.7653 0.2140 -0.0585" axis="1.0000 0.0000 0.0000" range="-180.0000 180.0000"/>
                      <geom type="mesh" mesh="LeftHand" contype="1" conaffinity="1"/>
                    </body>
                  </body>
                </body>
              </body>
            </body>
            <body name="6_RightChest" pos="-0.0791 0.1926 -0.0106" quat="1.0000 0.0000 0.0000 0.0000">
              <joint name="6_RightChest_z" type="hinge" pos="-0.0791 0.1926 -0.0106" axis="0.0000 0.0000 1.0000" range="-180.0000 180.0000"/>
              <joint name="6_RightChest_y" type="hinge" pos="-0.0791 0.1926 -0.0106" axis="0.0000 1.0000 0.0000" range="-180.0000 180.0000"/>
              <joint name="6_RightChest_x" type="hinge" pos="-0.0791 0.1926 -0.0106" axis="1.0000 0.0000 0.0000" range="-180.0000 180.0000"/>
              <geom type="mesh" mesh="RightChest" contype="1" conaffinity="1"/>
              <body name="6_RightShoulder" pos="-0.1752 0.2251 -0.0197" quat="1.0000 0.0000 0.0000 0.0000">
                <joint name="6_RightShoulder_z" type="hinge" pos="-0.1752 0.2251 -0.0197" axis="0.0000 0.0000 1.0000" range="-180.0000 180.0000"/>
                <joint name="6_RightShoulder_y" type="hinge" pos="-0.1752 0.2251 -0.0197" axis="0.0000 1.0000 0.0000" range="-180.0000 180.0000"/>
                <joint name="6_RightShoulder_x" type="hinge" pos="-0.1752 0.2251 -0.0197" axis="1.0000 0.0000 0.0000" range="-180.0000 180.0000"/>
                <geom type="mesh" mesh="RightShoulder" contype="1" conaffinity="1"/>
                <body name="6_RightArm" pos="-0.4289 0.2118 -0.0411" quat="1.0000 0.0000 0.0000 0.0000">
                  <joint name="6_RightArm_z" type="hinge" pos="-0.4289 0.2118 -0.0411" axis="0.0000 0.0000 1.0000" range="-720.0000 720.0000"/>
                  <joint name="6_RightArm_y" type="hinge" pos="-0.4289 0.2118 -0.0411" axis="0.0000 1.0000 0.0000" range="-720.0000 720.0000"/>
                  <joint name="6_RightArm_x" type="hinge" pos="-0.4289 0.2118 -0.0411" axis="1.0000 0.0000 0.0000" range="-720.0000 720.0000"/>
                  <geom type="mesh" mesh="RightArm" contype="1" conaffinity="1"/>
                  <body name="6_RightWrist" pos="-0.6842 0.2196 -0.0467" quat="1.0000 0.0000 0.0000 0.0000">
                    <joint name="6_RightWrist_z" type="hinge" pos="-0.6842 0.2196 -0.0467" axis="0.0000 0.0000 1.0000" range="-180.0000 180.0000"/>
                    <joint name="6_RightWrist_y" type="hinge" pos="-0.6842 0.2196 -0.0467" axis="0.0000 1.0000 0.0000" range="-180.0000 180.0000"/>
                    <joint name="6_RightWrist_x" type="hinge" pos="-0.6842 0.2196 -0.0467" axis="1.0000 0.0000 0.0000" range="-180.0000 180.0000"/>
                    <geom type="mesh" mesh="RightWrist" contype="1" conaffinity="1"/>
                    <body name="6_RightHand" pos="-0.7688 0.2134 -0.0570" quat="1.0000 0.0000 0.0000 0.0000">
                      <joint name="6_RightHand_z" type="hinge" pos="-0.7688 0.2134 -0.0570" axis="0.0000 0.0000 1.0000" range="-180.0000 180.0000"/>
                      <joint name="6_RightHand_y" type="hinge" pos="-0.7688 0.2134 -0.0570" axis="0.0000 1.0000 0.0000" range="-180.0000 180.0000"/>
                      <joint name="6_RightHand_x" type="hinge" pos="-0.7688 0.2134 -0.0570" axis="1.0000 0.0000 0.0000" range="-180.0000 180.0000"/>
                      <geom type="mesh" mesh="RightHand" contype="1" conaffinity="1"/>
                    </body>
                  </body>
                </body>
              </body>
            </body>
          </body>
        </body>
      </body>
    </body>
    <body name="7_Hips" pos="-0.0018 -0.2233 0.0282" quat="1.0000 0.0000 0.0000 0.0000">
      <joint name="7_Hips" pos="-0.0018 -0.2233 0.0282" limited="false" type="free" armature="0" damping="0" stiffness="0"/>
      <geom type="mesh" mesh="Hips" contype="1" conaffinity="1"/>
      <body name="7_LeftUpLeg" pos="0.0677 -0.3147 0.0214" quat="1.0000 0.0000 0.0000 0.0000">
        <joint name="7_LeftUpLeg_z" type="hinge" pos="0.0677 -0.3147 0.0214" axis="0.0000 0.0000 1.0000" range="-180.0000 180.0000"/>
        <joint name="7_LeftUpLeg_y" type="hinge" pos="0.0677 -0.3147 0.0214" axis="0.0000 1.0000 0.0000" range="-180.0000 180.0000"/>
        <joint name="7_LeftUpLeg_x" type="hinge" pos="0.0677 -0.3147 0.0214" axis="1.0000 0.0000 0.0000" range="-180.0000 180.0000"/>
        <geom type="mesh" mesh="LeftUpLeg" contype="1" conaffinity="1"/>
        <body name="7_LeftLeg" pos="0.1020 -0.6899 0.0169" quat="1.0000 0.0000 0.0000 0.0000">
          <joint name="7_LeftLeg_z" type="hinge" pos="0.1020 -0.6899 0.0169" axis="0.0000 0.0000 1.0000" range="-180.0000 180.0000"/>
          <joint name="7_LeftLeg_y" type="hinge" pos="0.1020 -0.6899 0.0169" axis="0.0000 1.0000 0.0000" range="-180.0000 180.0000"/>
          <joint name="7_LeftLeg_x" type="hinge" pos="0.1020 -0.6899 0.0169" axis="1.0000 0.0000 0.0000" range="-180.0000 180.0000"/>
          <geom type="mesh" mesh="LeftLeg" contype="1" conaffinity="1"/>
          <body name="7_LeftFoot" pos="0.0884 -1.0879 -0.0268" quat="1.0000 0.0000 0.0000 0.0000">
            <joint name="7_LeftFoot_z" type="hinge" pos="0.0884 -1.0879 -0.0268" axis="0.0000 0.0000 1.0000" range="-180.0000 180.0000"/>
            <joint name="7_LeftFoot_y" type="hinge" pos="0.0884 -1.0879 -0.0268" axis="0.0000 1.0000 0.0000" range="-180.0000 180.0000"/>
            <joint name="7_LeftFoot_x" type="hinge" pos="0.0884 -1.0879 -0.0268" axis="1.0000 0.0000 0.0000" range="-180.0000 180.0000"/>
            <geom type="mesh" mesh="LeftFoot" contype="1" conaffinity="1"/>
            <body name="7_LeftToe" pos="0.1148 -1.1437 0.0925" quat="1.0000 0.0000 0.0000 0.0000">
              <joint name="7_LeftToe_z" type="hinge" pos="0.1148 -1.1437 0.0925" axis="0.0000 0.0000 1.0000" range="-180.0000 180.0000"/>
              <joint name="7_LeftToe_y" type="hinge" pos="0.1148 -1.1437 0.0925" axis="0.0000 1.0000 0.0000" range="-180.0000 180.0000"/>
              <joint name="7_LeftToe_x" type="hinge" pos="0.1148 -1.1437 0.0925" axis="1.0000 0.0000 0.0000" range="-180.0000 180.0000"/>
              <geom type="mesh" mesh="LeftToe" contype="1" conaffinity="1"/>
            </body>
          </body>
        </body>
      </body>
      <body name="7_RightUpLeg" pos="-0.0695 -0.3139 0.0239" quat="1.0000 0.0000 0.0000 0.0000">
        <joint name="7_RightUpLeg_z" type="hinge" pos="-0.0695 -0.3139 0.0239" axis="0.0000 0.0000 1.0000" range="-180.0000 180.0000"/>
        <joint name="7_RightUpLeg_y" type="hinge" pos="-0.0695 -0.3139 0.0239" axis="0.0000 1.0000 0.0000" range="-180.0000 180.0000"/>
        <joint name="7_RightUpLeg_x" type="hinge" pos="-0.0695 -0.3139 0.0239" axis="1.0000 0.0000 0.0000" range="-180.0000 180.0000"/>
        <geom type="mesh" mesh="RightUpLeg" contype="1" conaffinity="1"/>
        <body name="7_RightLeg" pos="-0.1078 -0.6964 0.0150" quat="1.0000 0.0000 0.0000 0.0000">
          <joint name="7_RightLeg_z" type="hinge" pos="-0.1078 -0.6964 0.0150" axis="0.0000 0.0000 1.0000" range="-180.0000 180.0000"/>
          <joint name="7_RightLeg_y" type="hinge" pos="-0.1078 -0.6964 0.0150" axis="0.0000 1.0000 0.0000" range="-180.0000 180.0000"/>
          <joint name="7_RightLeg_x" type="hinge" pos="-0.1078 -0.6964 0.0150" axis="1.0000 0.0000 0.0000" range="-180.0000 180.0000"/>
          <geom type="mesh" mesh="RightLeg" contype="1" conaffinity="1"/>
          <body name="7_RightFoot" pos="-0.0920 -1.0948 -0.0273" quat="1.0000 0.0000 0.0000 0.0000">
            <joint name="7_RightFoot_z" type="hinge" pos="-0.0920 -1.0948 -0.0273" axis="0.0000 0.0000 1.0000" range="-180.0000 180.0000"/>
            <joint name="7_RightFoot_y" type="hinge" pos="-0.0920 -1.0948 -0.0273" axis="0.0000 1.0000 0.0000" range="-180.0000 180.0000"/>
            <joint name="7_RightFoot_x" type="hinge" pos="-0.0920 -1.0948 -0.0273" axis="1.0000 0.0000 0.0000" range="-180.0000 180.0000"/>
            <geom type="mesh" mesh="RightFoot" contype="1" conaffinity="1"/>
            <body name="7_RightToe" pos="-0.1174 -1.1430 0.0961" quat="1.0000 0.0000 0.0000 0.0000">
              <joint name="7_RightToe_z" type="hinge" pos="-0.1174 -1.1430 0.0961" axis="0.0000 0.0000 1.0000" range="-180.0000 180.0000"/>
              <joint name="7_RightToe_y" type="hinge" pos="-0.1174 -1.1430 0.0961" axis="0.0000 1.0000 0.0000" range="-180.0000 180.0000"/>
              <joint name="7_RightToe_x" type="hinge" pos="-0.1174 -1.1430 0.0961" axis="1.0000 0.0000 0.0000" range="-180.0000 180.0000"/>
              <geom type="mesh" mesh="RightToe" contype="1" conaffinity="1"/>
            </body>
          </body>
        </body>
      </body>
      <body name="7_Spine" pos="-0.0043 -0.1144 0.0015" quat="1.0000 0.0000 0.0000 0.0000">
        <joint name="7_Spine_z" type="hinge" pos="-0.0043 -0.1144 0.0015" axis="0.0000 0.0000 1.0000" range="-180.0000 180.0000"/>
        <joint name="7_Spine_y" type="hinge" pos="-0.0043 -0.1144 0.0015" axis="0.0000 1.0000 0.0000" range="-180.0000 180.0000"/>
        <joint name="7_Spine_x" type="hinge" pos="-0.0043 -0.1144 0.0015" axis="1.0000 0.0000 0.0000" range="-180.0000 180.0000"/>
        <geom type="mesh" mesh="Spine" contype="1" conaffinity="1"/>
        <body name="7_Spine1" pos="0.0012 0.0208 0.0026" quat="1.0000 0.0000 0.0000 0.0000">
          <joint name="7_Spine1_z" type="hinge" pos="0.0012 0.0208 0.0026" axis="0.0000 0.0000 1.0000" range="-180.0000 180.0000"/>
          <joint name="7_Spine1_y" type="hinge" pos="0.0012 0.0208 0.0026" axis="0.0000 1.0000 0.0000" range="-180.0000 180.0000"/>
          <joint name="7_Spine1_x" type="hinge" pos="0.0012 0.0208 0.0026" axis="1.0000 0.0000 0.0000" range="-180.0000 180.0000"/>
          <geom type="mesh" mesh="Spine1" contype="1" conaffinity="1"/>
          <body name="7_Spine2" pos="0.0026 0.0737 0.0280" quat="1.0000 0.0000 0.0000 0.0000">
            <joint name="7_Spine2_z" type="hinge" pos="0.0026 0.0737 0.0280" axis="0.0000 0.0000 1.0000" range="-180.0000 180.0000"/>
            <joint name="7_Spine2_y" type="hinge" pos="0.0026 0.0737 0.0280" axis="0.0000 1.0000 0.0000" range="-180.0000 180.0000"/>
            <joint name="7_Spine2_x" type="hinge" pos="0.0026 0.0737 0.0280" axis="1.0000 0.0000 0.0000" range="-180.0000 180.0000"/>
            <geom type="mesh" mesh="Spine2" contype="1" conaffinity="1"/>
            <body name="7_Neck" pos="-0.0002 0.2876 -0.0148" quat="1.0000 0.0000 0.0000 0.0000">
              <joint name="7_Neck_z" type="hinge" pos="-0.0002 0.2876 -0.0148" axis="0.0000 0.0000 1.0000" range="-180.0000 180.0000"/>
              <joint name="7_Neck_y" type="hinge" pos="-0.0002 0.2876 -0.0148" axis="0.0000 1.0000 0.0000" range="-180.0000 180.0000"/>
              <joint name="7_Neck_x" type="hinge" pos="-0.0002 0.2876 -0.0148" axis="1.0000 0.0000 0.0000" range="-180.0000 180.0000"/>
              <geom type="mesh" mesh="Neck" contype="1" conaffinity="1"/>
              <body name="7_Mouth" pos="0.0050 0.3526 0.0365" quat="1.0000 0.0000 0.0000 0.0000">
                <joint name="7_Mouth_z" type="hinge" pos="0.0050 0.3526 0.0365" axis="0.0000 0.0000 1.0000" range="-180.0000 180.0000"/>
                <joint name="7_Mouth_y" type="hinge" pos="0.0050 0.3526 0.0365" axis="0.0000 1.0000 0.0000" range="-180.0000 180.0000"/>
                <joint name="7_Mouth_x" type="hinge" pos="0.0050 0.3526 0.0365" axis="1.0000 0.0000 0.0000" range="-180.0000 180.0000"/>
                <geom type="mesh" mesh="Mouth" contype="1" conaffinity="1"/>
              </body>
            </body>
            <body name="7_LeftChest" pos="0.0815 0.1955 -0.0060" quat="1.0000 0.0000 0.0000 0.0000">
              <joint name="7_LeftChest_z" type="hinge" pos="0.0815 0.1955 -0.0060" axis="0.0000 0.0000 1.0000" range="-180.0000 180.0000"/>
              <joint name="7_LeftChest_y" type="hinge" pos="0.0815 0.1955 -0.0060" axis="0.0000 1.0000 0.0000" range="-180.0000 180.0000"/>
              <joint name="7_LeftChest_x" type="hinge" pos="0.0815 0.1955 -0.0060" axis="1.0000 0.0000 0.0000" range="-180.0000 180.0000"/>
              <geom type="mesh" mesh="LeftChest" contype="1" conaffinity="1"/>
              <body name="7_LeftShoulder" pos="0.1724 0.2260 -0.0149" quat="1.0000 0.0000 0.0000 0.0000">
                <joint name="7_LeftShoulder_z" type="hinge" pos="0.1724 0.2260 -0.0149" axis="0.0000 0.0000 1.0000" range="-180.0000 180.0000"/>
                <joint name="7_LeftShoulder_y" type="hinge" pos="0.1724 0.2260 -0.0149" axis="0.0000 1.0000 0.0000" range="-180.0000 180.0000"/>
                <joint name="7_LeftShoulder_x" type="hinge" pos="0.1724 0.2260 -0.0149" axis="1.0000 0.0000 0.0000" range="-180.0000 180.0000"/>
                <geom type="mesh" mesh="LeftShoulder" contype="1" conaffinity="1"/>
                <body name="7_LeftArm" pos="0.4320 0.2132 -0.0424" quat="1.0000 0.0000 0.0000 0.0000">
                  <joint name="7_LeftArm_z" type="hinge" pos="0.4320 0.2132 -0.0424" axis="0.0000 0.0000 1.0000" range="-720.0000 720.0000"/>
                  <joint name="7_LeftArm_y" type="hinge" pos="0.4320 0.2132 -0.0424" axis="0.0000 1.0000 0.0000" range="-720.0000 720.0000"/>
                  <joint name="7_LeftArm_x" type="hinge" pos="0.4320 0.2132 -0.0424" axis="1.0000 0.0000 0.0000" range="-720.0000 720.0000"/>
                  <geom type="mesh" mesh="LeftArm" contype="1" conaffinity="1"/>
                  <body name="7_LeftWrist" pos="0.6813 0.2222 -0.0435" quat="1.0000 0.0000 0.0000 0.0000">
                    <joint name="7_LeftWrist_z" type="hinge" pos="0.6813 0.2222 -0.0435" axis="0.0000 0.0000 1.0000" range="-180.0000 180.0000"/>
                    <joint name="7_LeftWrist_y" type="hinge" pos="0.6813 0.2222 -0.0435" axis="0.0000 1.0000 0.0000" range="-180.0000 180.0000"/>
                    <joint name="7_LeftWrist_x" type="hinge" pos="0.6813 0.2222 -0.0435" axis="1.0000 0.0000 0.0000" range="-180.0000 180.0000"/>
                    <geom type="mesh" mesh="LeftWrist" contype="1" conaffinity="1"/>
                    <body name="7_LeftHand" pos="0.7653 0.2140 -0.0585" quat="1.0000 0.0000 0.0000 0.0000">
                      <joint name="7_LeftHand_z" type="hinge" pos="0.7653 0.2140 -0.0585" axis="0.0000 0.0000 1.0000" range="-180.0000 180.0000"/>
                      <joint name="7_LeftHand_y" type="hinge" pos="0.7653 0.2140 -0.0585" axis="0.0000 1.0000 0.0000" range="-180.0000 180.0000"/>
                      <joint name="7_LeftHand_x" type="hinge" pos="0.7653 0.2140 -0.0585" axis="1.0000 0.0000 0.0000" range="-180.0000 180.0000"/>
                      <geom type="mesh" mesh="LeftHand" contype="1" conaffinity="1"/>
                    </body>
                  </body>
                </body>
              </body>
            </body>
            <body name="7_RightChest" pos="-0.0791 0.1926 -0.0106" quat="1.0000 0.0000 0.0000 0.0000">
              <joint name="7_RightChest_z" type="hinge" pos="-0.0791 0.1926 -0.0106" axis="0.0000 0.0000 1.0000" range="-180.0000 180.0000"/>
              <joint name="7_RightChest_y" type="hinge" pos="-0.0791 0.1926 -0.0106" axis="0.0000 1.0000 0.0000" range="-180.0000 180.0000"/>
              <joint name="7_RightChest_x" type="hinge" pos="-0.0791 0.1926 -0.0106" axis="1.0000 0.0000 0.0000" range="-180.0000 180.0000"/>
              <geom type="mesh" mesh="RightChest" contype="1" conaffinity="1"/>
              <body name="7_RightShoulder" pos="-0.1752 0.2251 -0.0197" quat="1.0000 0.0000 0.0000 0.0000">
                <joint name="7_RightShoulder_z" type="hinge" pos="-0.1752 0.2251 -0.0197" axis="0.0000 0.0000 1.0000" range="-180.0000 180.0000"/>
                <joint name="7_RightShoulder_y" type="hinge" pos="-0.1752 0.2251 -0.0197" axis="0.0000 1.0000 0.0000" range="-180.0000 180.0000"/>
                <joint name="7_RightShoulder_x" type="hinge" pos="-0.1752 0.2251 -0.0197" axis="1.0000 0.0000 0.0000" range="-180.0000 180.0000"/>
                <geom type="mesh" mesh="RightShoulder" contype="1" conaffinity="1"/>
                <body name="7_RightArm" pos="-0.4289 0.2118 -0.0411" quat="1.0000 0.0000 0.0000 0.0000">
                  <joint name="7_RightArm_z" type="hinge" pos="-0.4289 0.2118 -0.0411" axis="0.0000 0.0000 1.0000" range="-720.0000 720.0000"/>
                  <joint name="7_RightArm_y" type="hinge" pos="-0.4289 0.2118 -0.0411" axis="0.0000 1.0000 0.0000" range="-720.0000 720.0000"/>
                  <joint name="7_RightArm_x" type="hinge" pos="-0.4289 0.2118 -0.0411" axis="1.0000 0.0000 0.0000" range="-720.0000 720.0000"/>
                  <geom type="mesh" mesh="RightArm" contype="1" conaffinity="1"/>
                  <body name="7_RightWrist" pos="-0.6842 0.2196 -0.0467" quat="1.0000 0.0000 0.0000 0.0000">
                    <joint name="7_RightWrist_z" type="hinge" pos="-0.6842 0.2196 -0.0467" axis="0.0000 0.0000 1.0000" range="-180.0000 180.0000"/>
                    <joint name="7_RightWrist_y" type="hinge" pos="-0.6842 0.2196 -0.0467" axis="0.0000 1.0000 0.0000" range="-180.0000 180.0000"/>
                    <joint name="7_RightWrist_x" type="hinge" pos="-0.6842 0.2196 -0.0467" axis="1.0000 0.0000 0.0000" range="-180.0000 180.0000"/>
                    <geom type="mesh" mesh="RightWrist" contype="1" conaffinity="1"/>
                    <body name="7_RightHand" pos="-0.7688 0.2134 -0.0570" quat="1.0000 0.0000 0.0000 0.0000">
                      <joint name="7_RightHand_z" type="hinge" pos="-0.7688 0.2134 -0.0570" axis="0.0000 0.0000 1.0000" range="-180.0000 180.0000"/>
                      <joint name="7_RightHand_y" type="hinge" pos="-0.7688 0.2134 -0.0570" axis="0.0000 1.0000 0.0000" range="-180.0000 180.0000"/>
                      <joint name="7_RightHand_x" type="hinge" pos="-0.7688 0.2134 -0.0570" axis="1.0000 0.0000 0.0000" range="-180.0000 180.0000"/>
                      <geom type="mesh" mesh="RightHand" contype="1" conaffinity="1"/>
                    </body>
                  </body>
                </body>
              </body>
            </body>
          </body>
        </body>
      </body>
    </body>
    <body name="8_Hips" pos="-0.0018 -0.2233 0.0282" quat="1.0000 0.0000 0.0000 0.0000">
      <joint name="8_Hips" pos="-0.0018 -0.2233 0.0282" limited="false" type="free" armature="0" damping="0" stiffness="0"/>
      <geom type="mesh" mesh="Hips" contype="1" conaffinity="1"/>
      <body name="8_LeftUpLeg" pos="0.0677 -0.3147 0.0214" quat="1.0000 0.0000 0.0000 0.0000">
        <joint name="8_LeftUpLeg_z" type="hinge" pos="0.0677 -0.3147 0.0214" axis="0.0000 0.0000 1.0000" range="-180.0000 180.0000"/>
        <joint name="8_LeftUpLeg_y" type="hinge" pos="0.0677 -0.3147 0.0214" axis="0.0000 1.0000 0.0000" range="-180.0000 180.0000"/>
        <joint name="8_LeftUpLeg_x" type="hinge" pos="0.0677 -0.3147 0.0214" axis="1.0000 0.0000 0.0000" range="-180.0000 180.0000"/>
        <geom type="mesh" mesh="LeftUpLeg" contype="1" conaffinity="1"/>
        <body name="8_LeftLeg" pos="0.1020 -0.6899 0.0169" quat="1.0000 0.0000 0.0000 0.0000">
          <joint name="8_LeftLeg_z" type="hinge" pos="0.1020 -0.6899 0.0169" axis="0.0000 0.0000 1.0000" range="-180.0000 180.0000"/>
          <joint name="8_LeftLeg_y" type="hinge" pos="0.1020 -0.6899 0.0169" axis="0.0000 1.0000 0.0000" range="-180.0000 180.0000"/>
          <joint name="8_LeftLeg_x" type="hinge" pos="0.1020 -0.6899 0.0169" axis="1.0000 0.0000 0.0000" range="-180.0000 180.0000"/>
          <geom type="mesh" mesh="LeftLeg" contype="1" conaffinity="1"/>
          <body name="8_LeftFoot" pos="0.0884 -1.0879 -0.0268" quat="1.0000 0.0000 0.0000 0.0000">
            <joint name="8_LeftFoot_z" type="hinge" pos="0.0884 -1.0879 -0.0268" axis="0.0000 0.0000 1.0000" range="-180.0000 180.0000"/>
            <joint name="8_LeftFoot_y" type="hinge" pos="0.0884 -1.0879 -0.0268" axis="0.0000 1.0000 0.0000" range="-180.0000 180.0000"/>
            <joint name="8_LeftFoot_x" type="hinge" pos="0.0884 -1.0879 -0.0268" axis="1.0000 0.0000 0.0000" range="-180.0000 180.0000"/>
            <geom type="mesh" mesh="LeftFoot" contype="1" conaffinity="1"/>
            <body name="8_LeftToe" pos="0.1148 -1.1437 0.0925" quat="1.0000 0.0000 0.0000 0.0000">
              <joint name="8_LeftToe_z" type="hinge" pos="0.1148 -1.1437 0.0925" axis="0.0000 0.0000 1.0000" range="-180.0000 180.0000"/>
              <joint name="8_LeftToe_y" type="hinge" pos="0.1148 -1.1437 0.0925" axis="0.0000 1.0000 0.0000" range="-180.0000 180.0000"/>
              <joint name="8_LeftToe_x" type="hinge" pos="0.1148 -1.1437 0.0925" axis="1.0000 0.0000 0.0000" range="-180.0000 180.0000"/>
              <geom type="mesh" mesh="LeftToe" contype="1" conaffinity="1"/>
            </body>
          </body>
        </body>
      </body>
      <body name="8_RightUpLeg" pos="-0.0695 -0.3139 0.0239" quat="1.0000 0.0000 0.0000 0.0000">
        <joint name="8_RightUpLeg_z" type="hinge" pos="-0.0695 -0.3139 0.0239" axis="0.0000 0.0000 1.0000" range="-180.0000 180.0000"/>
        <joint name="8_RightUpLeg_y" type="hinge" pos="-0.0695 -0.3139 0.0239" axis="0.0000 1.0000 0.0000" range="-180.0000 180.0000"/>
        <joint name="8_RightUpLeg_x" type="hinge" pos="-0.0695 -0.3139 0.0239" axis="1.0000 0.0000 0.0000" range="-180.0000 180.0000"/>
        <geom type="mesh" mesh="RightUpLeg" contype="1" conaffinity="1"/>
        <body name="8_RightLeg" pos="-0.1078 -0.6964 0.0150" quat="1.0000 0.0000 0.0000 0.0000">
          <joint name="8_RightLeg_z" type="hinge" pos="-0.1078 -0.6964 0.0150" axis="0.0000 0.0000 1.0000" range="-180.0000 180.0000"/>
          <joint name="8_RightLeg_y" type="hinge" pos="-0.1078 -0.6964 0.0150" axis="0.0000 1.0000 0.0000" range="-180.0000 180.0000"/>
          <joint name="8_RightLeg_x" type="hinge" pos="-0.1078 -0.6964 0.0150" axis="1.0000 0.0000 0.0000" range="-180.0000 180.0000"/>
          <geom type="mesh" mesh="RightLeg" contype="1" conaffinity="1"/>
          <body name="8_RightFoot" pos="-0.0920 -1.0948 -0.0273" quat="1.0000 0.0000 0.0000 0.0000">
            <joint name="8_RightFoot_z" type="hinge" pos="-0.0920 -1.0948 -0.0273" axis="0.0000 0.0000 1.0000" range="-180.0000 180.0000"/>
            <joint name="8_RightFoot_y" type="hinge" pos="-0.0920 -1.0948 -0.0273" axis="0.0000 1.0000 0.0000" range="-180.0000 180.0000"/>
            <joint name="8_RightFoot_x" type="hinge" pos="-0.0920 -1.0948 -0.0273" axis="1.0000 0.0000 0.0000" range="-180.0000 180.0000"/>
            <geom type="mesh" mesh="RightFoot" contype="1" conaffinity="1"/>
            <body name="8_RightToe" pos="-0.1174 -1.1430 0.0961" quat="1.0000 0.0000 0.0000 0.0000">
              <joint name="8_RightToe_z" type="hinge" pos="-0.1174 -1.1430 0.0961" axis="0.0000 0.0000 1.0000" range="-180.0000 180.0000"/>
              <joint name="8_RightToe_y" type="hinge" pos="-0.1174 -1.1430 0.0961" axis="0.0000 1.0000 0.0000" range="-180.0000 180.0000"/>
              <joint name="8_RightToe_x" type="hinge" pos="-0.1174 -1.1430 0.0961" axis="1.0000 0.0000 0.0000" range="-180.0000 180.0000"/>
              <geom type="mesh" mesh="RightToe" contype="1" conaffinity="1"/>
            </body>
          </body>
        </body>
      </body>
      <body name="8_Spine" pos="-0.0043 -0.1144 0.0015" quat="1.0000 0.0000 0.0000 0.0000">
        <joint name="8_Spine_z" type="hinge" pos="-0.0043 -0.1144 0.0015" axis="0.0000 0.0000 1.0000" range="-180.0000 180.0000"/>
        <joint name="8_Spine_y" type="hinge" pos="-0.0043 -0.1144 0.0015" axis="0.0000 1.0000 0.0000" range="-180.0000 180.0000"/>
        <joint name="8_Spine_x" type="hinge" pos="-0.0043 -0.1144 0.0015" axis="1.0000 0.0000 0.0000" range="-180.0000 180.0000"/>
        <geom type="mesh" mesh="Spine" contype="1" conaffinity="1"/>
        <body name="8_Spine1" pos="0.0012 0.0208 0.0026" quat="1.0000 0.0000 0.0000 0.0000">
          <joint name="8_Spine1_z" type="hinge" pos="0.0012 0.0208 0.0026" axis="0.0000 0.0000 1.0000" range="-180.0000 180.0000"/>
          <joint name="8_Spine1_y" type="hinge" pos="0.0012 0.0208 0.0026" axis="0.0000 1.0000 0.0000" range="-180.0000 180.0000"/>
          <joint name="8_Spine1_x" type="hinge" pos="0.0012 0.0208 0.0026" axis="1.0000 0.0000 0.0000" range="-180.0000 180.0000"/>
          <geom type="mesh" mesh="Spine1" contype="1" conaffinity="1"/>
          <body name="8_Spine2" pos="0.0026 0.0737 0.0280" quat="1.0000 0.0000 0.0000 0.0000">
            <joint name="8_Spine2_z" type="hinge" pos="0.0026 0.0737 0.0280" axis="0.0000 0.0000 1.0000" range="-180.0000 180.0000"/>
            <joint name="8_Spine2_y" type="hinge" pos="0.0026 0.0737 0.0280" axis="0.0000 1.0000 0.0000" range="-180.0000 180.0000"/>
            <joint name="8_Spine2_x" type="hinge" pos="0.0026 0.0737 0.0280" axis="1.0000 0.0000 0.0000" range="-180.0000 180.0000"/>
            <geom type="mesh" mesh="Spine2" contype="1" conaffinity="1"/>
            <body name="8_Neck" pos="-0.0002 0.2876 -0.0148" quat="1.0000 0.0000 0.0000 0.0000">
              <joint name="8_Neck_z" type="hinge" pos="-0.0002 0.2876 -0.0148" axis="0.0000 0.0000 1.0000" range="-180.0000 180.0000"/>
              <joint name="8_Neck_y" type="hinge" pos="-0.0002 0.2876 -0.0148" axis="0.0000 1.0000 0.0000" range="-180.0000 180.0000"/>
              <joint name="8_Neck_x" type="hinge" pos="-0.0002 0.2876 -0.0148" axis="1.0000 0.0000 0.0000" range="-180.0000 180.0000"/>
              <geom type="mesh" mesh="Neck" contype="1" conaffinity="1"/>
              <body name="8_Mouth" pos="0.0050 0.3526 0.0365" quat="1.0000 0.0000 0.0000 0.0000">
                <joint name="8_Mouth_z" type="hinge" pos="0.0050 0.3526 0.0365" axis="0.0000 0.0000 1.0000" range="-180.0000 180.0000"/>
                <joint name="8_Mouth_y" type="hinge" pos="0.0050 0.3526 0.0365" axis="0.0000 1.0000 0.0000" range="-180.0000 180.0000"/>
                <joint name="8_Mouth_x" type="hinge" pos="0.0050 0.3526 0.0365" axis="1.0000 0.0000 0.0000" range="-180.0000 180.0000"/>
                <geom type="mesh" mesh="Mouth" contype="1" conaffinity="1"/>
              </body>
            </body>
            <body name="8_LeftChest" pos="0.0815 0.1955 -0.0060" quat="1.0000 0.0000 0.0000 0.0000">
              <joint name="8_LeftChest_z" type="hinge" pos="0.0815 0.1955 -0.0060" axis="0.0000 0.0000 1.0000" range="-180.0000 180.0000"/>
              <joint name="8_LeftChest_y" type="hinge" pos="0.0815 0.1955 -0.0060" axis="0.0000 1.0000 0.0000" range="-180.0000 180.0000"/>
              <joint name="8_LeftChest_x" type="hinge" pos="0.0815 0.1955 -0.0060" axis="1.0000 0.0000 0.0000" range="-180.0000 180.0000"/>
              <geom type="mesh" mesh="LeftChest" contype="1" conaffinity="1"/>
              <body name="8_LeftShoulder" pos="0.1724 0.2260 -0.0149" quat="1.0000 0.0000 0.0000 0.0000">
                <joint name="8_LeftShoulder_z" type="hinge" pos="0.1724 0.2260 -0.0149" axis="0.0000 0.0000 1.0000" range="-180.0000 180.0000"/>
                <joint name="8_LeftShoulder_y" type="hinge" pos="0.1724 0.2260 -0.0149" axis="0.0000 1.0000 0.0000" range="-180.0000 180.0000"/>
                <joint name="8_LeftShoulder_x" type="hinge" pos="0.1724 0.2260 -0.0149" axis="1.0000 0.0000 0.0000" range="-180.0000 180.0000"/>
                <geom type="mesh" mesh="LeftShoulder" contype="1" conaffinity="1"/>
                <body name="8_LeftArm" pos="0.4320 0.2132 -0.0424" quat="1.0000 0.0000 0.0000 0.0000">
                  <joint name="8_LeftArm_z" type="hinge" pos="0.4320 0.2132 -0.0424" axis="0.0000 0.0000 1.0000" range="-720.0000 720.0000"/>
                  <joint name="8_LeftArm_y" type="hinge" pos="0.4320 0.2132 -0.0424" axis="0.0000 1.0000 0.0000" range="-720.0000 720.0000"/>
                  <joint name="8_LeftArm_x" type="hinge" pos="0.4320 0.2132 -0.0424" axis="1.0000 0.0000 0.0000" range="-720.0000 720.0000"/>
                  <geom type="mesh" mesh="LeftArm" contype="1" conaffinity="1"/>
                  <body name="8_LeftWrist" pos="0.6813 0.2222 -0.0435" quat="1.0000 0.0000 0.0000 0.0000">
                    <joint name="8_LeftWrist_z" type="hinge" pos="0.6813 0.2222 -0.0435" axis="0.0000 0.0000 1.0000" range="-180.0000 180.0000"/>
                    <joint name="8_LeftWrist_y" type="hinge" pos="0.6813 0.2222 -0.0435" axis="0.0000 1.0000 0.0000" range="-180.0000 180.0000"/>
                    <joint name="8_LeftWrist_x" type="hinge" pos="0.6813 0.2222 -0.0435" axis="1.0000 0.0000 0.0000" range="-180.0000 180.0000"/>
                    <geom type="mesh" mesh="LeftWrist" contype="1" conaffinity="1"/>
                    <body name="8_LeftHand" pos="0.7653 0.2140 -0.0585" quat="1.0000 0.0000 0.0000 0.0000">
                      <joint name="8_LeftHand_z" type="hinge" pos="0.7653 0.2140 -0.0585" axis="0.0000 0.0000 1.0000" range="-180.0000 180.0000"/>
                      <joint name="8_LeftHand_y" type="hinge" pos="0.7653 0.2140 -0.0585" axis="0.0000 1.0000 0.0000" range="-180.0000 180.0000"/>
                      <joint name="8_LeftHand_x" type="hinge" pos="0.7653 0.2140 -0.0585" axis="1.0000 0.0000 0.0000" range="-180.0000 180.0000"/>
                      <geom type="mesh" mesh="LeftHand" contype="1" conaffinity="1"/>
                    </body>
                  </body>
                </body>
              </body>
            </body>
            <body name="8_RightChest" pos="-0.0791 0.1926 -0.0106" quat="1.0000 0.0000 0.0000 0.0000">
              <joint name="8_RightChest_z" type="hinge" pos="-0.0791 0.1926 -0.0106" axis="0.0000 0.0000 1.0000" range="-180.0000 180.0000"/>
              <joint name="8_RightChest_y" type="hinge" pos="-0.0791 0.1926 -0.0106" axis="0.0000 1.0000 0.0000" range="-180.0000 180.0000"/>
              <joint name="8_RightChest_x" type="hinge" pos="-0.0791 0.1926 -0.0106" axis="1.0000 0.0000 0.0000" range="-180.0000 180.0000"/>
              <geom type="mesh" mesh="RightChest" contype="1" conaffinity="1"/>
              <body name="8_RightShoulder" pos="-0.1752 0.2251 -0.0197" quat="1.0000 0.0000 0.0000 0.0000">
                <joint name="8_RightShoulder_z" type="hinge" pos="-0.1752 0.2251 -0.0197" axis="0.0000 0.0000 1.0000" range="-180.0000 180.0000"/>
                <joint name="8_RightShoulder_y" type="hinge" pos="-0.1752 0.2251 -0.0197" axis="0.0000 1.0000 0.0000" range="-180.0000 180.0000"/>
                <joint name="8_RightShoulder_x" type="hinge" pos="-0.1752 0.2251 -0.0197" axis="1.0000 0.0000 0.0000" range="-180.0000 180.0000"/>
                <geom type="mesh" mesh="RightShoulder" contype="1" conaffinity="1"/>
                <body name="8_RightArm" pos="-0.4289 0.2118 -0.0411" quat="1.0000 0.0000 0.0000 0.0000">
                  <joint name="8_RightArm_z" type="hinge" pos="-0.4289 0.2118 -0.0411" axis="0.0000 0.0000 1.0000" range="-720.0000 720.0000"/>
                  <joint name="8_RightArm_y" type="hinge" pos="-0.4289 0.2118 -0.0411" axis="0.0000 1.0000 0.0000" range="-720.0000 720.0000"/>
                  <joint name="8_RightArm_x" type="hinge" pos="-0.4289 0.2118 -0.0411" axis="1.0000 0.0000 0.0000" range="-720.0000 720.0000"/>
                  <geom type="mesh" mesh="RightArm" contype="1" conaffinity="1"/>
                  <body name="8_RightWrist" pos="-0.6842 0.2196 -0.0467" quat="1.0000 0.0000 0.0000 0.0000">
                    <joint name="8_RightWrist_z" type="hinge" pos="-0.6842 0.2196 -0.0467" axis="0.0000 0.0000 1.0000" range="-180.0000 180.0000"/>
                    <joint name="8_RightWrist_y" type="hinge" pos="-0.6842 0.2196 -0.0467" axis="0.0000 1.0000 0.0000" range="-180.0000 180.0000"/>
                    <joint name="8_RightWrist_x" type="hinge" pos="-0.6842 0.2196 -0.0467" axis="1.0000 0.0000 0.0000" range="-180.0000 180.0000"/>
                    <geom type="mesh" mesh="RightWrist" contype="1" conaffinity="1"/>
                    <body name="8_RightHand" pos="-0.7688 0.2134 -0.0570" quat="1.0000 0.0000 0.0000 0.0000">
                      <joint name="8_RightHand_z" type="hinge" pos="-0.7688 0.2134 -0.0570" axis="0.0000 0.0000 1.0000" range="-180.0000 180.0000"/>
                      <joint name="8_RightHand_y" type="hinge" pos="-0.7688 0.2134 -0.0570" axis="0.0000 1.0000 0.0000" range="-180.0000 180.0000"/>
                      <joint name="8_RightHand_x" type="hinge" pos="-0.7688 0.2134 -0.0570" axis="1.0000 0.0000 0.0000" range="-180.0000 180.0000"/>
                      <geom type="mesh" mesh="RightHand" contype="1" conaffinity="1"/>
                    </body>
                  </body>
                </body>
              </body>
            </body>
          </body>
        </body>
      </body>
    </body>
    <body name="9_Hips" pos="-0.0018 -0.2233 0.0282" quat="1.0000 0.0000 0.0000 0.0000">
      <joint name="9_Hips" pos="-0.0018 -0.2233 0.0282" limited="false" type="free" armature="0" damping="0" stiffness="0"/>
      <geom type="mesh" mesh="Hips" contype="1" conaffinity="1"/>
      <body name="9_LeftUpLeg" pos="0.0677 -0.3147 0.0214" quat="1.0000 0.0000 0.0000 0.0000">
        <joint name="9_LeftUpLeg_z" type="hinge" pos="0.0677 -0.3147 0.0214" axis="0.0000 0.0000 1.0000" range="-180.0000 180.0000"/>
        <joint name="9_LeftUpLeg_y" type="hinge" pos="0.0677 -0.3147 0.0214" axis="0.0000 1.0000 0.0000" range="-180.0000 180.0000"/>
        <joint name="9_LeftUpLeg_x" type="hinge" pos="0.0677 -0.3147 0.0214" axis="1.0000 0.0000 0.0000" range="-180.0000 180.0000"/>
        <geom type="mesh" mesh="LeftUpLeg" contype="1" conaffinity="1"/>
        <body name="9_LeftLeg" pos="0.1020 -0.6899 0.0169" quat="1.0000 0.0000 0.0000 0.0000">
          <joint name="9_LeftLeg_z" type="hinge" pos="0.1020 -0.6899 0.0169" axis="0.0000 0.0000 1.0000" range="-180.0000 180.0000"/>
          <joint name="9_LeftLeg_y" type="hinge" pos="0.1020 -0.6899 0.0169" axis="0.0000 1.0000 0.0000" range="-180.0000 180.0000"/>
          <joint name="9_LeftLeg_x" type="hinge" pos="0.1020 -0.6899 0.0169" axis="1.0000 0.0000 0.0000" range="-180.0000 180.0000"/>
          <geom type="mesh" mesh="LeftLeg" contype="1" conaffinity="1"/>
          <body name="9_LeftFoot" pos="0.0884 -1.0879 -0.0268" quat="1.0000 0.0000 0.0000 0.0000">
            <joint name="9_LeftFoot_z" type="hinge" pos="0.0884 -1.0879 -0.0268" axis="0.0000 0.0000 1.0000" range="-180.0000 180.0000"/>
            <joint name="9_LeftFoot_y" type="hinge" pos="0.0884 -1.0879 -0.0268" axis="0.0000 1.0000 0.0000" range="-180.0000 180.0000"/>
            <joint name="9_LeftFoot_x" type="hinge" pos="0.0884 -1.0879 -0.0268" axis="1.0000 0.0000 0.0000" range="-180.0000 180.0000"/>
            <geom type="mesh" mesh="LeftFoot" contype="1" conaffinity="1"/>
            <body name="9_LeftToe" pos="0.1148 -1.1437 0.0925" quat="1.0000 0.0000 0.0000 0.0000">
              <joint name="9_LeftToe_z" type="hinge" pos="0.1148 -1.1437 0.0925" axis="0.0000 0.0000 1.0000" range="-180.0000 180.0000"/>
              <joint name="9_LeftToe_y" type="hinge" pos="0.1148 -1.1437 0.0925" axis="0.0000 1.0000 0.0000" range="-180.0000 180.0000"/>
              <joint name="9_LeftToe_x" type="hinge" pos="0.1148 -1.1437 0.0925" axis="1.0000 0.0000 0.0000" range="-180.0000 180.0000"/>
              <geom type="mesh" mesh="LeftToe" contype="1" conaffinity="1"/>
            </body>
          </body>
        </body>
      </body>
      <body name="9_RightUpLeg" pos="-0.0695 -0.3139 0.0239" quat="1.0000 0.0000 0.0000 0.0000">
        <joint name="9_RightUpLeg_z" type="hinge" pos="-0.0695 -0.3139 0.0239" axis="0.0000 0.0000 1.0000" range="-180.0000 180.0000"/>
        <joint name="9_RightUpLeg_y" type="hinge" pos="-0.0695 -0.3139 0.0239" axis="0.0000 1.0000 0.0000" range="-180.0000 180.0000"/>
        <joint name="9_RightUpLeg_x" type="hinge" pos="-0.0695 -0.3139 0.0239" axis="1.0000 0.0000 0.0000" range="-180.0000 180.0000"/>
        <geom type="mesh" mesh="RightUpLeg" contype="1" conaffinity="1"/>
        <body name="9_RightLeg" pos="-0.1078 -0.6964 0.0150" quat="1.0000 0.0000 0.0000 0.0000">
          <joint name="9_RightLeg_z" type="hinge" pos="-0.1078 -0.6964 0.0150" axis="0.0000 0.0000 1.0000" range="-180.0000 180.0000"/>
          <joint name="9_RightLeg_y" type="hinge" pos="-0.1078 -0.6964 0.0150" axis="0.0000 1.0000 0.0000" range="-180.0000 180.0000"/>
          <joint name="9_RightLeg_x" type="hinge" pos="-0.1078 -0.6964 0.0150" axis="1.0000 0.0000 0.0000" range="-180.0000 180.0000"/>
          <geom type="mesh" mesh="RightLeg" contype="1" conaffinity="1"/>
          <body name="9_RightFoot" pos="-0.0920 -1.0948 -0.0273" quat="1.0000 0.0000 0.0000 0.0000">
            <joint name="9_RightFoot_z" type="hinge" pos="-0.0920 -1.0948 -0.0273" axis="0.0000 0.0000 1.0000" range="-180.0000 180.0000"/>
            <joint name="9_RightFoot_y" type="hinge" pos="-0.0920 -1.0948 -0.0273" axis="0.0000 1.0000 0.0000" range="-180.0000 180.0000"/>
            <joint name="9_RightFoot_x" type="hinge" pos="-0.0920 -1.0948 -0.0273" axis="1.0000 0.0000 0.0000" range="-180.0000 180.0000"/>
            <geom type="mesh" mesh="RightFoot" contype="1" conaffinity="1"/>
            <body name="9_RightToe" pos="-0.1174 -1.1430 0.0961" quat="1.0000 0.0000 0.0000 0.0000">
              <joint name="9_RightToe_z" type="hinge" pos="-0.1174 -1.1430 0.0961" axis="0.0000 0.0000 1.0000" range="-180.0000 180.0000"/>
              <joint name="9_RightToe_y" type="hinge" pos="-0.1174 -1.1430 0.0961" axis="0.0000 1.0000 0.0000" range="-180.0000 180.0000"/>
              <joint name="9_RightToe_x" type="hinge" pos="-0.1174 -1.1430 0.0961" axis="1.0000 0.0000 0.0000" range="-180.0000 180.0000"/>
              <geom type="mesh" mesh="RightToe" contype="1" conaffinity="1"/>
            </body>
          </body>
        </body>
      </body>
      <body name="9_Spine" pos="-0.0043 -0.1144 0.0015" quat="1.0000 0.0000 0.0000 0.0000">
        <joint name="9_Spine_z" type="hinge" pos="-0.0043 -0.1144 0.0015" axis="0.0000 0.0000 1.0000" range="-180.0000 180.0000"/>
        <joint name="9_Spine_y" type="hinge" pos="-0.0043 -0.1144 0.0015" axis="0.0000 1.0000 0.0000" range="-180.0000 180.0000"/>
        <joint name="9_Spine_x" type="hinge" pos="-0.0043 -0.1144 0.0015" axis="1.0000 0.0000 0.0000" range="-180.0000 180.0000"/>
        <geom type="mesh" mesh="Spine" contype="1" conaffinity="1"/>
        <body name="9_Spine1" pos="0.0012 0.0208 0.0026" quat="1.0000 0.0000 0.0000 0.0000">
          <joint name="9_Spine1_z" type="hinge" pos="0.0012 0.0208 0.0026" axis="0.0000 0.0000 1.0000" range="-180.0000 180.0000"/>
          <joint name="9_Spine1_y" type="hinge" pos="0.0012 0.0208 0.0026" axis="0.0000 1.0000 0.0000" range="-180.0000 180.0000"/>
          <joint name="9_Spine1_x" type="hinge" pos="0.0012 0.0208 0.0026" axis="1.0000 0.0000 0.0000" range="-180.0000 180.0000"/>
          <geom type="mesh" mesh="Spine1" contype="1" conaffinity="1"/>
          <body name="9_Spine2" pos="0.0026 0.0737 0.0280" quat="1.0000 0.0000 0.0000 0.0000">
            <joint name="9_Spine2_z" type="hinge" pos="0.0026 0.0737 0.0280" axis="0.0000 0.0000 1.0000" range="-180.0000 180.0000"/>
            <joint name="9_Spine2_y" type="hinge" pos="0.0026 0.0737 0.0280" axis="0.0000 1.0000 0.0000" range="-180.0000 180.0000"/>
            <joint name="9_Spine2_x" type="hinge" pos="0.0026 0.0737 0.0280" axis="1.0000 0.0000 0.0000" range="-180.0000 180.0000"/>
            <geom type="mesh" mesh="Spine2" contype="1" conaffinity="1"/>
            <body name="9_Neck" pos="-0.0002 0.2876 -0.0148" quat="1.0000 0.0000 0.0000 0.0000">
              <joint name="9_Neck_z" type="hinge" pos="-0.0002 0.2876 -0.0148" axis="0.0000 0.0000 1.0000" range="-180.0000 180.0000"/>
              <joint name="9_Neck_y" type="hinge" pos="-0.0002 0.2876 -0.0148" axis="0.0000 1.0000 0.0000" range="-180.0000 180.0000"/>
              <joint name="9_Neck_x" type="hinge" pos="-0.0002 0.2876 -0.0148" axis="1.0000 0.0000 0.0000" range="-180.0000 180.0000"/>
              <geom type="mesh" mesh="Neck" contype="1" conaffinity="1"/>
              <body name="9_Mouth" pos="0.0050 0.3526 0.0365" quat="1.0000 0.0000 0.0000 0.0000">
                <joint name="9_Mouth_z" type="hinge" pos="0.0050 0.3526 0.0365" axis="0.0000 0.0000 1.0000" range="-180.0000 180.0000"/>
                <joint name="9_Mouth_y" type="hinge" pos="0.0050 0.3526 0.0365" axis="0.0000 1.0000 0.0000" range="-180.0000 180.0000"/>
                <joint name="9_Mouth_x" type="hinge" pos="0.0050 0.3526 0.0365" axis="1.0000 0.0000 0.0000" range="-180.0000 180.0000"/>
                <geom type="mesh" mesh="Mouth" contype="1" conaffinity="1"/>
              </body>
            </body>
            <body name="9_LeftChest" pos="0.0815 0.1955 -0.0060" quat="1.0000 0.0000 0.0000 0.0000">
              <joint name="9_LeftChest_z" type="hinge" pos="0.0815 0.1955 -0.0060" axis="0.0000 0.0000 1.0000" range="-180.0000 180.0000"/>
              <joint name="9_LeftChest_y" type="hinge" pos="0.0815 0.1955 -0.0060" axis="0.0000 1.0000 0.0000" range="-180.0000 180.0000"/>
              <joint name="9_LeftChest_x" type="hinge" pos="0.0815 0.1955 -0.0060" axis="1.0000 0.0000 0.0000" range="-180.0000 180.0000"/>
              <geom type="mesh" mesh="LeftChest" contype="1" conaffinity="1"/>
              <body name="9_LeftShoulder" pos="0.1724 0.2260 -0.0149" quat="1.0000 0.0000 0.0000 0.0000">
                <joint name="9_LeftShoulder_z" type="hinge" pos="0.1724 0.2260 -0.0149" axis="0.0000 0.0000 1.0000" range="-180.0000 180.0000"/>
                <joint name="9_LeftShoulder_y" type="hinge" pos="0.1724 0.2260 -0.0149" axis="0.0000 1.0000 0.0000" range="-180.0000 180.0000"/>
                <joint name="9_LeftShoulder_x" type="hinge" pos="0.1724 0.2260 -0.0149" axis="1.0000 0.0000 0.0000" range="-180.0000 180.0000"/>
                <geom type="mesh" mesh="LeftShoulder" contype="1" conaffinity="1"/>
                <body name="9_LeftArm" pos="0.4320 0.2132 -0.0424" quat="1.0000 0.0000 0.0000 0.0000">
                  <joint name="9_LeftArm_z" type="hinge" pos="0.4320 0.2132 -0.0424" axis="0.0000 0.0000 1.0000" range="-720.0000 720.0000"/>
                  <joint name="9_LeftArm_y" type="hinge" pos="0.4320 0.2132 -0.0424" axis="0.0000 1.0000 0.0000" range="-720.0000 720.0000"/>
                  <joint name="9_LeftArm_x" type="hinge" pos="0.4320 0.2132 -0.0424" axis="1.0000 0.0000 0.0000" range="-720.0000 720.0000"/>
                  <geom type="mesh" mesh="LeftArm" contype="1" conaffinity="1"/>
                  <body name="9_LeftWrist" pos="0.6813 0.2222 -0.0435" quat="1.0000 0.0000 0.0000 0.0000">
                    <joint name="9_LeftWrist_z" type="hinge" pos="0.6813 0.2222 -0.0435" axis="0.0000 0.0000 1.0000" range="-180.0000 180.0000"/>
                    <joint name="9_LeftWrist_y" type="hinge" pos="0.6813 0.2222 -0.0435" axis="0.0000 1.0000 0.0000" range="-180.0000 180.0000"/>
                    <joint name="9_LeftWrist_x" type="hinge" pos="0.6813 0.2222 -0.0435" axis="1.0000 0.0000 0.0000" range="-180.0000 180.0000"/>
                    <geom type="mesh" mesh="LeftWrist" contype="1" conaffinity="1"/>
                    <body name="9_LeftHand" pos="0.7653 0.2140 -0.0585" quat="1.0000 0.0000 0.0000 0.0000">
                      <joint name="9_LeftHand_z" type="hinge" pos="0.7653 0.2140 -0.0585" axis="0.0000 0.0000 1.0000" range="-180.0000 180.0000"/>
                      <joint name="9_LeftHand_y" type="hinge" pos="0.7653 0.2140 -0.0585" axis="0.0000 1.0000 0.0000" range="-180.0000 180.0000"/>
                      <joint name="9_LeftHand_x" type="hinge" pos="0.7653 0.2140 -0.0585" axis="1.0000 0.0000 0.0000" range="-180.0000 180.0000"/>
                      <geom type="mesh" mesh="LeftHand" contype="1" conaffinity="1"/>
                    </body>
                  </body>
                </body>
              </body>
            </body>
            <body name="9_RightChest" pos="-0.0791 0.1926 -0.0106" quat="1.0000 0.0000 0.0000 0.0000">
              <joint name="9_RightChest_z" type="hinge" pos="-0.0791 0.1926 -0.0106" axis="0.0000 0.0000 1.0000" range="-180.0000 180.0000"/>
              <joint name="9_RightChest_y" type="hinge" pos="-0.0791 0.1926 -0.0106" axis="0.0000 1.0000 0.0000" range="-180.0000 180.0000"/>
              <joint name="9_RightChest_x" type="hinge" pos="-0.0791 0.1926 -0.0106" axis="1.0000 0.0000 0.0000" range="-180.0000 180.0000"/>
              <geom type="mesh" mesh="RightChest" contype="1" conaffinity="1"/>
              <body name="9_RightShoulder" pos="-0.1752 0.2251 -0.0197" quat="1.0000 0.0000 0.0000 0.0000">
                <joint name="9_RightShoulder_z" type="hinge" pos="-0.1752 0.2251 -0.0197" axis="0.0000 0.0000 1.0000" range="-180.0000 180.0000"/>
                <joint name="9_RightShoulder_y" type="hinge" pos="-0.1752 0.2251 -0.0197" axis="0.0000 1.0000 0.0000" range="-180.0000 180.0000"/>
                <joint name="9_RightShoulder_x" type="hinge" pos="-0.1752 0.2251 -0.0197" axis="1.0000 0.0000 0.0000" range="-180.0000 180.0000"/>
                <geom type="mesh" mesh="RightShoulder" contype="1" conaffinity="1"/>
                <body name="9_RightArm" pos="-0.4289 0.2118 -0.0411" quat="1.0000 0.0000 0.0000 0.0000">
                  <joint name="9_RightArm_z" type="hinge" pos="-0.4289 0.2118 -0.0411" axis="0.0000 0.0000 1.0000" range="-720.0000 720.0000"/>
                  <joint name="9_RightArm_y" type="hinge" pos="-0.4289 0.2118 -0.0411" axis="0.0000 1.0000 0.0000" range="-720.0000 720.0000"/>
                  <joint name="9_RightArm_x" type="hinge" pos="-0.4289 0.2118 -0.0411" axis="1.0000 0.0000 0.0000" range="-720.0000 720.0000"/>
                  <geom type="mesh" mesh="RightArm" contype="1" conaffinity="1"/>
                  <body name="9_RightWrist" pos="-0.6842 0.2196 -0.0467" quat="1.0000 0.0000 0.0000 0.0000">
                    <joint name="9_RightWrist_z" type="hinge" pos="-0.6842 0.2196 -0.0467" axis="0.0000 0.0000 1.0000" range="-180.0000 180.0000"/>
                    <joint name="9_RightWrist_y" type="hinge" pos="-0.6842 0.2196 -0.0467" axis="0.0000 1.0000 0.0000" range="-180.0000 180.0000"/>
                    <joint name="9_RightWrist_x" type="hinge" pos="-0.6842 0.2196 -0.0467" axis="1.0000 0.0000 0.0000" range="-180.0000 180.0000"/>
                    <geom type="mesh" mesh="RightWrist" contype="1" conaffinity="1"/>
                    <body name="9_RightHand" pos="-0.7688 0.2134 -0.0570" quat="1.0000 0.0000 0.0000 0.0000">
                      <joint name="9_RightHand_z" type="hinge" pos="-0.7688 0.2134 -0.0570" axis="0.0000 0.0000 1.0000" range="-180.0000 180.0000"/>
                      <joint name="9_RightHand_y" type="hinge" pos="-0.7688 0.2134 -0.0570" axis="0.0000 1.0000 0.0000" range="-180.0000 180.0000"/>
                      <joint name="9_RightHand_x" type="hinge" pos="-0.7688 0.2134 -0.0570" axis="1.0000 0.0000 0.0000" range="-180.0000 180.0000"/>
                      <geom type="mesh" mesh="RightHand" contype="1" conaffinity="1"/>
                    </body>
                  </body>
                </body>
              </body>
            </body>
          </body>
        </body>
      </body>
    </body>
  </worldbody>
</mujoco>
