<mujoco model="humanoid">
  <compiler angle="degree" inertiafromgeom="true" coordinate="global"/>
  <visual>
    <headlight ambient=".4 .4 .4" diffuse=".8 .8 .8" specular="0.1 0.1 0.1"/>
    <map znear=".01"/>
    <quality shadowsize="2048"/>
  </visual>
  <default>
    <joint damping="0.0" armature="0.01" stiffness="0.0" limited="true"/>
    <geom conaffinity="7" condim="1" contype="7" margin="0.001" rgba="0.8 0.6 .4 1"/>
  </default>
  <statistic extent="3" center="0 0 1"/>
  <option timestep="0.00222222222"/>
  <asset>
    <texture type="skybox" builtin="gradient" rgb1=".4 .5 .6" rgb2="0 0 0" width="100" height="100"/>
    <texture builtin="flat" height="1278" mark="cross" markrgb="1 1 1" name="texgeom" random="0.01" rgb1="0.8 0.6 0.4" rgb2="0.8 0.6 0.4" type="cube" width="127"/>
    <texture builtin="checker" height="100" name="texplane" rgb1="0 0 0" rgb2="0.8 0.8 0.8" type="2d" width="100"/>
    <material name="MatPlane" reflectance="0.5" shininess="1" specular="1" texrepeat="60 60" texture="texplane"/>
    <material name="geom" texture="texgeom" texuniform="true"/>
  </asset>
  <worldbody>
    <light cutoff="100" diffuse="1 1 1" dir="-0 0 -1.3" directional="true" exponent="1" pos="0 0 1.3" specular=".1 .1 .1"/>
    <geom conaffinity="1" condim="3" name="floor" pos="0 0 0" rgba="0.8 0.9 0.8 1" size="100 100 .2" type="plane" material="MatPlane"/>
    <body name="Pelvis" pos="0.0000 0.0000 1.0000" user="-0.0002 -0.0243 0.9874">
      <joint name="Pelvis" pos="0.0000 0.0000 1.0000" limited="false" type="free" armature="0" damping="0" stiffness="0"/>
      <geom type="sphere" contype="0" conaffinity="1" size="0.0800" pos="0.0000 0.0000 1.0000"/>
      <body name="L_Hip" pos="0.0695 -0.0914 0.9932" user="0.1038 -0.4666 0.9887">
        <joint name="L_Hip_z" type="hinge" pos="0.0695 -0.0914 0.9932" axis="0.0000 0.0000 1.0000" range="-180.0000 180.0000"/>
        <joint name="L_Hip_y" type="hinge" pos="0.0695 -0.0914 0.9932" axis="0.0000 1.0000 0.0000" range="-180.0000 180.0000"/>
        <joint name="L_Hip_x" type="hinge" pos="0.0695 -0.0914 0.9932" axis="1.0000 0.0000 0.0000" range="-180.0000 180.0000"/>
        <geom type="capsule" contype="0" conaffinity="1" fromto="0.0713 -0.1113 0.9929 0.1020 -0.4467 0.9889" size="0.0430"/>
        <body name="L_Knee" pos="0.1038 -0.4666 0.9887" user="0.0902 -0.8646 0.9450">
          <joint name="L_Knee_z" type="hinge" pos="0.1038 -0.4666 0.9887" axis="0.0000 0.0000 1.0000" range="-180.0000 180.0000"/>
          <joint name="L_Knee_y" type="hinge" pos="0.1038 -0.4666 0.9887" axis="0.0000 1.0000 0.0000" range="-180.0000 180.0000"/>
          <joint name="L_Knee_x" type="hinge" pos="0.1038 -0.4666 0.9887" axis="1.0000 0.0000 0.0000" range="-180.0000 180.0000"/>
          <geom type="capsule" contype="0" conaffinity="1" fromto="0.1031 -0.4865 0.9865 0.0909 -0.8447 0.9472" size="0.0350"/>
          <body name="L_Ankle" pos="0.0902 -0.8646 0.9450" user="0.1166 -0.9204 1.0643">
            <joint name="L_Ankle_z" type="hinge" pos="0.0902 -0.8646 0.9450" axis="0.0000 0.0000 1.0000" range="-180.0000 180.0000"/>
            <joint name="L_Ankle_y" type="hinge" pos="0.0902 -0.8646 0.9450" axis="0.0000 1.0000 0.0000" range="-180.0000 180.0000"/>
            <joint name="L_Ankle_x" type="hinge" pos="0.0902 -0.8646 0.9450" axis="1.0000 0.0000 0.0000" range="-180.0000 180.0000"/>
            <geom type="box" contype="0" conaffinity="1" pos="0.1034 -0.8925 1.0046" size="0.0619 0.0998 0.0299" quat="0.7071 -0.7071 -0.0000 -0.0000"/>
            <body name="L_Toe" pos="0.1166 -0.9204 1.0643" user="0.1166 -0.9204 1.0643">
              <joint name="L_Toe_z" type="hinge" pos="0.1166 -0.9204 1.0643" axis="0.0000 0.0000 1.0000" range="-180.0000 180.0000"/>
              <joint name="L_Toe_y" type="hinge" pos="0.1166 -0.9204 1.0643" axis="0.0000 1.0000 0.0000" range="-180.0000 180.0000"/>
              <joint name="L_Toe_x" type="hinge" pos="0.1166 -0.9204 1.0643" axis="1.0000 0.0000 0.0000" range="-180.0000 180.0000"/>
              <geom type="capsule" contype="0" conaffinity="1" fromto="0.1166 -0.9204 1.0683 0.1166 -0.9204 1.0603" size="0.0200"/>
            </body>
          </body>
        </body>
      </body>
      <body name="R_Hip" pos="-0.0677 -0.0905 0.9957" user="-0.1060 -0.4731 0.9868">
        <joint name="R_Hip_z" type="hinge" pos="-0.0677 -0.0905 0.9957" axis="0.0000 0.0000 1.0000" range="-180.0000 180.0000"/>
        <joint name="R_Hip_y" type="hinge" pos="-0.0677 -0.0905 0.9957" axis="0.0000 1.0000 0.0000" range="-180.0000 180.0000"/>
        <joint name="R_Hip_x" type="hinge" pos="-0.0677 -0.0905 0.9957" axis="1.0000 0.0000 0.0000" range="-180.0000 180.0000"/>
        <geom type="capsule" contype="0" conaffinity="1" fromto="-0.0697 -0.1104 0.9952 -0.1040 -0.4532 0.9873" size="0.0430"/>
        <body name="R_Knee" pos="-0.1060 -0.4731 0.9868" user="-0.0902 -0.8715 0.9445">
          <joint name="R_Knee_z" type="hinge" pos="-0.1060 -0.4731 0.9868" axis="0.0000 0.0000 1.0000" range="-180.0000 180.0000"/>
          <joint name="R_Knee_y" type="hinge" pos="-0.1060 -0.4731 0.9868" axis="0.0000 1.0000 0.0000" range="-180.0000 180.0000"/>
          <joint name="R_Knee_x" type="hinge" pos="-0.1060 -0.4731 0.9868" axis="1.0000 0.0000 0.0000" range="-180.0000 180.0000"/>
          <geom type="capsule" contype="0" conaffinity="1" fromto="-0.1052 -0.4930 0.9847 -0.0910 -0.8516 0.9466" size="0.0350"/>
          <body name="R_Ankle" pos="-0.0902 -0.8715 0.9445" user="-0.1156 -0.9196 1.0679">
            <joint name="R_Ankle_z" type="hinge" pos="-0.0902 -0.8715 0.9445" axis="0.0000 0.0000 1.0000" range="-180.0000 180.0000"/>
            <joint name="R_Ankle_y" type="hinge" pos="-0.0902 -0.8715 0.9445" axis="0.0000 1.0000 0.0000" range="-180.0000 180.0000"/>
            <joint name="R_Ankle_x" type="hinge" pos="-0.0902 -0.8715 0.9445" axis="1.0000 0.0000 0.0000" range="-180.0000 180.0000"/>
            <geom type="box" contype="0" conaffinity="1" pos="-0.1029 -0.8956 1.0062" size="0.0622 0.1003 0.0301" quat="0.7071 -0.7071 0.0000 0.0000"/>
            <body name="R_Toe" pos="-0.1156 -0.9196 1.0679" user="-0.1156 -0.9196 1.0679">
              <joint name="R_Toe_z" type="hinge" pos="-0.1156 -0.9196 1.0679" axis="0.0000 0.0000 1.0000" range="-180.0000 180.0000"/>
              <joint name="R_Toe_y" type="hinge" pos="-0.1156 -0.9196 1.0679" axis="0.0000 1.0000 0.0000" range="-180.0000 180.0000"/>
              <joint name="R_Toe_x" type="hinge" pos="-0.1156 -0.9196 1.0679" axis="1.0000 0.0000 0.0000" range="-180.0000 180.0000"/>
              <geom type="capsule" contype="0" conaffinity="1" fromto="-0.1156 -0.9196 1.0719 -0.1156 -0.9196 1.0639" size="0.0200"/>
            </body>
          </body>
        </body>
      </body>
      <body name="Torso" pos="-0.0025 0.1090 0.9733" user="0.0030 0.2441 0.9744">
        <joint name="Torso_z" type="hinge" pos="-0.0025 0.1090 0.9733" axis="0.0000 0.0000 1.0000" range="-180.0000 180.0000"/>
        <joint name="Torso_y" type="hinge" pos="-0.0025 0.1090 0.9733" axis="0.0000 1.0000 0.0000" range="-180.0000 180.0000"/>
        <joint name="Torso_x" type="hinge" pos="-0.0025 0.1090 0.9733" axis="1.0000 0.0000 0.0000" range="-180.0000 180.0000"/>
        <geom type="capsule" contype="0" conaffinity="1" fromto="-0.0017 0.1289 0.9735 0.0021 0.2242 0.9742" size="0.0550"/>
        <body name="Spine" pos="0.0030 0.2441 0.9744" user="0.0044 0.2971 0.9998">
          <joint name="Spine_z" type="hinge" pos="0.0030 0.2441 0.9744" axis="0.0000 0.0000 1.0000" range="-180.0000 180.0000"/>
          <joint name="Spine_y" type="hinge" pos="0.0030 0.2441 0.9744" axis="0.0000 1.0000 0.0000" range="-180.0000 180.0000"/>
          <joint name="Spine_x" type="hinge" pos="0.0030 0.2441 0.9744" axis="1.0000 0.0000 0.0000" range="-180.0000 180.0000"/>
          <geom type="capsule" contype="0" conaffinity="1" fromto="0.0035 0.2622 0.9831 0.0039 0.2790 0.9912" size="0.0510"/>
          <body name="Chest" pos="0.0044 0.2971 0.9998" user="0.0025 0.4486 0.9613">
            <joint name="Chest_z" type="hinge" pos="0.0044 0.2971 0.9998" axis="0.0000 0.0000 1.0000" range="-180.0000 180.0000"/>
            <joint name="Chest_y" type="hinge" pos="0.0044 0.2971 0.9998" axis="0.0000 1.0000 0.0000" range="-180.0000 180.0000"/>
            <joint name="Chest_x" type="hinge" pos="0.0044 0.2971 0.9998" axis="1.0000 0.0000 0.0000" range="-180.0000 180.0000"/>
            <geom type="capsule" contype="0" conaffinity="1" fromto="0.0042 0.3164 0.9949 0.0028 0.4292 0.9662" size="0.0500"/>
            <body name="Neck" pos="0.0016 0.5109 0.9570" user="0.0068 0.5759 1.0083">
              <joint name="Neck_z" type="hinge" pos="0.0016 0.5109 0.9570" axis="0.0000 0.0000 1.0000" range="-180.0000 180.0000"/>
              <joint name="Neck_y" type="hinge" pos="0.0016 0.5109 0.9570" axis="0.0000 1.0000 0.0000" range="-180.0000 180.0000"/>
              <joint name="Neck_x" type="hinge" pos="0.0016 0.5109 0.9570" axis="1.0000 0.0000 0.0000" range="-180.0000 180.0000"/>
              <geom type="capsule" contype="0" conaffinity="1" fromto="0.0029 0.5266 0.9693 0.0055 0.5602 0.9959" size="0.0300"/>
              <body name="Head" pos="0.0068 0.5759 1.0083" user="0.0068 0.5759 1.0083">
                <joint name="Head_z" type="hinge" pos="0.0068 0.5759 1.0083" axis="0.0000 0.0000 1.0000" range="-180.0000 180.0000"/>
                <joint name="Head_y" type="hinge" pos="0.0068 0.5759 1.0083" axis="0.0000 1.0000 0.0000" range="-180.0000 180.0000"/>
                <joint name="Head_x" type="hinge" pos="0.0068 0.5759 1.0083" axis="1.0000 0.0000 0.0000" range="-180.0000 180.0000"/>
                <geom type="capsule" contype="0" conaffinity="1" fromto="0.0068 0.5759 1.0123 0.0068 0.5759 1.0043" size="0.0650"/>
              </body>
            </body>
            <body name="L_Thorax" pos="0.0833 0.4188 0.9657" user="0.1742 0.4493 0.9569">
              <joint name="L_Thorax_z" type="hinge" pos="0.0833 0.4188 0.9657" axis="0.0000 0.0000 1.0000" range="-180.0000 180.0000"/>
              <joint name="L_Thorax_y" type="hinge" pos="0.0833 0.4188 0.9657" axis="0.0000 1.0000 0.0000" range="-180.0000 180.0000"/>
              <joint name="L_Thorax_x" type="hinge" pos="0.0833 0.4188 0.9657" axis="1.0000 0.0000 0.0000" range="-180.0000 180.0000"/>
              <geom type="capsule" contype="0" conaffinity="1" fromto="0.1021 0.4251 0.9639 0.1553 0.4430 0.9587" size="0.0300"/>
              <body name="L_Shoulder" pos="0.1742 0.4493 0.9569" user="0.4338 0.4365 0.9294">
                <joint name="L_Shoulder_z" type="hinge" pos="0.1742 0.4493 0.9569" axis="0.0000 0.0000 1.0000" range="-180.0000 180.0000"/>
                <joint name="L_Shoulder_y" type="hinge" pos="0.1742 0.4493 0.9569" axis="0.0000 1.0000 0.0000" range="-180.0000 180.0000"/>
                <joint name="L_Shoulder_x" type="hinge" pos="0.1742 0.4493 0.9569" axis="1.0000 0.0000 0.0000" range="-180.0000 180.0000"/>
                <geom type="capsule" contype="0" conaffinity="1" fromto="0.1941 0.4483 0.9548 0.4140 0.4375 0.9315" size="0.0300"/>
                <body name="L_Elbow" pos="0.4338 0.4365 0.9294" user="0.6831 0.4455 0.9282">
                  <joint name="L_Elbow_z" type="hinge" pos="0.4338 0.4365 0.9294" axis="0.0000 0.0000 1.0000" range="-720.0000 720.0000"/>
                  <joint name="L_Elbow_y" type="hinge" pos="0.4338 0.4365 0.9294" axis="0.0000 1.0000 0.0000" range="-720.0000 720.0000"/>
                  <joint name="L_Elbow_x" type="hinge" pos="0.4338 0.4365 0.9294" axis="1.0000 0.0000 0.0000" range="-720.0000 720.0000"/>
                  <geom type="capsule" contype="0" conaffinity="1" fromto="0.4538 0.4372 0.9293 0.6631 0.4448 0.9283" size="0.0300"/>
                  <body name="L_Wrist" pos="0.6831 0.4455 0.9282" user="0.7671 0.4373 0.9133">
                    <joint name="L_Wrist_z" type="hinge" pos="0.6831 0.4455 0.9282" axis="0.0000 0.0000 1.0000" range="-180.0000 180.0000"/>
                    <joint name="L_Wrist_y" type="hinge" pos="0.6831 0.4455 0.9282" axis="0.0000 1.0000 0.0000" range="-180.0000 180.0000"/>
                    <joint name="L_Wrist_x" type="hinge" pos="0.6831 0.4455 0.9282" axis="1.0000 0.0000 0.0000" range="-180.0000 180.0000"/>
                    <geom type="capsule" contype="0" conaffinity="1" fromto="0.7027 0.4436 0.9247 0.7475 0.4392 0.9168" size="0.0300"/>
                    <body name="L_Hand" pos="0.7671 0.4373 0.9133" user="0.7671 0.4373 0.9133">
                      <joint name="L_Hand_z" type="hinge" pos="0.7671 0.4373 0.9133" axis="0.0000 0.0000 1.0000" range="-180.0000 180.0000"/>
                      <joint name="L_Hand_y" type="hinge" pos="0.7671 0.4373 0.9133" axis="0.0000 1.0000 0.0000" range="-180.0000 180.0000"/>
                      <joint name="L_Hand_x" type="hinge" pos="0.7671 0.4373 0.9133" axis="1.0000 0.0000 0.0000" range="-180.0000 180.0000"/>
                      <geom type="capsule" contype="0" conaffinity="1" fromto="0.7671 0.4373 0.9173 0.7671 0.4373 0.9093" size="0.0350"/>
                    </body>
                  </body>
                </body>
              </body>
            </body>
            <body name="R_Thorax" pos="-0.0773 0.4159 0.9612" user="-0.1734 0.4484 0.9521">
              <joint name="R_Thorax_z" type="hinge" pos="-0.0773 0.4159 0.9612" axis="0.0000 0.0000 1.0000" range="-180.0000 180.0000"/>
              <joint name="R_Thorax_y" type="hinge" pos="-0.0773 0.4159 0.9612" axis="0.0000 1.0000 0.0000" range="-180.0000 180.0000"/>
              <joint name="R_Thorax_x" type="hinge" pos="-0.0773 0.4159 0.9612" axis="1.0000 0.0000 0.0000" range="-180.0000 180.0000"/>
              <geom type="capsule" contype="0" conaffinity="1" fromto="-0.0962 0.4223 0.9594 -0.1545 0.4421 0.9539" size="0.0300"/>
              <body name="R_Shoulder" pos="-0.1734 0.4484 0.9521" user="-0.4271 0.4351 0.9307">
                <joint name="R_Shoulder_z" type="hinge" pos="-0.1734 0.4484 0.9521" axis="0.0000 0.0000 1.0000" range="-180.0000 180.0000"/>
                <joint name="R_Shoulder_y" type="hinge" pos="-0.1734 0.4484 0.9521" axis="0.0000 1.0000 0.0000" range="-180.0000 180.0000"/>
                <joint name="R_Shoulder_x" type="hinge" pos="-0.1734 0.4484 0.9521" axis="1.0000 0.0000 0.0000" range="-180.0000 180.0000"/>
                <geom type="capsule" contype="0" conaffinity="1" fromto="-0.1933 0.4474 0.9504 -0.4072 0.4362 0.9323" size="0.0300"/>
                <body name="R_Elbow" pos="-0.4271 0.4351 0.9307" user="-0.6824 0.4429 0.9251">
                  <joint name="R_Elbow_z" type="hinge" pos="-0.4271 0.4351 0.9307" axis="0.0000 0.0000 1.0000" range="-720.0000 720.0000"/>
                  <joint name="R_Elbow_y" type="hinge" pos="-0.4271 0.4351 0.9307" axis="0.0000 1.0000 0.0000" range="-720.0000 720.0000"/>
                  <joint name="R_Elbow_x" type="hinge" pos="-0.4271 0.4351 0.9307" axis="1.0000 0.0000 0.0000" range="-720.0000 720.0000"/>
                  <geom type="capsule" contype="0" conaffinity="1" fromto="-0.4471 0.4357 0.9302 -0.6624 0.4423 0.9255" size="0.0300"/>
                  <body name="R_Wrist" pos="-0.6824 0.4429 0.9251" user="-0.7670 0.4368 0.9148">
                    <joint name="R_Wrist_z" type="hinge" pos="-0.6824 0.4429 0.9251" axis="0.0000 0.0000 1.0000" range="-180.0000 180.0000"/>
                    <joint name="R_Wrist_y" type="hinge" pos="-0.6824 0.4429 0.9251" axis="0.0000 1.0000 0.0000" range="-180.0000 180.0000"/>
                    <joint name="R_Wrist_x" type="hinge" pos="-0.6824 0.4429 0.9251" axis="1.0000 0.0000 0.0000" range="-180.0000 180.0000"/>
                    <geom type="capsule" contype="0" conaffinity="1" fromto="-0.7022 0.4415 0.9227 -0.7472 0.4382 0.9172" size="0.0300"/>
                    <body name="R_Hand" pos="-0.7670 0.4368 0.9148" user="-0.7670 0.4368 0.9148">
                      <joint name="R_Hand_z" type="hinge" pos="-0.7670 0.4368 0.9148" axis="0.0000 0.0000 1.0000" range="-180.0000 180.0000"/>
                      <joint name="R_Hand_y" type="hinge" pos="-0.7670 0.4368 0.9148" axis="0.0000 1.0000 0.0000" range="-180.0000 180.0000"/>
                      <joint name="R_Hand_x" type="hinge" pos="-0.7670 0.4368 0.9148" axis="1.0000 0.0000 0.0000" range="-180.0000 180.0000"/>
                      <geom type="capsule" contype="0" conaffinity="1" fromto="-0.7670 0.4368 0.9188 -0.7670 0.4368 0.9108" size="0.0350"/>
                    </body>
                  </body>
                </body>
              </body>
            </body>
          </body>
        </body>
      </body>
    </body>
  </worldbody>
  <actuator>
    <motor name="L_Hip_z" joint="L_Hip_z" gear="1"/>
    <motor name="L_Hip_y" joint="L_Hip_y" gear="1"/>
    <motor name="L_Hip_x" joint="L_Hip_x" gear="1"/>
    <motor name="L_Knee_z" joint="L_Knee_z" gear="1"/>
    <motor name="L_Knee_y" joint="L_Knee_y" gear="1"/>
    <motor name="L_Knee_x" joint="L_Knee_x" gear="1"/>
    <motor name="L_Ankle_z" joint="L_Ankle_z" gear="1"/>
    <motor name="L_Ankle_y" joint="L_Ankle_y" gear="1"/>
    <motor name="L_Ankle_x" joint="L_Ankle_x" gear="1"/>
    <motor name="L_Toe_z" joint="L_Toe_z" gear="1"/>
    <motor name="L_Toe_y" joint="L_Toe_y" gear="1"/>
    <motor name="L_Toe_x" joint="L_Toe_x" gear="1"/>
    <motor name="R_Hip_z" joint="R_Hip_z" gear="1"/>
    <motor name="R_Hip_y" joint="R_Hip_y" gear="1"/>
    <motor name="R_Hip_x" joint="R_Hip_x" gear="1"/>
    <motor name="R_Knee_z" joint="R_Knee_z" gear="1"/>
    <motor name="R_Knee_y" joint="R_Knee_y" gear="1"/>
    <motor name="R_Knee_x" joint="R_Knee_x" gear="1"/>
    <motor name="R_Ankle_z" joint="R_Ankle_z" gear="1"/>
    <motor name="R_Ankle_y" joint="R_Ankle_y" gear="1"/>
    <motor name="R_Ankle_x" joint="R_Ankle_x" gear="1"/>
    <motor name="R_Toe_z" joint="R_Toe_z" gear="1"/>
    <motor name="R_Toe_y" joint="R_Toe_y" gear="1"/>
    <motor name="R_Toe_x" joint="R_Toe_x" gear="1"/>
    <motor name="Torso_z" joint="Torso_z" gear="1"/>
    <motor name="Torso_y" joint="Torso_y" gear="1"/>
    <motor name="Torso_x" joint="Torso_x" gear="1"/>
    <motor name="Spine_z" joint="Spine_z" gear="1"/>
    <motor name="Spine_y" joint="Spine_y" gear="1"/>
    <motor name="Spine_x" joint="Spine_x" gear="1"/>
    <motor name="Chest_z" joint="Chest_z" gear="1"/>
    <motor name="Chest_y" joint="Chest_y" gear="1"/>
    <motor name="Chest_x" joint="Chest_x" gear="1"/>
    <motor name="Neck_z" joint="Neck_z" gear="1"/>
    <motor name="Neck_y" joint="Neck_y" gear="1"/>
    <motor name="Neck_x" joint="Neck_x" gear="1"/>
    <motor name="Head_z" joint="Head_z" gear="1"/>
    <motor name="Head_y" joint="Head_y" gear="1"/>
    <motor name="Head_x" joint="Head_x" gear="1"/>
    <motor name="L_Thorax_z" joint="L_Thorax_z" gear="1"/>
    <motor name="L_Thorax_y" joint="L_Thorax_y" gear="1"/>
    <motor name="L_Thorax_x" joint="L_Thorax_x" gear="1"/>
    <motor name="L_Shoulder_z" joint="L_Shoulder_z" gear="1"/>
    <motor name="L_Shoulder_y" joint="L_Shoulder_y" gear="1"/>
    <motor name="L_Shoulder_x" joint="L_Shoulder_x" gear="1"/>
    <motor name="L_Elbow_z" joint="L_Elbow_z" gear="1"/>
    <motor name="L_Elbow_y" joint="L_Elbow_y" gear="1"/>
    <motor name="L_Elbow_x" joint="L_Elbow_x" gear="1"/>
    <motor name="L_Wrist_z" joint="L_Wrist_z" gear="1"/>
    <motor name="L_Wrist_y" joint="L_Wrist_y" gear="1"/>
    <motor name="L_Wrist_x" joint="L_Wrist_x" gear="1"/>
    <motor name="L_Hand_z" joint="L_Hand_z" gear="1"/>
    <motor name="L_Hand_y" joint="L_Hand_y" gear="1"/>
    <motor name="L_Hand_x" joint="L_Hand_x" gear="1"/>
    <motor name="R_Thorax_z" joint="R_Thorax_z" gear="1"/>
    <motor name="R_Thorax_y" joint="R_Thorax_y" gear="1"/>
    <motor name="R_Thorax_x" joint="R_Thorax_x" gear="1"/>
    <motor name="R_Shoulder_z" joint="R_Shoulder_z" gear="1"/>
    <motor name="R_Shoulder_y" joint="R_Shoulder_y" gear="1"/>
    <motor name="R_Shoulder_x" joint="R_Shoulder_x" gear="1"/>
    <motor name="R_Elbow_z" joint="R_Elbow_z" gear="1"/>
    <motor name="R_Elbow_y" joint="R_Elbow_y" gear="1"/>
    <motor name="R_Elbow_x" joint="R_Elbow_x" gear="1"/>
    <motor name="R_Wrist_z" joint="R_Wrist_z" gear="1"/>
    <motor name="R_Wrist_y" joint="R_Wrist_y" gear="1"/>
    <motor name="R_Wrist_x" joint="R_Wrist_x" gear="1"/>
    <motor name="R_Hand_z" joint="R_Hand_z" gear="1"/>
    <motor name="R_Hand_y" joint="R_Hand_y" gear="1"/>
    <motor name="R_Hand_x" joint="R_Hand_x" gear="1"/>
  </actuator>
</mujoco>
