<mujoco model="humanoid">
  <compiler angle="degree" inertiafromgeom="true" coordinate="global"/>
  <size njmax="8000" nconmax="4000"/>
  <visual>
    <headlight ambient=".4 .4 .4" diffuse=".8 .8 .8" specular="0.1 0.1 0.1"/>
    <map znear=".01"/>
    <quality shadowsize="2048"/>
  </visual>
  <default>
    <joint damping="0.0" armature="0.01" stiffness="0.0" limited="true"/>
    <geom conaffinity="7" condim="1" contype="7" margin="0.001" rgba="0.8 0.6 .4 1"/>
  </default>
  <statistic extent="3" center="0 0 1"/>
  <option timestep="0.00222222222">
    <flag contact="disable"/>
  </option>
  <size njmax="1000"/>
  <asset>
    <texture type="skybox" builtin="gradient" rgb1=".4 .5 .6" rgb2="0 0 0" width="100" height="100"/>
    <texture builtin="flat" height="1278" mark="cross" markrgb="1 1 1" name="texgeom" random="0.01" rgb1="0.8 0.6 0.4" rgb2="0.8 0.6 0.4" type="cube" width="127"/>
    <texture builtin="checker" height="100" name="texplane" rgb1="0 0 0" rgb2="0.8 0.8 0.8" type="2d" width="100"/>
    <material name="MatPlane" reflectance="0.5" shininess="1" specular="1" texrepeat="60 60" texture="texplane"/>
    <material name="geom" texture="texgeom" texuniform="true"/>
    <mesh file="assets/mujoco_models//geom/Pelvis.stl"/>
    <mesh file="assets/mujoco_models//geom/L_Hip.stl"/>
    <mesh file="assets/mujoco_models//geom/R_Hip.stl"/>
    <mesh file="assets/mujoco_models//geom/Torso.stl"/>
    <mesh file="assets/mujoco_models//geom/L_Knee.stl"/>
    <mesh file="assets/mujoco_models//geom/R_Knee.stl"/>
    <mesh file="assets/mujoco_models//geom/Spine.stl"/>
    <mesh file="assets/mujoco_models//geom/L_Ankle.stl"/>
    <mesh file="assets/mujoco_models//geom/R_Ankle.stl"/>
    <mesh file="assets/mujoco_models//geom/Chest.stl"/>
    <mesh file="assets/mujoco_models//geom/L_Toe.stl"/>
    <mesh file="assets/mujoco_models//geom/R_Toe.stl"/>
    <mesh file="assets/mujoco_models//geom/Neck.stl"/>
    <mesh file="assets/mujoco_models//geom/L_Thorax.stl"/>
    <mesh file="assets/mujoco_models//geom/R_Thorax.stl"/>
    <mesh file="assets/mujoco_models//geom/Head.stl"/>
    <mesh file="assets/mujoco_models//geom/L_Shoulder.stl"/>
    <mesh file="assets/mujoco_models//geom/R_Shoulder.stl"/>
    <mesh file="assets/mujoco_models//geom/L_Elbow.stl"/>
    <mesh file="assets/mujoco_models//geom/R_Elbow.stl"/>
    <mesh file="assets/mujoco_models//geom/L_Wrist.stl"/>
    <mesh file="assets/mujoco_models//geom/R_Wrist.stl"/>
    <mesh file="assets/mujoco_models//geom/L_Hand.stl"/>
    <mesh file="assets/mujoco_models//geom/R_Hand.stl"/>
  </asset>
  <worldbody>
    <light cutoff="100" diffuse="1 1 1" dir="-0 0 -1.3" directional="true" exponent="1" pos="0 0 1.3" specular=".1 .1 .1"/>
    <geom conaffinity="1" condim="3" name="floor" pos="0 0 0" rgba="0.8 0.9 0.8 1" size="100 100 .2" type="plane" material="MatPlane"/>
    <body name="Pelvis" pos="-0.0018 -0.2233 0.0282" quat="1.0000 0.0000 0.0000 0.0000">
      <joint name="Pelvis" pos="-0.0018 -0.2233 0.0282" limited="false" type="free" armature="0" damping="0" stiffness="0"/>
      <geom type="mesh" mesh="Pelvis" contype="0" conaffinity="1"/>
      <body name="L_Hip" pos="0.0677 -0.3147 0.0214" quat="1.0000 0.0000 0.0000 0.0000">
        <joint name="L_Hip_z" type="hinge" pos="0.0677 -0.3147 0.0214" axis="0.0000 0.0000 1.0000" range="-180.0000 180.0000"/>
        <joint name="L_Hip_y" type="hinge" pos="0.0677 -0.3147 0.0214" axis="0.0000 1.0000 0.0000" range="-180.0000 180.0000"/>
        <joint name="L_Hip_x" type="hinge" pos="0.0677 -0.3147 0.0214" axis="1.0000 0.0000 0.0000" range="-180.0000 180.0000"/>
        <geom type="mesh" mesh="L_Hip" contype="0" conaffinity="1"/>
        <body name="L_Knee" pos="0.1020 -0.6899 0.0169" quat="1.0000 0.0000 0.0000 0.0000">
          <joint name="L_Knee_z" type="hinge" pos="0.1020 -0.6899 0.0169" axis="0.0000 0.0000 1.0000" range="-180.0000 180.0000"/>
          <joint name="L_Knee_y" type="hinge" pos="0.1020 -0.6899 0.0169" axis="0.0000 1.0000 0.0000" range="-180.0000 180.0000"/>
          <joint name="L_Knee_x" type="hinge" pos="0.1020 -0.6899 0.0169" axis="1.0000 0.0000 0.0000" range="-180.0000 180.0000"/>
          <geom type="mesh" mesh="L_Knee" contype="0" conaffinity="1"/>
          <body name="L_Ankle" pos="0.0884 -1.0879 -0.0268" quat="1.0000 0.0000 0.0000 0.0000">
            <joint name="L_Ankle_z" type="hinge" pos="0.0884 -1.0879 -0.0268" axis="0.0000 0.0000 1.0000" range="-180.0000 180.0000"/>
            <joint name="L_Ankle_y" type="hinge" pos="0.0884 -1.0879 -0.0268" axis="0.0000 1.0000 0.0000" range="-180.0000 180.0000"/>
            <joint name="L_Ankle_x" type="hinge" pos="0.0884 -1.0879 -0.0268" axis="1.0000 0.0000 0.0000" range="-180.0000 180.0000"/>
            <geom type="mesh" mesh="L_Ankle" contype="0" conaffinity="1"/>
            <body name="L_Toe" pos="0.1148 -1.1437 0.0925" quat="1.0000 0.0000 0.0000 0.0000">
              <joint name="L_Toe_z" type="hinge" pos="0.1148 -1.1437 0.0925" axis="0.0000 0.0000 1.0000" range="-180.0000 180.0000"/>
              <joint name="L_Toe_y" type="hinge" pos="0.1148 -1.1437 0.0925" axis="0.0000 1.0000 0.0000" range="-180.0000 180.0000"/>
              <joint name="L_Toe_x" type="hinge" pos="0.1148 -1.1437 0.0925" axis="1.0000 0.0000 0.0000" range="-180.0000 180.0000"/>
              <geom type="mesh" mesh="L_Toe" contype="0" conaffinity="1"/>
            </body>
          </body>
        </body>
      </body>
      <body name="R_Hip" pos="-0.0695 -0.3139 0.0239" quat="1.0000 0.0000 0.0000 0.0000">
        <joint name="R_Hip_z" type="hinge" pos="-0.0695 -0.3139 0.0239" axis="0.0000 0.0000 1.0000" range="-180.0000 180.0000"/>
        <joint name="R_Hip_y" type="hinge" pos="-0.0695 -0.3139 0.0239" axis="0.0000 1.0000 0.0000" range="-180.0000 180.0000"/>
        <joint name="R_Hip_x" type="hinge" pos="-0.0695 -0.3139 0.0239" axis="1.0000 0.0000 0.0000" range="-180.0000 180.0000"/>
        <geom type="mesh" mesh="R_Hip" contype="0" conaffinity="1"/>
        <body name="R_Knee" pos="-0.1078 -0.6964 0.0150" quat="1.0000 0.0000 0.0000 0.0000">
          <joint name="R_Knee_z" type="hinge" pos="-0.1078 -0.6964 0.0150" axis="0.0000 0.0000 1.0000" range="-180.0000 180.0000"/>
          <joint name="R_Knee_y" type="hinge" pos="-0.1078 -0.6964 0.0150" axis="0.0000 1.0000 0.0000" range="-180.0000 180.0000"/>
          <joint name="R_Knee_x" type="hinge" pos="-0.1078 -0.6964 0.0150" axis="1.0000 0.0000 0.0000" range="-180.0000 180.0000"/>
          <geom type="mesh" mesh="R_Knee" contype="0" conaffinity="1"/>
          <body name="R_Ankle" pos="-0.0920 -1.0948 -0.0273" quat="1.0000 0.0000 0.0000 0.0000">
            <joint name="R_Ankle_z" type="hinge" pos="-0.0920 -1.0948 -0.0273" axis="0.0000 0.0000 1.0000" range="-180.0000 180.0000"/>
            <joint name="R_Ankle_y" type="hinge" pos="-0.0920 -1.0948 -0.0273" axis="0.0000 1.0000 0.0000" range="-180.0000 180.0000"/>
            <joint name="R_Ankle_x" type="hinge" pos="-0.0920 -1.0948 -0.0273" axis="1.0000 0.0000 0.0000" range="-180.0000 180.0000"/>
            <geom type="mesh" mesh="R_Ankle" contype="0" conaffinity="1"/>
            <body name="R_Toe" pos="-0.1174 -1.1430 0.0961" quat="1.0000 0.0000 0.0000 0.0000">
              <joint name="R_Toe_z" type="hinge" pos="-0.1174 -1.1430 0.0961" axis="0.0000 0.0000 1.0000" range="-180.0000 180.0000"/>
              <joint name="R_Toe_y" type="hinge" pos="-0.1174 -1.1430 0.0961" axis="0.0000 1.0000 0.0000" range="-180.0000 180.0000"/>
              <joint name="R_Toe_x" type="hinge" pos="-0.1174 -1.1430 0.0961" axis="1.0000 0.0000 0.0000" range="-180.0000 180.0000"/>
              <geom type="mesh" mesh="R_Toe" contype="0" conaffinity="1"/>
            </body>
          </body>
        </body>
      </body>
      <body name="Torso" pos="-0.0043 -0.1144 0.0015" quat="1.0000 0.0000 0.0000 0.0000">
        <joint name="Torso_z" type="hinge" pos="-0.0043 -0.1144 0.0015" axis="0.0000 0.0000 1.0000" range="-180.0000 180.0000"/>
        <joint name="Torso_y" type="hinge" pos="-0.0043 -0.1144 0.0015" axis="0.0000 1.0000 0.0000" range="-180.0000 180.0000"/>
        <joint name="Torso_x" type="hinge" pos="-0.0043 -0.1144 0.0015" axis="1.0000 0.0000 0.0000" range="-180.0000 180.0000"/>
        <geom type="mesh" mesh="Torso" contype="0" conaffinity="1"/>
        <body name="Spine" pos="0.0012 0.0208 0.0026" quat="1.0000 0.0000 0.0000 0.0000">
          <joint name="Spine_z" type="hinge" pos="0.0012 0.0208 0.0026" axis="0.0000 0.0000 1.0000" range="-180.0000 180.0000"/>
          <joint name="Spine_y" type="hinge" pos="0.0012 0.0208 0.0026" axis="0.0000 1.0000 0.0000" range="-180.0000 180.0000"/>
          <joint name="Spine_x" type="hinge" pos="0.0012 0.0208 0.0026" axis="1.0000 0.0000 0.0000" range="-180.0000 180.0000"/>
          <geom type="mesh" mesh="Spine" contype="0" conaffinity="1"/>
          <body name="Chest" pos="0.0026 0.0737 0.0280" quat="1.0000 0.0000 0.0000 0.0000">
            <joint name="Chest_z" type="hinge" pos="0.0026 0.0737 0.0280" axis="0.0000 0.0000 1.0000" range="-180.0000 180.0000"/>
            <joint name="Chest_y" type="hinge" pos="0.0026 0.0737 0.0280" axis="0.0000 1.0000 0.0000" range="-180.0000 180.0000"/>
            <joint name="Chest_x" type="hinge" pos="0.0026 0.0737 0.0280" axis="1.0000 0.0000 0.0000" range="-180.0000 180.0000"/>
            <geom type="mesh" mesh="Chest" contype="0" conaffinity="1"/>
            <body name="Neck" pos="-0.0002 0.2876 -0.0148" quat="1.0000 0.0000 0.0000 0.0000">
              <joint name="Neck_z" type="hinge" pos="-0.0002 0.2876 -0.0148" axis="0.0000 0.0000 1.0000" range="-180.0000 180.0000"/>
              <joint name="Neck_y" type="hinge" pos="-0.0002 0.2876 -0.0148" axis="0.0000 1.0000 0.0000" range="-180.0000 180.0000"/>
              <joint name="Neck_x" type="hinge" pos="-0.0002 0.2876 -0.0148" axis="1.0000 0.0000 0.0000" range="-180.0000 180.0000"/>
              <geom type="mesh" mesh="Neck" contype="0" conaffinity="1"/>
              <body name="Head" pos="0.0050 0.3526 0.0365" quat="1.0000 0.0000 0.0000 0.0000">
                <joint name="Head_z" type="hinge" pos="0.0050 0.3526 0.0365" axis="0.0000 0.0000 1.0000" range="-180.0000 180.0000"/>
                <joint name="Head_y" type="hinge" pos="0.0050 0.3526 0.0365" axis="0.0000 1.0000 0.0000" range="-180.0000 180.0000"/>
                <joint name="Head_x" type="hinge" pos="0.0050 0.3526 0.0365" axis="1.0000 0.0000 0.0000" range="-180.0000 180.0000"/>
                <geom type="mesh" mesh="Head" contype="0" conaffinity="1"/>
              </body>
            </body>
            <body name="L_Thorax" pos="0.0815 0.1955 -0.0060" quat="1.0000 0.0000 0.0000 0.0000">
              <joint name="L_Thorax_z" type="hinge" pos="0.0815 0.1955 -0.0060" axis="0.0000 0.0000 1.0000" range="-180.0000 180.0000"/>
              <joint name="L_Thorax_y" type="hinge" pos="0.0815 0.1955 -0.0060" axis="0.0000 1.0000 0.0000" range="-180.0000 180.0000"/>
              <joint name="L_Thorax_x" type="hinge" pos="0.0815 0.1955 -0.0060" axis="1.0000 0.0000 0.0000" range="-180.0000 180.0000"/>
              <geom type="mesh" mesh="L_Thorax" contype="0" conaffinity="1"/>
              <body name="L_Shoulder" pos="0.1724 0.2260 -0.0149" quat="1.0000 0.0000 0.0000 0.0000">
                <joint name="L_Shoulder_z" type="hinge" pos="0.1724 0.2260 -0.0149" axis="0.0000 0.0000 1.0000" range="-180.0000 180.0000"/>
                <joint name="L_Shoulder_y" type="hinge" pos="0.1724 0.2260 -0.0149" axis="0.0000 1.0000 0.0000" range="-180.0000 180.0000"/>
                <joint name="L_Shoulder_x" type="hinge" pos="0.1724 0.2260 -0.0149" axis="1.0000 0.0000 0.0000" range="-180.0000 180.0000"/>
                <geom type="mesh" mesh="L_Shoulder" contype="0" conaffinity="1"/>
                <body name="L_Elbow" pos="0.4320 0.2132 -0.0424" quat="1.0000 0.0000 0.0000 0.0000">
                  <joint name="L_Elbow_z" type="hinge" pos="0.4320 0.2132 -0.0424" axis="0.0000 0.0000 1.0000" range="-720.0000 720.0000"/>
                  <joint name="L_Elbow_y" type="hinge" pos="0.4320 0.2132 -0.0424" axis="0.0000 1.0000 0.0000" range="-720.0000 720.0000"/>
                  <joint name="L_Elbow_x" type="hinge" pos="0.4320 0.2132 -0.0424" axis="1.0000 0.0000 0.0000" range="-720.0000 720.0000"/>
                  <geom type="mesh" mesh="L_Elbow" contype="0" conaffinity="1"/>
                  <body name="L_Wrist" pos="0.6813 0.2222 -0.0435" quat="1.0000 0.0000 0.0000 0.0000">
                    <joint name="L_Wrist_z" type="hinge" pos="0.6813 0.2222 -0.0435" axis="0.0000 0.0000 1.0000" range="-180.0000 180.0000"/>
                    <joint name="L_Wrist_y" type="hinge" pos="0.6813 0.2222 -0.0435" axis="0.0000 1.0000 0.0000" range="-180.0000 180.0000"/>
                    <joint name="L_Wrist_x" type="hinge" pos="0.6813 0.2222 -0.0435" axis="1.0000 0.0000 0.0000" range="-180.0000 180.0000"/>
                    <geom type="mesh" mesh="L_Wrist" contype="0" conaffinity="1"/>
                    <body name="L_Hand" pos="0.7653 0.2140 -0.0585" quat="1.0000 0.0000 0.0000 0.0000">
                      <joint name="L_Hand_z" type="hinge" pos="0.7653 0.2140 -0.0585" axis="0.0000 0.0000 1.0000" range="-180.0000 180.0000"/>
                      <joint name="L_Hand_y" type="hinge" pos="0.7653 0.2140 -0.0585" axis="0.0000 1.0000 0.0000" range="-180.0000 180.0000"/>
                      <joint name="L_Hand_x" type="hinge" pos="0.7653 0.2140 -0.0585" axis="1.0000 0.0000 0.0000" range="-180.0000 180.0000"/>
                      <geom type="mesh" mesh="L_Hand" contype="0" conaffinity="1"/>
                    </body>
                  </body>
                </body>
              </body>
            </body>
            <body name="R_Thorax" pos="-0.0791 0.1926 -0.0106" quat="1.0000 0.0000 0.0000 0.0000">
              <joint name="R_Thorax_z" type="hinge" pos="-0.0791 0.1926 -0.0106" axis="0.0000 0.0000 1.0000" range="-180.0000 180.0000"/>
              <joint name="R_Thorax_y" type="hinge" pos="-0.0791 0.1926 -0.0106" axis="0.0000 1.0000 0.0000" range="-180.0000 180.0000"/>
              <joint name="R_Thorax_x" type="hinge" pos="-0.0791 0.1926 -0.0106" axis="1.0000 0.0000 0.0000" range="-180.0000 180.0000"/>
              <geom type="mesh" mesh="R_Thorax" contype="0" conaffinity="1"/>
              <body name="R_Shoulder" pos="-0.1752 0.2251 -0.0197" quat="1.0000 0.0000 0.0000 0.0000">
                <joint name="R_Shoulder_z" type="hinge" pos="-0.1752 0.2251 -0.0197" axis="0.0000 0.0000 1.0000" range="-180.0000 180.0000"/>
                <joint name="R_Shoulder_y" type="hinge" pos="-0.1752 0.2251 -0.0197" axis="0.0000 1.0000 0.0000" range="-180.0000 180.0000"/>
                <joint name="R_Shoulder_x" type="hinge" pos="-0.1752 0.2251 -0.0197" axis="1.0000 0.0000 0.0000" range="-180.0000 180.0000"/>
                <geom type="mesh" mesh="R_Shoulder" contype="0" conaffinity="1"/>
                <body name="R_Elbow" pos="-0.4289 0.2118 -0.0411" quat="1.0000 0.0000 0.0000 0.0000">
                  <joint name="R_Elbow_z" type="hinge" pos="-0.4289 0.2118 -0.0411" axis="0.0000 0.0000 1.0000" range="-720.0000 720.0000"/>
                  <joint name="R_Elbow_y" type="hinge" pos="-0.4289 0.2118 -0.0411" axis="0.0000 1.0000 0.0000" range="-720.0000 720.0000"/>
                  <joint name="R_Elbow_x" type="hinge" pos="-0.4289 0.2118 -0.0411" axis="1.0000 0.0000 0.0000" range="-720.0000 720.0000"/>
                  <geom type="mesh" mesh="R_Elbow" contype="0" conaffinity="1"/>
                  <body name="R_Wrist" pos="-0.6842 0.2196 -0.0467" quat="1.0000 0.0000 0.0000 0.0000">
                    <joint name="R_Wrist_z" type="hinge" pos="-0.6842 0.2196 -0.0467" axis="0.0000 0.0000 1.0000" range="-180.0000 180.0000"/>
                    <joint name="R_Wrist_y" type="hinge" pos="-0.6842 0.2196 -0.0467" axis="0.0000 1.0000 0.0000" range="-180.0000 180.0000"/>
                    <joint name="R_Wrist_x" type="hinge" pos="-0.6842 0.2196 -0.0467" axis="1.0000 0.0000 0.0000" range="-180.0000 180.0000"/>
                    <geom type="mesh" mesh="R_Wrist" contype="0" conaffinity="1"/>
                    <body name="R_Hand" pos="-0.7688 0.2134 -0.0570" quat="1.0000 0.0000 0.0000 0.0000">
                      <joint name="R_Hand_z" type="hinge" pos="-0.7688 0.2134 -0.0570" axis="0.0000 0.0000 1.0000" range="-180.0000 180.0000"/>
                      <joint name="R_Hand_y" type="hinge" pos="-0.7688 0.2134 -0.0570" axis="0.0000 1.0000 0.0000" range="-180.0000 180.0000"/>
                      <joint name="R_Hand_x" type="hinge" pos="-0.7688 0.2134 -0.0570" axis="1.0000 0.0000 0.0000" range="-180.0000 180.0000"/>
                      <geom type="mesh" mesh="R_Hand" contype="0" conaffinity="1"/>
                    </body>
                  </body>
                </body>
              </body>
            </body>
          </body>
        </body>
      </body>
    </body>
    <body name="1_Pelvis" pos="-0.0018 -0.2233 0.0282" quat="1.0000 0.0000 0.0000 0.0000">
      <joint name="1_Pelvis" pos="-0.0018 -0.2233 0.0282" limited="false" type="free" armature="0" damping="0" stiffness="0"/>
      <geom type="mesh" mesh="Pelvis" contype="0" conaffinity="1"/>
      <body name="1_L_Hip" pos="0.0677 -0.3147 0.0214" quat="1.0000 0.0000 0.0000 0.0000">
        <joint name="1_L_Hip_z" type="hinge" pos="0.0677 -0.3147 0.0214" axis="0.0000 0.0000 1.0000" range="-180.0000 180.0000"/>
        <joint name="1_L_Hip_y" type="hinge" pos="0.0677 -0.3147 0.0214" axis="0.0000 1.0000 0.0000" range="-180.0000 180.0000"/>
        <joint name="1_L_Hip_x" type="hinge" pos="0.0677 -0.3147 0.0214" axis="1.0000 0.0000 0.0000" range="-180.0000 180.0000"/>
        <geom type="mesh" mesh="L_Hip" contype="0" conaffinity="1"/>
        <body name="1_L_Knee" pos="0.1020 -0.6899 0.0169" quat="1.0000 0.0000 0.0000 0.0000">
          <joint name="1_L_Knee_z" type="hinge" pos="0.1020 -0.6899 0.0169" axis="0.0000 0.0000 1.0000" range="-180.0000 180.0000"/>
          <joint name="1_L_Knee_y" type="hinge" pos="0.1020 -0.6899 0.0169" axis="0.0000 1.0000 0.0000" range="-180.0000 180.0000"/>
          <joint name="1_L_Knee_x" type="hinge" pos="0.1020 -0.6899 0.0169" axis="1.0000 0.0000 0.0000" range="-180.0000 180.0000"/>
          <geom type="mesh" mesh="L_Knee" contype="0" conaffinity="1"/>
          <body name="1_L_Ankle" pos="0.0884 -1.0879 -0.0268" quat="1.0000 0.0000 0.0000 0.0000">
            <joint name="1_L_Ankle_z" type="hinge" pos="0.0884 -1.0879 -0.0268" axis="0.0000 0.0000 1.0000" range="-180.0000 180.0000"/>
            <joint name="1_L_Ankle_y" type="hinge" pos="0.0884 -1.0879 -0.0268" axis="0.0000 1.0000 0.0000" range="-180.0000 180.0000"/>
            <joint name="1_L_Ankle_x" type="hinge" pos="0.0884 -1.0879 -0.0268" axis="1.0000 0.0000 0.0000" range="-180.0000 180.0000"/>
            <geom type="mesh" mesh="L_Ankle" contype="0" conaffinity="1"/>
            <body name="1_L_Toe" pos="0.1148 -1.1437 0.0925" quat="1.0000 0.0000 0.0000 0.0000">
              <joint name="1_L_Toe_z" type="hinge" pos="0.1148 -1.1437 0.0925" axis="0.0000 0.0000 1.0000" range="-180.0000 180.0000"/>
              <joint name="1_L_Toe_y" type="hinge" pos="0.1148 -1.1437 0.0925" axis="0.0000 1.0000 0.0000" range="-180.0000 180.0000"/>
              <joint name="1_L_Toe_x" type="hinge" pos="0.1148 -1.1437 0.0925" axis="1.0000 0.0000 0.0000" range="-180.0000 180.0000"/>
              <geom type="mesh" mesh="L_Toe" contype="0" conaffinity="1"/>
            </body>
          </body>
        </body>
      </body>
      <body name="1_R_Hip" pos="-0.0695 -0.3139 0.0239" quat="1.0000 0.0000 0.0000 0.0000">
        <joint name="1_R_Hip_z" type="hinge" pos="-0.0695 -0.3139 0.0239" axis="0.0000 0.0000 1.0000" range="-180.0000 180.0000"/>
        <joint name="1_R_Hip_y" type="hinge" pos="-0.0695 -0.3139 0.0239" axis="0.0000 1.0000 0.0000" range="-180.0000 180.0000"/>
        <joint name="1_R_Hip_x" type="hinge" pos="-0.0695 -0.3139 0.0239" axis="1.0000 0.0000 0.0000" range="-180.0000 180.0000"/>
        <geom type="mesh" mesh="R_Hip" contype="0" conaffinity="1"/>
        <body name="1_R_Knee" pos="-0.1078 -0.6964 0.0150" quat="1.0000 0.0000 0.0000 0.0000">
          <joint name="1_R_Knee_z" type="hinge" pos="-0.1078 -0.6964 0.0150" axis="0.0000 0.0000 1.0000" range="-180.0000 180.0000"/>
          <joint name="1_R_Knee_y" type="hinge" pos="-0.1078 -0.6964 0.0150" axis="0.0000 1.0000 0.0000" range="-180.0000 180.0000"/>
          <joint name="1_R_Knee_x" type="hinge" pos="-0.1078 -0.6964 0.0150" axis="1.0000 0.0000 0.0000" range="-180.0000 180.0000"/>
          <geom type="mesh" mesh="R_Knee" contype="0" conaffinity="1"/>
          <body name="1_R_Ankle" pos="-0.0920 -1.0948 -0.0273" quat="1.0000 0.0000 0.0000 0.0000">
            <joint name="1_R_Ankle_z" type="hinge" pos="-0.0920 -1.0948 -0.0273" axis="0.0000 0.0000 1.0000" range="-180.0000 180.0000"/>
            <joint name="1_R_Ankle_y" type="hinge" pos="-0.0920 -1.0948 -0.0273" axis="0.0000 1.0000 0.0000" range="-180.0000 180.0000"/>
            <joint name="1_R_Ankle_x" type="hinge" pos="-0.0920 -1.0948 -0.0273" axis="1.0000 0.0000 0.0000" range="-180.0000 180.0000"/>
            <geom type="mesh" mesh="R_Ankle" contype="0" conaffinity="1"/>
            <body name="1_R_Toe" pos="-0.1174 -1.1430 0.0961" quat="1.0000 0.0000 0.0000 0.0000">
              <joint name="1_R_Toe_z" type="hinge" pos="-0.1174 -1.1430 0.0961" axis="0.0000 0.0000 1.0000" range="-180.0000 180.0000"/>
              <joint name="1_R_Toe_y" type="hinge" pos="-0.1174 -1.1430 0.0961" axis="0.0000 1.0000 0.0000" range="-180.0000 180.0000"/>
              <joint name="1_R_Toe_x" type="hinge" pos="-0.1174 -1.1430 0.0961" axis="1.0000 0.0000 0.0000" range="-180.0000 180.0000"/>
              <geom type="mesh" mesh="R_Toe" contype="0" conaffinity="1"/>
            </body>
          </body>
        </body>
      </body>
      <body name="1_Torso" pos="-0.0043 -0.1144 0.0015" quat="1.0000 0.0000 0.0000 0.0000">
        <joint name="1_Torso_z" type="hinge" pos="-0.0043 -0.1144 0.0015" axis="0.0000 0.0000 1.0000" range="-180.0000 180.0000"/>
        <joint name="1_Torso_y" type="hinge" pos="-0.0043 -0.1144 0.0015" axis="0.0000 1.0000 0.0000" range="-180.0000 180.0000"/>
        <joint name="1_Torso_x" type="hinge" pos="-0.0043 -0.1144 0.0015" axis="1.0000 0.0000 0.0000" range="-180.0000 180.0000"/>
        <geom type="mesh" mesh="Torso" contype="0" conaffinity="1"/>
        <body name="1_Spine" pos="0.0012 0.0208 0.0026" quat="1.0000 0.0000 0.0000 0.0000">
          <joint name="1_Spine_z" type="hinge" pos="0.0012 0.0208 0.0026" axis="0.0000 0.0000 1.0000" range="-180.0000 180.0000"/>
          <joint name="1_Spine_y" type="hinge" pos="0.0012 0.0208 0.0026" axis="0.0000 1.0000 0.0000" range="-180.0000 180.0000"/>
          <joint name="1_Spine_x" type="hinge" pos="0.0012 0.0208 0.0026" axis="1.0000 0.0000 0.0000" range="-180.0000 180.0000"/>
          <geom type="mesh" mesh="Spine" contype="0" conaffinity="1"/>
          <body name="1_Chest" pos="0.0026 0.0737 0.0280" quat="1.0000 0.0000 0.0000 0.0000">
            <joint name="1_Chest_z" type="hinge" pos="0.0026 0.0737 0.0280" axis="0.0000 0.0000 1.0000" range="-180.0000 180.0000"/>
            <joint name="1_Chest_y" type="hinge" pos="0.0026 0.0737 0.0280" axis="0.0000 1.0000 0.0000" range="-180.0000 180.0000"/>
            <joint name="1_Chest_x" type="hinge" pos="0.0026 0.0737 0.0280" axis="1.0000 0.0000 0.0000" range="-180.0000 180.0000"/>
            <geom type="mesh" mesh="Chest" contype="0" conaffinity="1"/>
            <body name="1_Neck" pos="-0.0002 0.2876 -0.0148" quat="1.0000 0.0000 0.0000 0.0000">
              <joint name="1_Neck_z" type="hinge" pos="-0.0002 0.2876 -0.0148" axis="0.0000 0.0000 1.0000" range="-180.0000 180.0000"/>
              <joint name="1_Neck_y" type="hinge" pos="-0.0002 0.2876 -0.0148" axis="0.0000 1.0000 0.0000" range="-180.0000 180.0000"/>
              <joint name="1_Neck_x" type="hinge" pos="-0.0002 0.2876 -0.0148" axis="1.0000 0.0000 0.0000" range="-180.0000 180.0000"/>
              <geom type="mesh" mesh="Neck" contype="0" conaffinity="1"/>
              <body name="1_Head" pos="0.0050 0.3526 0.0365" quat="1.0000 0.0000 0.0000 0.0000">
                <joint name="1_Head_z" type="hinge" pos="0.0050 0.3526 0.0365" axis="0.0000 0.0000 1.0000" range="-180.0000 180.0000"/>
                <joint name="1_Head_y" type="hinge" pos="0.0050 0.3526 0.0365" axis="0.0000 1.0000 0.0000" range="-180.0000 180.0000"/>
                <joint name="1_Head_x" type="hinge" pos="0.0050 0.3526 0.0365" axis="1.0000 0.0000 0.0000" range="-180.0000 180.0000"/>
                <geom type="mesh" mesh="Head" contype="0" conaffinity="1"/>
              </body>
            </body>
            <body name="1_L_Thorax" pos="0.0815 0.1955 -0.0060" quat="1.0000 0.0000 0.0000 0.0000">
              <joint name="1_L_Thorax_z" type="hinge" pos="0.0815 0.1955 -0.0060" axis="0.0000 0.0000 1.0000" range="-180.0000 180.0000"/>
              <joint name="1_L_Thorax_y" type="hinge" pos="0.0815 0.1955 -0.0060" axis="0.0000 1.0000 0.0000" range="-180.0000 180.0000"/>
              <joint name="1_L_Thorax_x" type="hinge" pos="0.0815 0.1955 -0.0060" axis="1.0000 0.0000 0.0000" range="-180.0000 180.0000"/>
              <geom type="mesh" mesh="L_Thorax" contype="0" conaffinity="1"/>
              <body name="1_L_Shoulder" pos="0.1724 0.2260 -0.0149" quat="1.0000 0.0000 0.0000 0.0000">
                <joint name="1_L_Shoulder_z" type="hinge" pos="0.1724 0.2260 -0.0149" axis="0.0000 0.0000 1.0000" range="-180.0000 180.0000"/>
                <joint name="1_L_Shoulder_y" type="hinge" pos="0.1724 0.2260 -0.0149" axis="0.0000 1.0000 0.0000" range="-180.0000 180.0000"/>
                <joint name="1_L_Shoulder_x" type="hinge" pos="0.1724 0.2260 -0.0149" axis="1.0000 0.0000 0.0000" range="-180.0000 180.0000"/>
                <geom type="mesh" mesh="L_Shoulder" contype="0" conaffinity="1"/>
                <body name="1_L_Elbow" pos="0.4320 0.2132 -0.0424" quat="1.0000 0.0000 0.0000 0.0000">
                  <joint name="1_L_Elbow_z" type="hinge" pos="0.4320 0.2132 -0.0424" axis="0.0000 0.0000 1.0000" range="-720.0000 720.0000"/>
                  <joint name="1_L_Elbow_y" type="hinge" pos="0.4320 0.2132 -0.0424" axis="0.0000 1.0000 0.0000" range="-720.0000 720.0000"/>
                  <joint name="1_L_Elbow_x" type="hinge" pos="0.4320 0.2132 -0.0424" axis="1.0000 0.0000 0.0000" range="-720.0000 720.0000"/>
                  <geom type="mesh" mesh="L_Elbow" contype="0" conaffinity="1"/>
                  <body name="1_L_Wrist" pos="0.6813 0.2222 -0.0435" quat="1.0000 0.0000 0.0000 0.0000">
                    <joint name="1_L_Wrist_z" type="hinge" pos="0.6813 0.2222 -0.0435" axis="0.0000 0.0000 1.0000" range="-180.0000 180.0000"/>
                    <joint name="1_L_Wrist_y" type="hinge" pos="0.6813 0.2222 -0.0435" axis="0.0000 1.0000 0.0000" range="-180.0000 180.0000"/>
                    <joint name="1_L_Wrist_x" type="hinge" pos="0.6813 0.2222 -0.0435" axis="1.0000 0.0000 0.0000" range="-180.0000 180.0000"/>
                    <geom type="mesh" mesh="L_Wrist" contype="0" conaffinity="1"/>
                    <body name="1_L_Hand" pos="0.7653 0.2140 -0.0585" quat="1.0000 0.0000 0.0000 0.0000">
                      <joint name="1_L_Hand_z" type="hinge" pos="0.7653 0.2140 -0.0585" axis="0.0000 0.0000 1.0000" range="-180.0000 180.0000"/>
                      <joint name="1_L_Hand_y" type="hinge" pos="0.7653 0.2140 -0.0585" axis="0.0000 1.0000 0.0000" range="-180.0000 180.0000"/>
                      <joint name="1_L_Hand_x" type="hinge" pos="0.7653 0.2140 -0.0585" axis="1.0000 0.0000 0.0000" range="-180.0000 180.0000"/>
                      <geom type="mesh" mesh="L_Hand" contype="0" conaffinity="1"/>
                    </body>
                  </body>
                </body>
              </body>
            </body>
            <body name="1_R_Thorax" pos="-0.0791 0.1926 -0.0106" quat="1.0000 0.0000 0.0000 0.0000">
              <joint name="1_R_Thorax_z" type="hinge" pos="-0.0791 0.1926 -0.0106" axis="0.0000 0.0000 1.0000" range="-180.0000 180.0000"/>
              <joint name="1_R_Thorax_y" type="hinge" pos="-0.0791 0.1926 -0.0106" axis="0.0000 1.0000 0.0000" range="-180.0000 180.0000"/>
              <joint name="1_R_Thorax_x" type="hinge" pos="-0.0791 0.1926 -0.0106" axis="1.0000 0.0000 0.0000" range="-180.0000 180.0000"/>
              <geom type="mesh" mesh="R_Thorax" contype="0" conaffinity="1"/>
              <body name="1_R_Shoulder" pos="-0.1752 0.2251 -0.0197" quat="1.0000 0.0000 0.0000 0.0000">
                <joint name="1_R_Shoulder_z" type="hinge" pos="-0.1752 0.2251 -0.0197" axis="0.0000 0.0000 1.0000" range="-180.0000 180.0000"/>
                <joint name="1_R_Shoulder_y" type="hinge" pos="-0.1752 0.2251 -0.0197" axis="0.0000 1.0000 0.0000" range="-180.0000 180.0000"/>
                <joint name="1_R_Shoulder_x" type="hinge" pos="-0.1752 0.2251 -0.0197" axis="1.0000 0.0000 0.0000" range="-180.0000 180.0000"/>
                <geom type="mesh" mesh="R_Shoulder" contype="0" conaffinity="1"/>
                <body name="1_R_Elbow" pos="-0.4289 0.2118 -0.0411" quat="1.0000 0.0000 0.0000 0.0000">
                  <joint name="1_R_Elbow_z" type="hinge" pos="-0.4289 0.2118 -0.0411" axis="0.0000 0.0000 1.0000" range="-720.0000 720.0000"/>
                  <joint name="1_R_Elbow_y" type="hinge" pos="-0.4289 0.2118 -0.0411" axis="0.0000 1.0000 0.0000" range="-720.0000 720.0000"/>
                  <joint name="1_R_Elbow_x" type="hinge" pos="-0.4289 0.2118 -0.0411" axis="1.0000 0.0000 0.0000" range="-720.0000 720.0000"/>
                  <geom type="mesh" mesh="R_Elbow" contype="0" conaffinity="1"/>
                  <body name="1_R_Wrist" pos="-0.6842 0.2196 -0.0467" quat="1.0000 0.0000 0.0000 0.0000">
                    <joint name="1_R_Wrist_z" type="hinge" pos="-0.6842 0.2196 -0.0467" axis="0.0000 0.0000 1.0000" range="-180.0000 180.0000"/>
                    <joint name="1_R_Wrist_y" type="hinge" pos="-0.6842 0.2196 -0.0467" axis="0.0000 1.0000 0.0000" range="-180.0000 180.0000"/>
                    <joint name="1_R_Wrist_x" type="hinge" pos="-0.6842 0.2196 -0.0467" axis="1.0000 0.0000 0.0000" range="-180.0000 180.0000"/>
                    <geom type="mesh" mesh="R_Wrist" contype="0" conaffinity="1"/>
                    <body name="1_R_Hand" pos="-0.7688 0.2134 -0.0570" quat="1.0000 0.0000 0.0000 0.0000">
                      <joint name="1_R_Hand_z" type="hinge" pos="-0.7688 0.2134 -0.0570" axis="0.0000 0.0000 1.0000" range="-180.0000 180.0000"/>
                      <joint name="1_R_Hand_y" type="hinge" pos="-0.7688 0.2134 -0.0570" axis="0.0000 1.0000 0.0000" range="-180.0000 180.0000"/>
                      <joint name="1_R_Hand_x" type="hinge" pos="-0.7688 0.2134 -0.0570" axis="1.0000 0.0000 0.0000" range="-180.0000 180.0000"/>
                      <geom type="mesh" mesh="R_Hand" contype="0" conaffinity="1"/>
                    </body>
                  </body>
                </body>
              </body>
            </body>
          </body>
        </body>
      </body>
    </body>
  </worldbody>
</mujoco>
