<mujoco model="humanoid">
  <compiler angle="degree" inertiafromgeom="true" coordinate="global"/>
  <include file="./common/materials.xml"/>
  <visual>
    <headlight ambient=".4 .4 .4" diffuse=".8 .8 .8" specular="0.1 0.1 0.1"/>
    <map znear=".01"/>
    <quality shadowsize="2048"/>
  </visual>
  <default>
    <joint damping="0.0" armature="0.01" stiffness="0.0" limited="true"/>
    <geom conaffinity="7" condim="1" contype="7" margin="0.001" material="self" rgba="0.8 0.6 .4 1"/>
    <default class="smpl">
        <geom rgba="0.7 0.0 0.0 1"/>
    </default>
  </default>
  <statistic extent="3" center="0 0 1"/>
  <option timestep="0.00222222222"/>
  <asset>
    <texture type="skybox" file="./common/sky1.png" gridsize="3 4" gridlayout=".U..LFRB.D.." width="8192" height="8192"/>
    <texture builtin="flat" height="1278" mark="cross" markrgb="1 1 1" name="texgeom" random="0.01" rgb1=".8 .6 .4" rgb2=".8 .6 .4" type="cube" width="127"/>
  </asset>
  <worldbody>
    <light cutoff="100" diffuse="1 1 1" dir="-0 0 -1.3" directional="true" exponent="1" pos="0 0 1.3" specular=".1 .1 .1"/>
    <geom condim="3" friction="1. .1 .1" material="grid" name="floor" pos="0 0 0" rgba=".8 .9 .8 1" size="100 100 .2" type="plane"/>
    <body name="1_Hips"   pos="0.0000 0.0000 1.0000" user="-0.0002 -0.0243 0.9874">
      <joint name="1_Hips" pos="0.0000 0.0000 1.0000" limited="false" type="free" armature="0" damping="0" stiffness="0"/>
      <geom size="0.0300" type="sphere" pos="0.0000 0.0000 1.0000"/>
      <body name="1_LeftUpLeg" pos="0.0695 -0.0914 0.9932" user="0.1038 -0.4666 0.9887">
        <joint name="1_LeftUpLeg_z" type="hinge" pos="0.0695 -0.0914 0.9932" axis="0.0000 0.0000 1.0000" range="-180.0000 180.0000"/>
        <joint name="1_LeftUpLeg_x" type="hinge" pos="0.0695 -0.0914 0.9932" axis="1.0000 0.0000 0.0000" range="-180.0000 180.0000"/>
        <joint name="1_LeftUpLeg_y" type="hinge" pos="0.0695 -0.0914 0.9932" axis="0.0000 1.0000 0.0000" range="-180.0000 180.0000"/>
        <geom size="0.0300" type="capsule" fromto="0.0713 -0.1113 0.9929 0.1020 -0.4467 0.9889"/>
        <body name="1_LeftLeg" pos="0.1038 -0.4666 0.9887" user="0.0902 -0.8646 0.9450">
          <joint name="1_LeftLeg_z" type="hinge" pos="0.1038 -0.4666 0.9887" axis="0.0000 0.0000 1.0000" range="-180.0000 180.0000"/>
          <joint name="1_LeftLeg_x" type="hinge" pos="0.1038 -0.4666 0.9887" axis="1.0000 0.0000 0.0000" range="-180.0000 180.0000"/>
          <joint name="1_LeftLeg_y" type="hinge" pos="0.1038 -0.4666 0.9887" axis="0.0000 1.0000 0.0000" range="-180.0000 180.0000"/>
          <geom size="0.0300" type="capsule" fromto="0.1031 -0.4865 0.9865 0.0909 -0.8447 0.9472"/>
          <body name="1_LeftFoot" pos="0.0902 -0.8646 0.9450" user="0.1166 -0.9204 1.0643">
            <joint name="1_LeftFoot_z" type="hinge" pos="0.0902 -0.8646 0.9450" axis="0.0000 0.0000 1.0000" range="-180.0000 180.0000"/>
            <joint name="1_LeftFoot_x" type="hinge" pos="0.0902 -0.8646 0.9450" axis="1.0000 0.0000 0.0000" range="-180.0000 180.0000"/>
            <joint name="1_LeftFoot_y" type="hinge" pos="0.0902 -0.8646 0.9450" axis="0.0000 1.0000 0.0000" range="-180.0000 180.0000"/>
            <geom size="0.0300" type="capsule" fromto="0.0941 -0.8729 0.9628 0.1126 -0.9120 1.0465"/>
            <body name="1_LeftToe" pos="0.1166 -0.9204 1.0643" user="0.1166 -0.9204 1.0643">
              <joint name="1_LeftToe_z" type="hinge" pos="0.1166 -0.9204 1.0643" axis="0.0000 0.0000 1.0000" range="-180.0000 180.0000"/>
              <joint name="1_LeftToe_x" type="hinge" pos="0.1166 -0.9204 1.0643" axis="1.0000 0.0000 0.0000" range="-180.0000 180.0000"/>
              <joint name="1_LeftToe_y" type="hinge" pos="0.1166 -0.9204 1.0643" axis="0.0000 1.0000 0.0000" range="-180.0000 180.0000"/>
              <geom size="0.0300" type="capsule" fromto="0.1166 -0.9204 1.0683 0.1166 -0.9204 1.0603"/>
            </body>
          </body>
        </body>
      </body>
      <body name="1_RightUpLeg" pos="-0.0677 -0.0905 0.9957" user="-0.1060 -0.4731 0.9868">
        <joint name="1_RightUpLeg_z" type="hinge" pos="-0.0677 -0.0905 0.9957" axis="0.0000 0.0000 1.0000" range="-180.0000 180.0000"/>
        <joint name="1_RightUpLeg_x" type="hinge" pos="-0.0677 -0.0905 0.9957" axis="1.0000 0.0000 0.0000" range="-180.0000 180.0000"/>
        <joint name="1_RightUpLeg_y" type="hinge" pos="-0.0677 -0.0905 0.9957" axis="0.0000 1.0000 0.0000" range="-180.0000 180.0000"/>
        <geom size="0.0300" type="capsule" fromto="-0.0697 -0.1104 0.9952 -0.1040 -0.4532 0.9873"/>
        <body name="1_RightLeg" pos="-0.1060 -0.4731 0.9868" user="-0.0902 -0.8715 0.9445">
          <joint name="1_RightLeg_z" type="hinge" pos="-0.1060 -0.4731 0.9868" axis="0.0000 0.0000 1.0000" range="-180.0000 180.0000"/>
          <joint name="1_RightLeg_x" type="hinge" pos="-0.1060 -0.4731 0.9868" axis="1.0000 0.0000 0.0000" range="-180.0000 180.0000"/>
          <joint name="1_RightLeg_y" type="hinge" pos="-0.1060 -0.4731 0.9868" axis="0.0000 1.0000 0.0000" range="-180.0000 180.0000"/>
          <geom size="0.0300" type="capsule" fromto="-0.1052 -0.4930 0.9847 -0.0910 -0.8516 0.9466"/>
          <body name="1_RightFoot" pos="-0.0902 -0.8715 0.9445" user="-0.1156 -0.9196 1.0679">
            <joint name="1_RightFoot_z" type="hinge" pos="-0.0902 -0.8715 0.9445" axis="0.0000 0.0000 1.0000" range="-180.0000 180.0000"/>
            <joint name="1_RightFoot_x" type="hinge" pos="-0.0902 -0.8715 0.9445" axis="1.0000 0.0000 0.0000" range="-180.0000 180.0000"/>
            <joint name="1_RightFoot_y" type="hinge" pos="-0.0902 -0.8715 0.9445" axis="0.0000 1.0000 0.0000" range="-180.0000 180.0000"/>
            <geom size="0.0300" type="capsule" fromto="-0.0940 -0.8786 0.9628 -0.1118 -0.9125 1.0496"/>
            <body name="1_RightToe" pos="-0.1156 -0.9196 1.0679" user="-0.1156 -0.9196 1.0679">
              <joint name="1_RightToe_z" type="hinge" pos="-0.1156 -0.9196 1.0679" axis="0.0000 0.0000 1.0000" range="-180.0000 180.0000"/>
              <joint name="1_RightToe_x" type="hinge" pos="-0.1156 -0.9196 1.0679" axis="1.0000 0.0000 0.0000" range="-180.0000 180.0000"/>
              <joint name="1_RightToe_y" type="hinge" pos="-0.1156 -0.9196 1.0679" axis="0.0000 1.0000 0.0000" range="-180.0000 180.0000"/>
              <geom size="0.0300" type="capsule" fromto="-0.1156 -0.9196 1.0719 -0.1156 -0.9196 1.0639"/>
            </body>
          </body>
        </body>
      </body>
      <body name="1_Spine" pos="-0.0025 0.1090 0.9733" user="0.0030 0.2441 0.9744">
        <joint name="1_Spine_z" type="hinge" pos="-0.0025 0.1090 0.9733" axis="0.0000 0.0000 1.0000" range="-180.0000 180.0000"/>
        <joint name="1_Spine_x" type="hinge" pos="-0.0025 0.1090 0.9733" axis="1.0000 0.0000 0.0000" range="-180.0000 180.0000"/>
        <joint name="1_Spine_y" type="hinge" pos="-0.0025 0.1090 0.9733" axis="0.0000 1.0000 0.0000" range="-180.0000 180.0000"/>
        <geom size="0.0300" type="capsule" fromto="-0.0017 0.1289 0.9735 0.0021 0.2242 0.9742"/>
        <body name="1_Spine1" pos="0.0030 0.2441 0.9744" user="0.0044 0.2971 0.9998">
          <joint name="1_Spine1_z" type="hinge" pos="0.0030 0.2441 0.9744" axis="0.0000 0.0000 1.0000" range="-180.0000 180.0000"/>
          <joint name="1_Spine1_x" type="hinge" pos="0.0030 0.2441 0.9744" axis="1.0000 0.0000 0.0000" range="-180.0000 180.0000"/>
          <joint name="1_Spine1_y" type="hinge" pos="0.0030 0.2441 0.9744" axis="0.0000 1.0000 0.0000" range="-180.0000 180.0000"/>
          <geom size="0.0300" type="capsule" fromto="0.0035 0.2622 0.9831 0.0039 0.2790 0.9912"/>
          <body name="1_Spine2" pos="0.0044 0.2971 0.9998" user="0.0025 0.4486 0.9613">
            <joint name="1_Spine2_z" type="hinge" pos="0.0044 0.2971 0.9998" axis="0.0000 0.0000 1.0000" range="-180.0000 180.0000"/>
            <joint name="1_Spine2_x" type="hinge" pos="0.0044 0.2971 0.9998" axis="1.0000 0.0000 0.0000" range="-180.0000 180.0000"/>
            <joint name="1_Spine2_y" type="hinge" pos="0.0044 0.2971 0.9998" axis="0.0000 1.0000 0.0000" range="-180.0000 180.0000"/>
            <geom size="0.0300" type="capsule" fromto="0.0042 0.3164 0.9949 0.0028 0.4292 0.9662"/>
            <body name="1_Neck" pos="0.0016 0.5109 0.9570" user="0.0068 0.5759 1.0083">
              <joint name="1_Neck_z" type="hinge" pos="0.0016 0.5109 0.9570" axis="0.0000 0.0000 1.0000" range="-180.0000 180.0000"/>
              <joint name="1_Neck_x" type="hinge" pos="0.0016 0.5109 0.9570" axis="1.0000 0.0000 0.0000" range="-180.0000 180.0000"/>
              <joint name="1_Neck_y" type="hinge" pos="0.0016 0.5109 0.9570" axis="0.0000 1.0000 0.0000" range="-180.0000 180.0000"/>
              <geom size="0.0300" type="capsule" fromto="0.0029 0.5266 0.9693 0.0055 0.5602 0.9959"/>
              <body name="1_Mouth" pos="0.0068 0.5759 1.0083" user="0.0068 0.5759 1.0083">
                <joint name="1_Mouth_z" type="hinge" pos="0.0068 0.5759 1.0083" axis="0.0000 0.0000 1.0000" range="-180.0000 180.0000"/>
                <joint name="1_Mouth_x" type="hinge" pos="0.0068 0.5759 1.0083" axis="1.0000 0.0000 0.0000" range="-180.0000 180.0000"/>
                <joint name="1_Mouth_y" type="hinge" pos="0.0068 0.5759 1.0083" axis="0.0000 1.0000 0.0000" range="-180.0000 180.0000"/>
                <geom size="0.0300" type="capsule" fromto="0.0068 0.5759 1.0123 0.0068 0.5759 1.0043"/>
              </body>
            </body>
            <body name="1_LeftChest" pos="0.0833 0.4188 0.9657" user="0.1742 0.4493 0.9569">
              <joint name="1_LeftChest_z" type="hinge" pos="0.0833 0.4188 0.9657" axis="0.0000 0.0000 1.0000" range="-180.0000 180.0000"/>
              <joint name="1_LeftChest_x" type="hinge" pos="0.0833 0.4188 0.9657" axis="1.0000 0.0000 0.0000" range="-180.0000 180.0000"/>
              <joint name="1_LeftChest_y" type="hinge" pos="0.0833 0.4188 0.9657" axis="0.0000 1.0000 0.0000" range="-180.0000 180.0000"/>
              <geom size="0.0300" type="capsule" fromto="0.1021 0.4251 0.9639 0.1553 0.4430 0.9587"/>
              <body name="1_LeftShoulder" pos="0.1742 0.4493 0.9569" user="0.4338 0.4365 0.9294">
                <joint name="1_LeftShoulder_z" type="hinge" pos="0.1742 0.4493 0.9569" axis="0.0000 0.0000 1.0000" range="-180.0000 180.0000"/>
                <joint name="1_LeftShoulder_x" type="hinge" pos="0.1742 0.4493 0.9569" axis="1.0000 0.0000 0.0000" range="-180.0000 180.0000"/>
                <joint name="1_LeftShoulder_y" type="hinge" pos="0.1742 0.4493 0.9569" axis="0.0000 1.0000 0.0000" range="-180.0000 180.0000"/>
                <geom size="0.0300" type="capsule" fromto="0.1941 0.4483 0.9548 0.4140 0.4375 0.9315"/>
                <body name="1_LeftArm" pos="0.4338 0.4365 0.9294" user="0.6831 0.4455 0.9282">
                  <joint name="1_LeftArm_z" type="hinge" pos="0.4338 0.4365 0.9294" axis="0.0000 0.0000 1.0000" range="-180.0000 180.0000"/>
                  <joint name="1_LeftArm_x" type="hinge" pos="0.4338 0.4365 0.9294" axis="1.0000 0.0000 0.0000" range="-180.0000 180.0000"/>
                  <joint name="1_LeftArm_y" type="hinge" pos="0.4338 0.4365 0.9294" axis="0.0000 1.0000 0.0000" range="-180.0000 180.0000"/>
                  <geom size="0.0300" type="capsule" fromto="0.4538 0.4372 0.9293 0.6631 0.4448 0.9283"/>
                  <body name="1_LeftWrist" pos="0.6831 0.4455 0.9282" user="0.7671 0.4373 0.9133">
                    <joint name="1_LeftWrist_z" type="hinge" pos="0.6831 0.4455 0.9282" axis="0.0000 0.0000 1.0000" range="-180.0000 180.0000"/>
                    <joint name="1_LeftWrist_x" type="hinge" pos="0.6831 0.4455 0.9282" axis="1.0000 0.0000 0.0000" range="-180.0000 180.0000"/>
                    <joint name="1_LeftWrist_y" type="hinge" pos="0.6831 0.4455 0.9282" axis="0.0000 1.0000 0.0000" range="-180.0000 180.0000"/>
                    <geom size="0.0300" type="capsule" fromto="0.7027 0.4436 0.9247 0.7475 0.4392 0.9168"/>
                    <body name="1_LeftHand" pos="0.7671 0.4373 0.9133" user="0.7671 0.4373 0.9133">
                      <joint name="1_LeftHand_z" type="hinge" pos="0.7671 0.4373 0.9133" axis="0.0000 0.0000 1.0000" range="-180.0000 180.0000"/>
                      <joint name="1_LeftHand_x" type="hinge" pos="0.7671 0.4373 0.9133" axis="1.0000 0.0000 0.0000" range="-180.0000 180.0000"/>
                      <joint name="1_LeftHand_y" type="hinge" pos="0.7671 0.4373 0.9133" axis="0.0000 1.0000 0.0000" range="-180.0000 180.0000"/>
                      <geom size="0.0300" type="capsule" fromto="0.7671 0.4373 0.9173 0.7671 0.4373 0.9093"/>
                    </body>
                  </body>
                </body>
              </body>
            </body>
            <body name="1_RightChest" pos="-0.0773 0.4159 0.9612" user="-0.1734 0.4484 0.9521">
              <joint name="1_RightChest_z" type="hinge" pos="-0.0773 0.4159 0.9612" axis="0.0000 0.0000 1.0000" range="-180.0000 180.0000"/>
              <joint name="1_RightChest_x" type="hinge" pos="-0.0773 0.4159 0.9612" axis="1.0000 0.0000 0.0000" range="-180.0000 180.0000"/>
              <joint name="1_RightChest_y" type="hinge" pos="-0.0773 0.4159 0.9612" axis="0.0000 1.0000 0.0000" range="-180.0000 180.0000"/>
              <geom size="0.0300" type="capsule" fromto="-0.0962 0.4223 0.9594 -0.1545 0.4421 0.9539"/>
              <body name="1_RightShoulder" pos="-0.1734 0.4484 0.9521" user="-0.4271 0.4351 0.9307">
                <joint name="1_RightShoulder_z" type="hinge" pos="-0.1734 0.4484 0.9521" axis="0.0000 0.0000 1.0000" range="-180.0000 180.0000"/>
                <joint name="1_RightShoulder_x" type="hinge" pos="-0.1734 0.4484 0.9521" axis="1.0000 0.0000 0.0000" range="-180.0000 180.0000"/>
                <joint name="1_RightShoulder_y" type="hinge" pos="-0.1734 0.4484 0.9521" axis="0.0000 1.0000 0.0000" range="-180.0000 180.0000"/>
                <geom size="0.0300" type="capsule" fromto="-0.1933 0.4474 0.9504 -0.4072 0.4362 0.9323"/>
                <body name="1_RightArm" pos="-0.4271 0.4351 0.9307" user="-0.6824 0.4429 0.9251">
                  <joint name="1_RightArm_z" type="hinge" pos="-0.4271 0.4351 0.9307" axis="0.0000 0.0000 1.0000" range="-180.0000 180.0000"/>
                  <joint name="1_RightArm_x" type="hinge" pos="-0.4271 0.4351 0.9307" axis="1.0000 0.0000 0.0000" range="-180.0000 180.0000"/>
                  <joint name="1_RightArm_y" type="hinge" pos="-0.4271 0.4351 0.9307" axis="0.0000 1.0000 0.0000" range="-180.0000 180.0000"/>
                  <geom size="0.0300" type="capsule" fromto="-0.4471 0.4357 0.9302 -0.6624 0.4423 0.9255"/>
                  <body name="1_RightWrist" pos="-0.6824 0.4429 0.9251" user="-0.7670 0.4368 0.9148">
                    <joint name="1_RightWrist_z" type="hinge" pos="-0.6824 0.4429 0.9251" axis="0.0000 0.0000 1.0000" range="-180.0000 180.0000"/>
                    <joint name="1_RightWrist_x" type="hinge" pos="-0.6824 0.4429 0.9251" axis="1.0000 0.0000 0.0000" range="-180.0000 180.0000"/>
                    <joint name="1_RightWrist_y" type="hinge" pos="-0.6824 0.4429 0.9251" axis="0.0000 1.0000 0.0000" range="-180.0000 180.0000"/>
                    <geom size="0.0300" type="capsule" fromto="-0.7022 0.4415 0.9227 -0.7472 0.4382 0.9172"/>
                    <body name="1_RightHand" pos="-0.7670 0.4368 0.9148" user="-0.7670 0.4368 0.9148">
                      <joint name="1_RightHand_z" type="hinge" pos="-0.7670 0.4368 0.9148" axis="0.0000 0.0000 1.0000" range="-180.0000 180.0000"/>
                      <joint name="1_RightHand_x" type="hinge" pos="-0.7670 0.4368 0.9148" axis="1.0000 0.0000 0.0000" range="-180.0000 180.0000"/>
                      <joint name="1_RightHand_y" type="hinge" pos="-0.7670 0.4368 0.9148" axis="0.0000 1.0000 0.0000" range="-180.0000 180.0000"/>
                      <geom size="0.0300" type="capsule" fromto="-0.7670 0.4368 0.9188 -0.7670 0.4368 0.9108"/>
                    </body>
                  </body>
                </body>
              </body>
            </body>
          </body>
        </body>
      </body>
    </body>

      <body childclass="smpl" name="Hips" user="0.0000 0.0146 0.0054" pos="0.0000 0.0146 0.0054">
      <geom fromto="-0.0750 0.0506 0.0054 0.0750 0.0506 0.0054" size="0.0820" type="capsule"/>
      <joint armature="0" damping="0" limited="false" name="Hips" pos="0.0000 0.0000 0.0000" stiffness="0" type="free"/>
      <body name="Spine" user="0.0000 0.0591 0.1523" pos="0.0000 0.0146 0.0054">
        <geom fromto="-0.0550 0.0369 0.1109 0.0550 0.0369 0.1109" size="0.0590" type="capsule"/>
        <joint axis="1.0000 0.0000 0.0000" name="Spine_x" pos="0.0000 0.0439 0.0658" range="-30.0000 45.0000" type="hinge"/>
        <joint axis="0.0000 1.0000 0.0000" name="Spine_y" pos="0.0000 0.0439 0.0658" range="-30.0000 30.0000" type="hinge"/>
        <joint axis="0.0000 0.0000 1.0000" name="Spine_z" pos="0.0000 0.0439 0.0658" range="-30.0000 30.0000" type="hinge"/>
        <body name="Spine1" user="0.0000 0.0668 0.2397" pos="0.0000 0.0591 0.1523">
          <geom fromto="-0.0600 0.0370 0.1960 0.0600 0.0370 0.1960" size="0.0540" type="capsule"/>
          <joint axis="1.0000 0.0000 0.0000" name="Spine1_x" pos="0.0000 0.0591 0.1523" range="-30.0000 45.0000" type="hinge"/>
          <joint axis="0.0000 1.0000 0.0000" name="Spine1_y" pos="0.0000 0.0591 0.1523" range="-30.0000 30.0000" type="hinge"/>
          <joint axis="0.0000 0.0000 1.0000" name="Spine1_z" pos="0.0000 0.0591 0.1523" range="-30.0000 30.0000" type="hinge"/>
          <body name="Spine2" user="0.0000 0.0668 0.3275" pos="0.0000 0.0668 0.2397">
            <geom fromto="-0.0575 0.0308 0.2896 0.0575 0.0308 0.2896" size="0.0570" type="capsule"/>
            <joint axis="1.0000 0.0000 0.0000" name="Spine2_x" pos="0.0000 0.0668 0.2397" range="-30.0000 45.0000" type="hinge"/>
            <joint axis="0.0000 1.0000 0.0000" name="Spine2_y" pos="0.0000 0.0668 0.2397" range="-30.0000 30.0000" type="hinge"/>
            <joint axis="0.0000 0.0000 1.0000" name="Spine2_z" pos="0.0000 0.0668 0.2397" range="-30.0000 30.0000" type="hinge"/>
            <body name="Spine3" user="0.0000 0.0240 0.5074" pos="0.0000 0.0668 0.3275">
              <geom fromto="-0.0550 0.0274 0.3914 0.0550 0.0274 0.3914" size="0.0620" type="capsule"/>
              <joint axis="1.0000 0.0000 0.0000" name="Spine3_x" pos="0.0000 0.0668 0.3275" range="-30.0000 45.0000" type="hinge"/>
              <joint axis="0.0000 1.0000 0.0000" name="Spine3_y" pos="0.0000 0.0668 0.3275" range="-30.0000 30.0000" type="hinge"/>
              <joint axis="0.0000 0.0000 1.0000" name="Spine3_z" pos="0.0000 0.0668 0.3275" range="-30.0000 30.0000" type="hinge"/>
              <body name="Neck" user="0.0000 0.0129 0.6768" pos="0.0000 0.0240 0.5074">
                <joint axis="1.0000 0.0000 0.0000" name="Neck_x" pos="0.0000 0.0339 0.5579" range="-30.0000 45.0000" type="hinge"/>
                <joint axis="0.0000 1.0000 0.0000" name="Neck_y" pos="0.0000 0.0339 0.5579" range="-30.0000 30.0000" type="hinge"/>
                <joint axis="0.0000 0.0000 1.0000" name="Neck_z" pos="0.0000 0.0339 0.5579" range="-30.0000 30.0000" type="hinge"/>
                <geom fromto="0.0000 0.0304 0.5336 0.0000 0.0164 0.6131" size="0.0370" type="capsule"/>
                <body name="Head" user="0.0000 0.0129 0.8188" pos="0.0000 0.0129 0.6768">
                  <geom pos="0.0200 -0.0471 0.6968" size="0.0150" type="sphere"/>
                  <geom pos="-0.0200 -0.0471 0.6968" size="0.0150" type="sphere"/>
                  <geom fromto="0.0000 0.0129 0.6543 0.0000 0.0129 0.7013" size="0.0680" type="capsule"/>
                  <joint axis="1.0000 0.0000 0.0000" name="Head_x" pos="0.0000 0.0129 0.6768" range="-30.0000 45.0000" type="hinge"/>
                  <joint axis="0.0000 1.0000 0.0000" name="Head_y" pos="0.0000 0.0129 0.6768" range="-30.0000 30.0000" type="hinge"/>
                  <joint axis="0.0000 0.0000 1.0000" name="Head_z" pos="0.0000 0.0129 0.6768" range="-30.0000 30.0000" type="hinge"/>
                </body>
              </body>
              <body name="RightShoulder" user="-0.1708 0.0191 0.4821" pos="0.0000 0.0240 0.5074">
                <joint axis="1.0000 0.0000 0.0000" name="RightShoulder_x" pos="-0.0286 0.0191 0.4821" range="-20.0000 20.0000" type="hinge"/>
                <joint axis="0.0000 1.0000 0.0000" name="RightShoulder_y" pos="-0.0286 0.0191 0.4821" range="-20.0000 20.0000" type="hinge"/>
                <joint axis="0.0000 0.0000 1.0000" name="RightShoulder_z" pos="-0.0286 0.0191 0.4821" range="-20.0000 20.0000" type="hinge"/>
                <geom fromto="-0.0406 0.0191 0.4821 -0.1228 0.0191 0.4821" size="0.0590" type="capsule"/>
                <body name="RightArm" user="-0.4103 0.0191 0.4821" pos="-0.1708 0.0191 0.4821">
                  <joint axis="1.0000 0.0000 0.0000" name="RightArm_x" pos="-0.1708 0.0191 0.4821" range="-90.0000 90.0000" type="hinge"/>
                  <joint axis="0.0000 1.0000 0.0000" name="RightArm_y" pos="-0.1708 0.0191 0.4821" range="-90.0000 90.0000" type="hinge"/>
                  <joint axis="0.0000 0.0000 1.0000" name="RightArm_z" pos="-0.1708 0.0191 0.4821" range="-60.0000 90.0000" type="hinge"/>
                  <geom fromto="-0.1558 0.0191 0.4821 -0.4253 0.0191 0.4821" size="0.0340" type="capsule"/>
                  <body name="RightForeArm" user="-0.6643 0.0191 0.4821" pos="-0.4103 0.0191 0.4821">
                    <joint axis="0.0000 0.0000 1.0000" name="RightForeArm_z" pos="-0.4103 0.0191 0.4821" range="-10.0000 170.0000" type="hinge"/>
                    <geom fromto="-0.4303 0.0191 0.4821 -0.6443 0.0191 0.4821" size="0.0300" type="capsule"/>
                    <body name="RightHand" user="-0.7282 0.0191 0.4821" pos="-0.6643 0.0191 0.4821">
                      <geom pos="-0.6683 0.0191 0.4821" size="0.0400" type="sphere"/>
                      <joint axis="1.0000 0.0000 0.0000" name="RightHand_x" pos="-0.6643 0.0191 0.4821" range="-90.0000 90.0000" type="hinge"/>
                      <joint axis="0.0000 1.0000 0.0000" name="RightHand_y" pos="-0.6643 0.0191 0.4821" range="-90.0000 90.0000" type="hinge"/>
                      <joint axis="0.0000 0.0000 1.0000" name="RightHand_z" pos="-0.6643 0.0191 0.4821" range="-90.0000 90.0000" type="hinge"/>
                    </body>
                  </body>
                </body>
              </body>
              <body name="LeftShoulder" user="0.1708 0.0191 0.4821" pos="-0.0000 0.0240 0.5074">
                <joint axis="1.0000 0.0000 0.0000" name="LeftShoulder_x" pos="0.0286 0.0191 0.4821" range="-20.0000 20.0000" type="hinge"/>
                <joint axis="0.0000 1.0000 0.0000" name="LeftShoulder_y" pos="0.0286 0.0191 0.4821" range="-20.0000 20.0000" type="hinge"/>
                <joint axis="0.0000 0.0000 1.0000" name="LeftShoulder_z" pos="0.0286 0.0191 0.4821" range="-20.0000 20.0000" type="hinge"/>
                <geom fromto="0.0406 0.0191 0.4821 0.1228 0.0191 0.4821" size="0.0590" type="capsule"/>
                <body name="LeftArm" user="0.4103 0.0191 0.4821" pos="0.1708 0.0191 0.4821">
                  <joint axis="1.0000 0.0000 0.0000" name="LeftArm_x" pos="0.1708 0.0191 0.4821" range="-90.0000 90.0000" type="hinge"/>
                  <joint axis="0.0000 1.0000 0.0000" name="LeftArm_y" pos="0.1708 0.0191 0.4821" range="-90.0000 90.0000" type="hinge"/>
                  <joint axis="0.0000 0.0000 1.0000" name="LeftArm_z" pos="0.1708 0.0191 0.4821" range="-90.0000 60.0000" type="hinge"/>
                  <geom fromto="0.1558 0.0191 0.4821 0.4253 0.0191 0.4821" size="0.0340" type="capsule"/>
                  <body name="LeftForeArm" user="0.6643 0.0191 0.4821" pos="0.4103 0.0191 0.4821">
                    <joint axis="0.0000 0.0000 1.0000" name="LeftForeArm_z" pos="0.4103 0.0191 0.4821" range="-170.0000 10.0000" type="hinge"/>
                    <geom fromto="0.4303 0.0191 0.4821 0.6443 0.0191 0.4821" size="0.0300" type="capsule"/>
                    <body name="LeftHand" user="0.7282 0.0191 0.4821" pos="0.6643 0.0191 0.4821">
                      <geom pos="0.6683 0.0191 0.4821" size="0.0400" type="sphere"/>
                      <joint axis="1.0000 0.0000 0.0000" name="LeftHand_x" pos="0.6643 0.0191 0.4821" range="-90.0000 90.0000" type="hinge"/>
                      <joint axis="0.0000 1.0000 0.0000" name="LeftHand_y" pos="0.6643 0.0191 0.4821" range="-90.0000 90.0000" type="hinge"/>
                      <joint axis="0.0000 0.0000 1.0000" name="LeftHand_z" pos="0.6643 0.0191 0.4821" range="-90.0000 90.0000" type="hinge"/>
                    </body>
                  </body>
                </body>
              </body>
            </body>
          </body>
        </body>
      </body>
      <body name="RightUpLeg" user="-0.0849 0.0000 -0.4027" pos="0.0000 0.0146 0.0054">
        <joint axis="1.0000 0.0000 0.0000" name="RightUpLeg_x" pos="-0.0849 0.0000 -0.0248" range="-170.0000 20.0000" type="hinge"/>
        <joint axis="0.0000 1.0000 0.0000" name="RightUpLeg_y" pos="-0.0849 0.0000 -0.0248" range="-40.0000 90.0000" type="hinge"/>
        <joint axis="0.0000 0.0000 1.0000" name="RightUpLeg_z" pos="-0.0849 0.0000 -0.0248" range="-70.0000 70.0000" type="hinge"/>
        <geom fromto="-0.0849 0.0000 -0.0448 -0.0849 0.0000 -0.3827" size="0.0490" type="capsule"/>
        <body name="RightLeg" user="-0.0849 0.0000 -0.7988" pos="-0.0849 0.0000 -0.4027">
          <joint axis="1.0000 0.0000 0.0000" name="RightLeg_x" pos="-0.0849 0.0000 -0.4027" range="0.0000 170.0000" type="hinge"/>
          <geom contype="1" conaffinity="1" fromto="-0.0849 0.0000 -0.4227 -0.0849 0.0000 -0.7788" size="0.0400" type="capsule"/>
          <body name="RightFoot" user="-0.0849 -0.1308 -0.8464" pos="-0.0849 0.0000 -0.7988">
            <geom contype="1" conaffinity="1" pos="-0.0849 -0.0514 -0.8306" size="0.0620 0.1000 0.0300" quat="1.0000 -0.0000 -0.0000 -0.0000" type="box"/>
            <joint axis="1.0000 0.0000 0.0000" name="RightFoot_x" pos="-0.0849 0.0000 -0.7988" range="-90.0000 90.0000" type="hinge"/>
            <joint axis="0.0000 1.0000 0.0000" name="RightFoot_y" pos="-0.0849 0.0000 -0.7988" range="-60.0000 60.0000" type="hinge"/>
            <joint axis="0.0000 0.0000 1.0000" name="RightFoot_z" pos="-0.0849 0.0000 -0.7988" range="-90.0000 90.0000" type="hinge"/>
          </body>
        </body>
      </body>
      <body name="LeftUpLeg" user="0.0849 0.0000 -0.4027" pos="-0.0000 0.0146 0.0054">
        <joint axis="1.0000 0.0000 0.0000" name="LeftUpLeg_x" pos="0.0849 0.0000 -0.0248" range="-170.0000 20.0000" type="hinge"/>
        <joint axis="0.0000 1.0000 0.0000" name="LeftUpLeg_y" pos="0.0849 0.0000 -0.0248" range="-90.0000 40.0000" type="hinge"/>
        <joint axis="0.0000 0.0000 1.0000" name="LeftUpLeg_z" pos="0.0849 0.0000 -0.0248" range="-70.0000 70.0000" type="hinge"/>
        <geom fromto="0.0849 0.0000 -0.0448 0.0849 0.0000 -0.3827" size="0.0490" type="capsule"/>
        <body name="LeftLeg" user="0.0849 0.0000 -0.7988" pos="0.0849 0.0000 -0.4027">
          <joint axis="1.0000 0.0000 0.0000" name="LeftLeg_x" pos="0.0849 0.0000 -0.4027" range="0.0000 170.0000" type="hinge"/>
          <geom contype="2" conaffinity="2" fromto="0.0849 0.0000 -0.4227 0.0849 0.0000 -0.7788" size="0.0400" type="capsule"/>
          <body name="LeftFoot" user="0.0849 -0.1308 -0.8464" pos="0.0849 0.0000 -0.7988">
            <geom contype="2" conaffinity="2" pos="0.0849 -0.0514 -0.8306" size="0.0620 0.1000 0.0300" quat="1.0000 -0.0000 -0.0000 0.0000" type="box"/>
            <joint axis="1.0000 0.0000 0.0000" name="LeftFoot_x" pos="0.0849 0.0000 -0.7988" range="-90.0000 90.0000" type="hinge"/>
            <joint axis="0.0000 1.0000 0.0000" name="LeftFoot_y" pos="0.0849 0.0000 -0.7988" range="-60.0000 60.0000" type="hinge"/>
            <joint axis="0.0000 0.0000 1.0000" name="LeftFoot_z" pos="0.0849 0.0000 -0.7988" range="-90.0000 90.0000" type="hinge"/>
          </body>
        </body>
      </body>
    </body>

  </worldbody>
  <actuator>
    <motor name="1_LeftUpLeg_z" joint="1_LeftUpLeg_z" gear="1"/>
    <motor name="1_LeftUpLeg_x" joint="1_LeftUpLeg_x" gear="1"/>
    <motor name="1_LeftUpLeg_y" joint="1_LeftUpLeg_y" gear="1"/>
    <motor name="1_LeftLeg_z" joint="1_LeftLeg_z" gear="1"/>
    <motor name="1_LeftLeg_x" joint="1_LeftLeg_x" gear="1"/>
    <motor name="1_LeftLeg_y" joint="1_LeftLeg_y" gear="1"/>
    <motor name="1_LeftFoot_z" joint="1_LeftFoot_z" gear="1"/>
    <motor name="1_LeftFoot_x" joint="1_LeftFoot_x" gear="1"/>
    <motor name="1_LeftFoot_y" joint="1_LeftFoot_y" gear="1"/>
    <motor name="1_LeftToe_z" joint="1_LeftToe_z" gear="1"/>
    <motor name="1_LeftToe_x" joint="1_LeftToe_x" gear="1"/>
    <motor name="1_LeftToe_y" joint="1_LeftToe_y" gear="1"/>
    <motor name="1_RightUpLeg_z" joint="1_RightUpLeg_z" gear="1"/>
    <motor name="1_RightUpLeg_x" joint="1_RightUpLeg_x" gear="1"/>
    <motor name="1_RightUpLeg_y" joint="1_RightUpLeg_y" gear="1"/>
    <motor name="1_RightLeg_z" joint="1_RightLeg_z" gear="1"/>
    <motor name="1_RightLeg_x" joint="1_RightLeg_x" gear="1"/>
    <motor name="1_RightLeg_y" joint="1_RightLeg_y" gear="1"/>
    <motor name="1_RightFoot_z" joint="1_RightFoot_z" gear="1"/>
    <motor name="1_RightFoot_x" joint="1_RightFoot_x" gear="1"/>
    <motor name="1_RightFoot_y" joint="1_RightFoot_y" gear="1"/>
    <motor name="1_RightToe_z" joint="1_RightToe_z" gear="1"/>
    <motor name="1_RightToe_x" joint="1_RightToe_x" gear="1"/>
    <motor name="1_RightToe_y" joint="1_RightToe_y" gear="1"/>
    <motor name="1_Spine_z" joint="1_Spine_z" gear="1"/>
    <motor name="1_Spine_x" joint="1_Spine_x" gear="1"/>
    <motor name="1_Spine_y" joint="1_Spine_y" gear="1"/>
    <motor name="1_Spine1_z" joint="1_Spine1_z" gear="1"/>
    <motor name="1_Spine1_x" joint="1_Spine1_x" gear="1"/>
    <motor name="1_Spine1_y" joint="1_Spine1_y" gear="1"/>
    <motor name="1_Spine2_z" joint="1_Spine2_z" gear="1"/>
    <motor name="1_Spine2_x" joint="1_Spine2_x" gear="1"/>
    <motor name="1_Spine2_y" joint="1_Spine2_y" gear="1"/>
    <motor name="1_Neck_z" joint="1_Neck_z" gear="1"/>
    <motor name="1_Neck_x" joint="1_Neck_x" gear="1"/>
    <motor name="1_Neck_y" joint="1_Neck_y" gear="1"/>
    <motor name="1_Mouth_z" joint="1_Mouth_z" gear="1"/>
    <motor name="1_Mouth_x" joint="1_Mouth_x" gear="1"/>
    <motor name="1_Mouth_y" joint="1_Mouth_y" gear="1"/>
    <motor name="1_LeftChest_z" joint="1_LeftChest_z" gear="1"/>
    <motor name="1_LeftChest_x" joint="1_LeftChest_x" gear="1"/>
    <motor name="1_LeftChest_y" joint="1_LeftChest_y" gear="1"/>
    <motor name="1_LeftShoulder_z" joint="1_LeftShoulder_z" gear="1"/>
    <motor name="1_LeftShoulder_x" joint="1_LeftShoulder_x" gear="1"/>
    <motor name="1_LeftShoulder_y" joint="1_LeftShoulder_y" gear="1"/>
    <motor name="1_LeftArm_z" joint="1_LeftArm_z" gear="1"/>
    <motor name="1_LeftArm_x" joint="1_LeftArm_x" gear="1"/>
    <motor name="1_LeftArm_y" joint="1_LeftArm_y" gear="1"/>
    <motor name="1_LeftWrist_z" joint="1_LeftWrist_z" gear="1"/>
    <motor name="1_LeftWrist_x" joint="1_LeftWrist_x" gear="1"/>
    <motor name="1_LeftWrist_y" joint="1_LeftWrist_y" gear="1"/>
    <motor name="1_LeftHand_z" joint="1_LeftHand_z" gear="1"/>
    <motor name="1_LeftHand_x" joint="1_LeftHand_x" gear="1"/>
    <motor name="1_LeftHand_y" joint="1_LeftHand_y" gear="1"/>
    <motor name="1_RightChest_z" joint="1_RightChest_z" gear="1"/>
    <motor name="1_RightChest_x" joint="1_RightChest_x" gear="1"/>
    <motor name="1_RightChest_y" joint="1_RightChest_y" gear="1"/>
    <motor name="1_RightShoulder_z" joint="1_RightShoulder_z" gear="1"/>
    <motor name="1_RightShoulder_x" joint="1_RightShoulder_x" gear="1"/>
    <motor name="1_RightShoulder_y" joint="1_RightShoulder_y" gear="1"/>
    <motor name="1_RightArm_z" joint="1_RightArm_z" gear="1"/>
    <motor name="1_RightArm_x" joint="1_RightArm_x" gear="1"/>
    <motor name="1_RightArm_y" joint="1_RightArm_y" gear="1"/>
    <motor name="1_RightWrist_z" joint="1_RightWrist_z" gear="1"/>
    <motor name="1_RightWrist_x" joint="1_RightWrist_x" gear="1"/>
    <motor name="1_RightWrist_y" joint="1_RightWrist_y" gear="1"/>
    <motor name="1_RightHand_z" joint="1_RightHand_z" gear="1"/>
    <motor name="1_RightHand_x" joint="1_RightHand_x" gear="1"/>
    <motor name="1_RightHand_y" joint="1_RightHand_y" gear="1"/>
  </actuator>
</mujoco>
