<mujoco model="humanoid">
  <compiler angle="degree" inertiafromgeom="true" coordinate="global"/>
  <include file="./common/materials.xml"/>
    <size njmax="8000" nconmax="4000"/>
  <visual>
    <headlight ambient=".4 .4 .4" diffuse=".8 .8 .8" specular="0.1 0.1 0.1"/>
    <map znear=".01"/>
    <quality shadowsize="2048"/>
  </visual>
  <default>
    <joint damping="0.0" armature="0.01" stiffness="0.0" limited="true"/>
    <geom conaffinity="7" condim="1" contype="7" margin="0.001" material="self" rgba="0.8 0.6 .4 1"/>
  </default>
  <statistic extent="3" center="0 0 1"/>
  <option timestep="0.00222222222"/>
  <asset>
    <texture type="skybox" file="./common/sky1.png" gridsize="3 4" gridlayout=".U..LFRB.D.." width="8192" height="8192"/>
    <texture builtin="flat" height="1278" mark="cross" markrgb="1 1 1" name="texgeom" random="0.01" rgb1=".8 .6 .4" rgb2=".8 .6 .4" type="cube" width="127"/>
  </asset>
  <worldbody>
    <light cutoff="100" diffuse="1 1 1" dir="-0 0 -1.3" directional="true" exponent="1" pos="0 0 1.3" specular=".1 .1 .1"/>
    <geom condim="3" friction="1. .1 .1" material="grid" name="floor" pos="0 0 0" rgba=".8 .9 .8 1" size="100 100 .2" type="plane"/>
    <body name="Hips" pos="0.0000 0.0000 1.0000" user="0.0009 -0.0161 0.9768">
      <joint name="Hips" pos="0.0000 0.0000 1.0000" limited="false" type="free" armature="0" damping="0" stiffness="0"/>
      <geom size="0.0300" type="sphere" pos="0.0000 0.0000 1.0000"/>
      <body name="LeftUpLeg" pos="0.0586 -0.0823 0.9823" user="0.1020 -0.4687 0.9904">
        <joint name="LeftUpLeg_z" type="hinge" pos="0.0586 -0.0823 0.9823" axis="0.0000 0.0000 1.0000" range="-180.0000 180.0000"/>
        <joint name="LeftUpLeg_x" type="hinge" pos="0.0586 -0.0823 0.9823" axis="1.0000 0.0000 0.0000" range="-180.0000 180.0000"/>
        <joint name="LeftUpLeg_y" type="hinge" pos="0.0586 -0.0823 0.9823" axis="0.0000 1.0000 0.0000" range="-180.0000 180.0000"/>
        <geom size="0.0300" type="capsule" fromto="0.0608 -0.1022 0.9827 0.0998 -0.4489 0.9900"/>
        <body name="LeftLeg" pos="0.1020 -0.4687 0.9904" user="0.0872 -0.8956 0.9529">
          <joint name="LeftLeg_z" type="hinge" pos="0.1020 -0.4687 0.9904" axis="0.0000 0.0000 1.0000" range="-180.0000 180.0000"/>
          <joint name="LeftLeg_x" type="hinge" pos="0.1020 -0.4687 0.9904" axis="1.0000 0.0000 0.0000" range="-180.0000 180.0000"/>
          <joint name="LeftLeg_y" type="hinge" pos="0.1020 -0.4687 0.9904" axis="0.0000 1.0000 0.0000" range="-180.0000 180.0000"/>
          <geom size="0.0300" type="capsule" fromto="0.1013 -0.4887 0.9886 0.0879 -0.8757 0.9547"/>
          <body name="LeftFoot" pos="0.0872 -0.8956 0.9529" user="0.1283 -0.9559 1.0750">
            <joint name="LeftFoot_z" type="hinge" pos="0.0872 -0.8956 0.9529" axis="0.0000 0.0000 1.0000" range="-180.0000 180.0000"/>
            <joint name="LeftFoot_x" type="hinge" pos="0.0872 -0.8956 0.9529" axis="1.0000 0.0000 0.0000" range="-180.0000 180.0000"/>
            <joint name="LeftFoot_y" type="hinge" pos="0.0872 -0.8956 0.9529" axis="0.0000 1.0000 0.0000" range="-180.0000 180.0000"/>
            <geom size="0.0300" type="capsule" fromto="0.0930 -0.9041 0.9701 0.1225 -0.9474 1.0578"/>
            <body name="LeftToe" pos="0.1283 -0.9559 1.0750" user="0.1283 -0.9559 1.0750">
              <joint name="LeftToe_z" type="hinge" pos="0.1283 -0.9559 1.0750" axis="0.0000 0.0000 1.0000" range="-180.0000 180.0000"/>
              <joint name="LeftToe_x" type="hinge" pos="0.1283 -0.9559 1.0750" axis="1.0000 0.0000 0.0000" range="-180.0000 180.0000"/>
              <joint name="LeftToe_y" type="hinge" pos="0.1283 -0.9559 1.0750" axis="0.0000 1.0000 0.0000" range="-180.0000 180.0000"/>
              <geom size="0.0300" type="capsule" fromto="0.1283 -0.9559 1.0790 0.1283 -0.9559 1.0710"/>
            </body>
          </body>
        </body>
      </body>
      <body name="RightUpLeg" pos="-0.0603 -0.0905 0.9865" user="-0.1036 -0.4742 0.9816">
        <joint name="RightUpLeg_z" type="hinge" pos="-0.0603 -0.0905 0.9865" axis="0.0000 0.0000 1.0000" range="-180.0000 180.0000"/>
        <joint name="RightUpLeg_x" type="hinge" pos="-0.0603 -0.0905 0.9865" axis="1.0000 0.0000 0.0000" range="-180.0000 180.0000"/>
        <joint name="RightUpLeg_y" type="hinge" pos="-0.0603 -0.0905 0.9865" axis="0.0000 1.0000 0.0000" range="-180.0000 180.0000"/>
        <geom size="0.0300" type="capsule" fromto="-0.0626 -0.1104 0.9862 -0.1013 -0.4543 0.9819"/>
        <body name="RightLeg" pos="-0.1036 -0.4742 0.9816" user="-0.0845 -0.8942 0.9471">
          <joint name="RightLeg_z" type="hinge" pos="-0.1036 -0.4742 0.9816" axis="0.0000 0.0000 1.0000" range="-180.0000 180.0000"/>
          <joint name="RightLeg_x" type="hinge" pos="-0.1036 -0.4742 0.9816" axis="1.0000 0.0000 0.0000" range="-180.0000 180.0000"/>
          <joint name="RightLeg_y" type="hinge" pos="-0.1036 -0.4742 0.9816" axis="0.0000 1.0000 0.0000" range="-180.0000 180.0000"/>
          <geom size="0.0300" type="capsule" fromto="-0.1027 -0.4941 0.9800 -0.0854 -0.8743 0.9487"/>
          <body name="RightFoot" pos="-0.0845 -0.8942 0.9471" user="-0.1194 -0.9564 1.0774">
            <joint name="RightFoot_z" type="hinge" pos="-0.0845 -0.8942 0.9471" axis="0.0000 0.0000 1.0000" range="-180.0000 180.0000"/>
            <joint name="RightFoot_x" type="hinge" pos="-0.0845 -0.8942 0.9471" axis="1.0000 0.0000 0.0000" range="-180.0000 180.0000"/>
            <joint name="RightFoot_y" type="hinge" pos="-0.0845 -0.8942 0.9471" axis="0.0000 1.0000 0.0000" range="-180.0000 180.0000"/>
            <geom size="0.0300" type="capsule" fromto="-0.0892 -0.9026 0.9646 -0.1147 -0.9480 1.0598"/>
            <body name="RightToe" pos="-0.1194 -0.9564 1.0774" user="-0.1194 -0.9564 1.0774">
              <joint name="RightToe_z" type="hinge" pos="-0.1194 -0.9564 1.0774" axis="0.0000 0.0000 1.0000" range="-180.0000 180.0000"/>
              <joint name="RightToe_x" type="hinge" pos="-0.1194 -0.9564 1.0774" axis="1.0000 0.0000 0.0000" range="-180.0000 180.0000"/>
              <joint name="RightToe_y" type="hinge" pos="-0.1194 -0.9564 1.0774" axis="0.0000 1.0000 0.0000" range="-180.0000 180.0000"/>
              <geom size="0.0300" type="capsule" fromto="-0.1194 -0.9564 1.0814 -0.1194 -0.9564 1.0734"/>
            </body>
          </body>
        </body>
      </body>
      <body name="Spine" pos="0.0044 0.1244 0.9616" user="0.0089 0.2624 0.9884">
        <joint name="Spine_z" type="hinge" pos="0.0044 0.1244 0.9616" axis="0.0000 0.0000 1.0000" range="-180.0000 180.0000"/>
        <joint name="Spine_x" type="hinge" pos="0.0044 0.1244 0.9616" axis="1.0000 0.0000 0.0000" range="-180.0000 180.0000"/>
        <joint name="Spine_y" type="hinge" pos="0.0044 0.1244 0.9616" axis="0.0000 1.0000 0.0000" range="-180.0000 180.0000"/>
        <geom size="0.0300" type="capsule" fromto="0.0051 0.1440 0.9654 0.0083 0.2427 0.9846"/>
        <body name="Spine1" pos="0.0089 0.2624 0.9884" user="0.0067 0.3184 0.9913">
          <joint name="Spine1_z" type="hinge" pos="0.0089 0.2624 0.9884" axis="0.0000 0.0000 1.0000" range="-180.0000 180.0000"/>
          <joint name="Spine1_x" type="hinge" pos="0.0089 0.2624 0.9884" axis="1.0000 0.0000 0.0000" range="-180.0000 180.0000"/>
          <joint name="Spine1_y" type="hinge" pos="0.0089 0.2624 0.9884" axis="0.0000 1.0000 0.0000" range="-180.0000 180.0000"/>
          <geom size="0.0300" type="capsule" fromto="0.0081 0.2823 0.9895 0.0075 0.2984 0.9903"/>
          <body name="Spine2" pos="0.0067 0.3184 0.9913" user="-0.0016 0.4644 0.9659">
            <joint name="Spine2_z" type="hinge" pos="0.0067 0.3184 0.9913" axis="0.0000 0.0000 1.0000" range="-180.0000 180.0000"/>
            <joint name="Spine2_x" type="hinge" pos="0.0067 0.3184 0.9913" axis="1.0000 0.0000 0.0000" range="-180.0000 180.0000"/>
            <joint name="Spine2_y" type="hinge" pos="0.0067 0.3184 0.9913" axis="0.0000 1.0000 0.0000" range="-180.0000 180.0000"/>
            <geom size="0.0300" type="capsule" fromto="0.0056 0.3381 0.9879 -0.0004 0.4448 0.9693"/>
            <body name="Neck" pos="-0.0067 0.5300 0.9578" user="0.0034 0.6190 1.0082">
              <joint name="Neck_z" type="hinge" pos="-0.0067 0.5300 0.9578" axis="0.0000 0.0000 1.0000" range="-180.0000 180.0000"/>
              <joint name="Neck_x" type="hinge" pos="-0.0067 0.5300 0.9578" axis="1.0000 0.0000 0.0000" range="-180.0000 180.0000"/>
              <joint name="Neck_y" type="hinge" pos="-0.0067 0.5300 0.9578" axis="0.0000 1.0000 0.0000" range="-180.0000 180.0000"/>
              <geom size="0.0300" type="capsule" fromto="-0.0048 0.5473 0.9676 0.0014 0.6017 0.9984"/>
              <body name="Mouth" pos="0.0034 0.6190 1.0082" user="0.0034 0.6190 1.0082">
                <joint name="Mouth_z" type="hinge" pos="0.0034 0.6190 1.0082" axis="0.0000 0.0000 1.0000" range="-180.0000 180.0000"/>
                <joint name="Mouth_x" type="hinge" pos="0.0034 0.6190 1.0082" axis="1.0000 0.0000 0.0000" range="-180.0000 180.0000"/>
                <joint name="Mouth_y" type="hinge" pos="0.0034 0.6190 1.0082" axis="0.0000 1.0000 0.0000" range="-180.0000 180.0000"/>
                <geom size="0.0300" type="capsule" fromto="0.0034 0.6190 1.0122 0.0034 0.6190 1.0042"/>
              </body>
            </body>
            <body name="LeftChest" pos="0.0784 0.4324 0.9724" user="0.2013 0.4776 0.9533">
              <joint name="LeftChest_z" type="hinge" pos="0.0784 0.4324 0.9724" axis="0.0000 0.0000 1.0000" range="-180.0000 180.0000"/>
              <joint name="LeftChest_x" type="hinge" pos="0.0784 0.4324 0.9724" axis="1.0000 0.0000 0.0000" range="-180.0000 180.0000"/>
              <joint name="LeftChest_y" type="hinge" pos="0.0784 0.4324 0.9724" axis="0.0000 1.0000 0.0000" range="-180.0000 180.0000"/>
              <geom size="0.0300" type="capsule" fromto="0.0969 0.4392 0.9695 0.1827 0.4708 0.9562"/>
              <body name="LeftShoulder" pos="0.2013 0.4776 0.9533" user="0.4566 0.4619 0.9304">
                <joint name="LeftShoulder_z" type="hinge" pos="0.2013 0.4776 0.9533" axis="0.0000 0.0000 1.0000" range="-180.0000 180.0000"/>
                <joint name="LeftShoulder_x" type="hinge" pos="0.2013 0.4776 0.9533" axis="1.0000 0.0000 0.0000" range="-180.0000 180.0000"/>
                <joint name="LeftShoulder_y" type="hinge" pos="0.2013 0.4776 0.9533" axis="0.0000 1.0000 0.0000" range="-180.0000 180.0000"/>
                <geom size="0.0300" type="capsule" fromto="0.2212 0.4764 0.9516 0.4367 0.4632 0.9322"/>
                <body name="LeftArm" pos="0.4566 0.4619 0.9304" user="0.7223 0.4746 0.9230">
                  <joint name="LeftArm_z" type="hinge" pos="0.4566 0.4619 0.9304" axis="0.0000 0.0000 1.0000" range="-180.0000 180.0000"/>
                  <joint name="LeftArm_x" type="hinge" pos="0.4566 0.4619 0.9304" axis="1.0000 0.0000 0.0000" range="-180.0000 180.0000"/>
                  <joint name="LeftArm_y" type="hinge" pos="0.4566 0.4619 0.9304" axis="0.0000 1.0000 0.0000" range="-180.0000 180.0000"/>
                  <geom size="0.0300" type="capsule" fromto="0.4766 0.4629 0.9298 0.7024 0.4737 0.9236"/>
                  <body name="LeftWrist" pos="0.7223 0.4746 0.9230" user="0.8090 0.4640 0.9074">
                    <joint name="LeftWrist_z" type="hinge" pos="0.7223 0.4746 0.9230" axis="0.0000 0.0000 1.0000" range="-180.0000 180.0000"/>
                    <joint name="LeftWrist_x" type="hinge" pos="0.7223 0.4746 0.9230" axis="1.0000 0.0000 0.0000" range="-180.0000 180.0000"/>
                    <joint name="LeftWrist_y" type="hinge" pos="0.7223 0.4746 0.9230" axis="0.0000 1.0000 0.0000" range="-180.0000 180.0000"/>
                    <geom size="0.0300" type="capsule" fromto="0.7419 0.4722 0.9195 0.7895 0.4664 0.9109"/>
                    <body name="LeftHand" pos="0.8090 0.4640 0.9074" user="0.8090 0.4640 0.9074">
                      <joint name="LeftHand_z" type="hinge" pos="0.8090 0.4640 0.9074" axis="0.0000 0.0000 1.0000" range="-180.0000 180.0000"/>
                      <joint name="LeftHand_x" type="hinge" pos="0.8090 0.4640 0.9074" axis="1.0000 0.0000 0.0000" range="-180.0000 180.0000"/>
                      <joint name="LeftHand_y" type="hinge" pos="0.8090 0.4640 0.9074" axis="0.0000 1.0000 0.0000" range="-180.0000 180.0000"/>
                      <geom size="0.0300" type="capsule" fromto="0.8090 0.4640 0.9114 0.8090 0.4640 0.9034"/>
                    </body>
                  </body>
                </body>
              </body>
            </body>
            <body name="RightChest" pos="-0.0763 0.4309 0.9676" user="-0.1895 0.4777 0.9591">
              <joint name="RightChest_z" type="hinge" pos="-0.0763 0.4309 0.9676" axis="0.0000 0.0000 1.0000" range="-180.0000 180.0000"/>
              <joint name="RightChest_x" type="hinge" pos="-0.0763 0.4309 0.9676" axis="1.0000 0.0000 0.0000" range="-180.0000 180.0000"/>
              <joint name="RightChest_y" type="hinge" pos="-0.0763 0.4309 0.9676" axis="0.0000 1.0000 0.0000" range="-180.0000 180.0000"/>
              <geom size="0.0300" type="capsule" fromto="-0.0947 0.4385 0.9662 -0.1711 0.4701 0.9605"/>
              <body name="RightShoulder" pos="-0.1895 0.4777 0.9591" user="-0.4496 0.4633 0.9278">
                <joint name="RightShoulder_z" type="hinge" pos="-0.1895 0.4777 0.9591" axis="0.0000 0.0000 1.0000" range="-180.0000 180.0000"/>
                <joint name="RightShoulder_x" type="hinge" pos="-0.1895 0.4777 0.9591" axis="1.0000 0.0000 0.0000" range="-180.0000 180.0000"/>
                <joint name="RightShoulder_y" type="hinge" pos="-0.1895 0.4777 0.9591" axis="0.0000 1.0000 0.0000" range="-180.0000 180.0000"/>
                <geom size="0.0300" type="capsule" fromto="-0.2093 0.4766 0.9567 -0.4298 0.4644 0.9302"/>
                <body name="RightArm" pos="-0.4496 0.4633 0.9278" user="-0.7188 0.4701 0.9218">
                  <joint name="RightArm_z" type="hinge" pos="-0.4496 0.4633 0.9278" axis="0.0000 0.0000 1.0000" range="-180.0000 180.0000"/>
                  <joint name="RightArm_x" type="hinge" pos="-0.4496 0.4633 0.9278" axis="1.0000 0.0000 0.0000" range="-180.0000 180.0000"/>
                  <joint name="RightArm_y" type="hinge" pos="-0.4496 0.4633 0.9278" axis="0.0000 1.0000 0.0000" range="-180.0000 180.0000"/>
                  <geom size="0.0300" type="capsule" fromto="-0.4696 0.4639 0.9274 -0.6988 0.4696 0.9223"/>
                  <body name="RightWrist" pos="-0.7188 0.4701 0.9218" user="-0.8075 0.4615 0.9117">
                    <joint name="RightWrist_z" type="hinge" pos="-0.7188 0.4701 0.9218" axis="0.0000 0.0000 1.0000" range="-180.0000 180.0000"/>
                    <joint name="RightWrist_x" type="hinge" pos="-0.7188 0.4701 0.9218" axis="1.0000 0.0000 0.0000" range="-180.0000 180.0000"/>
                    <joint name="RightWrist_y" type="hinge" pos="-0.7188 0.4701 0.9218" axis="0.0000 1.0000 0.0000" range="-180.0000 180.0000"/>
                    <geom size="0.0300" type="capsule" fromto="-0.7385 0.4682 0.9196 -0.7877 0.4634 0.9140"/>
                    <body name="RightHand" pos="-0.8075 0.4615 0.9117" user="-0.8075 0.4615 0.9117">
                      <joint name="RightHand_z" type="hinge" pos="-0.8075 0.4615 0.9117" axis="0.0000 0.0000 1.0000" range="-180.0000 180.0000"/>
                      <joint name="RightHand_x" type="hinge" pos="-0.8075 0.4615 0.9117" axis="1.0000 0.0000 0.0000" range="-180.0000 180.0000"/>
                      <joint name="RightHand_y" type="hinge" pos="-0.8075 0.4615 0.9117" axis="0.0000 1.0000 0.0000" range="-180.0000 180.0000"/>
                      <geom size="0.0300" type="capsule" fromto="-0.8075 0.4615 0.9157 -0.8075 0.4615 0.9077"/>
                    </body>
                  </body>
                </body>
              </body>
            </body>
          </body>
        </body>
      </body>
    </body>
  </worldbody>
  <actuator>
    <motor name="LeftUpLeg_z" joint="LeftUpLeg_z" gear="1"/>
    <motor name="LeftUpLeg_x" joint="LeftUpLeg_x" gear="1"/>
    <motor name="LeftUpLeg_y" joint="LeftUpLeg_y" gear="1"/>
    <motor name="LeftLeg_z" joint="LeftLeg_z" gear="1"/>
    <motor name="LeftLeg_x" joint="LeftLeg_x" gear="1"/>
    <motor name="LeftLeg_y" joint="LeftLeg_y" gear="1"/>
    <motor name="LeftFoot_z" joint="LeftFoot_z" gear="1"/>
    <motor name="LeftFoot_x" joint="LeftFoot_x" gear="1"/>
    <motor name="LeftFoot_y" joint="LeftFoot_y" gear="1"/>
    <motor name="LeftToe_z" joint="LeftToe_z" gear="1"/>
    <motor name="LeftToe_x" joint="LeftToe_x" gear="1"/>
    <motor name="LeftToe_y" joint="LeftToe_y" gear="1"/>
    <motor name="RightUpLeg_z" joint="RightUpLeg_z" gear="1"/>
    <motor name="RightUpLeg_x" joint="RightUpLeg_x" gear="1"/>
    <motor name="RightUpLeg_y" joint="RightUpLeg_y" gear="1"/>
    <motor name="RightLeg_z" joint="RightLeg_z" gear="1"/>
    <motor name="RightLeg_x" joint="RightLeg_x" gear="1"/>
    <motor name="RightLeg_y" joint="RightLeg_y" gear="1"/>
    <motor name="RightFoot_z" joint="RightFoot_z" gear="1"/>
    <motor name="RightFoot_x" joint="RightFoot_x" gear="1"/>
    <motor name="RightFoot_y" joint="RightFoot_y" gear="1"/>
    <motor name="RightToe_z" joint="RightToe_z" gear="1"/>
    <motor name="RightToe_x" joint="RightToe_x" gear="1"/>
    <motor name="RightToe_y" joint="RightToe_y" gear="1"/>
    <motor name="Spine_z" joint="Spine_z" gear="1"/>
    <motor name="Spine_x" joint="Spine_x" gear="1"/>
    <motor name="Spine_y" joint="Spine_y" gear="1"/>
    <motor name="Spine1_z" joint="Spine1_z" gear="1"/>
    <motor name="Spine1_x" joint="Spine1_x" gear="1"/>
    <motor name="Spine1_y" joint="Spine1_y" gear="1"/>
    <motor name="Spine2_z" joint="Spine2_z" gear="1"/>
    <motor name="Spine2_x" joint="Spine2_x" gear="1"/>
    <motor name="Spine2_y" joint="Spine2_y" gear="1"/>
    <motor name="Neck_z" joint="Neck_z" gear="1"/>
    <motor name="Neck_x" joint="Neck_x" gear="1"/>
    <motor name="Neck_y" joint="Neck_y" gear="1"/>
    <motor name="Mouth_z" joint="Mouth_z" gear="1"/>
    <motor name="Mouth_x" joint="Mouth_x" gear="1"/>
    <motor name="Mouth_y" joint="Mouth_y" gear="1"/>
    <motor name="LeftChest_z" joint="LeftChest_z" gear="1"/>
    <motor name="LeftChest_x" joint="LeftChest_x" gear="1"/>
    <motor name="LeftChest_y" joint="LeftChest_y" gear="1"/>
    <motor name="LeftShoulder_z" joint="LeftShoulder_z" gear="1"/>
    <motor name="LeftShoulder_x" joint="LeftShoulder_x" gear="1"/>
    <motor name="LeftShoulder_y" joint="LeftShoulder_y" gear="1"/>
    <motor name="LeftArm_z" joint="LeftArm_z" gear="1"/>
    <motor name="LeftArm_x" joint="LeftArm_x" gear="1"/>
    <motor name="LeftArm_y" joint="LeftArm_y" gear="1"/>
    <motor name="LeftWrist_z" joint="LeftWrist_z" gear="1"/>
    <motor name="LeftWrist_x" joint="LeftWrist_x" gear="1"/>
    <motor name="LeftWrist_y" joint="LeftWrist_y" gear="1"/>
    <motor name="LeftHand_z" joint="LeftHand_z" gear="1"/>
    <motor name="LeftHand_x" joint="LeftHand_x" gear="1"/>
    <motor name="LeftHand_y" joint="LeftHand_y" gear="1"/>
    <motor name="RightChest_z" joint="RightChest_z" gear="1"/>
    <motor name="RightChest_x" joint="RightChest_x" gear="1"/>
    <motor name="RightChest_y" joint="RightChest_y" gear="1"/>
    <motor name="RightShoulder_z" joint="RightShoulder_z" gear="1"/>
    <motor name="RightShoulder_x" joint="RightShoulder_x" gear="1"/>
    <motor name="RightShoulder_y" joint="RightShoulder_y" gear="1"/>
    <motor name="RightArm_z" joint="RightArm_z" gear="1"/>
    <motor name="RightArm_x" joint="RightArm_x" gear="1"/>
    <motor name="RightArm_y" joint="RightArm_y" gear="1"/>
    <motor name="RightWrist_z" joint="RightWrist_z" gear="1"/>
    <motor name="RightWrist_x" joint="RightWrist_x" gear="1"/>
    <motor name="RightWrist_y" joint="RightWrist_y" gear="1"/>
    <motor name="RightHand_z" joint="RightHand_z" gear="1"/>
    <motor name="RightHand_x" joint="RightHand_x" gear="1"/>
    <motor name="RightHand_y" joint="RightHand_y" gear="1"/>
  </actuator>
</mujoco>
