<mujoco model="humanoid">
  <compiler angle="degree" inertiafromgeom="true" coordinate="global"/>
  <include file="./common/materials.xml"/>
    <visual>
    <headlight ambient=".4 .4 .4" diffuse=".8 .8 .8" specular="0.3 0.3 0.3"/>
    <map znear=".01"/>
    <quality shadowsize="2048"/>
  </visual>
  <default>
    <joint damping="0.0" armature="0.01" stiffness="0.0" limited="true"/>
    <geom conaffinity="7" condim="1" contype="7" margin="0.001" material="self" rgba=".98 .54 .56 1."/>
  </default>
  <statistic extent="3" center="0 0 1"/>
  <option timestep="0.00222222222"/>
  <asset>
    <texture type="skybox" file="./common/sky1.png" gridsize="3 4" gridlayout=".U..LFRB.D.." width="8192" height="8192"/>
    <texture builtin="flat" height="1278" mark="cross" markrgb="1 1 1" name="texgeom" random="0.01" rgb1=".8 .6 .4" rgb2=".8 .6 .4" type="cube" width="127"/>
  </asset>
  <worldbody>
    <light cutoff="100" diffuse="1 1 1" dir="-0 0 -1.3" directional="true" exponent="1" pos="0 0 1.3" specular=".1 .1 .1"/>
    <geom condim="3" friction="1. .1 .1" material="grid_new" name="floor" pos="0 0 0" rgba=".8 .9 .8 1" size="100 100 .2" type="plane"/>
    <body name="root" user="0.0000 -0.0000 0.0000" pos="0.0000 -0.0000 0.0000">
      <joint armature="0.0" limited="false" name="root" pos="0.0000 -0.0000 0.0000" stiffness="0" type="free"/>
      <geom pos="0.0000 0.0000 -0.0240" size="0.1100" type="sphere"/>
      <body name="lhipjoint" user="0.0963 -0.0494 -0.0918" pos="0.0000 -0.0000 0.0000">
        <body name="lfemur" user="0.2274 -0.0494 -0.4521" pos="0.0963 -0.0494 -0.0918">
          <joint axis="0.0000 -1.0000 0.0000" name="lfemur_z" pos="0.0963 -0.0494 -0.0918" range="-60.0000 70.0000" type="hinge"/>
          <joint axis="-0.3420 -0.0000 0.9397" name="lfemur_y" pos="0.0963 -0.0494 -0.0918" range="-70.0000 70.0000" type="hinge"/>
          <joint axis="0.9397 0.0000 0.3420" name="lfemur_x" pos="0.0963 -0.0494 -0.0918" range="-160.0000 20.0000" type="hinge"/>
          <geom fromto="0.1031 -0.0494 -0.1106 0.2206 -0.0494 -0.4333" size="0.0520" type="capsule"/>
          <body name="ltibia" user="0.3657 -0.0494 -0.8321" pos="0.2274 -0.0494 -0.4521">
            <joint axis="0.9397 0.0000 0.3420" name="ltibia_x" pos="0.2274 -0.0494 -0.4521" range="0.0000 170.0000" type="hinge"/>
            <geom contype="1" conaffinity="1" fromto="0.2343 -0.0494 -0.4709 0.3589 -0.0494 -0.8133" size="0.0370" type="capsule"/>
            <body name="lfoot" user="0.3731 -0.1606 -0.8523" pos="0.3657 -0.0494 -0.8321">
              <geom contype="1" conaffinity="1" pos="0.3714 -0.0990 -0.8442" size="0.0600 0.1070 0.0240" quat="0.9848 -0.0000 -0.1736 0.0000" type="box"/>
              <joint axis="-0.3420 -0.0000 0.9397" name="lfoot_z" pos="0.3657 -0.0494 -0.8321" range="-70.0000 20.0000" type="hinge"/>
              <joint axis="0.0000 -1.0000 0.0000" name="lfoot_y" pos="0.3657 -0.0494 -0.8321" range="-45.0000 45.0000" type="hinge"/>
              <joint axis="0.9397 0.0000 0.3420" name="lfoot_x" pos="0.3657 -0.0494 -0.8321" range="-45.0000 90.0000" type="hinge"/>
            </body>
          </body>
        </body>
      </body>
      <body name="rhipjoint" user="-0.0963 -0.0494 -0.0918" pos="-0.0000 -0.0000 0.0000">
        <body name="rfemur" user="-0.2274 -0.0494 -0.4521" pos="-0.0963 -0.0494 -0.0918">
          <joint axis="0.0000 -1.0000 -0.0000" name="rfemur_z" pos="-0.0963 -0.0494 -0.0918" range="-70.0000 60.0000" type="hinge"/>
          <joint axis="0.3420 -0.0000 0.9397" name="rfemur_y" pos="-0.0963 -0.0494 -0.0918" range="-70.0000 70.0000" type="hinge"/>
          <joint axis="0.9397 0.0000 -0.3420" name="rfemur_x" pos="-0.0963 -0.0494 -0.0918" range="-160.0000 20.0000" type="hinge"/>
          <geom fromto="-0.1031 -0.0494 -0.1106 -0.2206 -0.0494 -0.4333" size="0.0520" type="capsule"/>
          <body name="rtibia" user="-0.3657 -0.0494 -0.8321" pos="-0.2274 -0.0494 -0.4521">
            <joint axis="0.9397 0.0000 -0.3420" name="rtibia_x" pos="-0.2274 -0.0494 -0.4521" range="0.0000 170.0000" type="hinge"/>
            <geom contype="2" conaffinity="2" fromto="-0.2343 -0.0494 -0.4709 -0.3589 -0.0494 -0.8133" size="0.0370" type="capsule"/>
            <body name="rfoot" user="-0.3731 -0.1606 -0.8523" pos="-0.3657 -0.0494 -0.8321">
              <geom contype="2" conaffinity="2" pos="-0.3714 -0.0990 -0.8442" size="0.0600 0.1070 0.0240" quat="0.9848 -0.0000 0.1736 -0.0000" type="box"/>
              <joint axis="0.3420 -0.0000 0.9397" name="rfoot_z" pos="-0.3657 -0.0494 -0.8321" range="-20.0000 70.0000" type="hinge"/>
              <joint axis="0.0000 -1.0000 0.0000" name="rfoot_y" pos="-0.3657 -0.0494 -0.8321" range="-45.0000 45.0000" type="hinge"/>
              <joint axis="0.9397 -0.0000 -0.3420" name="rfoot_x" pos="-0.3657 -0.0494 -0.8321" range="-45.0000 90.0000" type="hinge"/>
            </body>
          </body>
        </body>
      </body>
      <body name="lowerback" user="0.0006 0.0081 0.1132" pos="0.0000 -0.0000 0.0000">
        <body name="upperback" user="0.0011 0.0071 0.2268" pos="0.0006 0.0081 0.1132">
          <geom pos="0.0006 0.0081 0.1232" size="0.0700" type="sphere"/>
          <joint axis="0.0000 -1.0000 0.0000" name="upperback_z" pos="0.0006 0.0081 0.1132" range="-30.0000 30.0000" type="hinge"/>
          <joint axis="0.0000 -0.0000 1.0000" name="upperback_y" pos="0.0006 0.0081 0.1132" range="-30.0000 30.0000" type="hinge"/>
          <joint axis="1.0000 0.0000 0.0000" name="upperback_x" pos="0.0006 0.0081 0.1132" range="-20.0000 45.0000" type="hinge"/>
          <body name="thorax" user="0.0010 0.0024 0.3407" pos="0.0011 0.0071 0.2268">
            <geom pos="0.0011 0.0071 0.2808" size="0.1000" type="sphere"/>
            <body name="lowerneck" user="-0.0023 -0.0083 0.4312" pos="0.0010 0.0024 0.3407">
              <geom pos="-0.0023 -0.0083 0.5472" size="0.0800" type="sphere"/>
              <joint axis="0.0000 -1.0000 0.0000" name="lowerneck_z" pos="0.0010 0.0024 0.3407" range="-30.0000 30.0000" type="hinge"/>
              <joint axis="0.0000 -0.0000 1.0000" name="lowerneck_y" pos="0.0010 0.0024 0.3407" range="-30.0000 30.0000" type="hinge"/>
              <joint axis="1.0000 0.0000 0.0000" name="lowerneck_x" pos="0.0010 0.0024 0.3407" range="-20.0000 45.0000" type="hinge"/>
              <body name="upperneck" user="-0.0013 -0.0038 0.5212" pos="-0.0023 -0.0083 0.4312">
                <body name="head" user="-0.0006 -0.0008 0.6176" pos="-0.0013 -0.0038 0.5212">
                  <camera mode="fixed" xyaxes="-1 0 0 0 0 1"/>
                </body>
              </body>
              <body name="lclavicle" user="0.1790 -0.0149 0.4121" pos="-0.0023 -0.0083 0.4312">
                <geom fromto="0.0101 -0.0088 0.4299 0.1666 -0.0144 0.4134" size="0.0340" type="capsule"/>
                <joint axis="0.0000 -1.0000 0.0000" name="lclavicle_z" pos="0.0010 0.0024 0.3407" range="0.0000 20.0000" type="hinge"/>
                <joint axis="0.0000 -0.0000 1.0000" name="lclavicle_y" pos="0.0010 0.0024 0.3407" range="-20.0000 10.0000" type="hinge"/>
                <body name="lhumerus" user="0.4599 -0.0149 0.4121" pos="0.1790 -0.0149 0.4121">
                  <joint axis="-0.0000 0.8660 -0.5000" name="lhumerus_z" pos="0.1790 -0.0149 0.4121" range="-90.0000 90.0000" type="hinge"/>
                  <joint axis="-1.0000 -0.0000 -0.0000" name="lhumerus_y" pos="0.1790 -0.0149 0.4121" range="-90.0000 90.0000" type="hinge"/>
                  <joint axis="0.0000 -0.5000 -0.8660" name="lhumerus_x" pos="0.1790 -0.0149 0.4121" range="-60.0000 90.0000" type="hinge"/>
                  <geom fromto="0.1965 -0.0149 0.4121 0.4424 -0.0149 0.4121" size="0.0310" type="capsule"/>
                  <body name="lradius" user="0.6374 -0.0149 0.4121" pos="0.4599 -0.0149 0.4121">
                    <geom fromto="0.4599 -0.0149 0.4121 0.6374 -0.0149 0.4121" size="0.0250" type="capsule"/>
                    <joint axis="0.0000 -0.5000 -0.8660" name="lradius_x" pos="0.4599 -0.0149 0.4121" range="-10.0000 170.0000" type="hinge"/>
                    <body name="lwrist" user="0.7261 -0.0149 0.4121" pos="0.6374 -0.0149 0.4121">
                      <geom pos="0.6814 -0.0149 0.4121" size="0.0400" type="sphere"/>
                    </body>
                  </body>
                </body>
              </body>
              <body name="rclavicle" user="-0.1790 -0.0149 0.4121" pos="0.0023 -0.0083 0.4312">
                <geom fromto="-0.0101 -0.0088 0.4299 -0.1666 -0.0144 0.4134" size="0.0340" type="capsule"/>
                <joint axis="0.0000 -1.0000 0.0000" name="rclavicle_z" pos="-0.0010 0.0024 0.3407" range="-20.0000 0.0000" type="hinge"/>
                <joint axis="0.0000 -0.0000 1.0000" name="rclavicle_y" pos="-0.0010 0.0024 0.3407" range="-10.0000 20.0000" type="hinge"/>
                <body name="rhumerus" user="-0.4599 -0.0149 0.4121" pos="-0.1790 -0.0149 0.4121">
                  <joint axis="0.0000 0.8660 -0.5000" name="rhumerus_z" pos="-0.1790 -0.0149 0.4121" range="-90.0000 90.0000" type="hinge"/>
                  <joint axis="1.0000 -0.0000 -0.0000" name="rhumerus_y" pos="-0.1790 -0.0149 0.4121" range="-90.0000 90.0000" type="hinge"/>
                  <joint axis="0.0000 0.5000 0.8660" name="rhumerus_x" pos="-0.1790 -0.0149 0.4121" range="-90.0000 60.0000" type="hinge"/>
                  <geom fromto="-0.1965 -0.0149 0.4121 -0.4424 -0.0149 0.4121" size="0.0310" type="capsule"/>
                  <body name="rradius" user="-0.6374 -0.0149 0.4121" pos="-0.4599 -0.0149 0.4121">
                    <geom fromto="-0.4599 -0.0149 0.4121 -0.6374 -0.0149 0.4121" size="0.0250" type="capsule"/>
                    <joint axis="0.0000 0.5000 0.8660" name="rradius_x" pos="-0.4599 -0.0149 0.4121" range="-10.0000 170.0000" type="hinge"/>
                    <body name="rwrist" user="-0.7261 -0.0149 0.4121" pos="-0.6374 -0.0149 0.4121">
                      <geom pos="-0.6814 -0.0149 0.4121" size="0.0400" type="sphere"/>
                    </body>
                  </body>
                </body>
              </body>
            </body>
          </body>
        </body>
      </body>
    </body>
  </worldbody>
  <actuator>
    <motor gear="1" joint="lfemur_z" name="lfemur_z"/>
    <motor gear="1" joint="lfemur_y" name="lfemur_y"/>
    <motor gear="1" joint="lfemur_x" name="lfemur_x"/>
    <motor gear="1" joint="ltibia_x" name="ltibia_x"/>
    <motor gear="1" joint="lfoot_z" name="lfoot_z"/>
    <motor gear="1" joint="lfoot_y" name="lfoot_y"/>
    <motor gear="1" joint="lfoot_x" name="lfoot_x"/>
    <motor gear="1" joint="rfemur_z" name="rfemur_z"/>
    <motor gear="1" joint="rfemur_y" name="rfemur_y"/>
    <motor gear="1" joint="rfemur_x" name="rfemur_x"/>
    <motor gear="1" joint="rtibia_x" name="rtibia_x"/>
    <motor gear="1" joint="rfoot_z" name="rfoot_z"/>
    <motor gear="1" joint="rfoot_y" name="rfoot_y"/>
    <motor gear="1" joint="rfoot_x" name="rfoot_x"/>
    <motor gear="1" joint="upperback_z" name="upperback_z"/>
    <motor gear="1" joint="upperback_y" name="upperback_y"/>
    <motor gear="1" joint="upperback_x" name="upperback_x"/>
    <motor gear="1" joint="lowerneck_z" name="lowerneck_z"/>
    <motor gear="1" joint="lowerneck_y" name="lowerneck_y"/>
    <motor gear="1" joint="lowerneck_x" name="lowerneck_x"/>
    <motor gear="1" joint="lclavicle_z" name="lclavicle_z"/>
    <motor gear="1" joint="lclavicle_y" name="lclavicle_y"/>
    <motor gear="1" joint="lhumerus_z" name="lhumerus_z"/>
    <motor gear="1" joint="lhumerus_y" name="lhumerus_y"/>
    <motor gear="1" joint="lhumerus_x" name="lhumerus_x"/>
    <motor gear="1" joint="lradius_x" name="lradius_x"/>
    <motor gear="1" joint="rclavicle_z" name="rclavicle_z"/>
    <motor gear="1" joint="rclavicle_y" name="rclavicle_y"/>
    <motor gear="1" joint="rhumerus_z" name="rhumerus_z"/>
    <motor gear="1" joint="rhumerus_y" name="rhumerus_y"/>
    <motor gear="1" joint="rhumerus_x" name="rhumerus_x"/>
    <motor gear="1" joint="rradius_x" name="rradius_x"/>
  </actuator>
</mujoco>