<mujoco model="PROX-D 3D Scenes inside MujoCo">
<compiler angle="degree" inertiafromgeom="true" coordinate="global"/>
  <include file="./common/materials.xml"/>
  <size njmax="8000" nconmax="4000"/>
  <visual>
    <headlight ambient=".4 .4 .4" diffuse=".8 .8 .8" specular="0.1 0.1 0.1"/>
    <map znear=".01"/>
    <quality shadowsize="2048"/>
  </visual>
  <default>
    <joint damping="0.0" armature="0.01" stiffness="0.0" limited="true"/>
    <geom conaffinity="7" condim="1" contype="7" margin="0.001" material="self" rgba="0.8 0.6 .4 1"/>
  </default>
  <statistic extent="3" center="0 0 1"/>
  <option timestep="0.00222222222"/>
  <asset>
    <texture type="skybox" file="./common/sky1.png" gridsize="3 4" gridlayout=".U..LFRB.D.." width="8192" height="8192"/>
    <texture builtin="flat" height="1278" mark="cross" markrgb="1 1 1" name="texgeom" random="0.01" rgb1=".8 .6 .4" rgb2=".8 .6 .4" type="cube" width="127"/>
    <mesh file="./geom/Pelvis.stl"/>
    <mesh file="./geom/L_Hip.stl"/>
    <mesh file="./geom/R_Hip.stl"/>
    <mesh file="./geom/Torso.stl"/>
    <mesh file="./geom/L_Knee.stl"/>
    <mesh file="./geom/R_Knee.stl"/>
    <mesh file="./geom/Spine.stl"/>
    <mesh file="./geom/L_Ankle.stl"/>
    <mesh file="./geom/R_Ankle.stl"/>
    <mesh file="./geom/Chest.stl"/>
    <mesh file="./geom/L_Toe.stl"/>
    <mesh file="./geom/R_Toe.stl"/>
    <mesh file="./geom/Neck.stl"/>
    <mesh file="./geom/L_Thorax.stl"/>
    <mesh file="./geom/R_Thorax.stl"/>
    <mesh file="./geom/Head.stl"/>
    <mesh file="./geom/L_Shoulder.stl"/>
    <mesh file="./geom/R_Shoulder.stl"/>
    <mesh file="./geom/L_Elbow.stl"/>
    <mesh file="./geom/R_Elbow.stl"/>
    <mesh file="./geom/L_Wrist.stl"/>
    <mesh file="./geom/R_Wrist.stl"/>
    <mesh file="./geom/L_Hand.stl"/>
    <mesh file="./geom/R_Hand.stl"/>
    <mesh file="./geom/MPH8/convex_0.stl"/>
    <mesh file="./geom/MPH8/convex_1.stl"/>
    <mesh file="./geom/MPH8/convex_10.stl"/>
    <mesh file="./geom/MPH8/convex_100.stl"/>
    <mesh file="./geom/MPH8/convex_101.stl"/>
    <mesh file="./geom/MPH8/convex_102.stl"/>
    <mesh file="./geom/MPH8/convex_103.stl"/>
    <mesh file="./geom/MPH8/convex_104.stl"/>
    <mesh file="./geom/MPH8/convex_105.stl"/>
    <mesh file="./geom/MPH8/convex_106.stl"/>
    <mesh file="./geom/MPH8/convex_107.stl"/>
    <mesh file="./geom/MPH8/convex_108.stl"/>
    <mesh file="./geom/MPH8/convex_109.stl"/>
    <mesh file="./geom/MPH8/convex_11.stl"/>
    <mesh file="./geom/MPH8/convex_110.stl"/>
    <mesh file="./geom/MPH8/convex_111.stl"/>
    <mesh file="./geom/MPH8/convex_112.stl"/>
    <mesh file="./geom/MPH8/convex_113.stl"/>
    <mesh file="./geom/MPH8/convex_114.stl"/>
    <mesh file="./geom/MPH8/convex_115.stl"/>
    <mesh file="./geom/MPH8/convex_116.stl"/>
    <mesh file="./geom/MPH8/convex_117.stl"/>
    <mesh file="./geom/MPH8/convex_118.stl"/>
    <mesh file="./geom/MPH8/convex_119.stl"/>
    <mesh file="./geom/MPH8/convex_12.stl"/>
    <mesh file="./geom/MPH8/convex_120.stl"/>
    <mesh file="./geom/MPH8/convex_121.stl"/>
    <mesh file="./geom/MPH8/convex_122.stl"/>
    <mesh file="./geom/MPH8/convex_123.stl"/>
    <mesh file="./geom/MPH8/convex_124.stl"/>
    <mesh file="./geom/MPH8/convex_125.stl"/>
    <mesh file="./geom/MPH8/convex_126.stl"/>
    <mesh file="./geom/MPH8/convex_127.stl"/>
    <mesh file="./geom/MPH8/convex_128.stl"/>
    <mesh file="./geom/MPH8/convex_129.stl"/>
    <mesh file="./geom/MPH8/convex_13.stl"/>
    <mesh file="./geom/MPH8/convex_130.stl"/>
    <mesh file="./geom/MPH8/convex_131.stl"/>
    <mesh file="./geom/MPH8/convex_132.stl"/>
    <mesh file="./geom/MPH8/convex_133.stl"/>
    <mesh file="./geom/MPH8/convex_134.stl"/>
    <mesh file="./geom/MPH8/convex_135.stl"/>
    <mesh file="./geom/MPH8/convex_136.stl"/>
    <mesh file="./geom/MPH8/convex_137.stl"/>
    <mesh file="./geom/MPH8/convex_138.stl"/>
    <mesh file="./geom/MPH8/convex_139.stl"/>
    <mesh file="./geom/MPH8/convex_14.stl"/>
    <mesh file="./geom/MPH8/convex_140.stl"/>
    <mesh file="./geom/MPH8/convex_141.stl"/>
    <mesh file="./geom/MPH8/convex_142.stl"/>
    <mesh file="./geom/MPH8/convex_143.stl"/>
    <mesh file="./geom/MPH8/convex_144.stl"/>
    <mesh file="./geom/MPH8/convex_145.stl"/>
    <mesh file="./geom/MPH8/convex_146.stl"/>
    <mesh file="./geom/MPH8/convex_147.stl"/>
    <mesh file="./geom/MPH8/convex_148.stl"/>
    <mesh file="./geom/MPH8/convex_149.stl"/>
    <mesh file="./geom/MPH8/convex_15.stl"/>
    <mesh file="./geom/MPH8/convex_150.stl"/>
    <mesh file="./geom/MPH8/convex_151.stl"/>
    <mesh file="./geom/MPH8/convex_152.stl"/>
    <mesh file="./geom/MPH8/convex_153.stl"/>
    <mesh file="./geom/MPH8/convex_154.stl"/>
    <mesh file="./geom/MPH8/convex_155.stl"/>
    <mesh file="./geom/MPH8/convex_156.stl"/>
    <mesh file="./geom/MPH8/convex_157.stl"/>
    <mesh file="./geom/MPH8/convex_158.stl"/>
    <mesh file="./geom/MPH8/convex_159.stl"/>
    <mesh file="./geom/MPH8/convex_16.stl"/>
    <mesh file="./geom/MPH8/convex_160.stl"/>
    <mesh file="./geom/MPH8/convex_161.stl"/>
    <mesh file="./geom/MPH8/convex_162.stl"/>
    <mesh file="./geom/MPH8/convex_163.stl"/>
    <mesh file="./geom/MPH8/convex_164.stl"/>
    <mesh file="./geom/MPH8/convex_165.stl"/>
    <mesh file="./geom/MPH8/convex_166.stl"/>
    <mesh file="./geom/MPH8/convex_167.stl"/>
    <mesh file="./geom/MPH8/convex_168.stl"/>
    <mesh file="./geom/MPH8/convex_169.stl"/>
    <mesh file="./geom/MPH8/convex_17.stl"/>
    <mesh file="./geom/MPH8/convex_170.stl"/>
    <mesh file="./geom/MPH8/convex_171.stl"/>
    <mesh file="./geom/MPH8/convex_172.stl"/>
    <mesh file="./geom/MPH8/convex_173.stl"/>
    <mesh file="./geom/MPH8/convex_174.stl"/>
    <mesh file="./geom/MPH8/convex_175.stl"/>
    <mesh file="./geom/MPH8/convex_176.stl"/>
    <mesh file="./geom/MPH8/convex_177.stl"/>
    <mesh file="./geom/MPH8/convex_178.stl"/>
    <mesh file="./geom/MPH8/convex_179.stl"/>
    <mesh file="./geom/MPH8/convex_18.stl"/>
    <mesh file="./geom/MPH8/convex_180.stl"/>
    <mesh file="./geom/MPH8/convex_181.stl"/>
    <mesh file="./geom/MPH8/convex_182.stl"/>
    <mesh file="./geom/MPH8/convex_183.stl"/>
    <mesh file="./geom/MPH8/convex_184.stl"/>
    <mesh file="./geom/MPH8/convex_185.stl"/>
    <mesh file="./geom/MPH8/convex_186.stl"/>
    <mesh file="./geom/MPH8/convex_187.stl"/>
    <mesh file="./geom/MPH8/convex_188.stl"/>
    <mesh file="./geom/MPH8/convex_189.stl"/>
    <mesh file="./geom/MPH8/convex_19.stl"/>
    <mesh file="./geom/MPH8/convex_190.stl"/>
    <mesh file="./geom/MPH8/convex_191.stl"/>
    <mesh file="./geom/MPH8/convex_192.stl"/>
    <mesh file="./geom/MPH8/convex_193.stl"/>
    <mesh file="./geom/MPH8/convex_194.stl"/>
    <mesh file="./geom/MPH8/convex_195.stl"/>
    <mesh file="./geom/MPH8/convex_196.stl"/>
    <mesh file="./geom/MPH8/convex_197.stl"/>
    <mesh file="./geom/MPH8/convex_198.stl"/>
    <mesh file="./geom/MPH8/convex_199.stl"/>
    <mesh file="./geom/MPH8/convex_2.stl"/>
    <mesh file="./geom/MPH8/convex_20.stl"/>
    <mesh file="./geom/MPH8/convex_200.stl"/>
    <mesh file="./geom/MPH8/convex_201.stl"/>
    <mesh file="./geom/MPH8/convex_202.stl"/>
    <mesh file="./geom/MPH8/convex_203.stl"/>
    <mesh file="./geom/MPH8/convex_204.stl"/>
    <mesh file="./geom/MPH8/convex_205.stl"/>
    <mesh file="./geom/MPH8/convex_206.stl"/>
    <mesh file="./geom/MPH8/convex_207.stl"/>
    <mesh file="./geom/MPH8/convex_208.stl"/>
    <mesh file="./geom/MPH8/convex_209.stl"/>
    <mesh file="./geom/MPH8/convex_21.stl"/>
    <mesh file="./geom/MPH8/convex_210.stl"/>
    <mesh file="./geom/MPH8/convex_211.stl"/>
    <mesh file="./geom/MPH8/convex_212.stl"/>
    <mesh file="./geom/MPH8/convex_213.stl"/>
    <mesh file="./geom/MPH8/convex_214.stl"/>
    <mesh file="./geom/MPH8/convex_215.stl"/>
    <mesh file="./geom/MPH8/convex_216.stl"/>
    <mesh file="./geom/MPH8/convex_217.stl"/>
    <mesh file="./geom/MPH8/convex_218.stl"/>
    <mesh file="./geom/MPH8/convex_219.stl"/>
    <mesh file="./geom/MPH8/convex_22.stl"/>
    <mesh file="./geom/MPH8/convex_220.stl"/>
    <mesh file="./geom/MPH8/convex_221.stl"/>
    <mesh file="./geom/MPH8/convex_222.stl"/>
    <mesh file="./geom/MPH8/convex_223.stl"/>
    <mesh file="./geom/MPH8/convex_224.stl"/>
    <mesh file="./geom/MPH8/convex_225.stl"/>
    <mesh file="./geom/MPH8/convex_226.stl"/>
    <mesh file="./geom/MPH8/convex_227.stl"/>
    <mesh file="./geom/MPH8/convex_228.stl"/>
    <mesh file="./geom/MPH8/convex_229.stl"/>
    <mesh file="./geom/MPH8/convex_23.stl"/>
    <mesh file="./geom/MPH8/convex_230.stl"/>
    <mesh file="./geom/MPH8/convex_231.stl"/>
    <mesh file="./geom/MPH8/convex_232.stl"/>
    <mesh file="./geom/MPH8/convex_233.stl"/>
    <mesh file="./geom/MPH8/convex_234.stl"/>
    <mesh file="./geom/MPH8/convex_235.stl"/>
    <mesh file="./geom/MPH8/convex_236.stl"/>
    <mesh file="./geom/MPH8/convex_237.stl"/>
    <mesh file="./geom/MPH8/convex_238.stl"/>
    <mesh file="./geom/MPH8/convex_239.stl"/>
    <mesh file="./geom/MPH8/convex_24.stl"/>
    <mesh file="./geom/MPH8/convex_240.stl"/>
    <mesh file="./geom/MPH8/convex_241.stl"/>
    <mesh file="./geom/MPH8/convex_242.stl"/>
    <mesh file="./geom/MPH8/convex_243.stl"/>
    <mesh file="./geom/MPH8/convex_244.stl"/>
    <mesh file="./geom/MPH8/convex_245.stl"/>
    <mesh file="./geom/MPH8/convex_246.stl"/>
    <mesh file="./geom/MPH8/convex_247.stl"/>
    <mesh file="./geom/MPH8/convex_248.stl"/>
    <mesh file="./geom/MPH8/convex_249.stl"/>
    <mesh file="./geom/MPH8/convex_25.stl"/>
    <mesh file="./geom/MPH8/convex_250.stl"/>
    <mesh file="./geom/MPH8/convex_251.stl"/>
    <mesh file="./geom/MPH8/convex_252.stl"/>
    <mesh file="./geom/MPH8/convex_253.stl"/>
    <mesh file="./geom/MPH8/convex_254.stl"/>
    <mesh file="./geom/MPH8/convex_255.stl"/>
    <mesh file="./geom/MPH8/convex_256.stl"/>
    <mesh file="./geom/MPH8/convex_257.stl"/>
    <mesh file="./geom/MPH8/convex_258.stl"/>
    <mesh file="./geom/MPH8/convex_259.stl"/>
    <mesh file="./geom/MPH8/convex_26.stl"/>
    <mesh file="./geom/MPH8/convex_260.stl"/>
    <mesh file="./geom/MPH8/convex_261.stl"/>
    <mesh file="./geom/MPH8/convex_262.stl"/>
    <mesh file="./geom/MPH8/convex_263.stl"/>
    <mesh file="./geom/MPH8/convex_264.stl"/>
    <mesh file="./geom/MPH8/convex_265.stl"/>
    <mesh file="./geom/MPH8/convex_266.stl"/>
    <mesh file="./geom/MPH8/convex_267.stl"/>
    <mesh file="./geom/MPH8/convex_268.stl"/>
    <mesh file="./geom/MPH8/convex_269.stl"/>
    <mesh file="./geom/MPH8/convex_27.stl"/>
    <mesh file="./geom/MPH8/convex_270.stl"/>
    <mesh file="./geom/MPH8/convex_271.stl"/>
    <mesh file="./geom/MPH8/convex_272.stl"/>
    <mesh file="./geom/MPH8/convex_273.stl"/>
    <mesh file="./geom/MPH8/convex_274.stl"/>
    <mesh file="./geom/MPH8/convex_275.stl"/>
    <mesh file="./geom/MPH8/convex_276.stl"/>
    <mesh file="./geom/MPH8/convex_277.stl"/>
    <mesh file="./geom/MPH8/convex_278.stl"/>
    <mesh file="./geom/MPH8/convex_279.stl"/>
    <mesh file="./geom/MPH8/convex_28.stl"/>
    <mesh file="./geom/MPH8/convex_280.stl"/>
    <mesh file="./geom/MPH8/convex_281.stl"/>
    <mesh file="./geom/MPH8/convex_282.stl"/>
    <mesh file="./geom/MPH8/convex_283.stl"/>
    <mesh file="./geom/MPH8/convex_284.stl"/>
    <mesh file="./geom/MPH8/convex_285.stl"/>
    <mesh file="./geom/MPH8/convex_286.stl"/>
    <mesh file="./geom/MPH8/convex_287.stl"/>
    <mesh file="./geom/MPH8/convex_288.stl"/>
    <mesh file="./geom/MPH8/convex_289.stl"/>
    <mesh file="./geom/MPH8/convex_29.stl"/>
    <mesh file="./geom/MPH8/convex_290.stl"/>
    <mesh file="./geom/MPH8/convex_291.stl"/>
    <mesh file="./geom/MPH8/convex_292.stl"/>
    <mesh file="./geom/MPH8/convex_293.stl"/>
    <mesh file="./geom/MPH8/convex_294.stl"/>
    <mesh file="./geom/MPH8/convex_295.stl"/>
    <mesh file="./geom/MPH8/convex_296.stl"/>
    <mesh file="./geom/MPH8/convex_297.stl"/>
    <mesh file="./geom/MPH8/convex_298.stl"/>
    <mesh file="./geom/MPH8/convex_299.stl"/>
    <mesh file="./geom/MPH8/convex_3.stl"/>
    <mesh file="./geom/MPH8/convex_30.stl"/>
    <mesh file="./geom/MPH8/convex_300.stl"/>
    <mesh file="./geom/MPH8/convex_301.stl"/>
    <mesh file="./geom/MPH8/convex_302.stl"/>
    <mesh file="./geom/MPH8/convex_303.stl"/>
    <mesh file="./geom/MPH8/convex_304.stl"/>
    <mesh file="./geom/MPH8/convex_305.stl"/>
    <mesh file="./geom/MPH8/convex_306.stl"/>
    <mesh file="./geom/MPH8/convex_307.stl"/>
    <mesh file="./geom/MPH8/convex_308.stl"/>
    <mesh file="./geom/MPH8/convex_309.stl"/>
    <mesh file="./geom/MPH8/convex_31.stl"/>
    <mesh file="./geom/MPH8/convex_310.stl"/>
    <mesh file="./geom/MPH8/convex_311.stl"/>
    <mesh file="./geom/MPH8/convex_312.stl"/>
    <mesh file="./geom/MPH8/convex_313.stl"/>
    <mesh file="./geom/MPH8/convex_314.stl"/>
    <mesh file="./geom/MPH8/convex_315.stl"/>
    <mesh file="./geom/MPH8/convex_316.stl"/>
    <mesh file="./geom/MPH8/convex_317.stl"/>
    <mesh file="./geom/MPH8/convex_318.stl"/>
    <mesh file="./geom/MPH8/convex_319.stl"/>
    <mesh file="./geom/MPH8/convex_32.stl"/>
    <mesh file="./geom/MPH8/convex_320.stl"/>
    <mesh file="./geom/MPH8/convex_321.stl"/>
    <mesh file="./geom/MPH8/convex_322.stl"/>
    <mesh file="./geom/MPH8/convex_323.stl"/>
    <mesh file="./geom/MPH8/convex_324.stl"/>
    <mesh file="./geom/MPH8/convex_325.stl"/>
    <mesh file="./geom/MPH8/convex_326.stl"/>
    <mesh file="./geom/MPH8/convex_327.stl"/>
    <mesh file="./geom/MPH8/convex_328.stl"/>
    <mesh file="./geom/MPH8/convex_329.stl"/>
    <mesh file="./geom/MPH8/convex_33.stl"/>
    <mesh file="./geom/MPH8/convex_330.stl"/>
    <mesh file="./geom/MPH8/convex_331.stl"/>
    <mesh file="./geom/MPH8/convex_332.stl"/>
    <mesh file="./geom/MPH8/convex_333.stl"/>
    <mesh file="./geom/MPH8/convex_334.stl"/>
    <mesh file="./geom/MPH8/convex_335.stl"/>
    <mesh file="./geom/MPH8/convex_336.stl"/>
    <mesh file="./geom/MPH8/convex_337.stl"/>
    <mesh file="./geom/MPH8/convex_338.stl"/>
    <mesh file="./geom/MPH8/convex_339.stl"/>
    <mesh file="./geom/MPH8/convex_34.stl"/>
    <mesh file="./geom/MPH8/convex_340.stl"/>
    <mesh file="./geom/MPH8/convex_341.stl"/>
    <mesh file="./geom/MPH8/convex_342.stl"/>
    <mesh file="./geom/MPH8/convex_343.stl"/>
    <mesh file="./geom/MPH8/convex_344.stl"/>
    <mesh file="./geom/MPH8/convex_345.stl"/>
    <mesh file="./geom/MPH8/convex_346.stl"/>
    <mesh file="./geom/MPH8/convex_347.stl"/>
    <mesh file="./geom/MPH8/convex_348.stl"/>
    <mesh file="./geom/MPH8/convex_349.stl"/>
    <mesh file="./geom/MPH8/convex_35.stl"/>
    <mesh file="./geom/MPH8/convex_350.stl"/>
    <mesh file="./geom/MPH8/convex_351.stl"/>
    <mesh file="./geom/MPH8/convex_352.stl"/>
    <mesh file="./geom/MPH8/convex_353.stl"/>
    <mesh file="./geom/MPH8/convex_354.stl"/>
    <mesh file="./geom/MPH8/convex_355.stl"/>
    <mesh file="./geom/MPH8/convex_356.stl"/>
    <mesh file="./geom/MPH8/convex_357.stl"/>
    <mesh file="./geom/MPH8/convex_358.stl"/>
    <mesh file="./geom/MPH8/convex_359.stl"/>
    <mesh file="./geom/MPH8/convex_36.stl"/>
    <mesh file="./geom/MPH8/convex_360.stl"/>
    <mesh file="./geom/MPH8/convex_361.stl"/>
    <mesh file="./geom/MPH8/convex_362.stl"/>
    <mesh file="./geom/MPH8/convex_363.stl"/>
    <mesh file="./geom/MPH8/convex_364.stl"/>
    <mesh file="./geom/MPH8/convex_365.stl"/>
    <mesh file="./geom/MPH8/convex_366.stl"/>
    <mesh file="./geom/MPH8/convex_367.stl"/>
    <mesh file="./geom/MPH8/convex_368.stl"/>
    <mesh file="./geom/MPH8/convex_369.stl"/>
    <mesh file="./geom/MPH8/convex_37.stl"/>
    <mesh file="./geom/MPH8/convex_370.stl"/>
    <mesh file="./geom/MPH8/convex_371.stl"/>
    <mesh file="./geom/MPH8/convex_372.stl"/>
    <mesh file="./geom/MPH8/convex_373.stl"/>
    <mesh file="./geom/MPH8/convex_374.stl"/>
    <mesh file="./geom/MPH8/convex_375.stl"/>
    <mesh file="./geom/MPH8/convex_376.stl"/>
    <mesh file="./geom/MPH8/convex_377.stl"/>
    <mesh file="./geom/MPH8/convex_378.stl"/>
    <mesh file="./geom/MPH8/convex_379.stl"/>
    <mesh file="./geom/MPH8/convex_38.stl"/>
    <mesh file="./geom/MPH8/convex_380.stl"/>
    <mesh file="./geom/MPH8/convex_381.stl"/>
    <mesh file="./geom/MPH8/convex_382.stl"/>
    <mesh file="./geom/MPH8/convex_383.stl"/>
    <mesh file="./geom/MPH8/convex_384.stl"/>
    <mesh file="./geom/MPH8/convex_385.stl"/>
    <mesh file="./geom/MPH8/convex_386.stl"/>
    <mesh file="./geom/MPH8/convex_387.stl"/>
    <mesh file="./geom/MPH8/convex_388.stl"/>
    <mesh file="./geom/MPH8/convex_389.stl"/>
    <mesh file="./geom/MPH8/convex_39.stl"/>
    <mesh file="./geom/MPH8/convex_390.stl"/>
    <mesh file="./geom/MPH8/convex_391.stl"/>
    <mesh file="./geom/MPH8/convex_392.stl"/>
    <mesh file="./geom/MPH8/convex_393.stl"/>
    <mesh file="./geom/MPH8/convex_394.stl"/>
    <mesh file="./geom/MPH8/convex_395.stl"/>
    <mesh file="./geom/MPH8/convex_396.stl"/>
    <mesh file="./geom/MPH8/convex_397.stl"/>
    <mesh file="./geom/MPH8/convex_398.stl"/>
    <mesh file="./geom/MPH8/convex_399.stl"/>
    <mesh file="./geom/MPH8/convex_4.stl"/>
    <mesh file="./geom/MPH8/convex_40.stl"/>
    <mesh file="./geom/MPH8/convex_400.stl"/>
    <mesh file="./geom/MPH8/convex_401.stl"/>
    <mesh file="./geom/MPH8/convex_402.stl"/>
    <mesh file="./geom/MPH8/convex_403.stl"/>
    <mesh file="./geom/MPH8/convex_404.stl"/>
    <mesh file="./geom/MPH8/convex_405.stl"/>
    <mesh file="./geom/MPH8/convex_406.stl"/>
    <mesh file="./geom/MPH8/convex_407.stl"/>
    <mesh file="./geom/MPH8/convex_408.stl"/>
    <mesh file="./geom/MPH8/convex_409.stl"/>
    <mesh file="./geom/MPH8/convex_41.stl"/>
    <mesh file="./geom/MPH8/convex_410.stl"/>
    <mesh file="./geom/MPH8/convex_411.stl"/>
    <mesh file="./geom/MPH8/convex_412.stl"/>
    <mesh file="./geom/MPH8/convex_413.stl"/>
    <mesh file="./geom/MPH8/convex_414.stl"/>
    <mesh file="./geom/MPH8/convex_415.stl"/>
    <mesh file="./geom/MPH8/convex_416.stl"/>
    <mesh file="./geom/MPH8/convex_417.stl"/>
    <mesh file="./geom/MPH8/convex_418.stl"/>
    <mesh file="./geom/MPH8/convex_419.stl"/>
    <mesh file="./geom/MPH8/convex_42.stl"/>
    <mesh file="./geom/MPH8/convex_420.stl"/>
    <mesh file="./geom/MPH8/convex_421.stl"/>
    <mesh file="./geom/MPH8/convex_422.stl"/>
    <mesh file="./geom/MPH8/convex_423.stl"/>
    <mesh file="./geom/MPH8/convex_424.stl"/>
    <mesh file="./geom/MPH8/convex_425.stl"/>
    <mesh file="./geom/MPH8/convex_426.stl"/>
    <mesh file="./geom/MPH8/convex_427.stl"/>
    <mesh file="./geom/MPH8/convex_428.stl"/>
    <mesh file="./geom/MPH8/convex_429.stl"/>
    <mesh file="./geom/MPH8/convex_43.stl"/>
    <mesh file="./geom/MPH8/convex_430.stl"/>
    <mesh file="./geom/MPH8/convex_431.stl"/>
    <mesh file="./geom/MPH8/convex_432.stl"/>
    <mesh file="./geom/MPH8/convex_433.stl"/>
    <mesh file="./geom/MPH8/convex_434.stl"/>
    <mesh file="./geom/MPH8/convex_435.stl"/>
    <mesh file="./geom/MPH8/convex_436.stl"/>
    <mesh file="./geom/MPH8/convex_437.stl"/>
    <mesh file="./geom/MPH8/convex_438.stl"/>
    <mesh file="./geom/MPH8/convex_439.stl"/>
    <mesh file="./geom/MPH8/convex_44.stl"/>
    <mesh file="./geom/MPH8/convex_440.stl"/>
    <mesh file="./geom/MPH8/convex_441.stl"/>
    <mesh file="./geom/MPH8/convex_442.stl"/>
    <mesh file="./geom/MPH8/convex_443.stl"/>
    <mesh file="./geom/MPH8/convex_444.stl"/>
    <mesh file="./geom/MPH8/convex_445.stl"/>
    <mesh file="./geom/MPH8/convex_446.stl"/>
    <mesh file="./geom/MPH8/convex_447.stl"/>
    <mesh file="./geom/MPH8/convex_448.stl"/>
    <mesh file="./geom/MPH8/convex_449.stl"/>
    <mesh file="./geom/MPH8/convex_45.stl"/>
    <mesh file="./geom/MPH8/convex_450.stl"/>
    <mesh file="./geom/MPH8/convex_451.stl"/>
    <mesh file="./geom/MPH8/convex_452.stl"/>
    <mesh file="./geom/MPH8/convex_453.stl"/>
    <mesh file="./geom/MPH8/convex_454.stl"/>
    <mesh file="./geom/MPH8/convex_455.stl"/>
    <mesh file="./geom/MPH8/convex_456.stl"/>
    <mesh file="./geom/MPH8/convex_457.stl"/>
    <mesh file="./geom/MPH8/convex_458.stl"/>
    <mesh file="./geom/MPH8/convex_459.stl"/>
    <mesh file="./geom/MPH8/convex_46.stl"/>
    <mesh file="./geom/MPH8/convex_460.stl"/>
    <mesh file="./geom/MPH8/convex_461.stl"/>
    <mesh file="./geom/MPH8/convex_462.stl"/>
    <mesh file="./geom/MPH8/convex_463.stl"/>
    <mesh file="./geom/MPH8/convex_464.stl"/>
    <mesh file="./geom/MPH8/convex_465.stl"/>
    <mesh file="./geom/MPH8/convex_466.stl"/>
    <mesh file="./geom/MPH8/convex_467.stl"/>
    <mesh file="./geom/MPH8/convex_468.stl"/>
    <mesh file="./geom/MPH8/convex_469.stl"/>
    <mesh file="./geom/MPH8/convex_47.stl"/>
    <mesh file="./geom/MPH8/convex_470.stl"/>
    <mesh file="./geom/MPH8/convex_471.stl"/>
    <mesh file="./geom/MPH8/convex_472.stl"/>
    <mesh file="./geom/MPH8/convex_473.stl"/>
    <mesh file="./geom/MPH8/convex_474.stl"/>
    <mesh file="./geom/MPH8/convex_475.stl"/>
    <mesh file="./geom/MPH8/convex_476.stl"/>
    <mesh file="./geom/MPH8/convex_477.stl"/>
    <mesh file="./geom/MPH8/convex_478.stl"/>
    <mesh file="./geom/MPH8/convex_479.stl"/>
    <mesh file="./geom/MPH8/convex_48.stl"/>
    <mesh file="./geom/MPH8/convex_480.stl"/>
    <mesh file="./geom/MPH8/convex_481.stl"/>
    <mesh file="./geom/MPH8/convex_482.stl"/>
    <mesh file="./geom/MPH8/convex_483.stl"/>
    <mesh file="./geom/MPH8/convex_484.stl"/>
    <mesh file="./geom/MPH8/convex_485.stl"/>
    <mesh file="./geom/MPH8/convex_486.stl"/>
    <mesh file="./geom/MPH8/convex_487.stl"/>
    <mesh file="./geom/MPH8/convex_488.stl"/>
    <mesh file="./geom/MPH8/convex_489.stl"/>
    <mesh file="./geom/MPH8/convex_49.stl"/>
    <mesh file="./geom/MPH8/convex_490.stl"/>
    <mesh file="./geom/MPH8/convex_491.stl"/>
    <mesh file="./geom/MPH8/convex_492.stl"/>
    <mesh file="./geom/MPH8/convex_493.stl"/>
    <mesh file="./geom/MPH8/convex_494.stl"/>
    <mesh file="./geom/MPH8/convex_495.stl"/>
    <mesh file="./geom/MPH8/convex_496.stl"/>
    <mesh file="./geom/MPH8/convex_497.stl"/>
    <mesh file="./geom/MPH8/convex_498.stl"/>
    <mesh file="./geom/MPH8/convex_499.stl"/>
    <mesh file="./geom/MPH8/convex_5.stl"/>
    <mesh file="./geom/MPH8/convex_50.stl"/>
    <mesh file="./geom/MPH8/convex_500.stl"/>
    <mesh file="./geom/MPH8/convex_501.stl"/>
    <mesh file="./geom/MPH8/convex_502.stl"/>
    <mesh file="./geom/MPH8/convex_503.stl"/>
    <mesh file="./geom/MPH8/convex_504.stl"/>
    <mesh file="./geom/MPH8/convex_505.stl"/>
    <mesh file="./geom/MPH8/convex_506.stl"/>
    <mesh file="./geom/MPH8/convex_507.stl"/>
    <mesh file="./geom/MPH8/convex_508.stl"/>
    <mesh file="./geom/MPH8/convex_509.stl"/>
    <mesh file="./geom/MPH8/convex_51.stl"/>
    <mesh file="./geom/MPH8/convex_510.stl"/>
    <mesh file="./geom/MPH8/convex_511.stl"/>
    <mesh file="./geom/MPH8/convex_512.stl"/>
    <mesh file="./geom/MPH8/convex_513.stl"/>
    <mesh file="./geom/MPH8/convex_514.stl"/>
    <mesh file="./geom/MPH8/convex_515.stl"/>
    <mesh file="./geom/MPH8/convex_516.stl"/>
    <mesh file="./geom/MPH8/convex_517.stl"/>
    <mesh file="./geom/MPH8/convex_518.stl"/>
    <mesh file="./geom/MPH8/convex_519.stl"/>
    <mesh file="./geom/MPH8/convex_52.stl"/>
    <mesh file="./geom/MPH8/convex_520.stl"/>
    <mesh file="./geom/MPH8/convex_521.stl"/>
    <mesh file="./geom/MPH8/convex_522.stl"/>
    <mesh file="./geom/MPH8/convex_523.stl"/>
    <mesh file="./geom/MPH8/convex_524.stl"/>
    <mesh file="./geom/MPH8/convex_525.stl"/>
    <mesh file="./geom/MPH8/convex_526.stl"/>
    <mesh file="./geom/MPH8/convex_527.stl"/>
    <mesh file="./geom/MPH8/convex_528.stl"/>
    <mesh file="./geom/MPH8/convex_529.stl"/>
    <mesh file="./geom/MPH8/convex_53.stl"/>
    <mesh file="./geom/MPH8/convex_530.stl"/>
    <mesh file="./geom/MPH8/convex_531.stl"/>
    <mesh file="./geom/MPH8/convex_532.stl"/>
    <mesh file="./geom/MPH8/convex_533.stl"/>
    <mesh file="./geom/MPH8/convex_534.stl"/>
    <mesh file="./geom/MPH8/convex_535.stl"/>
    <mesh file="./geom/MPH8/convex_536.stl"/>
    <mesh file="./geom/MPH8/convex_537.stl"/>
    <mesh file="./geom/MPH8/convex_538.stl"/>
    <mesh file="./geom/MPH8/convex_539.stl"/>
    <mesh file="./geom/MPH8/convex_54.stl"/>
    <mesh file="./geom/MPH8/convex_540.stl"/>
    <mesh file="./geom/MPH8/convex_541.stl"/>
    <mesh file="./geom/MPH8/convex_542.stl"/>
    <mesh file="./geom/MPH8/convex_543.stl"/>
    <mesh file="./geom/MPH8/convex_544.stl"/>
    <mesh file="./geom/MPH8/convex_545.stl"/>
    <mesh file="./geom/MPH8/convex_546.stl"/>
    <mesh file="./geom/MPH8/convex_547.stl"/>
    <mesh file="./geom/MPH8/convex_548.stl"/>
    <mesh file="./geom/MPH8/convex_549.stl"/>
    <mesh file="./geom/MPH8/convex_55.stl"/>
    <mesh file="./geom/MPH8/convex_550.stl"/>
    <mesh file="./geom/MPH8/convex_551.stl"/>
    <mesh file="./geom/MPH8/convex_552.stl"/>
    <mesh file="./geom/MPH8/convex_553.stl"/>
    <mesh file="./geom/MPH8/convex_554.stl"/>
    <mesh file="./geom/MPH8/convex_555.stl"/>
    <mesh file="./geom/MPH8/convex_556.stl"/>
    <mesh file="./geom/MPH8/convex_557.stl"/>
    <mesh file="./geom/MPH8/convex_558.stl"/>
    <mesh file="./geom/MPH8/convex_559.stl"/>
    <mesh file="./geom/MPH8/convex_56.stl"/>
    <mesh file="./geom/MPH8/convex_560.stl"/>
    <mesh file="./geom/MPH8/convex_561.stl"/>
    <mesh file="./geom/MPH8/convex_562.stl"/>
    <mesh file="./geom/MPH8/convex_563.stl"/>
    <mesh file="./geom/MPH8/convex_564.stl"/>
    <mesh file="./geom/MPH8/convex_565.stl"/>
    <mesh file="./geom/MPH8/convex_566.stl"/>
    <mesh file="./geom/MPH8/convex_567.stl"/>
    <mesh file="./geom/MPH8/convex_568.stl"/>
    <mesh file="./geom/MPH8/convex_569.stl"/>
    <mesh file="./geom/MPH8/convex_57.stl"/>
    <mesh file="./geom/MPH8/convex_570.stl"/>
    <mesh file="./geom/MPH8/convex_571.stl"/>
    <mesh file="./geom/MPH8/convex_572.stl"/>
    <mesh file="./geom/MPH8/convex_573.stl"/>
    <mesh file="./geom/MPH8/convex_574.stl"/>
    <mesh file="./geom/MPH8/convex_575.stl"/>
    <mesh file="./geom/MPH8/convex_576.stl"/>
    <mesh file="./geom/MPH8/convex_577.stl"/>
    <mesh file="./geom/MPH8/convex_578.stl"/>
    <mesh file="./geom/MPH8/convex_579.stl"/>
    <mesh file="./geom/MPH8/convex_58.stl"/>
    <mesh file="./geom/MPH8/convex_580.stl"/>
    <mesh file="./geom/MPH8/convex_581.stl"/>
    <mesh file="./geom/MPH8/convex_582.stl"/>
    <mesh file="./geom/MPH8/convex_583.stl"/>
    <mesh file="./geom/MPH8/convex_584.stl"/>
    <mesh file="./geom/MPH8/convex_585.stl"/>
    <mesh file="./geom/MPH8/convex_586.stl"/>
    <mesh file="./geom/MPH8/convex_587.stl"/>
    <mesh file="./geom/MPH8/convex_588.stl"/>
    <mesh file="./geom/MPH8/convex_589.stl"/>
    <mesh file="./geom/MPH8/convex_59.stl"/>
    <mesh file="./geom/MPH8/convex_590.stl"/>
    <mesh file="./geom/MPH8/convex_591.stl"/>
    <mesh file="./geom/MPH8/convex_592.stl"/>
    <mesh file="./geom/MPH8/convex_593.stl"/>
    <mesh file="./geom/MPH8/convex_594.stl"/>
    <mesh file="./geom/MPH8/convex_595.stl"/>
    <mesh file="./geom/MPH8/convex_596.stl"/>
    <mesh file="./geom/MPH8/convex_597.stl"/>
    <mesh file="./geom/MPH8/convex_598.stl"/>
    <mesh file="./geom/MPH8/convex_599.stl"/>
    <mesh file="./geom/MPH8/convex_6.stl"/>
    <mesh file="./geom/MPH8/convex_60.stl"/>
    <mesh file="./geom/MPH8/convex_600.stl"/>
    <mesh file="./geom/MPH8/convex_601.stl"/>
    <mesh file="./geom/MPH8/convex_602.stl"/>
    <mesh file="./geom/MPH8/convex_603.stl"/>
    <mesh file="./geom/MPH8/convex_604.stl"/>
    <mesh file="./geom/MPH8/convex_605.stl"/>
    <mesh file="./geom/MPH8/convex_606.stl"/>
    <mesh file="./geom/MPH8/convex_607.stl"/>
    <mesh file="./geom/MPH8/convex_608.stl"/>
    <mesh file="./geom/MPH8/convex_609.stl"/>
    <mesh file="./geom/MPH8/convex_61.stl"/>
    <mesh file="./geom/MPH8/convex_610.stl"/>
    <mesh file="./geom/MPH8/convex_611.stl"/>
    <mesh file="./geom/MPH8/convex_612.stl"/>
    <mesh file="./geom/MPH8/convex_613.stl"/>
    <mesh file="./geom/MPH8/convex_614.stl"/>
    <mesh file="./geom/MPH8/convex_615.stl"/>
    <mesh file="./geom/MPH8/convex_616.stl"/>
    <mesh file="./geom/MPH8/convex_617.stl"/>
    <mesh file="./geom/MPH8/convex_618.stl"/>
    <mesh file="./geom/MPH8/convex_619.stl"/>
    <mesh file="./geom/MPH8/convex_62.stl"/>
    <mesh file="./geom/MPH8/convex_620.stl"/>
    <mesh file="./geom/MPH8/convex_621.stl"/>
    <mesh file="./geom/MPH8/convex_622.stl"/>
    <mesh file="./geom/MPH8/convex_623.stl"/>
    <mesh file="./geom/MPH8/convex_624.stl"/>
    <mesh file="./geom/MPH8/convex_625.stl"/>
    <mesh file="./geom/MPH8/convex_626.stl"/>
    <mesh file="./geom/MPH8/convex_627.stl"/>
    <mesh file="./geom/MPH8/convex_628.stl"/>
    <mesh file="./geom/MPH8/convex_629.stl"/>
    <mesh file="./geom/MPH8/convex_63.stl"/>
    <mesh file="./geom/MPH8/convex_630.stl"/>
    <mesh file="./geom/MPH8/convex_631.stl"/>
    <mesh file="./geom/MPH8/convex_632.stl"/>
    <mesh file="./geom/MPH8/convex_633.stl"/>
    <mesh file="./geom/MPH8/convex_634.stl"/>
    <mesh file="./geom/MPH8/convex_635.stl"/>
    <mesh file="./geom/MPH8/convex_636.stl"/>
    <mesh file="./geom/MPH8/convex_637.stl"/>
    <mesh file="./geom/MPH8/convex_638.stl"/>
    <mesh file="./geom/MPH8/convex_639.stl"/>
    <mesh file="./geom/MPH8/convex_64.stl"/>
    <mesh file="./geom/MPH8/convex_640.stl"/>
    <mesh file="./geom/MPH8/convex_641.stl"/>
    <mesh file="./geom/MPH8/convex_642.stl"/>
    <mesh file="./geom/MPH8/convex_643.stl"/>
    <mesh file="./geom/MPH8/convex_644.stl"/>
    <mesh file="./geom/MPH8/convex_645.stl"/>
    <mesh file="./geom/MPH8/convex_646.stl"/>
    <mesh file="./geom/MPH8/convex_647.stl"/>
    <mesh file="./geom/MPH8/convex_648.stl"/>
    <mesh file="./geom/MPH8/convex_649.stl"/>
    <mesh file="./geom/MPH8/convex_65.stl"/>
    <mesh file="./geom/MPH8/convex_650.stl"/>
    <mesh file="./geom/MPH8/convex_651.stl"/>
    <mesh file="./geom/MPH8/convex_652.stl"/>
    <mesh file="./geom/MPH8/convex_653.stl"/>
    <mesh file="./geom/MPH8/convex_654.stl"/>
    <mesh file="./geom/MPH8/convex_655.stl"/>
    <mesh file="./geom/MPH8/convex_656.stl"/>
    <mesh file="./geom/MPH8/convex_657.stl"/>
    <mesh file="./geom/MPH8/convex_658.stl"/>
    <mesh file="./geom/MPH8/convex_659.stl"/>
    <mesh file="./geom/MPH8/convex_66.stl"/>
    <mesh file="./geom/MPH8/convex_660.stl"/>
    <mesh file="./geom/MPH8/convex_661.stl"/>
    <mesh file="./geom/MPH8/convex_67.stl"/>
    <mesh file="./geom/MPH8/convex_68.stl"/>
    <mesh file="./geom/MPH8/convex_69.stl"/>
    <mesh file="./geom/MPH8/convex_7.stl"/>
    <mesh file="./geom/MPH8/convex_70.stl"/>
    <mesh file="./geom/MPH8/convex_71.stl"/>
    <mesh file="./geom/MPH8/convex_72.stl"/>
    <mesh file="./geom/MPH8/convex_73.stl"/>
    <mesh file="./geom/MPH8/convex_74.stl"/>
    <mesh file="./geom/MPH8/convex_75.stl"/>
    <mesh file="./geom/MPH8/convex_76.stl"/>
    <mesh file="./geom/MPH8/convex_77.stl"/>
    <mesh file="./geom/MPH8/convex_78.stl"/>
    <mesh file="./geom/MPH8/convex_79.stl"/>
    <mesh file="./geom/MPH8/convex_8.stl"/>
    <mesh file="./geom/MPH8/convex_80.stl"/>
    <mesh file="./geom/MPH8/convex_81.stl"/>
    <mesh file="./geom/MPH8/convex_82.stl"/>
    <mesh file="./geom/MPH8/convex_83.stl"/>
    <mesh file="./geom/MPH8/convex_84.stl"/>
    <mesh file="./geom/MPH8/convex_85.stl"/>
    <mesh file="./geom/MPH8/convex_86.stl"/>
    <mesh file="./geom/MPH8/convex_87.stl"/>
    <mesh file="./geom/MPH8/convex_88.stl"/>
    <mesh file="./geom/MPH8/convex_89.stl"/>
    <mesh file="./geom/MPH8/convex_9.stl"/>
    <mesh file="./geom/MPH8/convex_90.stl"/>
    <mesh file="./geom/MPH8/convex_91.stl"/>
    <mesh file="./geom/MPH8/convex_92.stl"/>
    <mesh file="./geom/MPH8/convex_93.stl"/>
    <mesh file="./geom/MPH8/convex_94.stl"/>
    <mesh file="./geom/MPH8/convex_95.stl"/>
    <mesh file="./geom/MPH8/convex_96.stl"/>
    <mesh file="./geom/MPH8/convex_97.stl"/>
    <mesh file="./geom/MPH8/convex_98.stl"/>
    <mesh file="./geom/MPH8/convex_99.stl"/>
  </asset>
  <worldbody>
    <light cutoff="100" diffuse="1 1 1" dir="-0 0 -1.3" directional="true" exponent="1" pos="0 0 1.3" specular=".1 .1 .1"/>
    <geom condim="3" friction="1. .1 .1" material="grid" name="floor" pos="0 0 0" rgba=".8 .9 .8 1" size="100 100 .2" type="plane"/>
    <body name="Pelvis" pos="-0.0018 -0.2233 0.0282" quat="1.0000 0.0000 0.0000 0.0000">
      <joint name="Pelvis" pos="-0.0018 -0.2233 0.0282" limited="false" type="free" armature="0" damping="0" stiffness="0"/>
      <geom type="mesh" mesh="Pelvis" contype="0" conaffinity="1"/>
      <body name="L_Hip" pos="0.0677 -0.3147 0.0214" quat="1.0000 0.0000 0.0000 0.0000">
        <joint name="L_Hip_z" type="hinge" pos="0.0677 -0.3147 0.0214" axis="0.0000 0.0000 1.0000" range="-180.0000 180.0000"/>
        <joint name="L_Hip_y" type="hinge" pos="0.0677 -0.3147 0.0214" axis="0.0000 1.0000 0.0000" range="-180.0000 180.0000"/>
        <joint name="L_Hip_x" type="hinge" pos="0.0677 -0.3147 0.0214" axis="1.0000 0.0000 0.0000" range="-180.0000 180.0000"/>
        <geom type="mesh" mesh="L_Hip" contype="0" conaffinity="1"/>
        <body name="L_Knee" pos="0.1020 -0.6899 0.0169" quat="1.0000 0.0000 0.0000 0.0000">
          <joint name="L_Knee_z" type="hinge" pos="0.1020 -0.6899 0.0169" axis="0.0000 0.0000 1.0000" range="-180.0000 180.0000"/>
          <joint name="L_Knee_y" type="hinge" pos="0.1020 -0.6899 0.0169" axis="0.0000 1.0000 0.0000" range="-180.0000 180.0000"/>
          <joint name="L_Knee_x" type="hinge" pos="0.1020 -0.6899 0.0169" axis="1.0000 0.0000 0.0000" range="-180.0000 180.0000"/>
          <geom type="mesh" mesh="L_Knee" contype="0" conaffinity="1"/>
          <body name="L_Ankle" pos="0.0884 -1.0879 -0.0268" quat="1.0000 0.0000 0.0000 0.0000">
            <joint name="L_Ankle_z" type="hinge" pos="0.0884 -1.0879 -0.0268" axis="0.0000 0.0000 1.0000" range="-180.0000 180.0000"/>
            <joint name="L_Ankle_y" type="hinge" pos="0.0884 -1.0879 -0.0268" axis="0.0000 1.0000 0.0000" range="-180.0000 180.0000"/>
            <joint name="L_Ankle_x" type="hinge" pos="0.0884 -1.0879 -0.0268" axis="1.0000 0.0000 0.0000" range="-180.0000 180.0000"/>
            <geom type="mesh" mesh="L_Ankle" contype="0" conaffinity="1"/>
            <body name="L_Toe" pos="0.1148 -1.1437 0.0925" quat="1.0000 0.0000 0.0000 0.0000">
              <joint name="L_Toe_z" type="hinge" pos="0.1148 -1.1437 0.0925" axis="0.0000 0.0000 1.0000" range="-180.0000 180.0000"/>
              <joint name="L_Toe_y" type="hinge" pos="0.1148 -1.1437 0.0925" axis="0.0000 1.0000 0.0000" range="-180.0000 180.0000"/>
              <joint name="L_Toe_x" type="hinge" pos="0.1148 -1.1437 0.0925" axis="1.0000 0.0000 0.0000" range="-180.0000 180.0000"/>
              <geom type="mesh" mesh="L_Toe" contype="0" conaffinity="1"/>
            </body>
          </body>
        </body>
      </body>
      <body name="R_Hip" pos="-0.0695 -0.3139 0.0239" quat="1.0000 0.0000 0.0000 0.0000">
        <joint name="R_Hip_z" type="hinge" pos="-0.0695 -0.3139 0.0239" axis="0.0000 0.0000 1.0000" range="-180.0000 180.0000"/>
        <joint name="R_Hip_y" type="hinge" pos="-0.0695 -0.3139 0.0239" axis="0.0000 1.0000 0.0000" range="-180.0000 180.0000"/>
        <joint name="R_Hip_x" type="hinge" pos="-0.0695 -0.3139 0.0239" axis="1.0000 0.0000 0.0000" range="-180.0000 180.0000"/>
        <geom type="mesh" mesh="R_Hip" contype="0" conaffinity="1"/>
        <body name="R_Knee" pos="-0.1078 -0.6964 0.0150" quat="1.0000 0.0000 0.0000 0.0000">
          <joint name="R_Knee_z" type="hinge" pos="-0.1078 -0.6964 0.0150" axis="0.0000 0.0000 1.0000" range="-180.0000 180.0000"/>
          <joint name="R_Knee_y" type="hinge" pos="-0.1078 -0.6964 0.0150" axis="0.0000 1.0000 0.0000" range="-180.0000 180.0000"/>
          <joint name="R_Knee_x" type="hinge" pos="-0.1078 -0.6964 0.0150" axis="1.0000 0.0000 0.0000" range="-180.0000 180.0000"/>
          <geom type="mesh" mesh="R_Knee" contype="0" conaffinity="1"/>
          <body name="R_Ankle" pos="-0.0920 -1.0948 -0.0273" quat="1.0000 0.0000 0.0000 0.0000">
            <joint name="R_Ankle_z" type="hinge" pos="-0.0920 -1.0948 -0.0273" axis="0.0000 0.0000 1.0000" range="-180.0000 180.0000"/>
            <joint name="R_Ankle_y" type="hinge" pos="-0.0920 -1.0948 -0.0273" axis="0.0000 1.0000 0.0000" range="-180.0000 180.0000"/>
            <joint name="R_Ankle_x" type="hinge" pos="-0.0920 -1.0948 -0.0273" axis="1.0000 0.0000 0.0000" range="-180.0000 180.0000"/>
            <geom type="mesh" mesh="R_Ankle" contype="0" conaffinity="1"/>
            <body name="R_Toe" pos="-0.1174 -1.1430 0.0961" quat="1.0000 0.0000 0.0000 0.0000">
              <joint name="R_Toe_z" type="hinge" pos="-0.1174 -1.1430 0.0961" axis="0.0000 0.0000 1.0000" range="-180.0000 180.0000"/>
              <joint name="R_Toe_y" type="hinge" pos="-0.1174 -1.1430 0.0961" axis="0.0000 1.0000 0.0000" range="-180.0000 180.0000"/>
              <joint name="R_Toe_x" type="hinge" pos="-0.1174 -1.1430 0.0961" axis="1.0000 0.0000 0.0000" range="-180.0000 180.0000"/>
              <geom type="mesh" mesh="R_Toe" contype="0" conaffinity="1"/>
            </body>
          </body>
        </body>
      </body>
      <body name="Torso" pos="-0.0043 -0.1144 0.0015" quat="1.0000 0.0000 0.0000 0.0000">
        <joint name="Torso_z" type="hinge" pos="-0.0043 -0.1144 0.0015" axis="0.0000 0.0000 1.0000" range="-180.0000 180.0000"/>
        <joint name="Torso_y" type="hinge" pos="-0.0043 -0.1144 0.0015" axis="0.0000 1.0000 0.0000" range="-180.0000 180.0000"/>
        <joint name="Torso_x" type="hinge" pos="-0.0043 -0.1144 0.0015" axis="1.0000 0.0000 0.0000" range="-180.0000 180.0000"/>
        <geom type="mesh" mesh="Torso" contype="0" conaffinity="1"/>
        <body name="Spine" pos="0.0012 0.0208 0.0026" quat="1.0000 0.0000 0.0000 0.0000">
          <joint name="Spine_z" type="hinge" pos="0.0012 0.0208 0.0026" axis="0.0000 0.0000 1.0000" range="-180.0000 180.0000"/>
          <joint name="Spine_y" type="hinge" pos="0.0012 0.0208 0.0026" axis="0.0000 1.0000 0.0000" range="-180.0000 180.0000"/>
          <joint name="Spine_x" type="hinge" pos="0.0012 0.0208 0.0026" axis="1.0000 0.0000 0.0000" range="-180.0000 180.0000"/>
          <geom type="mesh" mesh="Spine" contype="0" conaffinity="1"/>
          <body name="Chest" pos="0.0026 0.0737 0.0280" quat="1.0000 0.0000 0.0000 0.0000">
            <joint name="Chest_z" type="hinge" pos="0.0026 0.0737 0.0280" axis="0.0000 0.0000 1.0000" range="-180.0000 180.0000"/>
            <joint name="Chest_y" type="hinge" pos="0.0026 0.0737 0.0280" axis="0.0000 1.0000 0.0000" range="-180.0000 180.0000"/>
            <joint name="Chest_x" type="hinge" pos="0.0026 0.0737 0.0280" axis="1.0000 0.0000 0.0000" range="-180.0000 180.0000"/>
            <geom type="mesh" mesh="Chest" contype="0" conaffinity="1"/>
            <body name="Neck" pos="-0.0002 0.2876 -0.0148" quat="1.0000 0.0000 0.0000 0.0000">
              <joint name="Neck_z" type="hinge" pos="-0.0002 0.2876 -0.0148" axis="0.0000 0.0000 1.0000" range="-180.0000 180.0000"/>
              <joint name="Neck_y" type="hinge" pos="-0.0002 0.2876 -0.0148" axis="0.0000 1.0000 0.0000" range="-180.0000 180.0000"/>
              <joint name="Neck_x" type="hinge" pos="-0.0002 0.2876 -0.0148" axis="1.0000 0.0000 0.0000" range="-180.0000 180.0000"/>
              <geom type="mesh" mesh="Neck" contype="0" conaffinity="1"/>
              <body name="Head" pos="0.0050 0.3526 0.0365" quat="1.0000 0.0000 0.0000 0.0000">
                <joint name="Head_z" type="hinge" pos="0.0050 0.3526 0.0365" axis="0.0000 0.0000 1.0000" range="-180.0000 180.0000"/>
                <joint name="Head_y" type="hinge" pos="0.0050 0.3526 0.0365" axis="0.0000 1.0000 0.0000" range="-180.0000 180.0000"/>
                <joint name="Head_x" type="hinge" pos="0.0050 0.3526 0.0365" axis="1.0000 0.0000 0.0000" range="-180.0000 180.0000"/>
                <geom type="mesh" mesh="Head" contype="0" conaffinity="1"/>
              </body>
            </body>
            <body name="L_Thorax" pos="0.0815 0.1955 -0.0060" quat="1.0000 0.0000 0.0000 0.0000">
              <joint name="L_Thorax_z" type="hinge" pos="0.0815 0.1955 -0.0060" axis="0.0000 0.0000 1.0000" range="-180.0000 180.0000"/>
              <joint name="L_Thorax_y" type="hinge" pos="0.0815 0.1955 -0.0060" axis="0.0000 1.0000 0.0000" range="-180.0000 180.0000"/>
              <joint name="L_Thorax_x" type="hinge" pos="0.0815 0.1955 -0.0060" axis="1.0000 0.0000 0.0000" range="-180.0000 180.0000"/>
              <geom type="mesh" mesh="L_Thorax" contype="0" conaffinity="1"/>
              <body name="L_Shoulder" pos="0.1724 0.2260 -0.0149" quat="1.0000 0.0000 0.0000 0.0000">
                <joint name="L_Shoulder_z" type="hinge" pos="0.1724 0.2260 -0.0149" axis="0.0000 0.0000 1.0000" range="-180.0000 180.0000"/>
                <joint name="L_Shoulder_y" type="hinge" pos="0.1724 0.2260 -0.0149" axis="0.0000 1.0000 0.0000" range="-180.0000 180.0000"/>
                <joint name="L_Shoulder_x" type="hinge" pos="0.1724 0.2260 -0.0149" axis="1.0000 0.0000 0.0000" range="-180.0000 180.0000"/>
                <geom type="mesh" mesh="L_Shoulder" contype="0" conaffinity="1"/>
                <body name="L_Elbow" pos="0.4320 0.2132 -0.0424" quat="1.0000 0.0000 0.0000 0.0000">
                  <joint name="L_Elbow_z" type="hinge" pos="0.4320 0.2132 -0.0424" axis="0.0000 0.0000 1.0000" range="-720.0000 720.0000"/>
                  <joint name="L_Elbow_y" type="hinge" pos="0.4320 0.2132 -0.0424" axis="0.0000 1.0000 0.0000" range="-720.0000 720.0000"/>
                  <joint name="L_Elbow_x" type="hinge" pos="0.4320 0.2132 -0.0424" axis="1.0000 0.0000 0.0000" range="-720.0000 720.0000"/>
                  <geom type="mesh" mesh="L_Elbow" contype="0" conaffinity="1"/>
                  <body name="L_Wrist" pos="0.6813 0.2222 -0.0435" quat="1.0000 0.0000 0.0000 0.0000">
                    <joint name="L_Wrist_z" type="hinge" pos="0.6813 0.2222 -0.0435" axis="0.0000 0.0000 1.0000" range="-180.0000 180.0000"/>
                    <joint name="L_Wrist_y" type="hinge" pos="0.6813 0.2222 -0.0435" axis="0.0000 1.0000 0.0000" range="-180.0000 180.0000"/>
                    <joint name="L_Wrist_x" type="hinge" pos="0.6813 0.2222 -0.0435" axis="1.0000 0.0000 0.0000" range="-180.0000 180.0000"/>
                    <geom type="mesh" mesh="L_Wrist" contype="0" conaffinity="1"/>
                    <body name="L_Hand" pos="0.7653 0.2140 -0.0585" quat="1.0000 0.0000 0.0000 0.0000">
                      <joint name="L_Hand_z" type="hinge" pos="0.7653 0.2140 -0.0585" axis="0.0000 0.0000 1.0000" range="-180.0000 180.0000"/>
                      <joint name="L_Hand_y" type="hinge" pos="0.7653 0.2140 -0.0585" axis="0.0000 1.0000 0.0000" range="-180.0000 180.0000"/>
                      <joint name="L_Hand_x" type="hinge" pos="0.7653 0.2140 -0.0585" axis="1.0000 0.0000 0.0000" range="-180.0000 180.0000"/>
                      <geom type="mesh" mesh="L_Hand" contype="0" conaffinity="1"/>
                    </body>
                  </body>
                </body>
              </body>
            </body>
            <body name="R_Thorax" pos="-0.0791 0.1926 -0.0106" quat="1.0000 0.0000 0.0000 0.0000">
              <joint name="R_Thorax_z" type="hinge" pos="-0.0791 0.1926 -0.0106" axis="0.0000 0.0000 1.0000" range="-180.0000 180.0000"/>
              <joint name="R_Thorax_y" type="hinge" pos="-0.0791 0.1926 -0.0106" axis="0.0000 1.0000 0.0000" range="-180.0000 180.0000"/>
              <joint name="R_Thorax_x" type="hinge" pos="-0.0791 0.1926 -0.0106" axis="1.0000 0.0000 0.0000" range="-180.0000 180.0000"/>
              <geom type="mesh" mesh="R_Thorax" contype="0" conaffinity="1"/>
              <body name="R_Shoulder" pos="-0.1752 0.2251 -0.0197" quat="1.0000 0.0000 0.0000 0.0000">
                <joint name="R_Shoulder_z" type="hinge" pos="-0.1752 0.2251 -0.0197" axis="0.0000 0.0000 1.0000" range="-180.0000 180.0000"/>
                <joint name="R_Shoulder_y" type="hinge" pos="-0.1752 0.2251 -0.0197" axis="0.0000 1.0000 0.0000" range="-180.0000 180.0000"/>
                <joint name="R_Shoulder_x" type="hinge" pos="-0.1752 0.2251 -0.0197" axis="1.0000 0.0000 0.0000" range="-180.0000 180.0000"/>
                <geom type="mesh" mesh="R_Shoulder" contype="0" conaffinity="1"/>
                <body name="R_Elbow" pos="-0.4289 0.2118 -0.0411" quat="1.0000 0.0000 0.0000 0.0000">
                  <joint name="R_Elbow_z" type="hinge" pos="-0.4289 0.2118 -0.0411" axis="0.0000 0.0000 1.0000" range="-720.0000 720.0000"/>
                  <joint name="R_Elbow_y" type="hinge" pos="-0.4289 0.2118 -0.0411" axis="0.0000 1.0000 0.0000" range="-720.0000 720.0000"/>
                  <joint name="R_Elbow_x" type="hinge" pos="-0.4289 0.2118 -0.0411" axis="1.0000 0.0000 0.0000" range="-720.0000 720.0000"/>
                  <geom type="mesh" mesh="R_Elbow" contype="0" conaffinity="1"/>
                  <body name="R_Wrist" pos="-0.6842 0.2196 -0.0467" quat="1.0000 0.0000 0.0000 0.0000">
                    <joint name="R_Wrist_z" type="hinge" pos="-0.6842 0.2196 -0.0467" axis="0.0000 0.0000 1.0000" range="-180.0000 180.0000"/>
                    <joint name="R_Wrist_y" type="hinge" pos="-0.6842 0.2196 -0.0467" axis="0.0000 1.0000 0.0000" range="-180.0000 180.0000"/>
                    <joint name="R_Wrist_x" type="hinge" pos="-0.6842 0.2196 -0.0467" axis="1.0000 0.0000 0.0000" range="-180.0000 180.0000"/>
                    <geom type="mesh" mesh="R_Wrist" contype="0" conaffinity="1"/>
                    <body name="R_Hand" pos="-0.7688 0.2134 -0.0570" quat="1.0000 0.0000 0.0000 0.0000">
                      <joint name="R_Hand_z" type="hinge" pos="-0.7688 0.2134 -0.0570" axis="0.0000 0.0000 1.0000" range="-180.0000 180.0000"/>
                      <joint name="R_Hand_y" type="hinge" pos="-0.7688 0.2134 -0.0570" axis="0.0000 1.0000 0.0000" range="-180.0000 180.0000"/>
                      <joint name="R_Hand_x" type="hinge" pos="-0.7688 0.2134 -0.0570" axis="1.0000 0.0000 0.0000" range="-180.0000 180.0000"/>
                      <geom type="mesh" mesh="R_Hand" contype="0" conaffinity="1"/>
                    </body>
                  </body>
                </body>
              </body>
            </body>
          </body>
        </body>
      </body>
    </body>
    
    <body>
      <geom name="scene0" type="mesh" mesh="convex_0" rgba="1 0 0 1.0" pos="0 0 0.4" friction="1. .1 .1"/>
      <geom name="scene1" type="mesh" mesh="convex_1" rgba="1 0 0 1.0" pos="0 0 0.4" friction="1. .1 .1"/>
      <geom name="scene2" type="mesh" mesh="convex_10" rgba="1 0 0 1.0" pos="0 0 0.4" friction="1. .1 .1"/>
      <geom name="scene3" type="mesh" mesh="convex_100" rgba="1 0 0 1.0" pos="0 0 0.4" friction="1. .1 .1"/>
      <geom name="scene4" type="mesh" mesh="convex_101" rgba="1 0 0 1.0" pos="0 0 0.4" friction="1. .1 .1"/>
      <geom name="scene5" type="mesh" mesh="convex_102" rgba="1 0 0 1.0" pos="0 0 0.4" friction="1. .1 .1"/>
      <geom name="scene6" type="mesh" mesh="convex_103" rgba="1 0 0 1.0" pos="0 0 0.4" friction="1. .1 .1"/>
      <geom name="scene7" type="mesh" mesh="convex_104" rgba="1 0 0 1.0" pos="0 0 0.4" friction="1. .1 .1"/>
      <geom name="scene8" type="mesh" mesh="convex_105" rgba="1 0 0 1.0" pos="0 0 0.4" friction="1. .1 .1"/>
      <geom name="scene9" type="mesh" mesh="convex_106" rgba="1 0 0 1.0" pos="0 0 0.4" friction="1. .1 .1"/>
      <geom name="scene10" type="mesh" mesh="convex_107" rgba="1 0 0 1.0" pos="0 0 0.4" friction="1. .1 .1"/>
      <geom name="scene11" type="mesh" mesh="convex_108" rgba="1 0 0 1.0" pos="0 0 0.4" friction="1. .1 .1"/>
      <geom name="scene12" type="mesh" mesh="convex_109" rgba="1 0 0 1.0" pos="0 0 0.4" friction="1. .1 .1"/>
      <geom name="scene13" type="mesh" mesh="convex_11" rgba="1 0 0 1.0" pos="0 0 0.4" friction="1. .1 .1"/>
      <geom name="scene14" type="mesh" mesh="convex_110" rgba="1 0 0 1.0" pos="0 0 0.4" friction="1. .1 .1"/>
      <geom name="scene15" type="mesh" mesh="convex_111" rgba="1 0 0 1.0" pos="0 0 0.4" friction="1. .1 .1"/>
      <geom name="scene16" type="mesh" mesh="convex_112" rgba="1 0 0 1.0" pos="0 0 0.4" friction="1. .1 .1"/>
      <geom name="scene17" type="mesh" mesh="convex_113" rgba="1 0 0 1.0" pos="0 0 0.4" friction="1. .1 .1"/>
      <geom name="scene18" type="mesh" mesh="convex_114" rgba="1 0 0 1.0" pos="0 0 0.4" friction="1. .1 .1"/>
      <geom name="scene19" type="mesh" mesh="convex_115" rgba="1 0 0 1.0" pos="0 0 0.4" friction="1. .1 .1"/>
      <geom name="scene20" type="mesh" mesh="convex_116" rgba="1 0 0 1.0" pos="0 0 0.4" friction="1. .1 .1"/>
      <geom name="scene21" type="mesh" mesh="convex_117" rgba="1 0 0 1.0" pos="0 0 0.4" friction="1. .1 .1"/>
      <geom name="scene22" type="mesh" mesh="convex_118" rgba="1 0 0 1.0" pos="0 0 0.4" friction="1. .1 .1"/>
      <geom name="scene23" type="mesh" mesh="convex_119" rgba="1 0 0 1.0" pos="0 0 0.4" friction="1. .1 .1"/>
      <geom name="scene24" type="mesh" mesh="convex_12" rgba="1 0 0 1.0" pos="0 0 0.4" friction="1. .1 .1"/>
      <geom name="scene25" type="mesh" mesh="convex_120" rgba="1 0 0 1.0" pos="0 0 0.4" friction="1. .1 .1"/>
      <geom name="scene26" type="mesh" mesh="convex_121" rgba="1 0 0 1.0" pos="0 0 0.4" friction="1. .1 .1"/>
      <geom name="scene27" type="mesh" mesh="convex_122" rgba="1 0 0 1.0" pos="0 0 0.4" friction="1. .1 .1"/>
      <geom name="scene28" type="mesh" mesh="convex_123" rgba="1 0 0 1.0" pos="0 0 0.4" friction="1. .1 .1"/>
      <geom name="scene29" type="mesh" mesh="convex_124" rgba="1 0 0 1.0" pos="0 0 0.4" friction="1. .1 .1"/>
      <geom name="scene30" type="mesh" mesh="convex_125" rgba="1 0 0 1.0" pos="0 0 0.4" friction="1. .1 .1"/>
      <geom name="scene31" type="mesh" mesh="convex_126" rgba="1 0 0 1.0" pos="0 0 0.4" friction="1. .1 .1"/>
      <geom name="scene32" type="mesh" mesh="convex_127" rgba="1 0 0 1.0" pos="0 0 0.4" friction="1. .1 .1"/>
      <geom name="scene33" type="mesh" mesh="convex_128" rgba="1 0 0 1.0" pos="0 0 0.4" friction="1. .1 .1"/>
      <geom name="scene34" type="mesh" mesh="convex_129" rgba="1 0 0 1.0" pos="0 0 0.4" friction="1. .1 .1"/>
      <geom name="scene35" type="mesh" mesh="convex_13" rgba="1 0 0 1.0" pos="0 0 0.4" friction="1. .1 .1"/>
      <geom name="scene36" type="mesh" mesh="convex_130" rgba="1 0 0 1.0" pos="0 0 0.4" friction="1. .1 .1"/>
      <geom name="scene37" type="mesh" mesh="convex_131" rgba="1 0 0 1.0" pos="0 0 0.4" friction="1. .1 .1"/>
      <geom name="scene38" type="mesh" mesh="convex_132" rgba="1 0 0 1.0" pos="0 0 0.4" friction="1. .1 .1"/>
      <geom name="scene39" type="mesh" mesh="convex_133" rgba="1 0 0 1.0" pos="0 0 0.4" friction="1. .1 .1"/>
      <geom name="scene40" type="mesh" mesh="convex_134" rgba="1 0 0 1.0" pos="0 0 0.4" friction="1. .1 .1"/>
      <geom name="scene41" type="mesh" mesh="convex_135" rgba="1 0 0 1.0" pos="0 0 0.4" friction="1. .1 .1"/>
      <geom name="scene42" type="mesh" mesh="convex_136" rgba="1 0 0 1.0" pos="0 0 0.4" friction="1. .1 .1"/>
      <geom name="scene43" type="mesh" mesh="convex_137" rgba="1 0 0 1.0" pos="0 0 0.4" friction="1. .1 .1"/>
      <geom name="scene44" type="mesh" mesh="convex_138" rgba="1 0 0 1.0" pos="0 0 0.4" friction="1. .1 .1"/>
      <geom name="scene45" type="mesh" mesh="convex_139" rgba="1 0 0 1.0" pos="0 0 0.4" friction="1. .1 .1"/>
      <geom name="scene46" type="mesh" mesh="convex_14" rgba="1 0 0 1.0" pos="0 0 0.4" friction="1. .1 .1"/>
      <geom name="scene47" type="mesh" mesh="convex_140" rgba="1 0 0 1.0" pos="0 0 0.4" friction="1. .1 .1"/>
      <geom name="scene48" type="mesh" mesh="convex_141" rgba="1 0 0 1.0" pos="0 0 0.4" friction="1. .1 .1"/>
      <geom name="scene49" type="mesh" mesh="convex_142" rgba="1 0 0 1.0" pos="0 0 0.4" friction="1. .1 .1"/>
      <geom name="scene50" type="mesh" mesh="convex_143" rgba="1 0 0 1.0" pos="0 0 0.4" friction="1. .1 .1"/>
      <geom name="scene51" type="mesh" mesh="convex_144" rgba="1 0 0 1.0" pos="0 0 0.4" friction="1. .1 .1"/>
      <geom name="scene52" type="mesh" mesh="convex_145" rgba="1 0 0 1.0" pos="0 0 0.4" friction="1. .1 .1"/>
      <geom name="scene53" type="mesh" mesh="convex_146" rgba="1 0 0 1.0" pos="0 0 0.4" friction="1. .1 .1"/>
      <geom name="scene54" type="mesh" mesh="convex_147" rgba="1 0 0 1.0" pos="0 0 0.4" friction="1. .1 .1"/>
      <geom name="scene55" type="mesh" mesh="convex_148" rgba="1 0 0 1.0" pos="0 0 0.4" friction="1. .1 .1"/>
      <geom name="scene56" type="mesh" mesh="convex_149" rgba="1 0 0 1.0" pos="0 0 0.4" friction="1. .1 .1"/>
      <geom name="scene57" type="mesh" mesh="convex_15" rgba="1 0 0 1.0" pos="0 0 0.4" friction="1. .1 .1"/>
      <geom name="scene58" type="mesh" mesh="convex_150" rgba="1 0 0 1.0" pos="0 0 0.4" friction="1. .1 .1"/>
      <geom name="scene59" type="mesh" mesh="convex_151" rgba="1 0 0 1.0" pos="0 0 0.4" friction="1. .1 .1"/>
      <geom name="scene60" type="mesh" mesh="convex_152" rgba="1 0 0 1.0" pos="0 0 0.4" friction="1. .1 .1"/>
      <geom name="scene61" type="mesh" mesh="convex_153" rgba="1 0 0 1.0" pos="0 0 0.4" friction="1. .1 .1"/>
      <geom name="scene62" type="mesh" mesh="convex_154" rgba="1 0 0 1.0" pos="0 0 0.4" friction="1. .1 .1"/>
      <geom name="scene63" type="mesh" mesh="convex_155" rgba="1 0 0 1.0" pos="0 0 0.4" friction="1. .1 .1"/>
      <geom name="scene64" type="mesh" mesh="convex_156" rgba="1 0 0 1.0" pos="0 0 0.4" friction="1. .1 .1"/>
      <geom name="scene65" type="mesh" mesh="convex_157" rgba="1 0 0 1.0" pos="0 0 0.4" friction="1. .1 .1"/>
      <geom name="scene66" type="mesh" mesh="convex_158" rgba="1 0 0 1.0" pos="0 0 0.4" friction="1. .1 .1"/>
      <geom name="scene67" type="mesh" mesh="convex_159" rgba="1 0 0 1.0" pos="0 0 0.4" friction="1. .1 .1"/>
      <geom name="scene68" type="mesh" mesh="convex_16" rgba="1 0 0 1.0" pos="0 0 0.4" friction="1. .1 .1"/>
      <geom name="scene69" type="mesh" mesh="convex_160" rgba="1 0 0 1.0" pos="0 0 0.4" friction="1. .1 .1"/>
      <geom name="scene70" type="mesh" mesh="convex_161" rgba="1 0 0 1.0" pos="0 0 0.4" friction="1. .1 .1"/>
      <geom name="scene71" type="mesh" mesh="convex_162" rgba="1 0 0 1.0" pos="0 0 0.4" friction="1. .1 .1"/>
      <geom name="scene72" type="mesh" mesh="convex_163" rgba="1 0 0 1.0" pos="0 0 0.4" friction="1. .1 .1"/>
      <geom name="scene73" type="mesh" mesh="convex_164" rgba="1 0 0 1.0" pos="0 0 0.4" friction="1. .1 .1"/>
      <geom name="scene74" type="mesh" mesh="convex_165" rgba="1 0 0 1.0" pos="0 0 0.4" friction="1. .1 .1"/>
      <geom name="scene75" type="mesh" mesh="convex_166" rgba="1 0 0 1.0" pos="0 0 0.4" friction="1. .1 .1"/>
      <geom name="scene76" type="mesh" mesh="convex_167" rgba="1 0 0 1.0" pos="0 0 0.4" friction="1. .1 .1"/>
      <geom name="scene77" type="mesh" mesh="convex_168" rgba="1 0 0 1.0" pos="0 0 0.4" friction="1. .1 .1"/>
      <geom name="scene78" type="mesh" mesh="convex_169" rgba="1 0 0 1.0" pos="0 0 0.4" friction="1. .1 .1"/>
      <geom name="scene79" type="mesh" mesh="convex_17" rgba="1 0 0 1.0" pos="0 0 0.4" friction="1. .1 .1"/>
      <geom name="scene80" type="mesh" mesh="convex_170" rgba="1 0 0 1.0" pos="0 0 0.4" friction="1. .1 .1"/>
      <geom name="scene81" type="mesh" mesh="convex_171" rgba="1 0 0 1.0" pos="0 0 0.4" friction="1. .1 .1"/>
      <geom name="scene82" type="mesh" mesh="convex_172" rgba="1 0 0 1.0" pos="0 0 0.4" friction="1. .1 .1"/>
      <geom name="scene83" type="mesh" mesh="convex_173" rgba="1 0 0 1.0" pos="0 0 0.4" friction="1. .1 .1"/>
      <geom name="scene84" type="mesh" mesh="convex_174" rgba="1 0 0 1.0" pos="0 0 0.4" friction="1. .1 .1"/>
      <geom name="scene85" type="mesh" mesh="convex_175" rgba="1 0 0 1.0" pos="0 0 0.4" friction="1. .1 .1"/>
      <geom name="scene86" type="mesh" mesh="convex_176" rgba="1 0 0 1.0" pos="0 0 0.4" friction="1. .1 .1"/>
      <geom name="scene87" type="mesh" mesh="convex_177" rgba="1 0 0 1.0" pos="0 0 0.4" friction="1. .1 .1"/>
      <geom name="scene88" type="mesh" mesh="convex_178" rgba="1 0 0 1.0" pos="0 0 0.4" friction="1. .1 .1"/>
      <geom name="scene89" type="mesh" mesh="convex_179" rgba="1 0 0 1.0" pos="0 0 0.4" friction="1. .1 .1"/>
      <geom name="scene90" type="mesh" mesh="convex_18" rgba="1 0 0 1.0" pos="0 0 0.4" friction="1. .1 .1"/>
      <geom name="scene91" type="mesh" mesh="convex_180" rgba="1 0 0 1.0" pos="0 0 0.4" friction="1. .1 .1"/>
      <geom name="scene92" type="mesh" mesh="convex_181" rgba="1 0 0 1.0" pos="0 0 0.4" friction="1. .1 .1"/>
      <geom name="scene93" type="mesh" mesh="convex_182" rgba="1 0 0 1.0" pos="0 0 0.4" friction="1. .1 .1"/>
      <geom name="scene94" type="mesh" mesh="convex_183" rgba="1 0 0 1.0" pos="0 0 0.4" friction="1. .1 .1"/>
      <geom name="scene95" type="mesh" mesh="convex_184" rgba="1 0 0 1.0" pos="0 0 0.4" friction="1. .1 .1"/>
      <geom name="scene96" type="mesh" mesh="convex_185" rgba="1 0 0 1.0" pos="0 0 0.4" friction="1. .1 .1"/>
      <geom name="scene97" type="mesh" mesh="convex_186" rgba="1 0 0 1.0" pos="0 0 0.4" friction="1. .1 .1"/>
      <geom name="scene98" type="mesh" mesh="convex_187" rgba="1 0 0 1.0" pos="0 0 0.4" friction="1. .1 .1"/>
      <geom name="scene99" type="mesh" mesh="convex_188" rgba="1 0 0 1.0" pos="0 0 0.4" friction="1. .1 .1"/>
      <geom name="scene100" type="mesh" mesh="convex_189" rgba="1 0 0 1.0" pos="0 0 0.4" friction="1. .1 .1"/>
      <geom name="scene101" type="mesh" mesh="convex_19" rgba="1 0 0 1.0" pos="0 0 0.4" friction="1. .1 .1"/>
      <geom name="scene102" type="mesh" mesh="convex_190" rgba="1 0 0 1.0" pos="0 0 0.4" friction="1. .1 .1"/>
      <geom name="scene103" type="mesh" mesh="convex_191" rgba="1 0 0 1.0" pos="0 0 0.4" friction="1. .1 .1"/>
      <geom name="scene104" type="mesh" mesh="convex_192" rgba="1 0 0 1.0" pos="0 0 0.4" friction="1. .1 .1"/>
      <geom name="scene105" type="mesh" mesh="convex_193" rgba="1 0 0 1.0" pos="0 0 0.4" friction="1. .1 .1"/>
      <geom name="scene106" type="mesh" mesh="convex_194" rgba="1 0 0 1.0" pos="0 0 0.4" friction="1. .1 .1"/>
      <geom name="scene107" type="mesh" mesh="convex_195" rgba="1 0 0 1.0" pos="0 0 0.4" friction="1. .1 .1"/>
      <geom name="scene108" type="mesh" mesh="convex_196" rgba="1 0 0 1.0" pos="0 0 0.4" friction="1. .1 .1"/>
      <geom name="scene109" type="mesh" mesh="convex_197" rgba="1 0 0 1.0" pos="0 0 0.4" friction="1. .1 .1"/>
      <geom name="scene110" type="mesh" mesh="convex_198" rgba="1 0 0 1.0" pos="0 0 0.4" friction="1. .1 .1"/>
      <geom name="scene111" type="mesh" mesh="convex_199" rgba="1 0 0 1.0" pos="0 0 0.4" friction="1. .1 .1"/>
      <geom name="scene112" type="mesh" mesh="convex_2" rgba="1 0 0 1.0" pos="0 0 0.4" friction="1. .1 .1"/>
      <geom name="scene113" type="mesh" mesh="convex_20" rgba="1 0 0 1.0" pos="0 0 0.4" friction="1. .1 .1"/>
      <geom name="scene114" type="mesh" mesh="convex_200" rgba="1 0 0 1.0" pos="0 0 0.4" friction="1. .1 .1"/>
      <geom name="scene115" type="mesh" mesh="convex_201" rgba="1 0 0 1.0" pos="0 0 0.4" friction="1. .1 .1"/>
      <geom name="scene116" type="mesh" mesh="convex_202" rgba="1 0 0 1.0" pos="0 0 0.4" friction="1. .1 .1"/>
      <geom name="scene117" type="mesh" mesh="convex_203" rgba="1 0 0 1.0" pos="0 0 0.4" friction="1. .1 .1"/>
      <geom name="scene118" type="mesh" mesh="convex_204" rgba="1 0 0 1.0" pos="0 0 0.4" friction="1. .1 .1"/>
      <geom name="scene119" type="mesh" mesh="convex_205" rgba="1 0 0 1.0" pos="0 0 0.4" friction="1. .1 .1"/>
      <geom name="scene120" type="mesh" mesh="convex_206" rgba="1 0 0 1.0" pos="0 0 0.4" friction="1. .1 .1"/>
      <geom name="scene121" type="mesh" mesh="convex_207" rgba="1 0 0 1.0" pos="0 0 0.4" friction="1. .1 .1"/>
      <geom name="scene122" type="mesh" mesh="convex_208" rgba="1 0 0 1.0" pos="0 0 0.4" friction="1. .1 .1"/>
      <geom name="scene123" type="mesh" mesh="convex_209" rgba="1 0 0 1.0" pos="0 0 0.4" friction="1. .1 .1"/>
      <geom name="scene124" type="mesh" mesh="convex_21" rgba="1 0 0 1.0" pos="0 0 0.4" friction="1. .1 .1"/>
      <geom name="scene125" type="mesh" mesh="convex_210" rgba="1 0 0 1.0" pos="0 0 0.4" friction="1. .1 .1"/>
      <geom name="scene126" type="mesh" mesh="convex_211" rgba="1 0 0 1.0" pos="0 0 0.4" friction="1. .1 .1"/>
      <geom name="scene127" type="mesh" mesh="convex_212" rgba="1 0 0 1.0" pos="0 0 0.4" friction="1. .1 .1"/>
      <geom name="scene128" type="mesh" mesh="convex_213" rgba="1 0 0 1.0" pos="0 0 0.4" friction="1. .1 .1"/>
      <geom name="scene129" type="mesh" mesh="convex_214" rgba="1 0 0 1.0" pos="0 0 0.4" friction="1. .1 .1"/>
      <geom name="scene130" type="mesh" mesh="convex_215" rgba="1 0 0 1.0" pos="0 0 0.4" friction="1. .1 .1"/>
      <geom name="scene131" type="mesh" mesh="convex_216" rgba="1 0 0 1.0" pos="0 0 0.4" friction="1. .1 .1"/>
      <geom name="scene132" type="mesh" mesh="convex_217" rgba="1 0 0 1.0" pos="0 0 0.4" friction="1. .1 .1"/>
      <geom name="scene133" type="mesh" mesh="convex_218" rgba="1 0 0 1.0" pos="0 0 0.4" friction="1. .1 .1"/>
      <geom name="scene134" type="mesh" mesh="convex_219" rgba="1 0 0 1.0" pos="0 0 0.4" friction="1. .1 .1"/>
      <geom name="scene135" type="mesh" mesh="convex_22" rgba="1 0 0 1.0" pos="0 0 0.4" friction="1. .1 .1"/>
      <geom name="scene136" type="mesh" mesh="convex_220" rgba="1 0 0 1.0" pos="0 0 0.4" friction="1. .1 .1"/>
      <geom name="scene137" type="mesh" mesh="convex_221" rgba="1 0 0 1.0" pos="0 0 0.4" friction="1. .1 .1"/>
      <geom name="scene138" type="mesh" mesh="convex_222" rgba="1 0 0 1.0" pos="0 0 0.4" friction="1. .1 .1"/>
      <geom name="scene139" type="mesh" mesh="convex_223" rgba="1 0 0 1.0" pos="0 0 0.4" friction="1. .1 .1"/>
      <geom name="scene140" type="mesh" mesh="convex_224" rgba="1 0 0 1.0" pos="0 0 0.4" friction="1. .1 .1"/>
      <geom name="scene141" type="mesh" mesh="convex_225" rgba="1 0 0 1.0" pos="0 0 0.4" friction="1. .1 .1"/>
      <geom name="scene142" type="mesh" mesh="convex_226" rgba="1 0 0 1.0" pos="0 0 0.4" friction="1. .1 .1"/>
      <geom name="scene143" type="mesh" mesh="convex_227" rgba="1 0 0 1.0" pos="0 0 0.4" friction="1. .1 .1"/>
      <geom name="scene144" type="mesh" mesh="convex_228" rgba="1 0 0 1.0" pos="0 0 0.4" friction="1. .1 .1"/>
      <geom name="scene145" type="mesh" mesh="convex_229" rgba="1 0 0 1.0" pos="0 0 0.4" friction="1. .1 .1"/>
      <geom name="scene146" type="mesh" mesh="convex_23" rgba="1 0 0 1.0" pos="0 0 0.4" friction="1. .1 .1"/>
      <geom name="scene147" type="mesh" mesh="convex_230" rgba="1 0 0 1.0" pos="0 0 0.4" friction="1. .1 .1"/>
      <geom name="scene148" type="mesh" mesh="convex_231" rgba="1 0 0 1.0" pos="0 0 0.4" friction="1. .1 .1"/>
      <geom name="scene149" type="mesh" mesh="convex_232" rgba="1 0 0 1.0" pos="0 0 0.4" friction="1. .1 .1"/>
      <geom name="scene150" type="mesh" mesh="convex_233" rgba="1 0 0 1.0" pos="0 0 0.4" friction="1. .1 .1"/>
      <geom name="scene151" type="mesh" mesh="convex_234" rgba="1 0 0 1.0" pos="0 0 0.4" friction="1. .1 .1"/>
      <geom name="scene152" type="mesh" mesh="convex_235" rgba="1 0 0 1.0" pos="0 0 0.4" friction="1. .1 .1"/>
      <geom name="scene153" type="mesh" mesh="convex_236" rgba="1 0 0 1.0" pos="0 0 0.4" friction="1. .1 .1"/>
      <geom name="scene154" type="mesh" mesh="convex_237" rgba="1 0 0 1.0" pos="0 0 0.4" friction="1. .1 .1"/>
      <geom name="scene155" type="mesh" mesh="convex_238" rgba="1 0 0 1.0" pos="0 0 0.4" friction="1. .1 .1"/>
      <geom name="scene156" type="mesh" mesh="convex_239" rgba="1 0 0 1.0" pos="0 0 0.4" friction="1. .1 .1"/>
      <geom name="scene157" type="mesh" mesh="convex_24" rgba="1 0 0 1.0" pos="0 0 0.4" friction="1. .1 .1"/>
      <geom name="scene158" type="mesh" mesh="convex_240" rgba="1 0 0 1.0" pos="0 0 0.4" friction="1. .1 .1"/>
      <geom name="scene159" type="mesh" mesh="convex_241" rgba="1 0 0 1.0" pos="0 0 0.4" friction="1. .1 .1"/>
      <geom name="scene160" type="mesh" mesh="convex_242" rgba="1 0 0 1.0" pos="0 0 0.4" friction="1. .1 .1"/>
      <geom name="scene161" type="mesh" mesh="convex_243" rgba="1 0 0 1.0" pos="0 0 0.4" friction="1. .1 .1"/>
      <geom name="scene162" type="mesh" mesh="convex_244" rgba="1 0 0 1.0" pos="0 0 0.4" friction="1. .1 .1"/>
      <geom name="scene163" type="mesh" mesh="convex_245" rgba="1 0 0 1.0" pos="0 0 0.4" friction="1. .1 .1"/>
      <geom name="scene164" type="mesh" mesh="convex_246" rgba="1 0 0 1.0" pos="0 0 0.4" friction="1. .1 .1"/>
      <geom name="scene165" type="mesh" mesh="convex_247" rgba="1 0 0 1.0" pos="0 0 0.4" friction="1. .1 .1"/>
      <geom name="scene166" type="mesh" mesh="convex_248" rgba="1 0 0 1.0" pos="0 0 0.4" friction="1. .1 .1"/>
      <geom name="scene167" type="mesh" mesh="convex_249" rgba="1 0 0 1.0" pos="0 0 0.4" friction="1. .1 .1"/>
      <geom name="scene168" type="mesh" mesh="convex_25" rgba="1 0 0 1.0" pos="0 0 0.4" friction="1. .1 .1"/>
      <geom name="scene169" type="mesh" mesh="convex_250" rgba="1 0 0 1.0" pos="0 0 0.4" friction="1. .1 .1"/>
      <geom name="scene170" type="mesh" mesh="convex_251" rgba="1 0 0 1.0" pos="0 0 0.4" friction="1. .1 .1"/>
      <geom name="scene171" type="mesh" mesh="convex_252" rgba="1 0 0 1.0" pos="0 0 0.4" friction="1. .1 .1"/>
      <geom name="scene172" type="mesh" mesh="convex_253" rgba="1 0 0 1.0" pos="0 0 0.4" friction="1. .1 .1"/>
      <geom name="scene173" type="mesh" mesh="convex_254" rgba="1 0 0 1.0" pos="0 0 0.4" friction="1. .1 .1"/>
      <geom name="scene174" type="mesh" mesh="convex_255" rgba="1 0 0 1.0" pos="0 0 0.4" friction="1. .1 .1"/>
      <geom name="scene175" type="mesh" mesh="convex_256" rgba="1 0 0 1.0" pos="0 0 0.4" friction="1. .1 .1"/>
      <geom name="scene176" type="mesh" mesh="convex_257" rgba="1 0 0 1.0" pos="0 0 0.4" friction="1. .1 .1"/>
      <geom name="scene177" type="mesh" mesh="convex_258" rgba="1 0 0 1.0" pos="0 0 0.4" friction="1. .1 .1"/>
      <geom name="scene178" type="mesh" mesh="convex_259" rgba="1 0 0 1.0" pos="0 0 0.4" friction="1. .1 .1"/>
      <geom name="scene179" type="mesh" mesh="convex_26" rgba="1 0 0 1.0" pos="0 0 0.4" friction="1. .1 .1"/>
      <geom name="scene180" type="mesh" mesh="convex_260" rgba="1 0 0 1.0" pos="0 0 0.4" friction="1. .1 .1"/>
      <geom name="scene181" type="mesh" mesh="convex_261" rgba="1 0 0 1.0" pos="0 0 0.4" friction="1. .1 .1"/>
      <geom name="scene182" type="mesh" mesh="convex_262" rgba="1 0 0 1.0" pos="0 0 0.4" friction="1. .1 .1"/>
      <geom name="scene183" type="mesh" mesh="convex_263" rgba="1 0 0 1.0" pos="0 0 0.4" friction="1. .1 .1"/>
      <geom name="scene184" type="mesh" mesh="convex_264" rgba="1 0 0 1.0" pos="0 0 0.4" friction="1. .1 .1"/>
      <geom name="scene185" type="mesh" mesh="convex_265" rgba="1 0 0 1.0" pos="0 0 0.4" friction="1. .1 .1"/>
      <geom name="scene186" type="mesh" mesh="convex_266" rgba="1 0 0 1.0" pos="0 0 0.4" friction="1. .1 .1"/>
      <geom name="scene187" type="mesh" mesh="convex_267" rgba="1 0 0 1.0" pos="0 0 0.4" friction="1. .1 .1"/>
      <geom name="scene188" type="mesh" mesh="convex_268" rgba="1 0 0 1.0" pos="0 0 0.4" friction="1. .1 .1"/>
      <geom name="scene189" type="mesh" mesh="convex_269" rgba="1 0 0 1.0" pos="0 0 0.4" friction="1. .1 .1"/>
      <geom name="scene190" type="mesh" mesh="convex_27" rgba="1 0 0 1.0" pos="0 0 0.4" friction="1. .1 .1"/>
      <geom name="scene191" type="mesh" mesh="convex_270" rgba="1 0 0 1.0" pos="0 0 0.4" friction="1. .1 .1"/>
      <geom name="scene192" type="mesh" mesh="convex_271" rgba="1 0 0 1.0" pos="0 0 0.4" friction="1. .1 .1"/>
      <geom name="scene193" type="mesh" mesh="convex_272" rgba="1 0 0 1.0" pos="0 0 0.4" friction="1. .1 .1"/>
      <geom name="scene194" type="mesh" mesh="convex_273" rgba="1 0 0 1.0" pos="0 0 0.4" friction="1. .1 .1"/>
      <geom name="scene195" type="mesh" mesh="convex_274" rgba="1 0 0 1.0" pos="0 0 0.4" friction="1. .1 .1"/>
      <geom name="scene196" type="mesh" mesh="convex_275" rgba="1 0 0 1.0" pos="0 0 0.4" friction="1. .1 .1"/>
      <geom name="scene197" type="mesh" mesh="convex_276" rgba="1 0 0 1.0" pos="0 0 0.4" friction="1. .1 .1"/>
      <geom name="scene198" type="mesh" mesh="convex_277" rgba="1 0 0 1.0" pos="0 0 0.4" friction="1. .1 .1"/>
      <geom name="scene199" type="mesh" mesh="convex_278" rgba="1 0 0 1.0" pos="0 0 0.4" friction="1. .1 .1"/>
      <geom name="scene200" type="mesh" mesh="convex_279" rgba="1 0 0 1.0" pos="0 0 0.4" friction="1. .1 .1"/>
      <geom name="scene201" type="mesh" mesh="convex_28" rgba="1 0 0 1.0" pos="0 0 0.4" friction="1. .1 .1"/>
      <geom name="scene202" type="mesh" mesh="convex_280" rgba="1 0 0 1.0" pos="0 0 0.4" friction="1. .1 .1"/>
      <geom name="scene203" type="mesh" mesh="convex_281" rgba="1 0 0 1.0" pos="0 0 0.4" friction="1. .1 .1"/>
      <geom name="scene204" type="mesh" mesh="convex_282" rgba="1 0 0 1.0" pos="0 0 0.4" friction="1. .1 .1"/>
      <geom name="scene205" type="mesh" mesh="convex_283" rgba="1 0 0 1.0" pos="0 0 0.4" friction="1. .1 .1"/>
      <geom name="scene206" type="mesh" mesh="convex_284" rgba="1 0 0 1.0" pos="0 0 0.4" friction="1. .1 .1"/>
      <geom name="scene207" type="mesh" mesh="convex_285" rgba="1 0 0 1.0" pos="0 0 0.4" friction="1. .1 .1"/>
      <geom name="scene208" type="mesh" mesh="convex_286" rgba="1 0 0 1.0" pos="0 0 0.4" friction="1. .1 .1"/>
      <geom name="scene209" type="mesh" mesh="convex_287" rgba="1 0 0 1.0" pos="0 0 0.4" friction="1. .1 .1"/>
      <geom name="scene210" type="mesh" mesh="convex_288" rgba="1 0 0 1.0" pos="0 0 0.4" friction="1. .1 .1"/>
      <geom name="scene211" type="mesh" mesh="convex_289" rgba="1 0 0 1.0" pos="0 0 0.4" friction="1. .1 .1"/>
      <geom name="scene212" type="mesh" mesh="convex_29" rgba="1 0 0 1.0" pos="0 0 0.4" friction="1. .1 .1"/>
      <geom name="scene213" type="mesh" mesh="convex_290" rgba="1 0 0 1.0" pos="0 0 0.4" friction="1. .1 .1"/>
      <geom name="scene214" type="mesh" mesh="convex_291" rgba="1 0 0 1.0" pos="0 0 0.4" friction="1. .1 .1"/>
      <geom name="scene215" type="mesh" mesh="convex_292" rgba="1 0 0 1.0" pos="0 0 0.4" friction="1. .1 .1"/>
      <geom name="scene216" type="mesh" mesh="convex_293" rgba="1 0 0 1.0" pos="0 0 0.4" friction="1. .1 .1"/>
      <geom name="scene217" type="mesh" mesh="convex_294" rgba="1 0 0 1.0" pos="0 0 0.4" friction="1. .1 .1"/>
      <geom name="scene218" type="mesh" mesh="convex_295" rgba="1 0 0 1.0" pos="0 0 0.4" friction="1. .1 .1"/>
      <geom name="scene219" type="mesh" mesh="convex_296" rgba="1 0 0 1.0" pos="0 0 0.4" friction="1. .1 .1"/>
      <geom name="scene220" type="mesh" mesh="convex_297" rgba="1 0 0 1.0" pos="0 0 0.4" friction="1. .1 .1"/>
      <geom name="scene221" type="mesh" mesh="convex_298" rgba="1 0 0 1.0" pos="0 0 0.4" friction="1. .1 .1"/>
      <geom name="scene222" type="mesh" mesh="convex_299" rgba="1 0 0 1.0" pos="0 0 0.4" friction="1. .1 .1"/>
      <geom name="scene223" type="mesh" mesh="convex_3" rgba="1 0 0 1.0" pos="0 0 0.4" friction="1. .1 .1"/>
      <geom name="scene224" type="mesh" mesh="convex_30" rgba="1 0 0 1.0" pos="0 0 0.4" friction="1. .1 .1"/>
      <geom name="scene225" type="mesh" mesh="convex_300" rgba="1 0 0 1.0" pos="0 0 0.4" friction="1. .1 .1"/>
      <geom name="scene226" type="mesh" mesh="convex_301" rgba="1 0 0 1.0" pos="0 0 0.4" friction="1. .1 .1"/>
      <geom name="scene227" type="mesh" mesh="convex_302" rgba="1 0 0 1.0" pos="0 0 0.4" friction="1. .1 .1"/>
      <geom name="scene228" type="mesh" mesh="convex_303" rgba="1 0 0 1.0" pos="0 0 0.4" friction="1. .1 .1"/>
      <geom name="scene229" type="mesh" mesh="convex_304" rgba="1 0 0 1.0" pos="0 0 0.4" friction="1. .1 .1"/>
      <geom name="scene230" type="mesh" mesh="convex_305" rgba="1 0 0 1.0" pos="0 0 0.4" friction="1. .1 .1"/>
      <geom name="scene231" type="mesh" mesh="convex_306" rgba="1 0 0 1.0" pos="0 0 0.4" friction="1. .1 .1"/>
      <geom name="scene232" type="mesh" mesh="convex_307" rgba="1 0 0 1.0" pos="0 0 0.4" friction="1. .1 .1"/>
      <geom name="scene233" type="mesh" mesh="convex_308" rgba="1 0 0 1.0" pos="0 0 0.4" friction="1. .1 .1"/>
      <geom name="scene234" type="mesh" mesh="convex_309" rgba="1 0 0 1.0" pos="0 0 0.4" friction="1. .1 .1"/>
      <geom name="scene235" type="mesh" mesh="convex_31" rgba="1 0 0 1.0" pos="0 0 0.4" friction="1. .1 .1"/>
      <geom name="scene236" type="mesh" mesh="convex_310" rgba="1 0 0 1.0" pos="0 0 0.4" friction="1. .1 .1"/>
      <geom name="scene237" type="mesh" mesh="convex_311" rgba="1 0 0 1.0" pos="0 0 0.4" friction="1. .1 .1"/>
      <geom name="scene238" type="mesh" mesh="convex_312" rgba="1 0 0 1.0" pos="0 0 0.4" friction="1. .1 .1"/>
      <geom name="scene239" type="mesh" mesh="convex_313" rgba="1 0 0 1.0" pos="0 0 0.4" friction="1. .1 .1"/>
      <geom name="scene240" type="mesh" mesh="convex_314" rgba="1 0 0 1.0" pos="0 0 0.4" friction="1. .1 .1"/>
      <geom name="scene241" type="mesh" mesh="convex_315" rgba="1 0 0 1.0" pos="0 0 0.4" friction="1. .1 .1"/>
      <geom name="scene242" type="mesh" mesh="convex_316" rgba="1 0 0 1.0" pos="0 0 0.4" friction="1. .1 .1"/>
      <geom name="scene243" type="mesh" mesh="convex_317" rgba="1 0 0 1.0" pos="0 0 0.4" friction="1. .1 .1"/>
      <geom name="scene244" type="mesh" mesh="convex_318" rgba="1 0 0 1.0" pos="0 0 0.4" friction="1. .1 .1"/>
      <geom name="scene245" type="mesh" mesh="convex_319" rgba="1 0 0 1.0" pos="0 0 0.4" friction="1. .1 .1"/>
      <geom name="scene246" type="mesh" mesh="convex_32" rgba="1 0 0 1.0" pos="0 0 0.4" friction="1. .1 .1"/>
      <geom name="scene247" type="mesh" mesh="convex_320" rgba="1 0 0 1.0" pos="0 0 0.4" friction="1. .1 .1"/>
      <geom name="scene248" type="mesh" mesh="convex_321" rgba="1 0 0 1.0" pos="0 0 0.4" friction="1. .1 .1"/>
      <geom name="scene249" type="mesh" mesh="convex_322" rgba="1 0 0 1.0" pos="0 0 0.4" friction="1. .1 .1"/>
      <geom name="scene250" type="mesh" mesh="convex_323" rgba="1 0 0 1.0" pos="0 0 0.4" friction="1. .1 .1"/>
      <geom name="scene251" type="mesh" mesh="convex_324" rgba="1 0 0 1.0" pos="0 0 0.4" friction="1. .1 .1"/>
      <geom name="scene252" type="mesh" mesh="convex_325" rgba="1 0 0 1.0" pos="0 0 0.4" friction="1. .1 .1"/>
      <geom name="scene253" type="mesh" mesh="convex_326" rgba="1 0 0 1.0" pos="0 0 0.4" friction="1. .1 .1"/>
      <geom name="scene254" type="mesh" mesh="convex_327" rgba="1 0 0 1.0" pos="0 0 0.4" friction="1. .1 .1"/>
      <geom name="scene255" type="mesh" mesh="convex_328" rgba="1 0 0 1.0" pos="0 0 0.4" friction="1. .1 .1"/>
      <geom name="scene256" type="mesh" mesh="convex_329" rgba="1 0 0 1.0" pos="0 0 0.4" friction="1. .1 .1"/>
      <geom name="scene257" type="mesh" mesh="convex_33" rgba="1 0 0 1.0" pos="0 0 0.4" friction="1. .1 .1"/>
      <geom name="scene258" type="mesh" mesh="convex_330" rgba="1 0 0 1.0" pos="0 0 0.4" friction="1. .1 .1"/>
      <geom name="scene259" type="mesh" mesh="convex_331" rgba="1 0 0 1.0" pos="0 0 0.4" friction="1. .1 .1"/>
      <geom name="scene260" type="mesh" mesh="convex_332" rgba="1 0 0 1.0" pos="0 0 0.4" friction="1. .1 .1"/>
      <geom name="scene261" type="mesh" mesh="convex_333" rgba="1 0 0 1.0" pos="0 0 0.4" friction="1. .1 .1"/>
      <geom name="scene262" type="mesh" mesh="convex_334" rgba="1 0 0 1.0" pos="0 0 0.4" friction="1. .1 .1"/>
      <geom name="scene263" type="mesh" mesh="convex_335" rgba="1 0 0 1.0" pos="0 0 0.4" friction="1. .1 .1"/>
      <geom name="scene264" type="mesh" mesh="convex_336" rgba="1 0 0 1.0" pos="0 0 0.4" friction="1. .1 .1"/>
      <geom name="scene265" type="mesh" mesh="convex_337" rgba="1 0 0 1.0" pos="0 0 0.4" friction="1. .1 .1"/>
      <geom name="scene266" type="mesh" mesh="convex_338" rgba="1 0 0 1.0" pos="0 0 0.4" friction="1. .1 .1"/>
      <geom name="scene267" type="mesh" mesh="convex_339" rgba="1 0 0 1.0" pos="0 0 0.4" friction="1. .1 .1"/>
      <geom name="scene268" type="mesh" mesh="convex_34" rgba="1 0 0 1.0" pos="0 0 0.4" friction="1. .1 .1"/>
      <geom name="scene269" type="mesh" mesh="convex_340" rgba="1 0 0 1.0" pos="0 0 0.4" friction="1. .1 .1"/>
      <geom name="scene270" type="mesh" mesh="convex_341" rgba="1 0 0 1.0" pos="0 0 0.4" friction="1. .1 .1"/>
      <geom name="scene271" type="mesh" mesh="convex_342" rgba="1 0 0 1.0" pos="0 0 0.4" friction="1. .1 .1"/>
      <geom name="scene272" type="mesh" mesh="convex_343" rgba="1 0 0 1.0" pos="0 0 0.4" friction="1. .1 .1"/>
      <geom name="scene273" type="mesh" mesh="convex_344" rgba="1 0 0 1.0" pos="0 0 0.4" friction="1. .1 .1"/>
      <geom name="scene274" type="mesh" mesh="convex_345" rgba="1 0 0 1.0" pos="0 0 0.4" friction="1. .1 .1"/>
      <geom name="scene275" type="mesh" mesh="convex_346" rgba="1 0 0 1.0" pos="0 0 0.4" friction="1. .1 .1"/>
      <geom name="scene276" type="mesh" mesh="convex_347" rgba="1 0 0 1.0" pos="0 0 0.4" friction="1. .1 .1"/>
      <geom name="scene277" type="mesh" mesh="convex_348" rgba="1 0 0 1.0" pos="0 0 0.4" friction="1. .1 .1"/>
      <geom name="scene278" type="mesh" mesh="convex_349" rgba="1 0 0 1.0" pos="0 0 0.4" friction="1. .1 .1"/>
      <geom name="scene279" type="mesh" mesh="convex_35" rgba="1 0 0 1.0" pos="0 0 0.4" friction="1. .1 .1"/>
      <geom name="scene280" type="mesh" mesh="convex_350" rgba="1 0 0 1.0" pos="0 0 0.4" friction="1. .1 .1"/>
      <geom name="scene281" type="mesh" mesh="convex_351" rgba="1 0 0 1.0" pos="0 0 0.4" friction="1. .1 .1"/>
      <geom name="scene282" type="mesh" mesh="convex_352" rgba="1 0 0 1.0" pos="0 0 0.4" friction="1. .1 .1"/>
      <geom name="scene283" type="mesh" mesh="convex_353" rgba="1 0 0 1.0" pos="0 0 0.4" friction="1. .1 .1"/>
      <geom name="scene284" type="mesh" mesh="convex_354" rgba="1 0 0 1.0" pos="0 0 0.4" friction="1. .1 .1"/>
      <geom name="scene285" type="mesh" mesh="convex_355" rgba="1 0 0 1.0" pos="0 0 0.4" friction="1. .1 .1"/>
      <geom name="scene286" type="mesh" mesh="convex_356" rgba="1 0 0 1.0" pos="0 0 0.4" friction="1. .1 .1"/>
      <geom name="scene287" type="mesh" mesh="convex_357" rgba="1 0 0 1.0" pos="0 0 0.4" friction="1. .1 .1"/>
      <geom name="scene288" type="mesh" mesh="convex_358" rgba="1 0 0 1.0" pos="0 0 0.4" friction="1. .1 .1"/>
      <geom name="scene289" type="mesh" mesh="convex_359" rgba="1 0 0 1.0" pos="0 0 0.4" friction="1. .1 .1"/>
      <geom name="scene290" type="mesh" mesh="convex_36" rgba="1 0 0 1.0" pos="0 0 0.4" friction="1. .1 .1"/>
      <geom name="scene291" type="mesh" mesh="convex_360" rgba="1 0 0 1.0" pos="0 0 0.4" friction="1. .1 .1"/>
      <geom name="scene292" type="mesh" mesh="convex_361" rgba="1 0 0 1.0" pos="0 0 0.4" friction="1. .1 .1"/>
      <geom name="scene293" type="mesh" mesh="convex_362" rgba="1 0 0 1.0" pos="0 0 0.4" friction="1. .1 .1"/>
      <geom name="scene294" type="mesh" mesh="convex_363" rgba="1 0 0 1.0" pos="0 0 0.4" friction="1. .1 .1"/>
      <geom name="scene295" type="mesh" mesh="convex_364" rgba="1 0 0 1.0" pos="0 0 0.4" friction="1. .1 .1"/>
      <geom name="scene296" type="mesh" mesh="convex_365" rgba="1 0 0 1.0" pos="0 0 0.4" friction="1. .1 .1"/>
      <geom name="scene297" type="mesh" mesh="convex_366" rgba="1 0 0 1.0" pos="0 0 0.4" friction="1. .1 .1"/>
      <geom name="scene298" type="mesh" mesh="convex_367" rgba="1 0 0 1.0" pos="0 0 0.4" friction="1. .1 .1"/>
      <geom name="scene299" type="mesh" mesh="convex_368" rgba="1 0 0 1.0" pos="0 0 0.4" friction="1. .1 .1"/>
      <geom name="scene300" type="mesh" mesh="convex_369" rgba="1 0 0 1.0" pos="0 0 0.4" friction="1. .1 .1"/>
      <geom name="scene301" type="mesh" mesh="convex_37" rgba="1 0 0 1.0" pos="0 0 0.4" friction="1. .1 .1"/>
      <geom name="scene302" type="mesh" mesh="convex_370" rgba="1 0 0 1.0" pos="0 0 0.4" friction="1. .1 .1"/>
      <geom name="scene303" type="mesh" mesh="convex_371" rgba="1 0 0 1.0" pos="0 0 0.4" friction="1. .1 .1"/>
      <geom name="scene304" type="mesh" mesh="convex_372" rgba="1 0 0 1.0" pos="0 0 0.4" friction="1. .1 .1"/>
      <geom name="scene305" type="mesh" mesh="convex_373" rgba="1 0 0 1.0" pos="0 0 0.4" friction="1. .1 .1"/>
      <geom name="scene306" type="mesh" mesh="convex_374" rgba="1 0 0 1.0" pos="0 0 0.4" friction="1. .1 .1"/>
      <geom name="scene307" type="mesh" mesh="convex_375" rgba="1 0 0 1.0" pos="0 0 0.4" friction="1. .1 .1"/>
      <geom name="scene308" type="mesh" mesh="convex_376" rgba="1 0 0 1.0" pos="0 0 0.4" friction="1. .1 .1"/>
      <geom name="scene309" type="mesh" mesh="convex_377" rgba="1 0 0 1.0" pos="0 0 0.4" friction="1. .1 .1"/>
      <geom name="scene310" type="mesh" mesh="convex_378" rgba="1 0 0 1.0" pos="0 0 0.4" friction="1. .1 .1"/>
      <geom name="scene311" type="mesh" mesh="convex_379" rgba="1 0 0 1.0" pos="0 0 0.4" friction="1. .1 .1"/>
      <geom name="scene312" type="mesh" mesh="convex_38" rgba="1 0 0 1.0" pos="0 0 0.4" friction="1. .1 .1"/>
      <geom name="scene313" type="mesh" mesh="convex_380" rgba="1 0 0 1.0" pos="0 0 0.4" friction="1. .1 .1"/>
      <geom name="scene314" type="mesh" mesh="convex_381" rgba="1 0 0 1.0" pos="0 0 0.4" friction="1. .1 .1"/>
      <geom name="scene315" type="mesh" mesh="convex_382" rgba="1 0 0 1.0" pos="0 0 0.4" friction="1. .1 .1"/>
      <geom name="scene316" type="mesh" mesh="convex_383" rgba="1 0 0 1.0" pos="0 0 0.4" friction="1. .1 .1"/>
      <geom name="scene317" type="mesh" mesh="convex_384" rgba="1 0 0 1.0" pos="0 0 0.4" friction="1. .1 .1"/>
      <geom name="scene318" type="mesh" mesh="convex_385" rgba="1 0 0 1.0" pos="0 0 0.4" friction="1. .1 .1"/>
      <geom name="scene319" type="mesh" mesh="convex_386" rgba="1 0 0 1.0" pos="0 0 0.4" friction="1. .1 .1"/>
      <geom name="scene320" type="mesh" mesh="convex_387" rgba="1 0 0 1.0" pos="0 0 0.4" friction="1. .1 .1"/>
      <geom name="scene321" type="mesh" mesh="convex_388" rgba="1 0 0 1.0" pos="0 0 0.4" friction="1. .1 .1"/>
      <geom name="scene322" type="mesh" mesh="convex_389" rgba="1 0 0 1.0" pos="0 0 0.4" friction="1. .1 .1"/>
      <geom name="scene323" type="mesh" mesh="convex_39" rgba="1 0 0 1.0" pos="0 0 0.4" friction="1. .1 .1"/>
      <geom name="scene324" type="mesh" mesh="convex_390" rgba="1 0 0 1.0" pos="0 0 0.4" friction="1. .1 .1"/>
      <geom name="scene325" type="mesh" mesh="convex_391" rgba="1 0 0 1.0" pos="0 0 0.4" friction="1. .1 .1"/>
      <geom name="scene326" type="mesh" mesh="convex_392" rgba="1 0 0 1.0" pos="0 0 0.4" friction="1. .1 .1"/>
      <geom name="scene327" type="mesh" mesh="convex_393" rgba="1 0 0 1.0" pos="0 0 0.4" friction="1. .1 .1"/>
      <geom name="scene328" type="mesh" mesh="convex_394" rgba="1 0 0 1.0" pos="0 0 0.4" friction="1. .1 .1"/>
      <geom name="scene329" type="mesh" mesh="convex_395" rgba="1 0 0 1.0" pos="0 0 0.4" friction="1. .1 .1"/>
      <geom name="scene330" type="mesh" mesh="convex_396" rgba="1 0 0 1.0" pos="0 0 0.4" friction="1. .1 .1"/>
      <geom name="scene331" type="mesh" mesh="convex_397" rgba="1 0 0 1.0" pos="0 0 0.4" friction="1. .1 .1"/>
      <geom name="scene332" type="mesh" mesh="convex_398" rgba="1 0 0 1.0" pos="0 0 0.4" friction="1. .1 .1"/>
      <geom name="scene333" type="mesh" mesh="convex_399" rgba="1 0 0 1.0" pos="0 0 0.4" friction="1. .1 .1"/>
      <geom name="scene334" type="mesh" mesh="convex_4" rgba="1 0 0 1.0" pos="0 0 0.4" friction="1. .1 .1"/>
      <geom name="scene335" type="mesh" mesh="convex_40" rgba="1 0 0 1.0" pos="0 0 0.4" friction="1. .1 .1"/>
      <geom name="scene336" type="mesh" mesh="convex_400" rgba="1 0 0 1.0" pos="0 0 0.4" friction="1. .1 .1"/>
      <geom name="scene337" type="mesh" mesh="convex_401" rgba="1 0 0 1.0" pos="0 0 0.4" friction="1. .1 .1"/>
      <geom name="scene338" type="mesh" mesh="convex_402" rgba="1 0 0 1.0" pos="0 0 0.4" friction="1. .1 .1"/>
      <geom name="scene339" type="mesh" mesh="convex_403" rgba="1 0 0 1.0" pos="0 0 0.4" friction="1. .1 .1"/>
      <geom name="scene340" type="mesh" mesh="convex_404" rgba="1 0 0 1.0" pos="0 0 0.4" friction="1. .1 .1"/>
      <geom name="scene341" type="mesh" mesh="convex_405" rgba="1 0 0 1.0" pos="0 0 0.4" friction="1. .1 .1"/>
      <geom name="scene342" type="mesh" mesh="convex_406" rgba="1 0 0 1.0" pos="0 0 0.4" friction="1. .1 .1"/>
      <geom name="scene343" type="mesh" mesh="convex_407" rgba="1 0 0 1.0" pos="0 0 0.4" friction="1. .1 .1"/>
      <geom name="scene344" type="mesh" mesh="convex_408" rgba="1 0 0 1.0" pos="0 0 0.4" friction="1. .1 .1"/>
      <geom name="scene345" type="mesh" mesh="convex_409" rgba="1 0 0 1.0" pos="0 0 0.4" friction="1. .1 .1"/>
      <geom name="scene346" type="mesh" mesh="convex_41" rgba="1 0 0 1.0" pos="0 0 0.4" friction="1. .1 .1"/>
      <geom name="scene347" type="mesh" mesh="convex_410" rgba="1 0 0 1.0" pos="0 0 0.4" friction="1. .1 .1"/>
      <geom name="scene348" type="mesh" mesh="convex_411" rgba="1 0 0 1.0" pos="0 0 0.4" friction="1. .1 .1"/>
      <geom name="scene349" type="mesh" mesh="convex_412" rgba="1 0 0 1.0" pos="0 0 0.4" friction="1. .1 .1"/>
      <geom name="scene350" type="mesh" mesh="convex_413" rgba="1 0 0 1.0" pos="0 0 0.4" friction="1. .1 .1"/>
      <geom name="scene351" type="mesh" mesh="convex_414" rgba="1 0 0 1.0" pos="0 0 0.4" friction="1. .1 .1"/>
      <geom name="scene352" type="mesh" mesh="convex_415" rgba="1 0 0 1.0" pos="0 0 0.4" friction="1. .1 .1"/>
      <geom name="scene353" type="mesh" mesh="convex_416" rgba="1 0 0 1.0" pos="0 0 0.4" friction="1. .1 .1"/>
      <geom name="scene354" type="mesh" mesh="convex_417" rgba="1 0 0 1.0" pos="0 0 0.4" friction="1. .1 .1"/>
      <geom name="scene355" type="mesh" mesh="convex_418" rgba="1 0 0 1.0" pos="0 0 0.4" friction="1. .1 .1"/>
      <geom name="scene356" type="mesh" mesh="convex_419" rgba="1 0 0 1.0" pos="0 0 0.4" friction="1. .1 .1"/>
      <geom name="scene357" type="mesh" mesh="convex_42" rgba="1 0 0 1.0" pos="0 0 0.4" friction="1. .1 .1"/>
      <geom name="scene358" type="mesh" mesh="convex_420" rgba="1 0 0 1.0" pos="0 0 0.4" friction="1. .1 .1"/>
      <geom name="scene359" type="mesh" mesh="convex_421" rgba="1 0 0 1.0" pos="0 0 0.4" friction="1. .1 .1"/>
      <geom name="scene360" type="mesh" mesh="convex_422" rgba="1 0 0 1.0" pos="0 0 0.4" friction="1. .1 .1"/>
      <geom name="scene361" type="mesh" mesh="convex_423" rgba="1 0 0 1.0" pos="0 0 0.4" friction="1. .1 .1"/>
      <geom name="scene362" type="mesh" mesh="convex_424" rgba="1 0 0 1.0" pos="0 0 0.4" friction="1. .1 .1"/>
      <geom name="scene363" type="mesh" mesh="convex_425" rgba="1 0 0 1.0" pos="0 0 0.4" friction="1. .1 .1"/>
      <geom name="scene364" type="mesh" mesh="convex_426" rgba="1 0 0 1.0" pos="0 0 0.4" friction="1. .1 .1"/>
      <geom name="scene365" type="mesh" mesh="convex_427" rgba="1 0 0 1.0" pos="0 0 0.4" friction="1. .1 .1"/>
      <geom name="scene366" type="mesh" mesh="convex_428" rgba="1 0 0 1.0" pos="0 0 0.4" friction="1. .1 .1"/>
      <geom name="scene367" type="mesh" mesh="convex_429" rgba="1 0 0 1.0" pos="0 0 0.4" friction="1. .1 .1"/>
      <geom name="scene368" type="mesh" mesh="convex_43" rgba="1 0 0 1.0" pos="0 0 0.4" friction="1. .1 .1"/>
      <geom name="scene369" type="mesh" mesh="convex_430" rgba="1 0 0 1.0" pos="0 0 0.4" friction="1. .1 .1"/>
      <geom name="scene370" type="mesh" mesh="convex_431" rgba="1 0 0 1.0" pos="0 0 0.4" friction="1. .1 .1"/>
      <geom name="scene371" type="mesh" mesh="convex_432" rgba="1 0 0 1.0" pos="0 0 0.4" friction="1. .1 .1"/>
      <geom name="scene372" type="mesh" mesh="convex_433" rgba="1 0 0 1.0" pos="0 0 0.4" friction="1. .1 .1"/>
      <geom name="scene373" type="mesh" mesh="convex_434" rgba="1 0 0 1.0" pos="0 0 0.4" friction="1. .1 .1"/>
      <geom name="scene374" type="mesh" mesh="convex_435" rgba="1 0 0 1.0" pos="0 0 0.4" friction="1. .1 .1"/>
      <geom name="scene375" type="mesh" mesh="convex_436" rgba="1 0 0 1.0" pos="0 0 0.4" friction="1. .1 .1"/>
      <geom name="scene376" type="mesh" mesh="convex_437" rgba="1 0 0 1.0" pos="0 0 0.4" friction="1. .1 .1"/>
      <geom name="scene377" type="mesh" mesh="convex_438" rgba="1 0 0 1.0" pos="0 0 0.4" friction="1. .1 .1"/>
      <geom name="scene378" type="mesh" mesh="convex_439" rgba="1 0 0 1.0" pos="0 0 0.4" friction="1. .1 .1"/>
      <geom name="scene379" type="mesh" mesh="convex_44" rgba="1 0 0 1.0" pos="0 0 0.4" friction="1. .1 .1"/>
      <geom name="scene380" type="mesh" mesh="convex_440" rgba="1 0 0 1.0" pos="0 0 0.4" friction="1. .1 .1"/>
      <geom name="scene381" type="mesh" mesh="convex_441" rgba="1 0 0 1.0" pos="0 0 0.4" friction="1. .1 .1"/>
      <geom name="scene382" type="mesh" mesh="convex_442" rgba="1 0 0 1.0" pos="0 0 0.4" friction="1. .1 .1"/>
      <geom name="scene383" type="mesh" mesh="convex_443" rgba="1 0 0 1.0" pos="0 0 0.4" friction="1. .1 .1"/>
      <geom name="scene384" type="mesh" mesh="convex_444" rgba="1 0 0 1.0" pos="0 0 0.4" friction="1. .1 .1"/>
      <geom name="scene385" type="mesh" mesh="convex_445" rgba="1 0 0 1.0" pos="0 0 0.4" friction="1. .1 .1"/>
      <geom name="scene386" type="mesh" mesh="convex_446" rgba="1 0 0 1.0" pos="0 0 0.4" friction="1. .1 .1"/>
      <geom name="scene387" type="mesh" mesh="convex_447" rgba="1 0 0 1.0" pos="0 0 0.4" friction="1. .1 .1"/>
      <geom name="scene388" type="mesh" mesh="convex_448" rgba="1 0 0 1.0" pos="0 0 0.4" friction="1. .1 .1"/>
      <geom name="scene389" type="mesh" mesh="convex_449" rgba="1 0 0 1.0" pos="0 0 0.4" friction="1. .1 .1"/>
      <geom name="scene390" type="mesh" mesh="convex_45" rgba="1 0 0 1.0" pos="0 0 0.4" friction="1. .1 .1"/>
      <geom name="scene391" type="mesh" mesh="convex_450" rgba="1 0 0 1.0" pos="0 0 0.4" friction="1. .1 .1"/>
      <geom name="scene392" type="mesh" mesh="convex_451" rgba="1 0 0 1.0" pos="0 0 0.4" friction="1. .1 .1"/>
      <geom name="scene393" type="mesh" mesh="convex_452" rgba="1 0 0 1.0" pos="0 0 0.4" friction="1. .1 .1"/>
      <geom name="scene394" type="mesh" mesh="convex_453" rgba="1 0 0 1.0" pos="0 0 0.4" friction="1. .1 .1"/>
      <geom name="scene395" type="mesh" mesh="convex_454" rgba="1 0 0 1.0" pos="0 0 0.4" friction="1. .1 .1"/>
      <geom name="scene396" type="mesh" mesh="convex_455" rgba="1 0 0 1.0" pos="0 0 0.4" friction="1. .1 .1"/>
      <geom name="scene397" type="mesh" mesh="convex_456" rgba="1 0 0 1.0" pos="0 0 0.4" friction="1. .1 .1"/>
      <geom name="scene398" type="mesh" mesh="convex_457" rgba="1 0 0 1.0" pos="0 0 0.4" friction="1. .1 .1"/>
      <geom name="scene399" type="mesh" mesh="convex_458" rgba="1 0 0 1.0" pos="0 0 0.4" friction="1. .1 .1"/>
      <geom name="scene400" type="mesh" mesh="convex_459" rgba="1 0 0 1.0" pos="0 0 0.4" friction="1. .1 .1"/>
      <geom name="scene401" type="mesh" mesh="convex_46" rgba="1 0 0 1.0" pos="0 0 0.4" friction="1. .1 .1"/>
      <geom name="scene402" type="mesh" mesh="convex_460" rgba="1 0 0 1.0" pos="0 0 0.4" friction="1. .1 .1"/>
      <geom name="scene403" type="mesh" mesh="convex_461" rgba="1 0 0 1.0" pos="0 0 0.4" friction="1. .1 .1"/>
      <geom name="scene404" type="mesh" mesh="convex_462" rgba="1 0 0 1.0" pos="0 0 0.4" friction="1. .1 .1"/>
      <geom name="scene405" type="mesh" mesh="convex_463" rgba="1 0 0 1.0" pos="0 0 0.4" friction="1. .1 .1"/>
      <geom name="scene406" type="mesh" mesh="convex_464" rgba="1 0 0 1.0" pos="0 0 0.4" friction="1. .1 .1"/>
      <geom name="scene407" type="mesh" mesh="convex_465" rgba="1 0 0 1.0" pos="0 0 0.4" friction="1. .1 .1"/>
      <geom name="scene408" type="mesh" mesh="convex_466" rgba="1 0 0 1.0" pos="0 0 0.4" friction="1. .1 .1"/>
      <geom name="scene409" type="mesh" mesh="convex_467" rgba="1 0 0 1.0" pos="0 0 0.4" friction="1. .1 .1"/>
      <geom name="scene410" type="mesh" mesh="convex_468" rgba="1 0 0 1.0" pos="0 0 0.4" friction="1. .1 .1"/>
      <geom name="scene411" type="mesh" mesh="convex_469" rgba="1 0 0 1.0" pos="0 0 0.4" friction="1. .1 .1"/>
      <geom name="scene412" type="mesh" mesh="convex_47" rgba="1 0 0 1.0" pos="0 0 0.4" friction="1. .1 .1"/>
      <geom name="scene413" type="mesh" mesh="convex_470" rgba="1 0 0 1.0" pos="0 0 0.4" friction="1. .1 .1"/>
      <geom name="scene414" type="mesh" mesh="convex_471" rgba="1 0 0 1.0" pos="0 0 0.4" friction="1. .1 .1"/>
      <geom name="scene415" type="mesh" mesh="convex_472" rgba="1 0 0 1.0" pos="0 0 0.4" friction="1. .1 .1"/>
      <geom name="scene416" type="mesh" mesh="convex_473" rgba="1 0 0 1.0" pos="0 0 0.4" friction="1. .1 .1"/>
      <geom name="scene417" type="mesh" mesh="convex_474" rgba="1 0 0 1.0" pos="0 0 0.4" friction="1. .1 .1"/>
      <geom name="scene418" type="mesh" mesh="convex_475" rgba="1 0 0 1.0" pos="0 0 0.4" friction="1. .1 .1"/>
      <geom name="scene419" type="mesh" mesh="convex_476" rgba="1 0 0 1.0" pos="0 0 0.4" friction="1. .1 .1"/>
      <geom name="scene420" type="mesh" mesh="convex_477" rgba="1 0 0 1.0" pos="0 0 0.4" friction="1. .1 .1"/>
      <geom name="scene421" type="mesh" mesh="convex_478" rgba="1 0 0 1.0" pos="0 0 0.4" friction="1. .1 .1"/>
      <geom name="scene422" type="mesh" mesh="convex_479" rgba="1 0 0 1.0" pos="0 0 0.4" friction="1. .1 .1"/>
      <geom name="scene423" type="mesh" mesh="convex_48" rgba="1 0 0 1.0" pos="0 0 0.4" friction="1. .1 .1"/>
      <geom name="scene424" type="mesh" mesh="convex_480" rgba="1 0 0 1.0" pos="0 0 0.4" friction="1. .1 .1"/>
      <geom name="scene425" type="mesh" mesh="convex_481" rgba="1 0 0 1.0" pos="0 0 0.4" friction="1. .1 .1"/>
      <geom name="scene426" type="mesh" mesh="convex_482" rgba="1 0 0 1.0" pos="0 0 0.4" friction="1. .1 .1"/>
      <geom name="scene427" type="mesh" mesh="convex_483" rgba="1 0 0 1.0" pos="0 0 0.4" friction="1. .1 .1"/>
      <geom name="scene428" type="mesh" mesh="convex_484" rgba="1 0 0 1.0" pos="0 0 0.4" friction="1. .1 .1"/>
      <geom name="scene429" type="mesh" mesh="convex_485" rgba="1 0 0 1.0" pos="0 0 0.4" friction="1. .1 .1"/>
      <geom name="scene430" type="mesh" mesh="convex_486" rgba="1 0 0 1.0" pos="0 0 0.4" friction="1. .1 .1"/>
      <geom name="scene431" type="mesh" mesh="convex_487" rgba="1 0 0 1.0" pos="0 0 0.4" friction="1. .1 .1"/>
      <geom name="scene432" type="mesh" mesh="convex_488" rgba="1 0 0 1.0" pos="0 0 0.4" friction="1. .1 .1"/>
      <geom name="scene433" type="mesh" mesh="convex_489" rgba="1 0 0 1.0" pos="0 0 0.4" friction="1. .1 .1"/>
      <geom name="scene434" type="mesh" mesh="convex_49" rgba="1 0 0 1.0" pos="0 0 0.4" friction="1. .1 .1"/>
      <geom name="scene435" type="mesh" mesh="convex_490" rgba="1 0 0 1.0" pos="0 0 0.4" friction="1. .1 .1"/>
      <geom name="scene436" type="mesh" mesh="convex_491" rgba="1 0 0 1.0" pos="0 0 0.4" friction="1. .1 .1"/>
      <geom name="scene437" type="mesh" mesh="convex_492" rgba="1 0 0 1.0" pos="0 0 0.4" friction="1. .1 .1"/>
      <geom name="scene438" type="mesh" mesh="convex_493" rgba="1 0 0 1.0" pos="0 0 0.4" friction="1. .1 .1"/>
      <geom name="scene439" type="mesh" mesh="convex_494" rgba="1 0 0 1.0" pos="0 0 0.4" friction="1. .1 .1"/>
      <geom name="scene440" type="mesh" mesh="convex_495" rgba="1 0 0 1.0" pos="0 0 0.4" friction="1. .1 .1"/>
      <geom name="scene441" type="mesh" mesh="convex_496" rgba="1 0 0 1.0" pos="0 0 0.4" friction="1. .1 .1"/>
      <geom name="scene442" type="mesh" mesh="convex_497" rgba="1 0 0 1.0" pos="0 0 0.4" friction="1. .1 .1"/>
      <geom name="scene443" type="mesh" mesh="convex_498" rgba="1 0 0 1.0" pos="0 0 0.4" friction="1. .1 .1"/>
      <geom name="scene444" type="mesh" mesh="convex_499" rgba="1 0 0 1.0" pos="0 0 0.4" friction="1. .1 .1"/>
      <geom name="scene445" type="mesh" mesh="convex_5" rgba="1 0 0 1.0" pos="0 0 0.4" friction="1. .1 .1"/>
      <geom name="scene446" type="mesh" mesh="convex_50" rgba="1 0 0 1.0" pos="0 0 0.4" friction="1. .1 .1"/>
      <geom name="scene447" type="mesh" mesh="convex_500" rgba="1 0 0 1.0" pos="0 0 0.4" friction="1. .1 .1"/>
      <geom name="scene448" type="mesh" mesh="convex_501" rgba="1 0 0 1.0" pos="0 0 0.4" friction="1. .1 .1"/>
      <geom name="scene449" type="mesh" mesh="convex_502" rgba="1 0 0 1.0" pos="0 0 0.4" friction="1. .1 .1"/>
      <geom name="scene450" type="mesh" mesh="convex_503" rgba="1 0 0 1.0" pos="0 0 0.4" friction="1. .1 .1"/>
      <geom name="scene451" type="mesh" mesh="convex_504" rgba="1 0 0 1.0" pos="0 0 0.4" friction="1. .1 .1"/>
      <geom name="scene452" type="mesh" mesh="convex_505" rgba="1 0 0 1.0" pos="0 0 0.4" friction="1. .1 .1"/>
      <geom name="scene453" type="mesh" mesh="convex_506" rgba="1 0 0 1.0" pos="0 0 0.4" friction="1. .1 .1"/>
      <geom name="scene454" type="mesh" mesh="convex_507" rgba="1 0 0 1.0" pos="0 0 0.4" friction="1. .1 .1"/>
      <geom name="scene455" type="mesh" mesh="convex_508" rgba="1 0 0 1.0" pos="0 0 0.4" friction="1. .1 .1"/>
      <geom name="scene456" type="mesh" mesh="convex_509" rgba="1 0 0 1.0" pos="0 0 0.4" friction="1. .1 .1"/>
      <geom name="scene457" type="mesh" mesh="convex_51" rgba="1 0 0 1.0" pos="0 0 0.4" friction="1. .1 .1"/>
      <geom name="scene458" type="mesh" mesh="convex_510" rgba="1 0 0 1.0" pos="0 0 0.4" friction="1. .1 .1"/>
      <geom name="scene459" type="mesh" mesh="convex_511" rgba="1 0 0 1.0" pos="0 0 0.4" friction="1. .1 .1"/>
      <geom name="scene460" type="mesh" mesh="convex_512" rgba="1 0 0 1.0" pos="0 0 0.4" friction="1. .1 .1"/>
      <geom name="scene461" type="mesh" mesh="convex_513" rgba="1 0 0 1.0" pos="0 0 0.4" friction="1. .1 .1"/>
      <geom name="scene462" type="mesh" mesh="convex_514" rgba="1 0 0 1.0" pos="0 0 0.4" friction="1. .1 .1"/>
      <geom name="scene463" type="mesh" mesh="convex_515" rgba="1 0 0 1.0" pos="0 0 0.4" friction="1. .1 .1"/>
      <geom name="scene464" type="mesh" mesh="convex_516" rgba="1 0 0 1.0" pos="0 0 0.4" friction="1. .1 .1"/>
      <geom name="scene465" type="mesh" mesh="convex_517" rgba="1 0 0 1.0" pos="0 0 0.4" friction="1. .1 .1"/>
      <geom name="scene466" type="mesh" mesh="convex_518" rgba="1 0 0 1.0" pos="0 0 0.4" friction="1. .1 .1"/>
      <geom name="scene467" type="mesh" mesh="convex_519" rgba="1 0 0 1.0" pos="0 0 0.4" friction="1. .1 .1"/>
      <geom name="scene468" type="mesh" mesh="convex_52" rgba="1 0 0 1.0" pos="0 0 0.4" friction="1. .1 .1"/>
      <geom name="scene469" type="mesh" mesh="convex_520" rgba="1 0 0 1.0" pos="0 0 0.4" friction="1. .1 .1"/>
      <geom name="scene470" type="mesh" mesh="convex_521" rgba="1 0 0 1.0" pos="0 0 0.4" friction="1. .1 .1"/>
      <geom name="scene471" type="mesh" mesh="convex_522" rgba="1 0 0 1.0" pos="0 0 0.4" friction="1. .1 .1"/>
      <geom name="scene472" type="mesh" mesh="convex_523" rgba="1 0 0 1.0" pos="0 0 0.4" friction="1. .1 .1"/>
      <geom name="scene473" type="mesh" mesh="convex_524" rgba="1 0 0 1.0" pos="0 0 0.4" friction="1. .1 .1"/>
      <geom name="scene474" type="mesh" mesh="convex_525" rgba="1 0 0 1.0" pos="0 0 0.4" friction="1. .1 .1"/>
      <geom name="scene475" type="mesh" mesh="convex_526" rgba="1 0 0 1.0" pos="0 0 0.4" friction="1. .1 .1"/>
      <geom name="scene476" type="mesh" mesh="convex_527" rgba="1 0 0 1.0" pos="0 0 0.4" friction="1. .1 .1"/>
      <geom name="scene477" type="mesh" mesh="convex_528" rgba="1 0 0 1.0" pos="0 0 0.4" friction="1. .1 .1"/>
      <geom name="scene478" type="mesh" mesh="convex_529" rgba="1 0 0 1.0" pos="0 0 0.4" friction="1. .1 .1"/>
      <geom name="scene479" type="mesh" mesh="convex_53" rgba="1 0 0 1.0" pos="0 0 0.4" friction="1. .1 .1"/>
      <geom name="scene480" type="mesh" mesh="convex_530" rgba="1 0 0 1.0" pos="0 0 0.4" friction="1. .1 .1"/>
      <geom name="scene481" type="mesh" mesh="convex_531" rgba="1 0 0 1.0" pos="0 0 0.4" friction="1. .1 .1"/>
      <geom name="scene482" type="mesh" mesh="convex_532" rgba="1 0 0 1.0" pos="0 0 0.4" friction="1. .1 .1"/>
      <geom name="scene483" type="mesh" mesh="convex_533" rgba="1 0 0 1.0" pos="0 0 0.4" friction="1. .1 .1"/>
      <geom name="scene484" type="mesh" mesh="convex_534" rgba="1 0 0 1.0" pos="0 0 0.4" friction="1. .1 .1"/>
      <geom name="scene485" type="mesh" mesh="convex_535" rgba="1 0 0 1.0" pos="0 0 0.4" friction="1. .1 .1"/>
      <geom name="scene486" type="mesh" mesh="convex_536" rgba="1 0 0 1.0" pos="0 0 0.4" friction="1. .1 .1"/>
      <geom name="scene487" type="mesh" mesh="convex_537" rgba="1 0 0 1.0" pos="0 0 0.4" friction="1. .1 .1"/>
      <geom name="scene488" type="mesh" mesh="convex_538" rgba="1 0 0 1.0" pos="0 0 0.4" friction="1. .1 .1"/>
      <geom name="scene489" type="mesh" mesh="convex_539" rgba="1 0 0 1.0" pos="0 0 0.4" friction="1. .1 .1"/>
      <geom name="scene490" type="mesh" mesh="convex_54" rgba="1 0 0 1.0" pos="0 0 0.4" friction="1. .1 .1"/>
      <geom name="scene491" type="mesh" mesh="convex_540" rgba="1 0 0 1.0" pos="0 0 0.4" friction="1. .1 .1"/>
      <geom name="scene492" type="mesh" mesh="convex_541" rgba="1 0 0 1.0" pos="0 0 0.4" friction="1. .1 .1"/>
      <geom name="scene493" type="mesh" mesh="convex_542" rgba="1 0 0 1.0" pos="0 0 0.4" friction="1. .1 .1"/>
      <geom name="scene494" type="mesh" mesh="convex_543" rgba="1 0 0 1.0" pos="0 0 0.4" friction="1. .1 .1"/>
      <geom name="scene495" type="mesh" mesh="convex_544" rgba="1 0 0 1.0" pos="0 0 0.4" friction="1. .1 .1"/>
      <geom name="scene496" type="mesh" mesh="convex_545" rgba="1 0 0 1.0" pos="0 0 0.4" friction="1. .1 .1"/>
      <geom name="scene497" type="mesh" mesh="convex_546" rgba="1 0 0 1.0" pos="0 0 0.4" friction="1. .1 .1"/>
      <geom name="scene498" type="mesh" mesh="convex_547" rgba="1 0 0 1.0" pos="0 0 0.4" friction="1. .1 .1"/>
      <geom name="scene499" type="mesh" mesh="convex_548" rgba="1 0 0 1.0" pos="0 0 0.4" friction="1. .1 .1"/>
      <geom name="scene500" type="mesh" mesh="convex_549" rgba="1 0 0 1.0" pos="0 0 0.4" friction="1. .1 .1"/>
      <geom name="scene501" type="mesh" mesh="convex_55" rgba="1 0 0 1.0" pos="0 0 0.4" friction="1. .1 .1"/>
      <geom name="scene502" type="mesh" mesh="convex_550" rgba="1 0 0 1.0" pos="0 0 0.4" friction="1. .1 .1"/>
      <geom name="scene503" type="mesh" mesh="convex_551" rgba="1 0 0 1.0" pos="0 0 0.4" friction="1. .1 .1"/>
      <geom name="scene504" type="mesh" mesh="convex_552" rgba="1 0 0 1.0" pos="0 0 0.4" friction="1. .1 .1"/>
      <geom name="scene505" type="mesh" mesh="convex_553" rgba="1 0 0 1.0" pos="0 0 0.4" friction="1. .1 .1"/>
      <geom name="scene506" type="mesh" mesh="convex_554" rgba="1 0 0 1.0" pos="0 0 0.4" friction="1. .1 .1"/>
      <geom name="scene507" type="mesh" mesh="convex_555" rgba="1 0 0 1.0" pos="0 0 0.4" friction="1. .1 .1"/>
      <geom name="scene508" type="mesh" mesh="convex_556" rgba="1 0 0 1.0" pos="0 0 0.4" friction="1. .1 .1"/>
      <geom name="scene509" type="mesh" mesh="convex_557" rgba="1 0 0 1.0" pos="0 0 0.4" friction="1. .1 .1"/>
      <geom name="scene510" type="mesh" mesh="convex_558" rgba="1 0 0 1.0" pos="0 0 0.4" friction="1. .1 .1"/>
      <geom name="scene511" type="mesh" mesh="convex_559" rgba="1 0 0 1.0" pos="0 0 0.4" friction="1. .1 .1"/>
      <geom name="scene512" type="mesh" mesh="convex_56" rgba="1 0 0 1.0" pos="0 0 0.4" friction="1. .1 .1"/>
      <geom name="scene513" type="mesh" mesh="convex_560" rgba="1 0 0 1.0" pos="0 0 0.4" friction="1. .1 .1"/>
      <geom name="scene514" type="mesh" mesh="convex_561" rgba="1 0 0 1.0" pos="0 0 0.4" friction="1. .1 .1"/>
      <geom name="scene515" type="mesh" mesh="convex_562" rgba="1 0 0 1.0" pos="0 0 0.4" friction="1. .1 .1"/>
      <geom name="scene516" type="mesh" mesh="convex_563" rgba="1 0 0 1.0" pos="0 0 0.4" friction="1. .1 .1"/>
      <geom name="scene517" type="mesh" mesh="convex_564" rgba="1 0 0 1.0" pos="0 0 0.4" friction="1. .1 .1"/>
      <geom name="scene518" type="mesh" mesh="convex_565" rgba="1 0 0 1.0" pos="0 0 0.4" friction="1. .1 .1"/>
      <geom name="scene519" type="mesh" mesh="convex_566" rgba="1 0 0 1.0" pos="0 0 0.4" friction="1. .1 .1"/>
      <geom name="scene520" type="mesh" mesh="convex_567" rgba="1 0 0 1.0" pos="0 0 0.4" friction="1. .1 .1"/>
      <geom name="scene521" type="mesh" mesh="convex_568" rgba="1 0 0 1.0" pos="0 0 0.4" friction="1. .1 .1"/>
      <geom name="scene522" type="mesh" mesh="convex_569" rgba="1 0 0 1.0" pos="0 0 0.4" friction="1. .1 .1"/>
      <geom name="scene523" type="mesh" mesh="convex_57" rgba="1 0 0 1.0" pos="0 0 0.4" friction="1. .1 .1"/>
      <geom name="scene524" type="mesh" mesh="convex_570" rgba="1 0 0 1.0" pos="0 0 0.4" friction="1. .1 .1"/>
      <geom name="scene525" type="mesh" mesh="convex_571" rgba="1 0 0 1.0" pos="0 0 0.4" friction="1. .1 .1"/>
      <geom name="scene526" type="mesh" mesh="convex_572" rgba="1 0 0 1.0" pos="0 0 0.4" friction="1. .1 .1"/>
      <geom name="scene527" type="mesh" mesh="convex_573" rgba="1 0 0 1.0" pos="0 0 0.4" friction="1. .1 .1"/>
      <geom name="scene528" type="mesh" mesh="convex_574" rgba="1 0 0 1.0" pos="0 0 0.4" friction="1. .1 .1"/>
      <geom name="scene529" type="mesh" mesh="convex_575" rgba="1 0 0 1.0" pos="0 0 0.4" friction="1. .1 .1"/>
      <geom name="scene530" type="mesh" mesh="convex_576" rgba="1 0 0 1.0" pos="0 0 0.4" friction="1. .1 .1"/>
      <geom name="scene531" type="mesh" mesh="convex_577" rgba="1 0 0 1.0" pos="0 0 0.4" friction="1. .1 .1"/>
      <geom name="scene532" type="mesh" mesh="convex_578" rgba="1 0 0 1.0" pos="0 0 0.4" friction="1. .1 .1"/>
      <geom name="scene533" type="mesh" mesh="convex_579" rgba="1 0 0 1.0" pos="0 0 0.4" friction="1. .1 .1"/>
      <geom name="scene534" type="mesh" mesh="convex_58" rgba="1 0 0 1.0" pos="0 0 0.4" friction="1. .1 .1"/>
      <geom name="scene535" type="mesh" mesh="convex_580" rgba="1 0 0 1.0" pos="0 0 0.4" friction="1. .1 .1"/>
      <geom name="scene536" type="mesh" mesh="convex_581" rgba="1 0 0 1.0" pos="0 0 0.4" friction="1. .1 .1"/>
      <geom name="scene537" type="mesh" mesh="convex_582" rgba="1 0 0 1.0" pos="0 0 0.4" friction="1. .1 .1"/>
      <geom name="scene538" type="mesh" mesh="convex_583" rgba="1 0 0 1.0" pos="0 0 0.4" friction="1. .1 .1"/>
      <geom name="scene539" type="mesh" mesh="convex_584" rgba="1 0 0 1.0" pos="0 0 0.4" friction="1. .1 .1"/>
      <geom name="scene540" type="mesh" mesh="convex_585" rgba="1 0 0 1.0" pos="0 0 0.4" friction="1. .1 .1"/>
      <geom name="scene541" type="mesh" mesh="convex_586" rgba="1 0 0 1.0" pos="0 0 0.4" friction="1. .1 .1"/>
      <geom name="scene542" type="mesh" mesh="convex_587" rgba="1 0 0 1.0" pos="0 0 0.4" friction="1. .1 .1"/>
      <geom name="scene543" type="mesh" mesh="convex_588" rgba="1 0 0 1.0" pos="0 0 0.4" friction="1. .1 .1"/>
      <geom name="scene544" type="mesh" mesh="convex_589" rgba="1 0 0 1.0" pos="0 0 0.4" friction="1. .1 .1"/>
      <geom name="scene545" type="mesh" mesh="convex_59" rgba="1 0 0 1.0" pos="0 0 0.4" friction="1. .1 .1"/>
      <geom name="scene546" type="mesh" mesh="convex_590" rgba="1 0 0 1.0" pos="0 0 0.4" friction="1. .1 .1"/>
      <geom name="scene547" type="mesh" mesh="convex_591" rgba="1 0 0 1.0" pos="0 0 0.4" friction="1. .1 .1"/>
      <geom name="scene548" type="mesh" mesh="convex_592" rgba="1 0 0 1.0" pos="0 0 0.4" friction="1. .1 .1"/>
      <geom name="scene549" type="mesh" mesh="convex_593" rgba="1 0 0 1.0" pos="0 0 0.4" friction="1. .1 .1"/>
      <geom name="scene550" type="mesh" mesh="convex_594" rgba="1 0 0 1.0" pos="0 0 0.4" friction="1. .1 .1"/>
      <geom name="scene551" type="mesh" mesh="convex_595" rgba="1 0 0 1.0" pos="0 0 0.4" friction="1. .1 .1"/>
      <geom name="scene552" type="mesh" mesh="convex_596" rgba="1 0 0 1.0" pos="0 0 0.4" friction="1. .1 .1"/>
      <geom name="scene553" type="mesh" mesh="convex_597" rgba="1 0 0 1.0" pos="0 0 0.4" friction="1. .1 .1"/>
      <geom name="scene554" type="mesh" mesh="convex_598" rgba="1 0 0 1.0" pos="0 0 0.4" friction="1. .1 .1"/>
      <geom name="scene555" type="mesh" mesh="convex_599" rgba="1 0 0 1.0" pos="0 0 0.4" friction="1. .1 .1"/>
      <geom name="scene556" type="mesh" mesh="convex_6" rgba="1 0 0 1.0" pos="0 0 0.4" friction="1. .1 .1"/>
      <geom name="scene557" type="mesh" mesh="convex_60" rgba="1 0 0 1.0" pos="0 0 0.4" friction="1. .1 .1"/>
      <geom name="scene558" type="mesh" mesh="convex_600" rgba="1 0 0 1.0" pos="0 0 0.4" friction="1. .1 .1"/>
      <geom name="scene559" type="mesh" mesh="convex_601" rgba="1 0 0 1.0" pos="0 0 0.4" friction="1. .1 .1"/>
      <geom name="scene560" type="mesh" mesh="convex_602" rgba="1 0 0 1.0" pos="0 0 0.4" friction="1. .1 .1"/>
      <geom name="scene561" type="mesh" mesh="convex_603" rgba="1 0 0 1.0" pos="0 0 0.4" friction="1. .1 .1"/>
      <geom name="scene562" type="mesh" mesh="convex_604" rgba="1 0 0 1.0" pos="0 0 0.4" friction="1. .1 .1"/>
      <geom name="scene563" type="mesh" mesh="convex_605" rgba="1 0 0 1.0" pos="0 0 0.4" friction="1. .1 .1"/>
      <geom name="scene564" type="mesh" mesh="convex_606" rgba="1 0 0 1.0" pos="0 0 0.4" friction="1. .1 .1"/>
      <geom name="scene565" type="mesh" mesh="convex_607" rgba="1 0 0 1.0" pos="0 0 0.4" friction="1. .1 .1"/>
      <geom name="scene566" type="mesh" mesh="convex_608" rgba="1 0 0 1.0" pos="0 0 0.4" friction="1. .1 .1"/>
      <geom name="scene567" type="mesh" mesh="convex_609" rgba="1 0 0 1.0" pos="0 0 0.4" friction="1. .1 .1"/>
      <geom name="scene568" type="mesh" mesh="convex_61" rgba="1 0 0 1.0" pos="0 0 0.4" friction="1. .1 .1"/>
      <geom name="scene569" type="mesh" mesh="convex_610" rgba="1 0 0 1.0" pos="0 0 0.4" friction="1. .1 .1"/>
      <geom name="scene570" type="mesh" mesh="convex_611" rgba="1 0 0 1.0" pos="0 0 0.4" friction="1. .1 .1"/>
      <geom name="scene571" type="mesh" mesh="convex_612" rgba="1 0 0 1.0" pos="0 0 0.4" friction="1. .1 .1"/>
      <geom name="scene572" type="mesh" mesh="convex_613" rgba="1 0 0 1.0" pos="0 0 0.4" friction="1. .1 .1"/>
      <geom name="scene573" type="mesh" mesh="convex_614" rgba="1 0 0 1.0" pos="0 0 0.4" friction="1. .1 .1"/>
      <geom name="scene574" type="mesh" mesh="convex_615" rgba="1 0 0 1.0" pos="0 0 0.4" friction="1. .1 .1"/>
      <geom name="scene575" type="mesh" mesh="convex_616" rgba="1 0 0 1.0" pos="0 0 0.4" friction="1. .1 .1"/>
      <geom name="scene576" type="mesh" mesh="convex_617" rgba="1 0 0 1.0" pos="0 0 0.4" friction="1. .1 .1"/>
      <geom name="scene577" type="mesh" mesh="convex_618" rgba="1 0 0 1.0" pos="0 0 0.4" friction="1. .1 .1"/>
      <geom name="scene578" type="mesh" mesh="convex_619" rgba="1 0 0 1.0" pos="0 0 0.4" friction="1. .1 .1"/>
      <geom name="scene579" type="mesh" mesh="convex_62" rgba="1 0 0 1.0" pos="0 0 0.4" friction="1. .1 .1"/>
      <geom name="scene580" type="mesh" mesh="convex_620" rgba="1 0 0 1.0" pos="0 0 0.4" friction="1. .1 .1"/>
      <geom name="scene581" type="mesh" mesh="convex_621" rgba="1 0 0 1.0" pos="0 0 0.4" friction="1. .1 .1"/>
      <geom name="scene582" type="mesh" mesh="convex_622" rgba="1 0 0 1.0" pos="0 0 0.4" friction="1. .1 .1"/>
      <geom name="scene583" type="mesh" mesh="convex_623" rgba="1 0 0 1.0" pos="0 0 0.4" friction="1. .1 .1"/>
      <geom name="scene584" type="mesh" mesh="convex_624" rgba="1 0 0 1.0" pos="0 0 0.4" friction="1. .1 .1"/>
      <geom name="scene585" type="mesh" mesh="convex_625" rgba="1 0 0 1.0" pos="0 0 0.4" friction="1. .1 .1"/>
      <geom name="scene586" type="mesh" mesh="convex_626" rgba="1 0 0 1.0" pos="0 0 0.4" friction="1. .1 .1"/>
      <geom name="scene587" type="mesh" mesh="convex_627" rgba="1 0 0 1.0" pos="0 0 0.4" friction="1. .1 .1"/>
      <geom name="scene588" type="mesh" mesh="convex_628" rgba="1 0 0 1.0" pos="0 0 0.4" friction="1. .1 .1"/>
      <geom name="scene589" type="mesh" mesh="convex_629" rgba="1 0 0 1.0" pos="0 0 0.4" friction="1. .1 .1"/>
      <geom name="scene590" type="mesh" mesh="convex_63" rgba="1 0 0 1.0" pos="0 0 0.4" friction="1. .1 .1"/>
      <geom name="scene591" type="mesh" mesh="convex_630" rgba="1 0 0 1.0" pos="0 0 0.4" friction="1. .1 .1"/>
      <geom name="scene592" type="mesh" mesh="convex_631" rgba="1 0 0 1.0" pos="0 0 0.4" friction="1. .1 .1"/>
      <geom name="scene593" type="mesh" mesh="convex_632" rgba="1 0 0 1.0" pos="0 0 0.4" friction="1. .1 .1"/>
      <geom name="scene594" type="mesh" mesh="convex_633" rgba="1 0 0 1.0" pos="0 0 0.4" friction="1. .1 .1"/>
      <geom name="scene595" type="mesh" mesh="convex_634" rgba="1 0 0 1.0" pos="0 0 0.4" friction="1. .1 .1"/>
      <geom name="scene596" type="mesh" mesh="convex_635" rgba="1 0 0 1.0" pos="0 0 0.4" friction="1. .1 .1"/>
      <geom name="scene597" type="mesh" mesh="convex_636" rgba="1 0 0 1.0" pos="0 0 0.4" friction="1. .1 .1"/>
      <geom name="scene598" type="mesh" mesh="convex_637" rgba="1 0 0 1.0" pos="0 0 0.4" friction="1. .1 .1"/>
      <geom name="scene599" type="mesh" mesh="convex_638" rgba="1 0 0 1.0" pos="0 0 0.4" friction="1. .1 .1"/>
      <geom name="scene600" type="mesh" mesh="convex_639" rgba="1 0 0 1.0" pos="0 0 0.4" friction="1. .1 .1"/>
      <geom name="scene601" type="mesh" mesh="convex_64" rgba="1 0 0 1.0" pos="0 0 0.4" friction="1. .1 .1"/>
      <geom name="scene602" type="mesh" mesh="convex_640" rgba="1 0 0 1.0" pos="0 0 0.4" friction="1. .1 .1"/>
      <geom name="scene603" type="mesh" mesh="convex_641" rgba="1 0 0 1.0" pos="0 0 0.4" friction="1. .1 .1"/>
      <geom name="scene604" type="mesh" mesh="convex_642" rgba="1 0 0 1.0" pos="0 0 0.4" friction="1. .1 .1"/>
      <geom name="scene605" type="mesh" mesh="convex_643" rgba="1 0 0 1.0" pos="0 0 0.4" friction="1. .1 .1"/>
      <geom name="scene606" type="mesh" mesh="convex_644" rgba="1 0 0 1.0" pos="0 0 0.4" friction="1. .1 .1"/>
      <geom name="scene607" type="mesh" mesh="convex_645" rgba="1 0 0 1.0" pos="0 0 0.4" friction="1. .1 .1"/>
      <geom name="scene608" type="mesh" mesh="convex_646" rgba="1 0 0 1.0" pos="0 0 0.4" friction="1. .1 .1"/>
      <geom name="scene609" type="mesh" mesh="convex_647" rgba="1 0 0 1.0" pos="0 0 0.4" friction="1. .1 .1"/>
      <geom name="scene610" type="mesh" mesh="convex_648" rgba="1 0 0 1.0" pos="0 0 0.4" friction="1. .1 .1"/>
      <geom name="scene611" type="mesh" mesh="convex_649" rgba="1 0 0 1.0" pos="0 0 0.4" friction="1. .1 .1"/>
      <geom name="scene612" type="mesh" mesh="convex_65" rgba="1 0 0 1.0" pos="0 0 0.4" friction="1. .1 .1"/>
      <geom name="scene613" type="mesh" mesh="convex_650" rgba="1 0 0 1.0" pos="0 0 0.4" friction="1. .1 .1"/>
      <geom name="scene614" type="mesh" mesh="convex_651" rgba="1 0 0 1.0" pos="0 0 0.4" friction="1. .1 .1"/>
      <geom name="scene615" type="mesh" mesh="convex_652" rgba="1 0 0 1.0" pos="0 0 0.4" friction="1. .1 .1"/>
      <geom name="scene616" type="mesh" mesh="convex_653" rgba="1 0 0 1.0" pos="0 0 0.4" friction="1. .1 .1"/>
      <geom name="scene617" type="mesh" mesh="convex_654" rgba="1 0 0 1.0" pos="0 0 0.4" friction="1. .1 .1"/>
      <geom name="scene618" type="mesh" mesh="convex_655" rgba="1 0 0 1.0" pos="0 0 0.4" friction="1. .1 .1"/>
      <geom name="scene619" type="mesh" mesh="convex_656" rgba="1 0 0 1.0" pos="0 0 0.4" friction="1. .1 .1"/>
      <geom name="scene620" type="mesh" mesh="convex_657" rgba="1 0 0 1.0" pos="0 0 0.4" friction="1. .1 .1"/>
      <geom name="scene621" type="mesh" mesh="convex_658" rgba="1 0 0 1.0" pos="0 0 0.4" friction="1. .1 .1"/>
      <geom name="scene622" type="mesh" mesh="convex_659" rgba="1 0 0 1.0" pos="0 0 0.4" friction="1. .1 .1"/>
      <geom name="scene623" type="mesh" mesh="convex_66" rgba="1 0 0 1.0" pos="0 0 0.4" friction="1. .1 .1"/>
      <geom name="scene624" type="mesh" mesh="convex_660" rgba="1 0 0 1.0" pos="0 0 0.4" friction="1. .1 .1"/>
      <geom name="scene625" type="mesh" mesh="convex_661" rgba="1 0 0 1.0" pos="0 0 0.4" friction="1. .1 .1"/>
      <geom name="scene626" type="mesh" mesh="convex_67" rgba="1 0 0 1.0" pos="0 0 0.4" friction="1. .1 .1"/>
      <geom name="scene627" type="mesh" mesh="convex_68" rgba="1 0 0 1.0" pos="0 0 0.4" friction="1. .1 .1"/>
      <geom name="scene628" type="mesh" mesh="convex_69" rgba="1 0 0 1.0" pos="0 0 0.4" friction="1. .1 .1"/>
      <geom name="scene629" type="mesh" mesh="convex_7" rgba="1 0 0 1.0" pos="0 0 0.4" friction="1. .1 .1"/>
      <geom name="scene630" type="mesh" mesh="convex_70" rgba="1 0 0 1.0" pos="0 0 0.4" friction="1. .1 .1"/>
      <geom name="scene631" type="mesh" mesh="convex_71" rgba="1 0 0 1.0" pos="0 0 0.4" friction="1. .1 .1"/>
      <geom name="scene632" type="mesh" mesh="convex_72" rgba="1 0 0 1.0" pos="0 0 0.4" friction="1. .1 .1"/>
      <geom name="scene633" type="mesh" mesh="convex_73" rgba="1 0 0 1.0" pos="0 0 0.4" friction="1. .1 .1"/>
      <geom name="scene634" type="mesh" mesh="convex_74" rgba="1 0 0 1.0" pos="0 0 0.4" friction="1. .1 .1"/>
      <geom name="scene635" type="mesh" mesh="convex_75" rgba="1 0 0 1.0" pos="0 0 0.4" friction="1. .1 .1"/>
      <geom name="scene636" type="mesh" mesh="convex_76" rgba="1 0 0 1.0" pos="0 0 0.4" friction="1. .1 .1"/>
      <geom name="scene637" type="mesh" mesh="convex_77" rgba="1 0 0 1.0" pos="0 0 0.4" friction="1. .1 .1"/>
      <geom name="scene638" type="mesh" mesh="convex_78" rgba="1 0 0 1.0" pos="0 0 0.4" friction="1. .1 .1"/>
      <geom name="scene639" type="mesh" mesh="convex_79" rgba="1 0 0 1.0" pos="0 0 0.4" friction="1. .1 .1"/>
      <geom name="scene640" type="mesh" mesh="convex_8" rgba="1 0 0 1.0" pos="0 0 0.4" friction="1. .1 .1"/>
      <geom name="scene641" type="mesh" mesh="convex_80" rgba="1 0 0 1.0" pos="0 0 0.4" friction="1. .1 .1"/>
      <geom name="scene642" type="mesh" mesh="convex_81" rgba="1 0 0 1.0" pos="0 0 0.4" friction="1. .1 .1"/>
      <geom name="scene643" type="mesh" mesh="convex_82" rgba="1 0 0 1.0" pos="0 0 0.4" friction="1. .1 .1"/>
      <geom name="scene644" type="mesh" mesh="convex_83" rgba="1 0 0 1.0" pos="0 0 0.4" friction="1. .1 .1"/>
      <geom name="scene645" type="mesh" mesh="convex_84" rgba="1 0 0 1.0" pos="0 0 0.4" friction="1. .1 .1"/>
      <geom name="scene646" type="mesh" mesh="convex_85" rgba="1 0 0 1.0" pos="0 0 0.4" friction="1. .1 .1"/>
      <geom name="scene647" type="mesh" mesh="convex_86" rgba="1 0 0 1.0" pos="0 0 0.4" friction="1. .1 .1"/>
      <geom name="scene648" type="mesh" mesh="convex_87" rgba="1 0 0 1.0" pos="0 0 0.4" friction="1. .1 .1"/>
      <geom name="scene649" type="mesh" mesh="convex_88" rgba="1 0 0 1.0" pos="0 0 0.4" friction="1. .1 .1"/>
      <geom name="scene650" type="mesh" mesh="convex_89" rgba="1 0 0 1.0" pos="0 0 0.4" friction="1. .1 .1"/>
      <geom name="scene651" type="mesh" mesh="convex_9" rgba="1 0 0 1.0" pos="0 0 0.4" friction="1. .1 .1"/>
      <geom name="scene652" type="mesh" mesh="convex_90" rgba="1 0 0 1.0" pos="0 0 0.4" friction="1. .1 .1"/>
      <geom name="scene653" type="mesh" mesh="convex_91" rgba="1 0 0 1.0" pos="0 0 0.4" friction="1. .1 .1"/>
      <geom name="scene654" type="mesh" mesh="convex_92" rgba="1 0 0 1.0" pos="0 0 0.4" friction="1. .1 .1"/>
      <geom name="scene655" type="mesh" mesh="convex_93" rgba="1 0 0 1.0" pos="0 0 0.4" friction="1. .1 .1"/>
      <geom name="scene656" type="mesh" mesh="convex_94" rgba="1 0 0 1.0" pos="0 0 0.4" friction="1. .1 .1"/>
      <geom name="scene657" type="mesh" mesh="convex_95" rgba="1 0 0 1.0" pos="0 0 0.4" friction="1. .1 .1"/>
      <geom name="scene658" type="mesh" mesh="convex_96" rgba="1 0 0 1.0" pos="0 0 0.4" friction="1. .1 .1"/>
      <geom name="scene659" type="mesh" mesh="convex_97" rgba="1 0 0 1.0" pos="0 0 0.4" friction="1. .1 .1"/>
      <geom name="scene660" type="mesh" mesh="convex_98" rgba="1 0 0 1.0" pos="0 0 0.4" friction="1. .1 .1"/>
      <geom name="scene661" type="mesh" mesh="convex_99" rgba="1 0 0 1.0" pos="0 0 0.4" friction="1. .1 .1"/>
    </body>
  </worldbody>
  <actuator>
    <motor name="L_Hip_z" joint="L_Hip_z" gear="1"/>
    <motor name="L_Hip_y" joint="L_Hip_y" gear="1"/>
    <motor name="L_Hip_x" joint="L_Hip_x" gear="1"/>
    <motor name="L_Knee_z" joint="L_Knee_z" gear="1"/>
    <motor name="L_Knee_y" joint="L_Knee_y" gear="1"/>
    <motor name="L_Knee_x" joint="L_Knee_x" gear="1"/>
    <motor name="L_Ankle_z" joint="L_Ankle_z" gear="1"/>
    <motor name="L_Ankle_y" joint="L_Ankle_y" gear="1"/>
    <motor name="L_Ankle_x" joint="L_Ankle_x" gear="1"/>
    <motor name="L_Toe_z" joint="L_Toe_z" gear="1"/>
    <motor name="L_Toe_y" joint="L_Toe_y" gear="1"/>
    <motor name="L_Toe_x" joint="L_Toe_x" gear="1"/>
    <motor name="R_Hip_z" joint="R_Hip_z" gear="1"/>
    <motor name="R_Hip_y" joint="R_Hip_y" gear="1"/>
    <motor name="R_Hip_x" joint="R_Hip_x" gear="1"/>
    <motor name="R_Knee_z" joint="R_Knee_z" gear="1"/>
    <motor name="R_Knee_y" joint="R_Knee_y" gear="1"/>
    <motor name="R_Knee_x" joint="R_Knee_x" gear="1"/>
    <motor name="R_Ankle_z" joint="R_Ankle_z" gear="1"/>
    <motor name="R_Ankle_y" joint="R_Ankle_y" gear="1"/>
    <motor name="R_Ankle_x" joint="R_Ankle_x" gear="1"/>
    <motor name="R_Toe_z" joint="R_Toe_z" gear="1"/>
    <motor name="R_Toe_y" joint="R_Toe_y" gear="1"/>
    <motor name="R_Toe_x" joint="R_Toe_x" gear="1"/>
    <motor name="Torso_z" joint="Torso_z" gear="1"/>
    <motor name="Torso_y" joint="Torso_y" gear="1"/>
    <motor name="Torso_x" joint="Torso_x" gear="1"/>
    <motor name="Spine_z" joint="Spine_z" gear="1"/>
    <motor name="Spine_y" joint="Spine_y" gear="1"/>
    <motor name="Spine_x" joint="Spine_x" gear="1"/>
    <motor name="Chest_z" joint="Chest_z" gear="1"/>
    <motor name="Chest_y" joint="Chest_y" gear="1"/>
    <motor name="Chest_x" joint="Chest_x" gear="1"/>
    <motor name="Neck_z" joint="Neck_z" gear="1"/>
    <motor name="Neck_y" joint="Neck_y" gear="1"/>
    <motor name="Neck_x" joint="Neck_x" gear="1"/>
    <motor name="Head_z" joint="Head_z" gear="1"/>
    <motor name="Head_y" joint="Head_y" gear="1"/>
    <motor name="Head_x" joint="Head_x" gear="1"/>
    <motor name="L_Thorax_z" joint="L_Thorax_z" gear="1"/>
    <motor name="L_Thorax_y" joint="L_Thorax_y" gear="1"/>
    <motor name="L_Thorax_x" joint="L_Thorax_x" gear="1"/>
    <motor name="L_Shoulder_z" joint="L_Shoulder_z" gear="1"/>
    <motor name="L_Shoulder_y" joint="L_Shoulder_y" gear="1"/>
    <motor name="L_Shoulder_x" joint="L_Shoulder_x" gear="1"/>
    <motor name="L_Elbow_z" joint="L_Elbow_z" gear="1"/>
    <motor name="L_Elbow_y" joint="L_Elbow_y" gear="1"/>
    <motor name="L_Elbow_x" joint="L_Elbow_x" gear="1"/>
    <motor name="L_Wrist_z" joint="L_Wrist_z" gear="1"/>
    <motor name="L_Wrist_y" joint="L_Wrist_y" gear="1"/>
    <motor name="L_Wrist_x" joint="L_Wrist_x" gear="1"/>
    <motor name="L_Hand_z" joint="L_Hand_z" gear="1"/>
    <motor name="L_Hand_y" joint="L_Hand_y" gear="1"/>
    <motor name="L_Hand_x" joint="L_Hand_x" gear="1"/>
    <motor name="R_Thorax_z" joint="R_Thorax_z" gear="1"/>
    <motor name="R_Thorax_y" joint="R_Thorax_y" gear="1"/>
    <motor name="R_Thorax_x" joint="R_Thorax_x" gear="1"/>
    <motor name="R_Shoulder_z" joint="R_Shoulder_z" gear="1"/>
    <motor name="R_Shoulder_y" joint="R_Shoulder_y" gear="1"/>
    <motor name="R_Shoulder_x" joint="R_Shoulder_x" gear="1"/>
    <motor name="R_Elbow_z" joint="R_Elbow_z" gear="1"/>
    <motor name="R_Elbow_y" joint="R_Elbow_y" gear="1"/>
    <motor name="R_Elbow_x" joint="R_Elbow_x" gear="1"/>
    <motor name="R_Wrist_z" joint="R_Wrist_z" gear="1"/>
    <motor name="R_Wrist_y" joint="R_Wrist_y" gear="1"/>
    <motor name="R_Wrist_x" joint="R_Wrist_x" gear="1"/>
    <motor name="R_Hand_z" joint="R_Hand_z" gear="1"/>
    <motor name="R_Hand_y" joint="R_Hand_y" gear="1"/>
    <motor name="R_Hand_x" joint="R_Hand_x" gear="1"/>
  </actuator>
</mujoco>