
<mujoco model="humanoid">
  <compiler angle="degree" inertiafromgeom="true" coordinate="global"/>
  <include file="./common/materials.xml"/>
  <visual>
    <headlight ambient=".4 .4 .4" diffuse=".8 .8 .8" specular="0.1 0.1 0.1"/>
    <map znear=".01"/>
    <quality shadowsize="2048"/>
  </visual>
  <default>
    <joint damping="0.0" armature="0.01" stiffness="0.0" limited="true"/>
    <geom conaffinity="7" condim="1" contype="7" margin="0.001" material="self" rgba="0.8 0.6 .4 1"/>
  </default>
  <statistic extent="3" center="0 0 1"/>
  <option timestep="0.00222222222"/>
  <asset>
    <texture type="skybox" file="./common/sky1.png" gridsize="3 4" gridlayout=".U..LFRB.D.." width="8192" height="8192"/>
    <texture builtin="flat" height="1278" mark="cross" markrgb="1 1 1" name="texgeom" random="0.01" rgb1=".8 .6 .4" rgb2=".8 .6 .4" type="cube" width="127"/>
  </asset>
  <worldbody>
    <light cutoff="100" diffuse="1 1 1" dir="-0 0 -1.3" directional="true" exponent="1" pos="0 0 1.3" specular=".1 .1 .1"/>
    <geom condim="3" friction="1. .1 .1" material="grid" name="floor" pos="0 0 0" rgba=".8 .9 .8 1" size="100 100 .2" type="plane"/>
    <body name="Pelvis" pos="0.0000 0.0000 1.0000" user="-0.0001 -0.0251 0.9883" >
      <joint name="Pelvis" pos="0.0000 0.0000 1.0000" limited="false" type="free" armature="0" damping="0" stiffness="0"/>
      <geom size="0.0800" type="sphere" pos="0.0000 0.0000 1.0000" contype="0" conaffinity="1"/>
      <body name="L_Hip" pos="0.0714 -0.0896 0.9920" user="0.1020 -0.4538 0.9853">
        <joint name="L_Hip_z" type="hinge" pos="0.0714 -0.0896 0.9920" axis="0.0000 0.0000 1.0000" range="-180.0000 180.0000"/>
        <joint name="L_Hip_y" type="hinge" pos="0.0714 -0.0896 0.9920" axis="0.0000 1.0000 0.0000" range="-180.0000 180.0000"/>
        <joint name="L_Hip_x" type="hinge" pos="0.0714 -0.0896 0.9920" axis="1.0000 0.0000 0.0000" range="-180.0000 180.0000"/>
        <geom size="0.0430" type="capsule" fromto="0.0730 -0.1095 0.9916 0.1004 -0.4339 0.9856" contype="0" conaffinity="1"/>
        <body name="L_Knee" pos="0.1020 -0.4538 0.9853" user="0.0905 -0.8371 0.9418">
          <joint name="L_Knee_z" type="hinge" pos="0.1020 -0.4538 0.9853" axis="0.0000 0.0000 1.0000" range="-180.0000 180.0000"/>
          <joint name="L_Knee_y" type="hinge" pos="0.1020 -0.4538 0.9853" axis="0.0000 1.0000 0.0000" range="-180.0000 180.0000"/>
          <joint name="L_Knee_x" type="hinge" pos="0.1020 -0.4538 0.9853" axis="1.0000 0.0000 0.0000" range="-180.0000 180.0000"/>
          <geom size="0.0350" type="capsule" fromto="0.1014 -0.4737 0.9830 0.0911 -0.8173 0.9440" contype="0" conaffinity="1"/>
          <body name="L_Ankle" pos="0.0905 -0.8371 0.9418" user="0.1138 -0.8918 1.0561">
            <joint name="L_Ankle_z" type="hinge" pos="0.0905 -0.8371 0.9418" axis="0.0000 0.0000 1.0000" range="-180.0000 180.0000"/>
            <joint name="L_Ankle_y" type="hinge" pos="0.0905 -0.8371 0.9418" axis="0.0000 1.0000 0.0000" range="-180.0000 180.0000"/>
            <joint name="L_Ankle_x" type="hinge" pos="0.0905 -0.8371 0.9418" axis="1.0000 0.0000 0.0000" range="-180.0000 180.0000"/>
            <geom pos="0.0905 -0.8851 1.0118" size="0.0620 0.1000 0.0300" quat="0.7071 -0.7071 -0.0000 -0.0000" type="box" contype="0" conaffinity="1"/>
            <body name="L_Toe" pos="0.1138 -0.8918 1.0561" user="0.1138 -0.8918 1.0561">
              <joint name="L_Toe_z" type="hinge" pos="0.1138 -0.8918 1.0561" axis="0.0000 0.0000 1.0000" range="-180.0000 180.0000"/>
              <joint name="L_Toe_y" type="hinge" pos="0.1138 -0.8918 1.0561" axis="0.0000 1.0000 0.0000" range="-180.0000 180.0000"/>
              <joint name="L_Toe_x" type="hinge" pos="0.1138 -0.8918 1.0561" axis="1.0000 0.0000 0.0000" range="-180.0000 180.0000"/>
              <geom size="0.0200" type="capsule" fromto="0.1138 -0.8918 1.0601 0.1138 -0.8918 1.0521" contype="0" conaffinity="1"/>
            </body>
          </body>
        </body>
      </body>
      <body name="R_Hip" pos="-0.0690 -0.0890 0.9952" user="-0.1052 -0.4596 0.9860">
        <joint name="R_Hip_z" type="hinge" pos="-0.0690 -0.0890 0.9952" axis="0.0000 0.0000 1.0000" range="-180.0000 180.0000"/>
        <joint name="R_Hip_y" type="hinge" pos="-0.0690 -0.0890 0.9952" axis="0.0000 1.0000 0.0000" range="-180.0000 180.0000"/>
        <joint name="R_Hip_x" type="hinge" pos="-0.0690 -0.0890 0.9952" axis="1.0000 0.0000 0.0000" range="-180.0000 180.0000"/>
        <geom size="0.0430" type="capsule" fromto="-0.0710 -0.1089 0.9947 -0.1032 -0.4397 0.9865" contype="0" conaffinity="1"/>
        <body name="R_Knee" pos="-0.1052 -0.4596 0.9860" user="-0.0911 -0.8432 0.9441">
          <joint name="R_Knee_z" type="hinge" pos="-0.1052 -0.4596 0.9860" axis="0.0000 0.0000 1.0000" range="-180.0000 180.0000"/>
          <joint name="R_Knee_y" type="hinge" pos="-0.1052 -0.4596 0.9860" axis="0.0000 1.0000 0.0000" range="-180.0000 180.0000"/>
          <joint name="R_Knee_x" type="hinge" pos="-0.1052 -0.4596 0.9860" axis="1.0000 0.0000 0.0000" range="-180.0000 180.0000"/>
          <geom size="0.0350" type="capsule" fromto="-0.1044 -0.4795 0.9838 -0.0919 -0.8234 0.9463" contype="0" conaffinity="1"/>
          <body name="R_Ankle" pos="-0.0911 -0.8432 0.9441" user="-0.1132 -0.8897 1.0620">
            <joint name="R_Ankle_z" type="hinge" pos="-0.0911 -0.8432 0.9441" axis="0.0000 0.0000 1.0000" range="-180.0000 180.0000"/>
            <joint name="R_Ankle_y" type="hinge" pos="-0.0911 -0.8432 0.9441" axis="0.0000 1.0000 0.0000" range="-180.0000 180.0000"/>
            <joint name="R_Ankle_x" type="hinge" pos="-0.0911 -0.8432 0.9441" axis="1.0000 0.0000 0.0000" range="-180.0000 180.0000"/>
            <geom pos="-0.0911 -0.8892 1.0118" size="0.0620 0.1000 0.0300" quat="0.7071 -0.7071 0.0000 0.0000" type="box" contype="0" conaffinity="1"/>
            <body name="R_Toe" pos="-0.1132 -0.8897 1.0620" user="-0.1132 -0.8897 1.0620">
              <joint name="R_Toe_z" type="hinge" pos="-0.1132 -0.8897 1.0620" axis="0.0000 0.0000 1.0000" range="-180.0000 180.0000"/>
              <joint name="R_Toe_y" type="hinge" pos="-0.1132 -0.8897 1.0620" axis="0.0000 1.0000 0.0000" range="-180.0000 180.0000"/>
              <joint name="R_Toe_x" type="hinge" pos="-0.1132 -0.8897 1.0620" axis="1.0000 0.0000 0.0000" range="-180.0000 180.0000"/>
              <geom size="0.0200" type="capsule" fromto="-0.1132 -0.8897 1.0660 -0.1132 -0.8897 1.0580" contype="0" conaffinity="1"/>
            </body>
          </body>
        </body>
      </body>
      <body name="Torso" pos="-0.0025 0.1033 0.9778" user="0.0011 0.2309 0.9761">
        <joint name="Torso_z" type="hinge" pos="-0.0025 0.1033 0.9778" axis="0.0000 0.0000 1.0000" range="-180.0000 180.0000"/>
        <joint name="Torso_y" type="hinge" pos="-0.0025 0.1033 0.9778" axis="0.0000 1.0000 0.0000" range="-180.0000 180.0000"/>
        <joint name="Torso_x" type="hinge" pos="-0.0025 0.1033 0.9778" axis="1.0000 0.0000 0.0000" range="-180.0000 180.0000"/>
        <geom size="0.0550" type="capsule" fromto="-0.0019 0.1232 0.9775 0.0005 0.2109 0.9764" contype="0" conaffinity="1"/>
        <body name="Spine" pos="0.0011 0.2309 0.9761" user="0.0031 0.2800 1.0040">
          <joint name="Spine_z" type="hinge" pos="0.0011 0.2309 0.9761" axis="0.0000 0.0000 1.0000" range="-180.0000 180.0000"/>
          <joint name="Spine_y" type="hinge" pos="0.0011 0.2309 0.9761" axis="0.0000 1.0000 0.0000" range="-180.0000 180.0000"/>
          <joint name="Spine_x" type="hinge" pos="0.0011 0.2309 0.9761" axis="1.0000 0.0000 0.0000" range="-180.0000 180.0000"/>
          <geom size="0.0510" type="capsule" fromto="0.0018 0.2483 0.9860 0.0024 0.2626 0.9941" contype="0" conaffinity="1"/>
          <body name="Chest" pos="0.0031 0.2800 1.0040" user="0.0019 0.4272 0.9612">
            <joint name="Chest_z" type="hinge" pos="0.0031 0.2800 1.0040" axis="0.0000 0.0000 1.0000" range="-180.0000 180.0000"/>
            <joint name="Chest_y" type="hinge" pos="0.0031 0.2800 1.0040" axis="0.0000 1.0000 0.0000" range="-180.0000 180.0000"/>
            <joint name="Chest_x" type="hinge" pos="0.0031 0.2800 1.0040" axis="1.0000 0.0000 0.0000" range="-180.0000 180.0000"/>
            <geom size="0.0500" type="capsule" fromto="0.0029 0.2992 0.9984 0.0020 0.4080 0.9667" contype="0" conaffinity="1"/>
            <body name="Neck" pos="0.0011 0.4882 0.9542" user="0.0047 0.5506 1.0044">
              <joint name="Neck_z" type="hinge" pos="0.0011 0.4882 0.9542" axis="0.0000 0.0000 1.0000" range="-180.0000 180.0000"/>
              <joint name="Neck_y" type="hinge" pos="0.0011 0.4882 0.9542" axis="0.0000 1.0000 0.0000" range="-180.0000 180.0000"/>
              <joint name="Neck_x" type="hinge" pos="0.0011 0.4882 0.9542" axis="1.0000 0.0000 0.0000" range="-180.0000 180.0000"/>
              <geom size="0.0300" type="capsule" fromto="0.0020 0.5038 0.9667 0.0038 0.5350 0.9919" contype="0" conaffinity="1"/>
              <body name="Head" pos="0.0047 0.5506 1.0044" user="0.0047 0.5506 1.0044">
                <joint name="Head_z" type="hinge" pos="0.0047 0.5506 1.0044" axis="0.0000 0.0000 1.0000" range="-180.0000 180.0000"/>
                <joint name="Head_y" type="hinge" pos="0.0047 0.5506 1.0044" axis="0.0000 1.0000 0.0000" range="-180.0000 180.0000"/>
                <joint name="Head_x" type="hinge" pos="0.0047 0.5506 1.0044" axis="1.0000 0.0000 0.0000" range="-180.0000 180.0000"/>
                <geom size="0.0650" type="capsule" fromto="0.0047 0.5506 1.0084 0.0047 0.5506 1.0004" contype="0" conaffinity="1"/>
              </body>
            </body>
            <body name="L_Thorax" pos="0.0784 0.3978 0.9671" user="0.1637 0.4295 0.9598">
              <joint name="L_Thorax_z" type="hinge" pos="0.0784 0.3978 0.9671" axis="0.0000 0.0000 1.0000" range="-180.0000 180.0000"/>
              <joint name="L_Thorax_y" type="hinge" pos="0.0784 0.3978 0.9671" axis="0.0000 1.0000 0.0000" range="-180.0000 180.0000"/>
              <joint name="L_Thorax_x" type="hinge" pos="0.0784 0.3978 0.9671" axis="1.0000 0.0000 0.0000" range="-180.0000 180.0000"/>
              <geom size="0.0300" type="capsule" fromto="0.0971 0.4047 0.9655 0.1450 0.4226 0.9614" contype="0" conaffinity="1"/>
              <body name="L_Shoulder" pos="0.1637 0.4295 0.9598" user="0.4150 0.4175 0.9323">
                <joint name="L_Shoulder_z" type="hinge" pos="0.1637 0.4295 0.9598" axis="0.0000 0.0000 1.0000" range="-180.0000 180.0000"/>
                <joint name="L_Shoulder_y" type="hinge" pos="0.1637 0.4295 0.9598" axis="0.0000 1.0000 0.0000" range="-180.0000 180.0000"/>
                <joint name="L_Shoulder_x" type="hinge" pos="0.1637 0.4295 0.9598" axis="1.0000 0.0000 0.0000" range="-180.0000 180.0000"/>
                <geom size="0.0300" type="capsule" fromto="0.1836 0.4286 0.9576 0.3951 0.4185 0.9345" contype="0" conaffinity="1"/>
                <body name="L_Elbow" pos="0.4150 0.4175 0.9323" user="0.6530 0.4265 0.9323">
                  <joint name="L_Elbow_z" type="hinge" pos="0.4150 0.4175 0.9323" axis="0.0000 0.0000 1.0000" range="-180.0000 180.0000"/>
                  <joint name="L_Elbow_y" type="hinge" pos="0.4150 0.4175 0.9323" axis="0.0000 1.0000 0.0000" range="-180.0000 180.0000"/>
                  <joint name="L_Elbow_x" type="hinge" pos="0.4150 0.4175 0.9323" axis="1.0000 0.0000 0.0000" range="-180.0000 180.0000"/>
                  <geom size="0.0300" type="capsule" fromto="0.4349 0.4183 0.9323 0.6330 0.4258 0.9323" contype="0" conaffinity="1"/>
                  <body name="L_Wrist" pos="0.6530 0.4265 0.9323" user="0.7326 0.4169 0.9191">
                    <joint name="L_Wrist_z" type="hinge" pos="0.6530 0.4265 0.9323" axis="0.0000 0.0000 1.0000" range="-180.0000 180.0000"/>
                    <joint name="L_Wrist_y" type="hinge" pos="0.6530 0.4265 0.9323" axis="0.0000 1.0000 0.0000" range="-180.0000 180.0000"/>
                    <joint name="L_Wrist_x" type="hinge" pos="0.6530 0.4265 0.9323" axis="1.0000 0.0000 0.0000" range="-180.0000 180.0000"/>
                    <geom size="0.0300" type="capsule" fromto="0.6726 0.4242 0.9291 0.7131 0.4192 0.9224" contype="0" conaffinity="1"/>
                    <body name="L_Hand" pos="0.7326 0.4169 0.9191" user="0.7326 0.4169 0.9191">
                      <joint name="L_Hand_z" type="hinge" pos="0.7326 0.4169 0.9191" axis="0.0000 0.0000 1.0000" range="-180.0000 180.0000"/>
                      <joint name="L_Hand_y" type="hinge" pos="0.7326 0.4169 0.9191" axis="0.0000 1.0000 0.0000" range="-180.0000 180.0000"/>
                      <joint name="L_Hand_x" type="hinge" pos="0.7326 0.4169 0.9191" axis="1.0000 0.0000 0.0000" range="-180.0000 180.0000"/>
                      <geom size="0.0350" type="capsule" fromto="0.7326 0.4169 0.9231 0.7326 0.4169 0.9151" contype="0" conaffinity="1"/>
                    </body>
                  </body>
                </body>
              </body>
            </body>
            <body name="R_Thorax" pos="-0.0739 0.3956 0.9622" user="-0.1631 0.4284 0.9524">
              <joint name="R_Thorax_z" type="hinge" pos="-0.0739 0.3956 0.9622" axis="0.0000 0.0000 1.0000" range="-180.0000 180.0000"/>
              <joint name="R_Thorax_y" type="hinge" pos="-0.0739 0.3956 0.9622" axis="0.0000 1.0000 0.0000" range="-180.0000 180.0000"/>
              <joint name="R_Thorax_x" type="hinge" pos="-0.0739 0.3956 0.9622" axis="1.0000 0.0000 0.0000" range="-180.0000 180.0000"/>
              <geom size="0.0300" type="capsule" fromto="-0.0926 0.4025 0.9601 -0.1445 0.4215 0.9544" contype="0" conaffinity="1"/>
              <body name="R_Shoulder" pos="-0.1631 0.4284 0.9524" user="-0.4091 0.4152 0.9322">
                <joint name="R_Shoulder_z" type="hinge" pos="-0.1631 0.4284 0.9524" axis="0.0000 0.0000 1.0000" range="-180.0000 180.0000"/>
                <joint name="R_Shoulder_y" type="hinge" pos="-0.1631 0.4284 0.9524" axis="0.0000 1.0000 0.0000" range="-180.0000 180.0000"/>
                <joint name="R_Shoulder_x" type="hinge" pos="-0.1631 0.4284 0.9524" axis="1.0000 0.0000 0.0000" range="-180.0000 180.0000"/>
                <geom size="0.0300" type="capsule" fromto="-0.1830 0.4273 0.9507 -0.3892 0.4163 0.9338" contype="0" conaffinity="1"/>
                <body name="R_Elbow" pos="-0.4091 0.4152 0.9322" user="-0.6543 0.4238 0.9287">
                  <joint name="R_Elbow_z" type="hinge" pos="-0.4091 0.4152 0.9322" axis="0.0000 0.0000 1.0000" range="-180.0000 180.0000"/>
                  <joint name="R_Elbow_y" type="hinge" pos="-0.4091 0.4152 0.9322" axis="0.0000 1.0000 0.0000" range="-180.0000 180.0000"/>
                  <joint name="R_Elbow_x" type="hinge" pos="-0.4091 0.4152 0.9322" axis="1.0000 0.0000 0.0000" range="-180.0000 180.0000"/>
                  <geom size="0.0300" type="capsule" fromto="-0.4291 0.4159 0.9319 -0.6343 0.4231 0.9290" contype="0" conaffinity="1"/>
                  <body name="R_Wrist" pos="-0.6543 0.4238 0.9287" user="-0.7347 0.4166 0.9182">
                    <joint name="R_Wrist_z" type="hinge" pos="-0.6543 0.4238 0.9287" axis="0.0000 0.0000 1.0000" range="-180.0000 180.0000"/>
                    <joint name="R_Wrist_y" type="hinge" pos="-0.6543 0.4238 0.9287" axis="0.0000 1.0000 0.0000" range="-180.0000 180.0000"/>
                    <joint name="R_Wrist_x" type="hinge" pos="-0.6543 0.4238 0.9287" axis="1.0000 0.0000 0.0000" range="-180.0000 180.0000"/>
                    <geom size="0.0300" type="capsule" fromto="-0.6741 0.4221 0.9261 -0.7149 0.4184 0.9208" contype="0" conaffinity="1"/>
                    <body name="R_Hand" pos="-0.7347 0.4166 0.9182" user="-0.7347 0.4166 0.9182">
                      <joint name="R_Hand_z" type="hinge" pos="-0.7347 0.4166 0.9182" axis="0.0000 0.0000 1.0000" range="-180.0000 180.0000"/>
                      <joint name="R_Hand_y" type="hinge" pos="-0.7347 0.4166 0.9182" axis="0.0000 1.0000 0.0000" range="-180.0000 180.0000"/>
                      <joint name="R_Hand_x" type="hinge" pos="-0.7347 0.4166 0.9182" axis="1.0000 0.0000 0.0000" range="-180.0000 180.0000"/>
                      <geom size="0.0350" type="capsule" fromto="-0.7347 0.4166 0.9222 -0.7347 0.4166 0.9142" contype="0" conaffinity="1"/>
                    </body>
                  </body>
                </body>
              </body>
            </body>
          </body>
        </body>
      </body>
    </body>
  </worldbody>
  <actuator>
    <motor name="L_Hip_z" joint="L_Hip_z" gear="1"/>
    <motor name="L_Hip_y" joint="L_Hip_y" gear="1"/>
    <motor name="L_Hip_x" joint="L_Hip_x" gear="1"/>
    <motor name="L_Knee_z" joint="L_Knee_z" gear="1"/>
    <motor name="L_Knee_y" joint="L_Knee_y" gear="1"/>
    <motor name="L_Knee_x" joint="L_Knee_x" gear="1"/>
    <motor name="L_Ankle_z" joint="L_Ankle_z" gear="1"/>
    <motor name="L_Ankle_y" joint="L_Ankle_y" gear="1"/>
    <motor name="L_Ankle_x" joint="L_Ankle_x" gear="1"/>
    <motor name="L_Toe_z" joint="L_Toe_z" gear="1"/>
    <motor name="L_Toe_y" joint="L_Toe_y" gear="1"/>
    <motor name="L_Toe_x" joint="L_Toe_x" gear="1"/>
    <motor name="R_Hip_z" joint="R_Hip_z" gear="1"/>
    <motor name="R_Hip_y" joint="R_Hip_y" gear="1"/>
    <motor name="R_Hip_x" joint="R_Hip_x" gear="1"/>
    <motor name="R_Knee_z" joint="R_Knee_z" gear="1"/>
    <motor name="R_Knee_y" joint="R_Knee_y" gear="1"/>
    <motor name="R_Knee_x" joint="R_Knee_x" gear="1"/>
    <motor name="R_Ankle_z" joint="R_Ankle_z" gear="1"/>
    <motor name="R_Ankle_y" joint="R_Ankle_y" gear="1"/>
    <motor name="R_Ankle_x" joint="R_Ankle_x" gear="1"/>
    <motor name="R_Toe_z" joint="R_Toe_z" gear="1"/>
    <motor name="R_Toe_y" joint="R_Toe_y" gear="1"/>
    <motor name="R_Toe_x" joint="R_Toe_x" gear="1"/>
    <motor name="Torso_z" joint="Torso_z" gear="1"/>
    <motor name="Torso_y" joint="Torso_y" gear="1"/>
    <motor name="Torso_x" joint="Torso_x" gear="1"/>
    <motor name="Spine_z" joint="Spine_z" gear="1"/>
    <motor name="Spine_y" joint="Spine_y" gear="1"/>
    <motor name="Spine_x" joint="Spine_x" gear="1"/>
    <motor name="Chest_z" joint="Chest_z" gear="1"/>
    <motor name="Chest_y" joint="Chest_y" gear="1"/>
    <motor name="Chest_x" joint="Chest_x" gear="1"/>
    <motor name="Neck_z" joint="Neck_z" gear="1"/>
    <motor name="Neck_y" joint="Neck_y" gear="1"/>
    <motor name="Neck_x" joint="Neck_x" gear="1"/>
    <motor name="Head_z" joint="Head_z" gear="1"/>
    <motor name="Head_y" joint="Head_y" gear="1"/>
    <motor name="Head_x" joint="Head_x" gear="1"/>
    <motor name="L_Thorax_z" joint="L_Thorax_z" gear="1"/>
    <motor name="L_Thorax_y" joint="L_Thorax_y" gear="1"/>
    <motor name="L_Thorax_x" joint="L_Thorax_x" gear="1"/>
    <motor name="L_Shoulder_z" joint="L_Shoulder_z" gear="1"/>
    <motor name="L_Shoulder_y" joint="L_Shoulder_y" gear="1"/>
    <motor name="L_Shoulder_x" joint="L_Shoulder_x" gear="1"/>
    <motor name="L_Elbow_z" joint="L_Elbow_z" gear="1"/>
    <motor name="L_Elbow_y" joint="L_Elbow_y" gear="1"/>
    <motor name="L_Elbow_x" joint="L_Elbow_x" gear="1"/>
    <motor name="L_Wrist_z" joint="L_Wrist_z" gear="1"/>
    <motor name="L_Wrist_y" joint="L_Wrist_y" gear="1"/>
    <motor name="L_Wrist_x" joint="L_Wrist_x" gear="1"/>
    <motor name="L_Hand_z" joint="L_Hand_z" gear="1"/>
    <motor name="L_Hand_y" joint="L_Hand_y" gear="1"/>
    <motor name="L_Hand_x" joint="L_Hand_x" gear="1"/>
    <motor name="R_Thorax_z" joint="R_Thorax_z" gear="1"/>
    <motor name="R_Thorax_y" joint="R_Thorax_y" gear="1"/>
    <motor name="R_Thorax_x" joint="R_Thorax_x" gear="1"/>
    <motor name="R_Shoulder_z" joint="R_Shoulder_z" gear="1"/>
    <motor name="R_Shoulder_y" joint="R_Shoulder_y" gear="1"/>
    <motor name="R_Shoulder_x" joint="R_Shoulder_x" gear="1"/>
    <motor name="R_Elbow_z" joint="R_Elbow_z" gear="1"/>
    <motor name="R_Elbow_y" joint="R_Elbow_y" gear="1"/>
    <motor name="R_Elbow_x" joint="R_Elbow_x" gear="1"/>
    <motor name="R_Wrist_z" joint="R_Wrist_z" gear="1"/>
    <motor name="R_Wrist_y" joint="R_Wrist_y" gear="1"/>
    <motor name="R_Wrist_x" joint="R_Wrist_x" gear="1"/>
    <motor name="R_Hand_z" joint="R_Hand_z" gear="1"/>
    <motor name="R_Hand_y" joint="R_Hand_y" gear="1"/>
    <motor name="R_Hand_x" joint="R_Hand_x" gear="1"/>
  </actuator>
</mujoco>
